Workbook

Sheet 1850
A2: 1850 | C2: 44197 | D2: 44228 | E2: 44256 | F2: 44286 | G2: 44316 | H2: 44348 | I2: 44379 | J2: 44410 | K2: 44441 | L2: 44470 | M2: 44501 | N2: 44531 | O2: 44562 | P2: voda | Q2: teplo | Y2: spotřeby po měsících
A3: byt č. | C3: prosinec | D3: leden | E3: únor | F3: březen | G3: duben | H3: květen | I3: červen | J3: červenec | K3: srpen | L3: září | M3: říjen | N3: listopad | O3: prosinec | P3: m3 | Q3: GJ | T3: byt | U3: leden | V3: únor | W3: březen | X3: duben | Y3: květen | Z3: červen | AA3: červenec | AB3: srpen | AC3: září | AD3: říjen | AE3: listopad | AF3: prosinec
A4: 1 | B4: vodoměr č. 190834092 | C4: 19.243 | D4: 20.569 | E4: 21.482 | F4: 22.18 | G4: 22.725 | H4: 23.582 | I4: 24.655 | J4: 25.497 | K4: 27.026 | L4: 27.442 | M4: 28.892 | N4: 29.709 | O4: 29.98 | P4: =O4-C4 -> 10.737 | T4: 1 | U4: =D4-C4 -> 1.326 | V4: =E4-D4 -> 0.913 | W4: =F4-E4 -> 0.698 | X4: =G4-F4 -> 0.545 | Y4: =H4-G4 -> 0.857 | Z4: =I4-H4 -> 1.073 | AA4: =J4-I4 -> 0.842 | AB4: =K4-J4 -> 1.529 | ... AF4: =O4-N4 -> 0.271
B5: kalorimetr č. SN 34582391 | C5: 48.868 | D5: 53.714 | E5: 57.69 | F5: 60.988 | G5: 62.63 | H5: 63.173 | I5: 63.396 | J5: 63.591 | K5: 63.827 | L5: 64.019 | M5: 64.939 | N5: 3.392 | O5: 4.385 | Q5: =O5+M5-C5 -> 20.456
A6: 2 | B6: vodoměr č. 190834090 | C6: 237.95 | D6: 257.112 | E6: 273.845 | F6: 290.811 | G6: 307.095 | H6: 322.734 | I6: 336.84 | J6: 344.485 | K6: 358.631 | L6: 372.001 | M6: 389.883 | N6: 405.272 | O6: 419.04 | P6: =O6-C6 -> 181.09 | T6: 2 | U6: =D6-C6 -> 19.162 | V6: =E6-D6 -> 16.733 | W6: =F6-E6 -> 16.966 | X6: =G6-F6 -> 16.284 | Y6: =H6-G6 -> 15.639 | Z6: =I6-H6 -> 14.106 | AA6: =J6-I6 -> 7.645 | AB6: =K6-J6 -> 14.146 | ... AF6: =O6-N6 -> 13.768
B7: kalorimetr č. SN 34582401 | C7: 88.086 | D7: 92.165 | E7: 95.813 | F7: 98.767 | G7: 100.937 | H7: 101.764 | I7: 102.224 | J7: 102.382 | K7: 102.734 | L7: 103.188 | M7: 104.553 | N7: 4.004 | O7: 9.432 | Q7: =O7+M7-C7 -> 25.899
A8: 3 | B8: vodoměr č. 190834097 | C8: 93.175 | D8: 99.538 | E8: 105.403 | F8: 111.275 | G8: 116.824 | H8: 122.66 | I8: 128.11 | J8: 132.844 | K8: 139.125 | L8: 143.265 | M8: 149.19 | N8: 154.308 | O8: 159.808 | P8: =O8-C8 -> 66.633 | T8: 3 | U8: =D8-C8 -> 6.363 | V8: =E8-D8 -> 5.865 | W8: =F8-E8 -> 5.872 | X8: =G8-F8 -> 5.549 | Y8: =H8-G8 -> 5.836 | Z8: =I8-H8 -> 5.45 | AA8: =J8-I8 -> 4.734 | AB8: =K8-J8 -> 6.281 | ... AF8: =O8-N8 -> 5.5
B9: kalorimetr č. SN 34582385 | C9: 72.679 | D9: 76.135 | E9: 79.069 | F9: 81.395 | G9: 83.406 | H9: 84.483 | I9: 84.889 | J9: 85.221 | K9: 85.675 | L9: 86.001 | M9: 87.258 | N9: 2.025 | O9: 5.553 | Q9: =O9+M9-C9 -> 20.132
A10: 4 | B10: vodoměr č. 190834098 | C10: 123.698 | D10: 133.59 | E10: 142.385 | F10: 151.352 | G10: 160.005 | H10: 168.96 | I10: 177.71 | J10: 184.748 | K10: 191.963 | L10: 198.934 | M10: 207.044 | N10: 216.011 | O10: 227.481 | P10: =O10-C10 -> 103.783 | T10: 4 | U10: =D10-C10 -> 9.892 | V10: =E10-D10 -> 8.795 | W10: =F10-E10 -> 8.967 | X10: =G10-F10 -> 8.653 | Y10: =H10-G10 -> 8.955 | Z10: =I10-H10 -> 8.75 | AA10: =J10-I10 -> 7.038 | AB10: =K10-J10 -> 7.215 | ... AF10: =O10-N10 -> 11.47
B11: kalorimetr č. SN 34582414 | C11: 42.203 | D11: 45.034 | E11: 47.509 | F11: 49.363 | G11: 50.789 | H11: 51.732 | I11: 52.345 | J11: 52.837 | K11: 53.439 | L11: 54.022 | M11: 55.071 | N11: 1.728 | O11: 4.205 | Q11: =O11+M11-C11 -> 17.073
A12: 5 | B12: vodoměr č. 190834095 | C12: 88.4 | D12: 93.837 | E12: 100.215 | F12: 106.95 | G12: 113.65 | H12: 120.398 | I12: 127.044 | J12: 134.998 | K12: 141.793 | L12: 148.771 | M12: 156.956 | N12: 165.039 | O12: 170.846 | P12: =O12-C12 -> 82.446 | T12: 5 | U12: =D12-C12 -> 5.437 | V12: =E12-D12 -> 6.378 | W12: =F12-E12 -> 6.735 | X12: =G12-F12 -> 6.7 | Y12: =H12-G12 -> 6.748 | Z12: =I12-H12 -> 6.646 | AA12: =J12-I12 -> 7.954 | AB12: =K12-J12 -> 6.795 | ... AF12: =O12-N12 -> 5.807
B13: kalorimetr č. SN 34582396 | C13: 62.988 | D13: 66.942 | E13: 71.021 | F13: 74.715 | G13: 76.829 | H13: 77.679 | I13: 78.098 | J13: 78.502 | K13: 78.879 | L13: 79.333 | M13: 79.861 | N13: 2.265 | O13: 5.129 | Q13: =O13+M13-C13 -> 22.002
A14: 6 | B14: vodoměr č. 190834099 | C14: 96.983 | D14: 104.33 | E14: 111.02 | F14: 119.217 | G14: 128.008 | H14: 132.552 | I14: 139.608 | J14: 148.201 | K14: 157.169 | L14: 164.735 | M14: 175.025 | N14: 184.606 | O14: 196.918 | P14: =O14-C14 -> 99.935 | T14: 6 | U14: =D14-C14 -> 7.347 | V14: =E14-D14 -> 6.69 | W14: =F14-E14 -> 8.197 | X14: =G14-F14 -> 8.791 | Y14: =H14-G14 -> 4.544 | Z14: =I14-H14 -> 7.056 | AA14: =J14-I14 -> 8.593 | AB14: =K14-J14 -> 8.968 | ... AF14: =O14-N14 -> 12.312
B15: kalorimetr č. SN 34582416 | C15: 92.789 | D15: 98.458 | E15: 103.255 | F15: 107.78 | G15: 110.551 | H15: 111.22 | I15: 111.705 | J15: 112.237 | K15: 112.892 | L15: 115.212 | M15: 116.577 | N15: 4.403 | O15: 9.852 | Q15: =O15+M15-C15 -> 33.64
A16: 7 | B16: vodoměr č. 190834102 | C16: 24.825 | D16: 26.187 | E16: 27.426 | F16: 28.524 | G16: 29.743 | H16: 30.912 | I16: 31.974 | J16: 33.501 | K16: 34.824 | L16: 35.585 | M16: 36.455 | N16: 37.847 | O16: 39.303 | P16: =O16-C16 -> 14.478 | T16: 7 | U16: =D16-C16 -> 1.362 | V16: =E16-D16 -> 1.239 | W16: =F16-E16 -> 1.098 | X16: =G16-F16 -> 1.219 | Y16: =H16-G16 -> 1.169 | Z16: =I16-H16 -> 1.062 | AA16: =J16-I16 -> 1.527 | AB16: =K16-J16 -> 1.323 | ... AF16: =O16-N16 -> 1.456
B17: kalorimetr č. SN 34582423 | C17: 21.853 | D17: 23.088 | E17: 24 | F17: 24.524 | G17: 24.802 | H17: 24.983 | I17: 25.102 | J17: 25.222 | K17: 25.345 | L17: 25.437 | M17: 25.612 | N17: 0.903 | O17: 2.484 | Q17: =O17+M17-C17 -> 6.243
A18: 8 | B18: vodoměr č. 200015742 | C18: 9.28 | D18: 10.861 | E18: 12.649 | F18: 12.709 | G18: 14.239 | H18: 15.866 | I18: 17.724 | J18: 20.257 | K18: 22.173 | L18: 24.832 | M18: 28.429 | N18: 30.744 | O18: 32.864 | P18: =O18-C18 -> 23.584 | T18: 8 | U18: =D18-C18 -> 1.581 | V18: =E18-D18 -> 1.788 | W18: =F18-E18 -> 0.06 | X18: =G18-F18 -> 1.53 | Y18: =H18-G18 -> 1.627 | Z18: =I18-H18 -> 1.858 | AA18: =J18-I18 -> 2.533 | AB18: =K18-J18 -> 1.916 | ... AF18: =O18-N18 -> 2.12
B19: kalorimetr č. SN 34582408 | C19: 65.264 | D19: 67.527 | E19: 69.644 | F19: 69.953 | G19: 70.955 | H19: 71.672 | I19: 71.967 | J19: 72.294 | K19: 72.529 | L19: 73.389 | M19: 75.868 | N19: 2.709 | O19: 6.075 | Q19: =O19+M19-C19 -> 16.679
A20: 9 | B20: vodoměr č. 190834109 | C20: 1.911 | D20: 1.94 | E20: 1.96 | F20: 1.985 | G20: 2.007 | H20: 2.058 | I20: 2.083 | J20: 2.106 | K20: 2.128 | L20: 2.161 | M20: 2.175 | N20: 2.203 | O20: 2.223 | P20: =O20-C20 -> 0.312 | T20: 9 | U20: =D20-C20 -> 0.029 | V20: =E20-D20 -> 0.02 | W20: =F20-E20 -> 0.025 | X20: =G20-F20 -> 0.022 | Y20: =H20-G20 -> 0.051 | Z20: =I20-H20 -> 0.025 | AA20: =J20-I20 -> 0.023 | AB20: =K20-J20 -> 0.022 | ... AF20: =O20-N20 -> 0.02
B21: kalorimetr č. SN 34582410 | C21: 8.213 | D21: 9.231 | E21: 9.78 | F21: 9.989 | G21: 10.189 | H21: 10.389 | I21: 10.548 | J21: 10.708 | K21: 10.877 | L21: 11.045 | M21: 11.245 | N21: 0.19 | O21: 0.387 | Q21: =O21+M21-C21 -> 3.419
A22: 10 | B22: vodoměr č. 191519263 | C22: 101.593 | D22: 108.709 | E22: 115.048 | F22: 121.564 | G22: 129.335 | H22: 137.892 | I22: 144.968 | J22: 150.91 | K22: 156.473 | L22: 163.14 | M22: 171.62 | N22: 179.328 | O22: 186.401 | P22: =O22-C22 -> 84.808 | T22: 10 | U22: =D22-C22 -> 7.116 | V22: =E22-D22 -> 6.339 | W22: =F22-E22 -> 6.516 | X22: =G22-F22 -> 7.771 | Y22: =H22-G22 -> 8.557 | Z22: =I22-H22 -> 7.076 | AA22: =J22-I22 -> 5.942 | AB22: =K22-J22 -> 5.563 | ... AF22: =O22-N22 -> 7.073
B23: kalorimetr č. SN 34582413 | C23: 57.821 | D23: 62.75 | E23: 66.692 | F23: 70.474 | G23: 72.459 | H23: 73.031 | I23: 73.354 | J23: 73.645 | K23: 73.915 | L23: 74.241 | M23: 74.991 | N23: 3.127 | O23: 7.061 | Q23: =O23+M23-C23 -> 24.231
P24: =SUM(P4:P23) -> 667.806 | Q24: =SUM(Q4:Q23) -> 189.774
A25: spol.spotř. | B25: elektroměr č. 18972503 | C25: 73254 | D25: 73470 | E25: 73892 | F25: 74089 | G25: 74303 | H25: 74534 | I25: 74767 | J25: 74985 | K25: 75202 | L25: 75399 | M25: 75635 | N25: 75860 | O25: 76098 | R25: =O25-C25 -> 2844
B26: patní vodoměr č. 190976787 | C26: 952.1 | D26: 1020.5 | E26: 1081.8 | F26: 1144.1 | G26: 1208.2 | H26: 1269.7 | I26: 1329.4 | J26: 1382.7 | K26: 1444 | L26: 1501 | M26: 1572.9 | N26: 1639 | O26: 1705.8 | P26: =O26-C26 -> 753.7
B27: patní kalorimetr č./MWh | C27: 73.33 | D27: 84.23 | E27: 93.5 | F27: 101.03 | G27: 105.98 | H27: 108.15 | I27: 109.34 | J27: 110.29 | K27: 111.73 | L27: 113.46 | M27: 116.46 | N27: 123.87 | O27: 132.72 | Q27: =(O27-C27)*3.6 -> 213.804 | R27: GJ
B28: patní kalorimetr č./kub.m | C28: 2917 | D28: 3302 | E28: 3632 | F28: 3897 | G28: 4064 | H28: 4154 | I28: 4221 | J28: 4275 | K28: 4427 | L28: 4525 | M28: 4633 | N28: 4841 | O28: 5092 | Q28: =O28-C28 -> 2175 | R28: m3
A29: fakturační vodoměr č. 63796 | C29: 11988 | D29: 12374.5 | E29: 12733.1 | F29: 13122.2 | G29: 13481.9 | H29: 13859.3 | I29: 14237.6 | J29: 14571.1 | K29: 14905.5 | L29: 15230.3 | M29: 15608.4 | N29: 15951 | O29: 16304 | P29: =O29-C29 -> 4316
D31: Reklamace - výměna
C32: 8 | D32: 43950 | E32: starý | N32: Odečet vodárny 30.11.2020 | O32: 11538
E33: nový | N33: Dohad 1.12.-31.12.2020 | O33: =C29-O32 -> 450
N34: Odečet vodárny 30.11.2021 | O34: =N29 -> 15951
N35: Dohad 1.12.-31.12.2021 | O35: =O29-N29 -> 353

Sheet 1851
AE1: Vytipování vadných vodoměrů
A2: Nové | B2: 1851 | D2: ='1850'!C2 -> 44197 | E2: ='1850'!D2 -> 44228 | F2: ='1850'!E2 -> 44256 | G2: ='1850'!F2 -> 44286 | H2: ='1850'!G2 -> 44316 | I2: ='1850'!H2 -> 44348 | J2: ='1850'!I2 -> 44379 | K2: ='1850'!J2 -> 44410 | ... P2: ='1850'!O2 -> 44562 | Q2: voda | R2: teplo | Z2: spotřeby po měsících | AH2: loňský
A3: číslování | B3: byt č. | D3: prosinec | E3: leden | F3: únor | G3: březen | H3: duben | I3: květen | J3: červen | K3: červenec | L3: srpen | M3: září | N3: říjen | O3: listopad | P3: prosinec | Q3: m3 | R3: GJ | U3: byt | V3: leden | W3: únor | X3: březen | Y3: duben | Z3: květen | AA3: červen | AB3: červenec | AC3: srpen | AD3: září | AE3: říjen | AF3: listopad | AG3: prosinec | AH3: průměr
A4: 1 | B4: 1 | C4: vodoměr č. 190834116 | D4: 205.567 | E4: 221.547 | F4: 236.764 | G4: 253.94 | H4: 270.5 | I4: 288.37 | J4: 303.361 | K4: 317.472 | L4: 333.694 | M4: 346.717 | N4: 361.688 | O4: 376.035 | P4: 391.196 | Q4: =P4-D4 -> 185.629 | U4: 1 | V4: =E4-D4 -> 15.98 | W4: =F4-E4 -> 15.217 | X4: =G4-F4 -> 17.176 | Y4: =H4-G4 -> 16.56 | Z4: =I4-H4 -> 17.87 | AA4: =J4-I4 -> 14.991 | AB4: =K4-J4 -> 14.111 | AC4: =L4-K4 -> 16.222 | ... AG4: =P4-O4 -> 15.161 | AH4: 11.905222
C5: kalorimetr č. SN 34582402 | D5: 93.112 | E5: 99.188 | F5: 104.513 | G5: 108.546 | H5: 111.529 | I5: 113.271 | J5: 114.033 | K5: 114.635 | L5: 115.237 | M5: 115.515 | N5: 116.202 | O5: 4.51 | P5: 9.87 | R5: =P5+N5-D5 -> 32.96 | U5: xx
A6: 2 | B6: 2 | C6: vodoměr SV č. 190834120 | D6: 72.047 | E6: 80.194 | F6: 88.071 | G6: 95.62 | H6: 103.93 | I6: 112.173 | J6: 122.152 | K6: 128.216 | L6: 134.824 | M6: 138.564 | N6: 138.613 | O6: 139.785 | P6: 143.997 | Q6: =P6-D6 -> 71.95 | U6: 2 | V6: =E6-D6 -> 8.147 | W6: =F6-E6 -> 7.877 | X6: =G6-F6 -> 7.549 | Y6: =H6-G6 -> 8.31 | Z6: =I6-H6 -> 8.243 | AA6: =J6-I6 -> 9.979 | AB6: =K6-J6 -> 6.064 | AC6: =L6-K6 -> 6.608 | ... AG6: =P6-O6 -> 4.212 | AH6: 4.9828889
A7: 2 a 3 | C7: kalorimetr č. SN 34582400 | D7: 175.328 | E7: 183.237 | F7: 190.779 | G7: 196.541 | H7: 200.35 | I7: 203.574 | J7: 205.16 | K7: 206.01 | L7: 207.223 | M7: 208.24 | N7: 210.654 | O7: 4.233 | P7: 11.013 | R7: =P7+N7-D7 -> 46.339 | U7: TV | V7: =V40 -> 4.067 | W7: =W40 -> 3.906 | X7: =X40 -> 4.554 | Y7: =Y40 -> 4.82 | Z7: =Z40 -> 5.119 | AA7: =AA40 -> 4.326 | AB7: =AB40 -> 1.896 | AC7: =AC40 -> 2.732 | ... AG7: =AG40 -> 2.439 | AH7: 4.43
A8: 5 | B8: 3 | C8: vodoměr SV č. 190834093 | D8: 9.729 | E8: 10.536 | F8: 11.245 | G8: 11.844 | H8: 12.409 | I8: 12.977 | J8: 13.463 | K8: 14.055 | L8: 14.589 | M8: 15.232 | N8: 15.92 | O8: 16.668 | P8: 17.464 | Q8: =P8-D8 -> 7.735 | U8: 5 | V8: =E8-D8 -> 0.807 | W8: =F8-E8 -> 0.709 | X8: =G8-F8 -> 0.599 | Y8: =H8-G8 -> 0.565 | Z8: =I8-H8 -> 0.568 | AA8: =J8-I8 -> 0.486 | AB8: =K8-J8 -> 0.592 | AC8: =L8-K8 -> 0.534 | ... AG8: =P8-O8 -> 0.796 | AH8: 0.94022222
A9: 5 a 6 | C9: kalorimetr č. SN 34582398 | D9: 111.321 | E9: 118.476 | F9: 123.894 | G9: 128.438 | H9: 131.98 | I9: 134.658 | J9: 136.071 | K9: 137.443 | L9: 138.471 | M9: 139.598 | N9: 142.494 | O9: 4.752 | P9: 11.368 | R9: =P9+N9-D9 -> 42.541 | U9: TV | V9: =V42 -> 0.616 | W9: =W42 -> 0.481 | X9: =X42 -> 0.471 | Y9: =Y42 -> 0.448 | Z9: =Z42 -> 0.569 | AA9: =AA42 -> 0.424 | AB9: =AB42 -> 0.528 | AC9: =AC42 -> 0.408 | ... AG9: =AG42 -> 0.659 | AH9: 0.37122222
A10: 4 | B10: 4 | C10: vodoměr č. 190834126 | D10: 86.836 | E10: 95.091 | F10: 102.059 | G10: 108.961 | H10: 109.153 | I10: 109.208 | J10: 109.235 | K10: 109.263 | L10: 109.323 | M10: 109.332 | N10: 109.342 | O10: 109.342 | P10: 109.346 | Q10: =P10-D10 -> 22.51 | U10: 4 | V10: =E10-D10 -> 8.255 | W10: =F10-E10 -> 6.968 | X10: =G10-F10 -> 6.902 | Y10: =H10-G10 -> 0.192 | Z10: =I10-H10 -> 0.055 | AA10: =J10-I10 -> 0.027 | AB10: =K10-J10 -> 0.028 | AC10: =L10-K10 -> 0.06 | ... AG10: =P10-O10 -> 0.004 | AH10: 5.9373333
C11: kalorimetr č. SN 34582419 | D11: 17.991 | E11: 19.115 | F11: 19.629 | G11: 20.135 | H11: 20.784 | I11: 20.808 | J11: 20.809 | K11: 20.809 | L11: 20.813 | M11: 20.816 | N11: 20.817 | O11: 0 | P11: 0 | R11: =P11+N11-D11 -> 2.826 | U11: xx
A12: 9 | B12: 5 | C12: vodoměr SV č. 190834122 | D12: 78.604 | E12: 83.889 | F12: 88.397 | G12: 94.781 | H12: 100.684 | I12: 100.768 | J12: 100.786 | K12: 100.878 | L12: 100.878 | M12: 102.689 | N12: 107.645 | O12: 111.189 | P12: 115.676 | Q12: =P12-D12 -> 37.072 | U12: 9 | V12: =E12-D12 -> 5.285 | W12: =F12-E12 -> 4.508 | X12: =G12-F12 -> 6.384 | Y12: =H12-G12 -> 5.903 | Z12: =I12-H12 -> 0.084 | AA12: =J12-I12 -> 0.018 | AB12: =K12-J12 -> 0.092 | AC12: =L12-K12 -> 0 | ... AG12: =P12-O12 -> 4.487 | AH12: 4.7323333
A13: 8 a 9 | C13: kalorimetr č. SN 34582384 | D13: 97.694 | E13: 102.617 | F13: 107.302 | G13: 111.972 | H13: 115.359 | I13: 116.116 | J13: 116.733 | K13: 117.253 | L13: 117.85 | M13: 118.619 | N13: 120.284 | O13: 3.32 | P13: 8.304 | R13: =P13+N13-D13 -> 30.894 | U13: TV | V13: =V44 -> 2.356 | W13: =W44 -> 2.099 | X13: =X44 -> 3.377 | Y13: =Y44 -> 3.065 | Z13: =Z44 -> 0.011 | AA13: =AA44 -> 0.006 | AB13: =AB44 -> 0.128 | AC13: =AC44 -> 0.003 | ... AG13: =AG44 -> 1.967 | AH13: 4.7182222
A14: 15 | B14: 6 | C14: vodoměr SV č. 200015757 | D14: 34.588 | E14: 34.819 | F14: 39.176 | G14: 45.971 | H14: 50.363 | I14: 54.964 | J14: 59.066 | K14: 63.972 | L14: 68.807 | M14: 73.365 | N14: 86.969 | O14: 90.483 | P14: 95.075 | Q14: =P14-D14 -> 60.487 | U14: 15 | V14: =E14-D14 -> 0.231 | W14: =F14-E14 -> 4.357 | X14: =G14-F14 -> 6.795 | Y14: =H14-G14 -> 4.392 | Z14: =I14-H14 -> 4.601 | AA14: =J14-I14 -> 4.102 | AB14: =K14-J14 -> 4.906 | AC14: =L14-K14 -> 4.835 | ... AG14: =P14-O14 -> 4.592 | AH14: 1.6821111
A15: 11 a 15 | C15: kalorimetr č. SN 34582397 | D15: 65.988 | E15: 68.122 | F15: 72.85 | G15: 74.825 | H15: 76.853 | I15: 78.093 | J15: 78.69 | K15: 79.174 | L15: 79.731 | M15: 80.236 | N15: 81.589 | O15: 2.134 | P15: 5.474 | R15: =P15+N15-D15 -> 21.075 | U15: TV | V15: =V46 -> 0.206 | W15: =W46 -> 3.217 | X15: =X46 -> 2.575 | Y15: =Y46 -> 2.86 | Z15: =Z46 -> 2.831 | AA15: =AA46 -> 2.186 | AB15: =AB46 -> 2.295 | AC15: =AC46 -> 2.481 | ... AG15: =AG46 -> 4.121 | AH15: 0.73344444
A16: 7 | B16: 7 | C16: vodoměr č. 190834119 | D16: 99.093 | E16: 106.462 | F16: 113.648 | G16: 119.619 | H16: 125.662 | I16: 131.111 | J16: 136.484 | K16: 139.39 | L16: 142.792 | M16: 147.191 | N16: 153.539 | O16: 159.654 | P16: 167.571 | Q16: =P16-D16 -> 68.478 | U16: 7 | V16: =E16-D16 -> 7.369 | W16: =F16-E16 -> 7.186 | X16: =G16-F16 -> 5.971 | Y16: =H16-G16 -> 6.043 | Z16: =I16-H16 -> 5.449 | AA16: =J16-I16 -> 5.373 | AB16: =K16-J16 -> 2.906 | AC16: =L16-K16 -> 3.402 | ... AG16: =P16-O16 -> 7.917 | AH16: 6.2735556
C17: kalorimetr č. SN 34582417 | D17: 18.508 | E17: 19.118 | F17: 19.738 | G17: 20.202 | H17: 20.645 | I17: 21.059 | J17: 21.429 | K17: 21.61 | L17: 21.871 | M17: 22.145 | N17: 22.574 | O17: 0.453 | P17: 1.141 | R17: =P17+N17-D17 -> 5.207 | U17: xx
A18: 13 | B18: 8 | C18: vodoměr SV č. 190834112 | D18: 48.475 | E18: 52.187 | F18: 54.804 | G18: 58.063 | H18: 61.339 | I18: 64.54 | J18: 65.347 | K18: 67.489 | L18: 70.17 | M18: 74.005 | N18: 77.902 | O18: 80.837 | P18: 81.12 | Q18: =P18-D18 -> 32.645 | U18: 13 | V18: =E18-D18 -> 3.712 | W18: =F18-E18 -> 2.617 | X18: =G18-F18 -> 3.259 | Y18: =H18-G18 -> 3.276 | Z18: =I18-H18 -> 3.201 | AA18: =J18-I18 -> 0.807 | AB18: =K18-J18 -> 2.142 | AC18: =L18-K18 -> 2.681 | ... AG18: =P18-O18 -> 0.283 | AH18: 2.5207778
A19: 12 a 13 | C19: kalorimetr č. SN 34582392 | D19: 105.54 | E19: 113.214 | F19: 119.452 | G19: 125.691 | H19: 130.393 | I19: 132.781 | J19: 133.318 | K19: 134.04 | L19: 135.124 | M19: 137.184 | N19: 140.95 | O19: 5.658 | P19: 10.751 | R19: =P19+N19-D19 -> 46.161 | U19: TV | V19: =V48 -> 2.522 | W19: =W48 -> 1.574 | X19: =X48 -> 2.173 | Y19: =Y48 -> 2.215 | Z19: =Z48 -> 1.648 | AA19: =AA48 -> 0.259 | AB19: =AB48 -> 0.961 | AC19: =AC48 -> 1.236 | ... AG19: =AG48 -> 0.24 | AH19: 1.2623333
A20: 14 | B20: 9 | C20: vodoměr č. 190834124 | D20: 131.206 | E20: 139.015 | F20: 147.416 | G20: 159.326 | H20: 171.807 | I20: 183.642 | J20: 195.663 | K20: 203.739 | L20: 211.599 | M20: 222.487 | N20: 233.54 | O20: 244.477 | P20: 254.696 | Q20: =P20-D20 -> 123.49 | U20: 14 | V20: =E20-D20 -> 7.809 | W20: =F20-E20 -> 8.401 | X20: =G20-F20 -> 11.91 | Y20: =H20-G20 -> 12.481 | Z20: =I20-H20 -> 11.835 | AA20: =J20-I20 -> 12.021 | AB20: =K20-J20 -> 8.076 | AC20: =L20-K20 -> 7.86 | ... AG20: =P20-O20 -> 10.219 | AH20: 6.9983333
C21: kalorimetr č. SN 34582418 | D21: 86.094 | E21: 91.259 | F21: 95.115 | G21: 99.365 | H21: 102.092 | I21: 103.356 | J21: 103.97 | K21: 104.382 | L21: 104.821 | M21: 105.33 | N21: 107.107 | O21: 4.224 | P21: 9.502 | R21: =P21+N21-D21 -> 30.515 | U21: xx
A22: 10 | B22: 10 | C22: vodoměr č. 190834091 | D22: 26.794 | E22: 29.017 | F22: 31.002 | G22: 32.96 | H22: 35.09 | I22: 37.34 | J22: 39.221 | K22: 41.299 | L22: 43.21 | M22: 44.72 | N22: 46.838 | O22: 48.628 | P22: 50.705 | Q22: =P22-D22 -> 23.911 | U22: 10 | V22: =E22-D22 -> 2.223 | W22: =F22-E22 -> 1.985 | X22: =G22-F22 -> 1.958 | Y22: =H22-G22 -> 2.13 | Z22: =I22-H22 -> 2.25 | AA22: =J22-I22 -> 1.881 | AB22: =K22-J22 -> 2.078 | AC22: =L22-K22 -> 1.911 | ... AG22: =P22-O22 -> 2.077 | AH22: 2.9007778
C23: kalorimetr č. SN 34582411 | D23: 55.147 | E23: 58.953 | F23: 62.427 | G23: 64.698 | H23: 65.852 | I23: 66.141 | J23: 66.348 | K23: 66.56 | L23: 66.79 | M23: 67.007 | N23: 67.955 | O23: 2.632 | P23: 6.162 | R23: =P23+N23-D23 -> 18.97 | U23: xx
B24: spol.spotř. | C24: elektroměr č. 2080200096 | D24: 2060 | E24: 2323 | F24: 2905 | G24: 3147 | H24: 3390 | I24: 3642 | J24: 3916 | K24: 4176 | L24: 4423 | M24: 4660 | N24: 4911 | O24: 5165 | P24: 5432 | Q24: =SUM(Q4:Q23)+SUM(Q33:Q49) -> 1143.893 | R24: =SUM(R4:R23) -> 277.488 | S24: =P24-D24 -> 3372 | U24: kWh
C26: patní vodoměr č. 190976791 | D26: 1630.8 | E26: 1748.6 | F26: 1866.3 | G26: 1998.5 | H26: 2113.8 | I26: 2226 | J26: 2322.3 | K26: 2402.7 | L26: 2487.9 | M26: 2568.8 | N26: 2672.9 | O26: 2759.8 | P26: 2853.6 | Q26: =P26-D26 -> 1222.8
C27: patní kalorimetr č. /MWh | D27: 125.62 | E27: 139.98 | F27: 153.15 | G27: 164.24 | H27: 172.68 | I27: 177.9 | J27: 180.92 | K27: 183.55 | L27: 186.38 | M27: 189.4 | N27: 195.31 | O27: 205.15 | P27: 217.78 | R27: =(P27-D27)*3.6 -> 331.776 | S27: GJ
C28: patní kalorimetr č./kub.m | D28: 15982 | E28: 16796 | F28: 17602 | G28: 18338 | H28: 19077 | I28: 19755 | J28: 20350 | K28: 20959 | L28: 22036 | M28: 22389 | N28: 22732 | O28: 23129 | P28: 23652 | R28: =P28-D28 -> 7670 | S28: m3
B29: ='1850'!A29 -> fakturační vodoměr č. 63796 | D29: ='1850'!C29 -> 11988 | E29: ='1850'!D29 -> 12374.5 | F29: ='1850'!E29 -> 12733.1 | G29: ='1850'!F29 -> 13122.2 | H29: ='1850'!G29 -> 13481.9 | I29: ='1850'!H29 -> 13859.3 | J29: ='1850'!I29 -> 14237.6 | K29: ='1850'!J29 -> 14571.1 | ... P29: ='1850'!O29 -> 16304 | Q29: =P29-D29 -> 4316 | V29: studená voda
U31: byt | V31: leden | W31: únor | X31: březen | Y31: duben | Z31: květen | AA31: červen | AB31: červenec | AC31: srpen | AD31: září | AE31: říjen | AF31: listopad | AG31: prosinec
A33: 3 | B33: 2B | C33: vodoměr SV č. 200015745 | D33: 79.952 | E33: 88.199 | F33: 96.154 | G33: 105.308 | H33: 113.576 | I33: 123.185 | J33: 130.92 | K33: 136.807 | L33: 144.653 | M33: 151.214 | N33: 159.786 | O33: 167.129 | P33: 174.759 | Q33: =P33-D33 -> 94.807 | U33: 3 | V33: =E33-D33 -> 8.247 | W33: =F33-E33 -> 7.955 | X33: =G33-F33 -> 9.154 | Y33: =H33-G33 -> 8.268 | Z33: =I33-H33 -> 9.609 | AA33: =J33-I33 -> 7.735 | AB33: =K33-J33 -> 5.887 | AC33: =L33-K33 -> 7.846 | ... AG33: =P33-O33 -> 7.63 | AH33: 7.9723
A34: 6 | B34: 3B | C34: vodoměr SV č. 190834107 | D34: 63.505 | E34: 68.027 | F34: 72.444 | G34: 78.21 | H34: 83.107 | I34: 89.214 | J34: 94.272 | K34: 98.86 | L34: 99.697 | M34: 100.705 | N34: 102.022 | O34: 103.03 | P34: 104.722 | Q34: =P34-D34 -> 41.217 | U34: 6 | V34: =E34-D34 -> 4.522 | W34: =F34-E34 -> 4.417 | X34: =G34-F34 -> 5.766 | Y34: =H34-G34 -> 4.897 | Z34: =I34-H34 -> 6.107 | AA34: =J34-I34 -> 5.058 | AB34: =K34-J34 -> 4.588 | AC34: =L34-K34 -> 0.837 | ... AG34: =P34-O34 -> 1.692 | AH34: 2.9773
A35: 8 | B35: 5B | C35: vodoměr SV č. 190834094 | D35: 96.878 | E35: 105.394 | F35: 113.217 | G35: 121.683 | H35: 126.481 | I35: 132.265 | J35: 138.812 | K35: 144.97 | L35: 152.941 | M35: 159.194 | N35: 166.476 | O35: 172.105 | P35: 177.033 | Q35: =P35-D35 -> 80.155 | U35: 8 | V35: =E35-D35 -> 8.516 | W35: =F35-E35 -> 7.823 | X35: =G35-F35 -> 8.466 | Y35: =H35-G35 -> 4.798 | Z35: =I35-H35 -> 5.784 | AA35: =J35-I35 -> 6.547 | AB35: =K35-J35 -> 6.158 | AC35: =L35-K35 -> 7.971 | ... AG35: =P35-O35 -> 4.928 | AH35: 5.4084
A36: 11 | B36: 6B | C36: vodoměr SV č. 200015744 | D36: 8.147 | E36: 8.744 | F36: 9.217 | G36: 9.435 | H36: 9.99 | I36: 10.343 | J36: 10.952 | K36: 11.449 | L36: 12.278 | M36: 12.466 | N36: 12.736 | O36: 12.914 | P36: 13.701 | Q36: =P36-D36 -> 5.554 | U36: 11 | V36: =E36-D36 -> 0.597 | W36: =F36-E36 -> 0.473 | X36: =G36-F36 -> 0.218 | Y36: =H36-G36 -> 0.555 | Z36: =I36-H36 -> 0.353 | AA36: =J36-I36 -> 0.609 | AB36: =K36-J36 -> 0.497 | AC36: =L36-K36 -> 0.829 | ... AG36: =P36-O36 -> 0.787 | AH36: 0.4723
A37: 12 | B37: 8B | C37: vodoměr SV č. 190834128 | D37: 28.67 | E37: 30.22 | F37: 31.622 | G37: 33.129 | H37: 35.414 | I37: 37.551 | J37: 39.374 | K37: 41.147 | L37: 42.868 | M37: 44.489 | N37: 46.26 | O37: 47.774 | P37: 49.424 | Q37: =P37-D37 -> 20.754 | U37: 12 | V37: =E37-D37 -> 1.55 | W37: =F37-E37 -> 1.402 | X37: =G37-F37 -> 1.507 | Y37: =H37-G37 -> 2.285 | Z37: =I37-H37 -> 2.137 | AA37: =J37-I37 -> 1.823 | AB37: =K37-J37 -> 1.773 | AC37: =L37-K37 -> 1.721 | ... AG37: =P37-O37 -> 1.65 | AH37: 2.1434
C39: VODOMĚRY TEPLÁ VODA | V39: teplá voda
A40: 2 | B40: 2 | C40: vodoměr TUV č. 200105142 | D40: 20.754 | E40: 24.821 | F40: 28.727 | G40: 33.281 | H40: 38.101 | I40: 43.22 | J40: 47.546 | K40: 49.442 | L40: 52.174 | M40: 53.511 | N40: 53.516 | O40: 54.347 | P40: 56.786 | Q40: =P40-D40 -> 36.032 | U40: 2 | V40: =E40-D40 -> 4.067 | W40: =F40-E40 -> 3.906 | X40: =G40-F40 -> 4.554 | Y40: =H40-G40 -> 4.82 | Z40: =I40-H40 -> 5.119 | AA40: =J40-I40 -> 4.326 | AB40: =K40-J40 -> 1.896 | AC40: =L40-K40 -> 2.732 | ... AG40: =P40-O40 -> 2.439 | AH40: 4.0477
A41: 3 | B41: 2B | C41: vodoměr TUV č. 200105133 | D41: 45.661 | E41: 52.39 | F41: 59.452 | G41: 66.645 | H41: 72.841 | I41: 79.726 | J41: 84.369 | K41: 87.31 | L41: 91.296 | M41: 95.538 | N41: 100.689 | O41: 106.248 | P41: 111.664 | Q41: =P41-D41 -> 66.003 | U41: 3 | V41: =E41-D41 -> 6.729 | W41: =F41-E41 -> 7.062 | X41: =G41-F41 -> 7.193 | Y41: =H41-G41 -> 6.196 | Z41: =I41-H41 -> 6.885 | AA41: =J41-I41 -> 4.643 | AB41: =K41-J41 -> 2.941 | AC41: =L41-K41 -> 3.986 | ... AG41: =P41-O41 -> 5.416 | AH41: 4.1811
A42: 5 | B42: 3 | C42: vodoměr TUV č. 190049448 | D42: 6.058 | E42: 6.674 | F42: 7.155 | G42: 7.626 | H42: 8.074 | I42: 8.643 | J42: 9.067 | K42: 9.595 | L42: 10.003 | M42: 10.488 | N42: 11.25 | O42: 11.95 | P42: 12.609 | Q42: =P42-D42 -> 6.551 | U42: 5 | V42: =E42-D42 -> 0.616 | W42: =F42-E42 -> 0.481 | X42: =G42-F42 -> 0.471 | Y42: =H42-G42 -> 0.448 | Z42: =I42-H42 -> 0.569 | AA42: =J42-I42 -> 0.424 | AB42: =K42-J42 -> 0.528 | AC42: =L42-K42 -> 0.408 | ... AG42: =P42-O42 -> 0.659 | AH42: 0.3771
A43: 6 | B43: 3B | C43: vodoměr TUV č. 190049255 | D43: 50.504 | E43: 55.02 | F43: 59.203 | G43: 63.576 | H43: 67.635 | I43: 72.055 | J43: 75.169 | K43: 77.982 | L43: 78.244 | M43: 78.837 | N43: 79.732 | O43: 80.626 | P43: 82.099 | Q43: =P43-D43 -> 31.595 | U43: 6 | V43: =E43-D43 -> 4.516 | W43: =F43-E43 -> 4.183 | X43: =G43-F43 -> 4.373 | Y43: =H43-G43 -> 4.059 | Z43: =I43-H43 -> 4.42 | AA43: =J43-I43 -> 3.114 | AB43: =K43-J43 -> 2.813 | AC43: =L43-K43 -> 0.262 | ... AG43: =P43-O43 -> 1.473 | AH43: 1.5876
A44: 9 | B44: 5 | C44: vodoměr TUV č. 200105131 | D44: 19.951 | E44: 22.307 | F44: 24.406 | G44: 27.783 | H44: 30.848 | I44: 30.859 | J44: 30.865 | K44: 30.993 | L44: 30.996 | M44: 31.652 | N44: 33.675 | O44: 35.288 | P44: 37.255 | Q44: =P44-D44 -> 17.304 | U44: 9 | V44: =E44-D44 -> 2.356 | W44: =F44-E44 -> 2.099 | X44: =G44-F44 -> 3.377 | Y44: =H44-G44 -> 3.065 | Z44: =I44-H44 -> 0.011 | AA44: =J44-I44 -> 0.006 | AB44: =K44-J44 -> 0.128 | AC44: =L44-K44 -> 0.003 | ... AG44: =P44-O44 -> 1.967 | AH44: 4.4403
...

Sheet 1852
A2: 1852 | C2: ='1850'!C2 -> 44197 | D2: ='1850'!D2 -> 44228 | E2: ='1850'!E2 -> 44256 | F2: ='1850'!F2 -> 44286 | G2: ='1850'!G2 -> 44316 | H2: ='1850'!H2 -> 44348 | I2: ='1850'!I2 -> 44379 | J2: ='1850'!J2 -> 44410 | ... O2: ='1850'!O2 -> 44562 | P2: voda | Q2: teplo | Y2: spotřeby po měsících
A3: byt č. | C3: prosinec | D3: leden | E3: únor | F3: březen | G3: duben | H3: květen | I3: červen | J3: červenec | K3: srpen | L3: září | M3: říjen | N3: listopad | O3: prosinec | P3: m3 | Q3: GJ | T3: byt | U3: leden | V3: únor | W3: březen | X3: duben | Y3: květen | Z3: červen | AA3: červenec | AB3: srpen | AC3: září | AD3: říjen | AE3: listopad | AF3: prosinec
A4: 1 | B4: vodoměr č. 190834115 | C4: 187.433 | D4: 199.897 | E4: 210.162 | F4: 220.238 | G4: 231.885 | H4: 243.812 | I4: 255.006 | J4: 265.96 | K4: 276.638 | L4: 287.038 | M4: 297.65 | N4: 307.706 | O4: 317.269 | P4: =O4-C4 -> 129.836 | T4: 1 | U4: =D4-C4 -> 12.464 | V4: =E4-D4 -> 10.265 | W4: =F4-E4 -> 10.076 | X4: =G4-F4 -> 11.647 | Y4: =H4-G4 -> 11.927 | Z4: =I4-H4 -> 11.194 | AA4: =J4-I4 -> 10.954 | AB4: =K4-J4 -> 10.678 | ... AF4: =O4-N4 -> 9.563
B5: kalorimetr č. SN 34582388 | C5: 78.606 | D5: 83.646 | E5: 88.59 | F5: 92.455 | G5: 95.461 | H5: 96.962 | I5: 97.605 | J5: 98.153 | K5: 98.705 | L5: 99.511 | M5: 101.518 | N5: 3.546 | O5: 7.696 | Q5: =O5+M5-C5 -> 30.608
A6: 2 | B6: vodoměr č. 190834121 | C6: 71.705 | D6: 79.867 | E6: 87.301 | F6: 93.336 | G6: 101.476 | H6: 111.487 | I6: 120.575 | J6: 128.309 | K6: 137.054 | L6: 141.254 | M6: 142.56 | N6: 147.208 | O6: 149.209 | P6: =O6-C6 -> 77.504 | T6: 2 | U6: =D6-C6 -> 8.162 | V6: =E6-D6 -> 7.434 | W6: =F6-E6 -> 6.035 | X6: =G6-F6 -> 8.14 | Y6: =H6-G6 -> 10.011 | Z6: =I6-H6 -> 9.088 | AA6: =J6-I6 -> 7.734 | AB6: =K6-J6 -> 8.745 | ... AF6: =O6-N6 -> 2.001
B7: kalorimetr č. SN 34582394 | C7: 58.143 | D7: 60.344 | E7: 62.435 | F7: 63.762 | G7: 64.78 | H7: 65.51 | I7: 65.995 | J7: 66.352 | K7: 66.788 | L7: 67.11 | M7: 67.856 | N7: 2.296 | O7: 4.266 | Q7: =O7+M7-C7 -> 13.979
A8: 3 | B8: vodoměr č. 200015760 | C8: 81.529 | D8: 89.8 | E8: 97.685 | F8: 106.906 | G8: 115.855 | H8: 125.94 | I8: 137.421 | J8: 149.275 | K8: 155.726 | L8: 165.651 | M8: 177.095 | N8: 188.923 | O8: 203.867 | P8: =O8-C8 -> 122.338 | T8: 3 | U8: =D8-C8 -> 8.271 | V8: =E8-D8 -> 7.885 | W8: =F8-E8 -> 9.221 | X8: =G8-F8 -> 8.949 | Y8: =H8-G8 -> 10.085 | Z8: =I8-H8 -> 11.481 | AA8: =J8-I8 -> 11.854 | AB8: =K8-J8 -> 6.451 | ... AF8: =O8-N8 -> 14.944
B9: kalorimetr č. SN 34582389 | C9: 96.054 | D9: 101.778 | E9: 107.323 | F9: 111.677 | G9: 115.169 | H9: 117.837 | I9: 120.017 | J9: 120.776 | K9: 121.233 | L9: 122.292 | M9: 125.583 | N9: 4.568 | O9: 10.111 | Q9: =O9+M9-C9 -> 39.64
A10: 4 | B10: vodoměr č. 190834096 | C10: 164.97 | D10: 180.491 | E10: 193.2 | F10: 206.537 | G10: 220.88 | H10: 233.454 | I10: 244.684 | J10: 248.239 | K10: 254.006 | L10: 266.797 | M10: 283.207 | N10: 296.321 | O10: 310.612 | P10: =O10-C10 -> 145.642 | T10: 4 | U10: =D10-C10 -> 15.521 | V10: =E10-D10 -> 12.709 | W10: =F10-E10 -> 13.337 | X10: =G10-F10 -> 14.343 | Y10: =H10-G10 -> 12.574 | Z10: =I10-H10 -> 11.23 | AA10: =J10-I10 -> 3.555 | AB10: =K10-J10 -> 5.767 | ... AF10: =O10-N10 -> 14.291
B11: kalorimetr č. SN 34582395 | C11: 105.124 | D11: 110.479 | E11: 114.917 | F11: 118.449 | G11: 121.36 | H11: 122.973 | I11: 123.596 | J11: 123.826 | K11: 124.191 | L11: 125.127 | M11: 128.281 | N11: 4.54 | O11: 9.533 | Q11: =O11+M11-C11 -> 32.69
A12: 5 | B12: vodoměr č. 190834110 | C12: 36.779 | D12: 42.789 | E12: 49.701 | F12: 57.395 | G12: 63.68 | H12: 69.968 | I12: 77.5 | J12: 85.466 | K12: 90.525 | L12: 100.222 | M12: 111.409 | N12: 121.996 | O12: 133.155 | P12: =O12-C12 -> 96.376 | T12: 5 | U12: =D12-C12 -> 6.01 | V12: =E12-D12 -> 6.912 | W12: =F12-E12 -> 7.694 | X12: =G12-F12 -> 6.285 | Y12: =H12-G12 -> 6.288 | Z12: =I12-H12 -> 7.532 | AA12: =J12-I12 -> 7.966 | AB12: =K12-J12 -> 5.059 | ... AF12: =O12-N12 -> 11.159
B13: kalorimetr č. SN 34582393 | C13: 21.764 | D13: 24.348 | E13: 26.424 | F13: 27.811 | G13: 28.937 | H13: 29.667 | I13: 30.197 | J13: 30.766 | K13: 31.208 | L13: 32.033 | M13: 33.416 | N13: 1.949 | O13: 4.064 | Q13: =O13+M13-C13 -> 15.716
A14: 6 | B14: vodoměr č. 190834127 | C14: 124.962 | D14: 133.594 | E14: 139.905 | F14: 149.525 | G14: 156.103 | H14: 165.081 | I14: 171.151 | J14: 176.652 | K14: 182.209 | L14: 190.243 | M14: 198.245 | N14: 206.957 | O14: 215.901 | P14: =O14-C14 -> 90.939 | T14: 6 | U14: =D14-C14 -> 8.632 | V14: =E14-D14 -> 6.311 | W14: =F14-E14 -> 9.62 | X14: =G14-F14 -> 6.578 | Y14: =H14-G14 -> 8.978 | Z14: =I14-H14 -> 6.07 | AA14: =J14-I14 -> 5.501 | AB14: =K14-J14 -> 5.557 | ... AF14: =O14-N14 -> 8.944
B15: kalorimetr č. SN 34582399 | C15: 139.772 | D15: 144.765 | E15: 149.124 | F15: 153.187 | G15: 155.784 | H15: 157.529 | I15: 158.489 | J15: 159.309 | K15: 159.919 | L15: 161.127 | M15: 163.696 | N15: 2.713 | O15: 6.688 | Q15: =O15+M15-C15 -> 30.612
A16: 7 | B16: vodoměr č. 190834123 | C16: 17.249 | D16: 17.893 | E16: 18.308 | F16: 18.98 | G16: 19.624 | H16: 20.672 | I16: 21.446 | J16: 23.465 | K16: 25.065 | L16: 25.604 | M16: 26.971 | N16: 28.58 | O16: 29.521 | P16: =O16-C16 -> 12.272 | T16: 7 | U16: =D16-C16 -> 0.644 | V16: =E16-D16 -> 0.415 | W16: =F16-E16 -> 0.672 | X16: =G16-F16 -> 0.644 | Y16: =H16-G16 -> 1.048 | Z16: =I16-H16 -> 0.774 | AA16: =J16-I16 -> 2.019 | AB16: =K16-J16 -> 1.6 | ... AF16: =O16-N16 -> 0.941
B17: kalorimetr č. SN 34582404 | C17: 39.837 | D17: 42.54 | E17: 44.369 | F17: 45.893 | G17: 46.434 | H17: 46.517 | I17: 46.533 | J17: 46.57 | K17: 46.618 | L17: 46.629 | M17: 46.719 | N17: 1.347 | O17: 3.464 | Q17: =O17+M17-C17 -> 10.346
A18: 8 | B18: vodoměr č. 190834118 | C18: 136.449 | D18: 146.323 | E18: 156.518 | F18: 167.766 | G18: 177.691 | H18: 189.343 | I18: 197.173 | J18: 204.762 | K18: 213.5 | L18: 220.531 | M18: 232.347 | N18: 242.121 | O18: 249.053 | P18: =O18-C18 -> 112.604 | T18: 8 | U18: =D18-C18 -> 9.874 | V18: =E18-D18 -> 10.195 | W18: =F18-E18 -> 11.248 | X18: =G18-F18 -> 9.925 | Y18: =H18-G18 -> 11.652 | Z18: =I18-H18 -> 7.83 | AA18: =J18-I18 -> 7.589 | AB18: =K18-J18 -> 8.738 | ... AF18: =O18-N18 -> 6.932
B19: kalorimetr č. SN 34582406 | C19: 54.3 | D19: 58.427 | E19: 61.379 | F19: 63.639 | G19: 65.226 | H19: 66.057 | I19: 66.511 | J19: 66.939 | K19: 67.427 | L19: 67.859 | M19: 68.758 | N19: 2.543 | O19: 5.175 | Q19: =O19+M19-C19 -> 19.633
A20: 9 | B20: vodoměr č. 190834113 | C20: 106.093 | D20: 109.998 | E20: 114.59 | F20: 119.052 | G20: 122.995 | H20: 126.643 | I20: 128.59 | J20: 129.587 | K20: 131.477 | L20: 133.877 | M20: 138.171 | N20: 140.916 | O20: 143.658 | P20: =O20-C20 -> 37.565 | T20: 9 | U20: =D20-C20 -> 3.905 | V20: =E20-D20 -> 4.592 | W20: =F20-E20 -> 4.462 | X20: =G20-F20 -> 3.943 | Y20: =H20-G20 -> 3.648 | Z20: =I20-H20 -> 1.947 | AA20: =J20-I20 -> 0.997 | AB20: =K20-J20 -> 1.89 | ... AF20: =O20-N20 -> 2.742
B21: kalorimetr č. SN 34582405 | C21: 107.631 | D21: 113.954 | E21: 119.379 | F21: 124.312 | G21: 127.787 | H21: 129.475 | I21: 130.122 | J21: 130.518 | K21: 131.075 | L21: 131.83 | M21: 135.275 | N21: 5.76 | O21: 11.394 | Q21: =O21+M21-C21 -> 39.038
A22: 10 | B22: vodoměr č. 190834129 | C22: 107.228 | D22: 116.851 | E22: 125.324 | F22: 134.541 | G22: 143.92 | H22: 152.62 | I22: 160.49 | J22: 166.456 | K22: 173.441 | L22: 179.765 | M22: 185.484 | N22: 193.033 | O22: 199.254 | P22: =O22-C22 -> 92.026 | T22: 10 | U22: =D22-C22 -> 9.623 | V22: =E22-D22 -> 8.473 | W22: =F22-E22 -> 9.217 | X22: =G22-F22 -> 9.379 | Y22: =H22-G22 -> 8.7 | Z22: =I22-H22 -> 7.87 | AA22: =J22-I22 -> 5.966 | AB22: =K22-J22 -> 6.985 | ... AF22: =O22-N22 -> 6.221
B23: kalorimetr č. SN 34582407 | C23: 51.404 | D23: 55.741 | E23: 59.389 | F23: 62.297 | G23: 63.644 | H23: 64.417 | I23: 64.938 | J23: 65.35 | K23: 65.87 | L23: 66.493 | M23: 67.651 | N23: 2.642 | O23: 6.284 | Q23: =O23+M23-C23 -> 22.531
P24: =SUM(P4:P23) -> 917.102 | Q24: =SUM(Q4:Q23) -> 254.793
A25: spol.spotř. | B25: elektroměr č. 2080200097 | C25: 1960 | D25: 2164 | E25: 3386 | F25: 3600 | G25: 3812 | H25: 4024 | I25: 4224 | J25: 4406 | K25: 4622 | L25: 4810 | M25: 4999 | N25: 5191 | O25: 5389 | R25: =O25-C25 -> 3429
B26: patní vodoměr č. 190976792 | C26: 1247.6 | D26: 1346.7 | E26: 1435.1 | F26: 1532.8 | G26: 1626.9 | H26: 1729.4 | I26: 1820.7 | J26: 1897.8 | K26: 1973.9 | L26: 2061.4 | M26: 2160 | N26: 2257.3 | O26: 2353 | P26: =O26-C26 -> 1105.4
B27: patní kalorimetr č./MWh | C27: 94.22 | D27: 106.89 | E27: 117.26 | F27: 125.69 | G27: 131.63 | H27: 134.96 | I27: 136.89 | J27: 137.85 | K27: 139.28 | L27: 140.74 | M27: 145.78 | N27: 154.91 | O27: 165.58 | Q27: =(O27-C27)*3.6 -> 256.896 | R27: GJ
B28: patní kalorimetr č./kub.m | C28: 4874 | D28: 5262 | E28: 5590 | F28: 5845 | G28: 6034 | H28: 6164 | I28: 6280 | J28: 6337 | K28: 6580 | L28: 6667 | M28: 6811 | N28: 7036 | O28: 7312 | Q28: =O28-C28 -> 2438 | R28: m3
A29: ='1850'!A29 -> fakturační vodoměr č. 63796 | C29: ='1850'!C29 -> 11988 | D29: ='1850'!D29 -> 12374.5 | E29: ='1850'!E29 -> 12733.1 | F29: ='1850'!F29 -> 13122.2 | G29: ='1850'!G29 -> 13481.9 | H29: ='1850'!H29 -> 13859.3 | I29: ='1850'!I29 -> 14237.6 | J29: ='1850'!J29 -> 14571.1 | ... O29: ='1850'!O29 -> 16304 | P29: =O29-C29 -> 4316
D31: Reklamace - výměna
C32: 3 | D32: 43950 | E32: starý
E33: nový
D35: Výměna elektroměru
D36: 43956 | E36: starý
E37: nový

Sheet 1853
A2: 1853 | C2: ='1850'!C2 -> 44197 | D2: ='1850'!D2 -> 44228 | E2: ='1850'!E2 -> 44256 | F2: ='1850'!F2 -> 44286 | G2: ='1850'!G2 -> 44316 | H2: ='1850'!H2 -> 44348 | I2: ='1850'!I2 -> 44379 | J2: ='1850'!J2 -> 44410 | ... O2: ='1850'!O2 -> 44562 | P2: Voda | Q2: Teplo | R2: Elektr | Y2: spotřeby po měsících
A3: byt č. | C3: prosinec | D3: leden | E3: únor | F3: březen | G3: duben | H3: květen | I3: červen | J3: červenec | K3: srpen | L3: září | M3: říjen | N3: listopad | O3: prosinec | P3: m3 | Q3: GJ | R3: KWh | T3: byt | U3: leden | V3: únor | W3: březen | X3: duben | Y3: květen | Z3: červen | AA3: červenec | AB3: srpen | AC3: září | AD3: říjen | AE3: listopad | AF3: prosinec
A4: 1 | B4: vodoměr č. 190834100 | C4: 210.134 | D4: 225.19 | E4: 240.626 | F4: 256.469 | G4: 270.571 | H4: 284.837 | I4: 298.902 | J4: 312.34 | K4: 325.859 | L4: 338.55 | M4: 352.808 | N4: 366.434 | O4: 380.509 | P4: =O4-C4 -> 170.375 | T4: 1 | U4: =D4-C4 -> 15.056 | V4: =E4-D4 -> 15.436 | W4: =F4-E4 -> 15.843 | X4: =G4-F4 -> 14.102 | Y4: =H4-G4 -> 14.266 | Z4: =I4-H4 -> 14.065 | AA4: =J4-I4 -> 13.438 | AB4: =K4-J4 -> 13.519 | ... AF4: =O4-N4 -> 14.075
B5: kalorimetr č. SN 34582390 | C5: 124.038 | D5: 129.636 | E5: 135.173 | F5: 139.923 | G5: 143.03 | H5: 144.664 | I5: 145.704 | J5: 146.627 | K5: 147.574 | L5: 148.512 | M5: 150.413 | N5: 3.83 | O5: 9.528 | Q5: =O5+M5-C5 -> 35.903
A6: 2 | B6: vodoměr č. 190906789 | C6: 116.709 | D6: 124.707 | E6: 133.277 | F6: 141.498 | G6: 151.197 | H6: 158.655 | I6: 166.783 | J6: 174.839 | K6: 183.011 | L6: 189.59 | M6: 196.961 | N6: 204.595 | O6: 212.804 | P6: =O6-C6 -> 96.095 | T6: 2 | U6: =D6-C6 -> 7.998 | V6: =E6-D6 -> 8.57 | W6: =F6-E6 -> 8.221 | X6: =G6-F6 -> 9.699 | Y6: =H6-G6 -> 7.458 | Z6: =I6-H6 -> 8.128 | AA6: =J6-I6 -> 8.056 | AB6: =K6-J6 -> 8.172 | ... AF6: =O6-N6 -> 8.209
B7: kalorimetr č. SN 34582422 | C7: 38.301 | D7: 39.968 | E7: 41.662 | F7: 43.007 | G7: 43.882 | H7: 44.483 | I7: 45.036 | J7: 45.562 | K7: 46.125 | L7: 46.657 | M7: 47.343 | N7: 1.121 | O7: 2.426 | Q7: =O7+M7-C7 -> 11.468
A8: 3 | B8: vodoměr č. 190906786 | C8: 35.335 | D8: 39.35 | E8: 42.505 | F8: 46.641 | G8: 50.573 | H8: 55.072 | I8: 59.553 | J8: 65.588 | K8: 73.323 | L8: 78.349 | M8: 82.464 | N8: 88.016 | O8: 93.933 | P8: =O8-C8 -> 58.598 | T8: 3 | U8: =D8-C8 -> 4.015 | V8: =E8-D8 -> 3.155 | W8: =F8-E8 -> 4.136 | X8: =G8-F8 -> 3.932 | Y8: =H8-G8 -> 4.499 | Z8: =I8-H8 -> 4.481 | AA8: =J8-I8 -> 6.035 | AB8: =K8-J8 -> 7.735 | ... AF8: =O8-N8 -> 5.917
B9: kalorimetr č. SN 34582386 | C9: 26.764 | D9: 31.255 | E9: 35.56 | F9: 38.966 | G9: 41.159 | H9: 41.925 | I9: 42.117 | J9: 42.323 | K9: 42.585 | L9: 42.898 | M9: 44.365 | N9: 2.709 | O9: 6.53 | Q9: =O9+M9-C9 -> 24.131
A10: 4 | B10: vodoměr č. 190834105 | C10: 87.347 | D10: 94.292 | E10: 100.373 | F10: 108.311 | G10: 108.345 | H10: 111.922 | I10: 116.917 | J10: 119.674 | K10: 125.285 | L10: 130.503 | M10: 136.102 | N10: 140.904 | O10: 146.769 | P10: =O10-C10 -> 59.422 | T10: 4 | U10: =D10-C10 -> 6.945 | V10: =E10-D10 -> 6.081 | W10: =F10-E10 -> 7.938 | X10: =G10-F10 -> 0.034 | Y10: =H10-G10 -> 3.577 | Z10: =I10-H10 -> 4.995 | AA10: =J10-I10 -> 2.757 | AB10: =K10-J10 -> 5.611 | ... AF10: =O10-N10 -> 5.865
B11: kalorimetr č. SN 34582421 | C11: 53.181 | D11: 56.515 | E11: 59.626 | F11: 61.732 | G11: 61.78 | H11: 62.009 | I11: 62.276 | J11: 62.399 | K11: 62.639 | L11: 63 | M11: 63.785 | N11: 1.663 | O11: 3.388 | Q11: =O11+M11-C11 -> 13.992
A12: 5 | B12: vodoměr č. 190906792 | C12: 129.352 | D12: 138.891 | E12: 146.336 | F12: 154.096 | G12: 162.636 | H12: 170.83 | I12: 179.159 | J12: 187.258 | K12: 195.175 | L12: 202.595 | M12: 210.844 | N12: 218.331 | O12: 226.914 | P12: =O12-C12 -> 97.562 | T12: 5 | U12: =D12-C12 -> 9.539 | V12: =E12-D12 -> 7.445 | W12: =F12-E12 -> 7.76 | X12: =G12-F12 -> 8.54 | Y12: =H12-G12 -> 8.194 | Z12: =I12-H12 -> 8.329 | AA12: =J12-I12 -> 8.099 | AB12: =K12-J12 -> 7.917 | ... AF12: =O12-N12 -> 8.583
B13: kalorimetr č. SN 34582387 | C13: 47.354 | D13: 49.682 | E13: 51.607 | F13: 53.193 | G13: 54.327 | H13: 54.922 | I13: 55.247 | J13: 55.539 | K13: 55.839 | L13: 56.212 | M13: 57.074 | N13: 1.455 | O13: 3.187 | Q13: =O13+M13-C13 -> 12.907
A14: 6 | B14: vodoměr č. 190906795 | C14: 70.472 | D14: 76.082 | E14: 80.361 | F14: 85.261 | G14: 89.975 | H14: 95.404 | I14: 98.632 | J14: 103.698 | K14: 107.937 | L14: 112.042 | M14: 117.073 | N14: 121.721 | O14: 126.237 | P14: =O14-C14 -> 55.765 | T14: 6 | U14: =D14-C14 -> 5.61 | V14: =E14-D14 -> 4.279 | W14: =F14-E14 -> 4.9 | X14: =G14-F14 -> 4.714 | Y14: =H14-G14 -> 5.429 | Z14: =I14-H14 -> 3.228 | AA14: =J14-I14 -> 5.066 | AB14: =K14-J14 -> 4.239 | ... AF14: =O14-N14 -> 4.516
B15: kalorimetr č. SN 34582420 | C15: 61.159 | D15: 63.315 | E15: 65.273 | F15: 66.837 | G15: 67.699 | H15: 68.052 | I15: 68.129 | J15: 68.219 | K15: 68.313 | L15: 68.415 | M15: 69.275 | N15: 2.491 | O15: 5.642 | Q15: =O15+M15-C15 -> 13.758
A16: 7 | B16: vodoměr č. 190834103 | C16: 153.776 | D16: 165.57 | E16: 176.528 | F16: 188.613 | G16: 199.702 | H16: 211.688 | I16: 221.085 | J16: 228.757 | K16: 238.38 | L16: 249.268 | M16: 262.98 | N16: 275.76 | O16: 287.97 | P16: =O16-C16 -> 134.194 | T16: 7 | U16: =D16-C16 -> 11.794 | V16: =E16-D16 -> 10.958 | W16: =F16-E16 -> 12.085 | X16: =G16-F16 -> 11.089 | Y16: =H16-G16 -> 11.986 | Z16: =I16-H16 -> 9.397 | AA16: =J16-I16 -> 7.672 | AB16: =K16-J16 -> 9.623 | ... AF16: =O16-N16 -> 12.21
B17: kalorimetr č. SN 34582412 | C17: 65.016 | D17: 69.919 | E17: 73.881 | F17: 77.087 | G17: 79.644 | H17: 81.213 | I17: 81.8 | J17: 82.25 | K17: 82.84 | L17: 83.639 | M17: 86.055 | N17: 4.144 | O17: 8.727 | Q17: =O17+M17-C17 -> 29.766
A18: 8 | B18: vodoměr č. 190834101 | C18: 100.621 | D18: 109.833 | E18: 116.945 | F18: 124.578 | G18: 132.565 | H18: 139.819 | I18: 146.527 | J18: 152.428 | K18: 157.722 | L18: 163.689 | M18: 170.613 | N18: 176.929 | O18: 184.437 | P18: =O18-C18 -> 83.816 | T18: 8 | U18: =D18-C18 -> 9.212 | V18: =E18-D18 -> 7.112 | W18: =F18-E18 -> 7.633 | X18: =G18-F18 -> 7.987 | Y18: =H18-G18 -> 7.254 | Z18: =I18-H18 -> 6.708 | AA18: =J18-I18 -> 5.901 | AB18: =K18-J18 -> 5.294 | ... AF18: =O18-N18 -> 7.508
B19: kalorimetr č. SN 34582403 | C19: 51.585 | D19: 56.377 | E19: 60.377 | F19: 63.328 | G19: 65.052 | H19: 65.661 | I19: 65.96 | J19: 66.223 | K19: 66.547 | L19: 66.872 | M19: 68.136 | N19: 3.331 | O19: 6.768 | Q19: =O19+M19-C19 -> 23.319
A20: 9 | B20: vodoměr č. 190834108 | C20: 56.467 | D20: 60.734 | E20: 64.62 | F20: 68.852 | G20: 72.319 | H20: 76.583 | I20: 80.779 | J20: 84.338 | K20: 88.07 | L20: 91.677 | M20: 95.506 | N20: 99.525 | O20: 103.436 | P20: =O20-C20 -> 46.969 | T20: 9 | U20: =D20-C20 -> 4.267 | V20: =E20-D20 -> 3.886 | W20: =F20-E20 -> 4.232 | X20: =G20-F20 -> 3.467 | Y20: =H20-G20 -> 4.264 | Z20: =I20-H20 -> 4.196 | AA20: =J20-I20 -> 3.559 | AB20: =K20-J20 -> 3.732 | ... AF20: =O20-N20 -> 3.911
B21: kalorimetr č. SN 34582409 | C21: 72.237 | D21: 76.583 | E21: 79.713 | F21: 82.199 | G21: 83.504 | H21: 84.088 | I21: 84.429 | J21: 84.721 | K21: 85.035 | L21: 85.367 | M21: 86.295 | N21: 2.659 | O21: 6.771 | Q21: =O21+M21-C21 -> 20.829
A22: 10 | B22: vodoměr č. 190906953 | C22: 76.907 | D22: 83.498 | E22: 89.534 | F22: 95.228 | G22: 99.579 | H22: 103.456 | I22: 107.555 | J22: 112.803 | K22: 116.072 | L22: 119.57 | M22: 123.563 | N22: 126.08 | O22: 129.324 | P22: =O22-C22 -> 52.417 | T22: 10 | U22: =D22-C22 -> 6.591 | V22: =E22-D22 -> 6.036 | W22: =F22-E22 -> 5.694 | X22: =G22-F22 -> 4.351 | Y22: =H22-G22 -> 3.877 | Z22: =I22-H22 -> 4.099 | AA22: =J22-I22 -> 5.248 | AB22: =K22-J22 -> 3.269 | ... AF22: =O22-N22 -> 3.244
B23: kalorimetr č. SN 34582415 | C23: 74.498 | D23: 78.33 | E23: 81.408 | F23: 83.832 | G23: 85.174 | H23: 85.695 | I23: 85.804 | J23: 85.953 | K23: 86.039 | L23: 86.147 | M23: 87.257 | N23: 2.898 | O23: 7.357 | Q23: =O23+M23-C23 -> 20.116
B24: elektroměr č.2080200105 dům | C24: 1993 | D24: 2177 | E24: 2343 | F24: 2552 | G24: 2727 | H24: 2922 | I24: 3122 | J24: 3295 | K24: 3480 | L24: 3646 | M24: 3827 | N24: 4003 | O24: 4181 | P24: =SUM(P4:P23) -> 855.213 | Q24: =SUM(Q4:Q23) -> 206.189 | R24: =O24-C24 -> 2188
A25: spol.spotř. | B25: elektroměr č. 2080200100 VO | C25: 2654 | D25: 3101 | E25: 3442 | F25: 3764 | G25: 4047 | H25: 4312 | I25: 4551 | J25: 4791 | K25: 5066 | L25: 5356 | M25: 5702 | N25: 6093 | O25: 6580 | R25: =O25-C25 -> 3926 | T25: Zahrada | U25: =D26-C26 -> 0 | V25: =E26-D26 -> 0 | W25: =F26-E26 -> 0 | X25: =G26-F26 -> 0.005 | Y25: =H26-G26 -> 6.695 | Z25: =I26-H26 -> 31.899 | AA25: =J26-I26 -> 24.052 | AB25: =K26-J26 -> 14.408 | ... AF25: =O26-N26 -> 0
B26: vodoměr areál č.200076532 | C26: 227.235 | D26: 227.235 | E26: 227.235 | F26: 227.235 | G26: 227.24 | H26: 233.935 | I26: 265.834 | J26: 289.886 | K26: 304.294 | L26: 313.422 | M26: 318.911 | N26: 318.911 | O26: 318.911 | P26: =O26-C26 -> 91.676 | Q26: =ROUND(P26,0) -> 92 | R26: zahrada
B27: patní vodoměr č. 190976789 | C27: 1315 | D27: 1403.9 | E27: 1484.5 | F27: 1570.9 | G27: 1645.5 | H27: 1729.5 | I27: 1834.9 | J27: 1930.6 | K27: 2020.8 | L27: 2101.2 | M27: 2188.3 | N27: 2263.9 | O27: 2345.2 | P27: =O27-C27 -> 1030.2 | Q27: =P27-Q26 -> 938.2 | R27: byty
B28: patní kalorimetr č./ MWh | C28: 86.8 | D28: 98.56 | E28: 108.85 | F28: 117.21 | G28: 122.54 | H28: 125.79 | I28: 127.8 | J28: 129.67 | K28: 131.61 | L28: 133.51 | M28: 137.6 | N28: 145.3 | O28: 155.36 | Q28: =(O28-C28)*3.6 -> 246.816 | R28: GJ
B29: patní kalorimetr č. /kub.m | C29: 7965 | D29: 8353 | E29: 8727 | F29: 9078 | G29: 9380 | H29: 9715 | I29: 10051 | J29: 10392 | K29: 10934 | L29: 11114 | M29: 11279 | N29: 11484 | O29: 11759 | Q29: =O29-C29 -> 3794 | R29: m3
A30: ='1850'!A29 -> fakturační vodoměr č. 63796 | C30: ='1850'!C29 -> 11988 | D30: ='1850'!D29 -> 12374.5 | E30: ='1850'!E29 -> 12733.1 | F30: ='1850'!F29 -> 13122.2 | G30: ='1850'!G29 -> 13481.9 | H30: ='1850'!H29 -> 13859.3 | I30: ='1850'!I29 -> 14237.6 | J30: ='1850'!J29 -> 14571.1 | ... O30: ='1850'!O29 -> 16304 | P30: =O30-C30 -> 4316
A32: 11 | B32: vodoměr SV č. 11717149 | C32: 4.74 | D32: 5.1 | E32: 5.339 | F32: 5.742 | G32: 6.121 | H32: 6.517 | I32: 6.949 | J32: 7.26 | K32: 7.743 | L32: 8.114 | M32: 8.541 | N32: 8.965 | O32: 9.369 | P32: =O32-C32 -> 4.629 | S32: SV | T32: 11 | U32: =D32-C32 -> 0.36 | V32: =E32-D32 -> 0.239 | W32: =F32-E32 -> 0.403 | X32: =G32-F32 -> 0.379 | Y32: =H32-G32 -> 0.396 | Z32: =I32-H32 -> 0.432 | AA32: =J32-I32 -> 0.311 | AB32: =K32-J32 -> 0.483 | ... AF32: =O32-N32 -> 0.404
B33: vodoměr TV č. 11683196 | C33: 0.199 | D33: 0.206 | E33: 0.206 | F33: 0.229 | G33: 0.27 | H33: 0.309 | I33: 0.318 | J33: 0.322 | K33: 0.336 | L33: 0.359 | M33: 0.387 | N33: 0.565 | O33: 0.594 | P33: =O33-C33 -> 0.395 | S33: TV | U33: =D33-C33 -> 0.007 | V33: =E33-D33 -> 0 | W33: =F33-E33 -> 0.023 | X33: =G33-F33 -> 0.041 | Y33: =H33-G33 -> 0.039 | Z33: =I33-H33 -> 0.009 | AA33: =J33-I33 -> 0.004 | AB33: =K33-J33 -> 0.014 | ... AF33: =O33-N33 -> 0.029
D35: Výměna elektroměru DŮM
D36: 43956 | E36: starý
E37: nový
D38: Výměna elektroměru AREÁL
D39: 43956 | E39: starý
E40: nový

Sheet 1854
A2: 1854 | C2: ='1850'!C2 -> 44197 | D2: ='1850'!D2 -> 44228 | E2: ='1850'!E2 -> 44256 | F2: ='1850'!F2 -> 44286 | G2: ='1850'!G2 -> 44316 | H2: ='1850'!H2 -> 44348 | I2: ='1850'!I2 -> 44379 | J2: ='1850'!J2 -> 44410 | ... O2: ='1850'!O2 -> 44562 | P2: voda | Q2: teplo | Y2: spotřeby po měsících
A3: byt č. | C3: prosinec | D3: leden | E3: únor | F3: březen | G3: duben | H3: květen | I3: červen | J3: červenec | K3: srpen | L3: září | M3: říjen | N3: listopad | O3: prosinec | P3: m3 | Q3: GJ | T3: byt | U3: leden | V3: únor | W3: březen | X3: duben | Y3: květen | Z3: červen | AA3: červenec | AB3: srpen | AC3: září | AD3: říjen | AE3: listopad | AF3: prosinec
A4: 1 | B4: vodoměr č. 190906992 | C4: 108.296 | D4: 117.934 | E4: 126.371 | F4: 137.142 | G4: 143.573 | H4: 151.368 | I4: 156.891 | J4: 160.635 | K4: 163.498 | L4: 170.96 | M4: 178.415 | N4: 186.131 | O4: 190.77 | P4: =O4-C4 -> 82.474 | T4: 1 | U4: =D4-C4 -> 9.638 | V4: =E4-D4 -> 8.437 | W4: =F4-E4 -> 10.771 | X4: =G4-F4 -> 6.431 | Y4: =H4-G4 -> 7.795 | Z4: =I4-H4 -> 5.523 | AA4: =J4-I4 -> 3.744 | AB4: =K4-J4 -> 2.863 | ... AF4: =O4-N4 -> 4.639
B5: kalorimetr č. SN 34672835 | C5: 55.873 | D5: 60.559 | E5: 64.612 | F5: 68.171 | G5: 70.575 | H5: 71.722 | I5: 72.07 | J5: 72.355 | K5: 72.598 | L5: 73.034 | M5: 74.463 | N5: 2.815 | O5: 6.792 | Q5: =O5+M5-C5 -> 25.382
A6: 2 | B6: vodoměr č. 190906991 | C6: 69.331 | D6: 74.159 | E6: 78.521 | F6: 82.637 | G6: 86.875 | H6: 92.6 | I6: 98.445 | J6: 103.959 | K6: 108.19 | L6: 114.812 | M6: 119.841 | N6: 125.586 | O6: 130.154 | P6: =O6-C6 -> 60.823 | T6: 2 | U6: =D6-C6 -> 4.828 | V6: =E6-D6 -> 4.362 | W6: =F6-E6 -> 4.116 | X6: =G6-F6 -> 4.238 | Y6: =H6-G6 -> 5.725 | Z6: =I6-H6 -> 5.845 | AA6: =J6-I6 -> 5.514 | AB6: =K6-J6 -> 4.231 | ... AF6: =O6-N6 -> 4.568
B7: kalorimetr č. SN 34672801 | C7: 120 | D7: 126.143 | E7: 131.767 | F7: 136.237 | G7: 139.338 | H7: 141.115 | I7: 141.519 | J7: 141.944 | K7: 142.28 | L7: 142.834 | M7: 144.521 | N7: 3.892 | O7: 9.411 | Q7: =O7+M7-C7 -> 33.932
A8: 3 | B8: vodoměr č. 190906988 | C8: 101.518 | D8: 108.332 | E8: 115.323 | F8: 122.072 | G8: 128.964 | H8: 136.831 | I8: 145.719 | J8: 153.25 | K8: 161.731 | L8: 168.763 | M8: 175.987 | N8: 182.694 | O8: 190.74 | P8: =O8-C8 -> 89.222 | T8: 3 | U8: =D8-C8 -> 6.814 | V8: =E8-D8 -> 6.991 | W8: =F8-E8 -> 6.749 | X8: =G8-F8 -> 6.892 | Y8: =H8-G8 -> 7.867 | Z8: =I8-H8 -> 8.888 | AA8: =J8-I8 -> 7.531 | AB8: =K8-J8 -> 8.481 | ... AF8: =O8-N8 -> 8.046
B9: kalorimetr č. SN 34672802 | C9: 120.421 | D9: 126.754 | E9: 132.548 | F9: 137.481 | G9: 142.241 | H9: 145.103 | I9: 145.403 | J9: 145.632 | K9: 146.189 | L9: 146.878 | M9: 149.519 | N9: 5.197 | O9: 11.59 | Q9: =O9+M9-C9 -> 40.688
A10: 4 | B10: vodoměr č. 190906987 | C10: 70.198 | D10: 74.825 | E10: 78.216 | F10: 81.361 | G10: 84.888 | H10: 89.821 | I10: 93.737 | J10: 97.617 | K10: 101.234 | L10: 105.38 | M10: 110.009 | N10: 116.852 | O10: 125.285 | P10: =O10-C10 -> 55.087 | T10: 4 | U10: =D10-C10 -> 4.627 | V10: =E10-D10 -> 3.391 | W10: =F10-E10 -> 3.145 | X10: =G10-F10 -> 3.527 | Y10: =H10-G10 -> 4.933 | Z10: =I10-H10 -> 3.916 | AA10: =J10-I10 -> 3.88 | AB10: =K10-J10 -> 3.617 | ... AF10: =O10-N10 -> 8.433
B11: kalorimetr č. SN 69067316 | C11: 50.563 | D11: 53.796 | E11: 55.883 | F11: 57.771 | G11: 59.018 | H11: 60.432 | I11: 60.804 | J11: 61.1 | K11: 61.431 | L11: 61.774 | M11: 62.689 | N11: 1.801 | O11: 3.734 | Q11: =O11+M11-C11 -> 15.86
A12: 5 | B12: vodoměr č. 190907002 | C12: 0.351 | D12: 0.351 | E12: 0.394 | F12: 0.394 | G12: 0.4 | H12: 0.406 | I12: 0.433 | J12: 0.433 | K12: 0.446 | L12: 0.459 | M12: 0.488 | N12: 0.49 | O12: 0.5 | P12: =O12-C12 -> 0.149 | T12: 5 | U12: =D12-C12 -> 0 | V12: =E12-D12 -> 0.043 | W12: =F12-E12 -> 0 | X12: =G12-F12 -> 0.006 | Y12: =H12-G12 -> 0.006 | Z12: =I12-H12 -> 0.027 | AA12: =J12-I12 -> 0 | AB12: =K12-J12 -> 0.013 | ... AF12: =O12-N12 -> 0.01
B13: kalorimetr č. SN 34672814 | C13: 16.744 | D13: 16.796 | E13: 17.823 | F13: 17.957 | G13: 18.128 | H13: 18.295 | I13: 18.423 | J13: 18.549 | K13: 18.68 | L13: 18.812 | M13: 19.756 | N13: 1.535 | O13: 1.731 | Q13: =O13+M13-C13 -> 4.743
A14: 6 | B14: vodoměr č. 190906994 | C14: 141.535 | D14: 151.572 | E14: 160.361 | F14: 169.755 | G14: 171.005 | H14: 176.65 | I14: 184.177 | J14: 191.534 | K14: 200.078 | L14: 208.774 | M14: 216.67 | N14: 225.03 | O14: 233.669 | P14: =O14-C14 -> 92.134 | T14: 6 | U14: =D14-C14 -> 10.037 | V14: =E14-D14 -> 8.789 | W14: =F14-E14 -> 9.394 | X14: =G14-F14 -> 1.25 | Y14: =H14-G14 -> 5.645 | Z14: =I14-H14 -> 7.527 | AA14: =J14-I14 -> 7.357 | AB14: =K14-J14 -> 8.544 | ... AF14: =O14-N14 -> 8.639
B15: kalorimetr č. SN 34672815 | C15: 78.857 | D15: 81.945 | E15: 84.348 | F15: 86.491 | G15: 86.881 | H15: 87.32 | I15: 87.792 | J15: 88.196 | K15: 88.596 | L15: 89.095 | M15: 89.723 | N15: 1.079 | O15: 2.625 | Q15: =O15+M15-C15 -> 13.491
A16: 7 | B16: vodoměr č. 190906986 | C16: 51.225 | D16: 55.634 | E16: 59.594 | F16: 63.799 | G16: 67.823 | H16: 71.991 | I16: 76.224 | J16: 80.807 | K16: 85.22 | L16: 89.017 | M16: 92.745 | N16: 97.034 | O16: 101.134 | P16: =O16-C16 -> 49.909 | T16: 7 | U16: =D16-C16 -> 4.409 | V16: =E16-D16 -> 3.96 | W16: =F16-E16 -> 4.205 | X16: =G16-F16 -> 4.024 | Y16: =H16-G16 -> 4.168 | Z16: =I16-H16 -> 4.233 | AA16: =J16-I16 -> 4.583 | AB16: =K16-J16 -> 4.413 | ... AF16: =O16-N16 -> 4.1
B17: kalorimetr č. SN 34672806 | C17: 19.596 | D17: 20.82 | E17: 21.83 | F17: 22.48 | G17: 23.085 | H17: 23.53 | I17: 23.831 | J17: 24.163 | K17: 24.644 | L17: 25.091 | M17: 25.625 | N17: 0.875 | O17: 2.488 | Q17: =O17+M17-C17 -> 8.517
A18: 8 | B18: vodoměr č. 191519281 | C18: 90.085 | D18: 97.705 | E18: 104.86 | F18: 112.267 | G18: 119.468 | H18: 127.056 | I18: 133.733 | J18: 140.574 | K18: 146.238 | L18: 152.066 | M18: 160.083 | N18: 167.194 | O18: 175.044 | P18: =O18-C18 -> 84.959 | T18: 8 | U18: =D18-C18 -> 7.62 | V18: =E18-D18 -> 7.155 | W18: =F18-E18 -> 7.407 | X18: =G18-F18 -> 7.201 | Y18: =H18-G18 -> 7.588 | Z18: =I18-H18 -> 6.677 | AA18: =J18-I18 -> 6.841 | AB18: =K18-J18 -> 5.664 | ... AF18: =O18-N18 -> 7.85
B19: kalorimetr č. SN 34672809 | C19: 99.643 | D19: 106.394 | E19: 112.071 | F19: 116.555 | G19: 119.253 | H19: 120.688 | I19: 121.152 | J19: 121.586 | K19: 121.979 | L19: 122.392 | M19: 124.129 | N19: 3.865 | O19: 9.78 | Q19: =O19+M19-C19 -> 34.266
A20: 9 | B20: vodoměr č. 190906990 | C20: 180.181 | D20: 194.155 | E20: 205.785 | F20: 218.926 | G20: 232.15 | H20: 245.726 | I20: 257.798 | J20: 269.32 | K20: 279.292 | L20: 289.528 | M20: 301.174 | N20: 314.489 | O20: 327.76 | P20: =O20-C20 -> 147.579 | T20: 9 | U20: =D20-C20 -> 13.974 | V20: =E20-D20 -> 11.63 | W20: =F20-E20 -> 13.141 | X20: =G20-F20 -> 13.224 | Y20: =H20-G20 -> 13.576 | Z20: =I20-H20 -> 12.072 | AA20: =J20-I20 -> 11.522 | AB20: =K20-J20 -> 9.972 | ... AF20: =O20-N20 -> 13.271
B21: kalorimetr č. SN 34672804 | C21: 115.847 | D21: 122.559 | E21: 127.787 | F21: 132.051 | G21: 135.375 | H21: 136.67 | I21: 137.322 | J21: 137.963 | K21: 138.598 | L21: 139.292 | M21: 141.213 | N21: 4.265 | O21: 9.923 | Q21: =O21+M21-C21 -> 35.289
A22: 10 | B22: vodoměr č. 190906995 | C22: 0.239 | D22: 0.243 | E22: 0.246 | F22: 0.249 | G22: 0.253 | H22: 0.259 | I22: 0.271 | J22: 0.279 | K22: 0.285 | L22: 0.302 | M22: 0.321 | N22: 0.325 | O22: 0.325 | P22: =O22-C22 -> 0.086 | T22: 10 | U22: =D22-C22 -> 0.004 | V22: =E22-D22 -> 0.003 | W22: =F22-E22 -> 0.003 | X22: =G22-F22 -> 0.004 | Y22: =H22-G22 -> 0.006 | Z22: =I22-H22 -> 0.012 | AA22: =J22-I22 -> 0.008 | AB22: =K22-J22 -> 0.006 | ... AF22: =O22-N22 -> 0
B23: kalorimetr č. SN 34672829 | C23: 1.417 | D23: 1.434 | E23: 1.458 | F23: 1.485 | G23: 1.519 | H23: 1.572 | I23: 1.6 | J23: 1.618 | K23: 1.658 | L23: 1.707 | M23: 1.768 | N23: 0 | O23: 0.004 | Q23: =O23+M23-C23 -> 0.355
P24: =SUM(P4:P23) -> 662.422 | Q24: =SUM(Q4:Q23) -> 212.523
A25: spol.spotř. | B25: elektroměr č. 72370871 | C25: 50228 | D25: 50474 | E25: 50709 | F25: 50963 | G25: 51152 | H25: 51366 | I25: 51586 | J25: 51782 | K25: 51995 | L25: 52184 | M25: 52363 | N25: 52545 | O25: 52736 | R25: =O25-C25 -> 2508
B26: patní vodoměr č. 190976793 | C26: 896.1 | D26: 963 | E26: 1022.8 | F26: 1086.8 | G26: 1138.3 | H26: 1200.4 | I26: 1260.9 | J26: 1316.5 | K26: 1368.7 | L26: 1427.7 | M26: 1487.9 | N26: 1553.4 | O26: 1618.4 | P26: =O26-C26 -> 722.3
B27: patní kalorimetr č. 70465263/ GJ | C27: 90.5 | D27: 130.9 | E27: 165.97 | F27: 194.05 | G27: 213.76 | H27: 225.19 | I27: 228.65 | J27: 231.7 | K27: 236.36 | L27: 240.08 | M27: 252.41 | N27: 279.14 | O27: 313.67 | Q27: =O27-C27 -> 223.17 | R27: GJ
B28: patní kalorimetr č. / kub.m | C28: 787 | D28: 1134 | E28: 1418 | F28: 1660 | G28: 1822 | H28: 1923 | I28: 1973 | J28: 2017 | K28: 2171 | L28: 2230 | M28: 2321 | N28: 2498 | O28: 2751 | Q28: =O28-C28 -> 1964 | R28: m3
A29: Fakturační vodoměr: 42012114941 | C29: 1085 | D29: 1404.3 | E29: 1696 | F29: 2013.8 | G29: 2336.4 | H29: 2664.8 | I29: 2958.3 | J29: 3200.4 | K29: 3449.5 | L29: 3713.1 | M29: 4002.8 | N29: 4300 | O29: 4605 | P29: =O29-C29 -> 3520
E32: Výměna kalorimetru pata | H32: MWh | I32: m3 | K32: Výměna faktur.vodoměru výr.č. | N32: m3
D33: demontáž | E33: 43984 | F33: starý | K33: 44095 | L33: starý
G34: výr.č. | H34: GJ | I34: m3 | M34: výr.č. | N34: m3
D35: montáž | E35: 43986 | F35: nový | K35: 44095 | L35: nový
N38: Odečet vodárny 30.11.2020 | O38: 701
N39: Dohad 1.12.-31.12.2020 | O39: =C29-O38 -> 384
N40: Odečet vodárny 30.11.2021 | O40: =N29 -> 4300
N41: Dohad 1.12.-31.12.2021 | O41: =O29-N29 -> 305

Sheet 1855
A2: 1855 | C2: ='1850'!C2 -> 44197 | D2: ='1850'!D2 -> 44228 | E2: ='1850'!E2 -> 44256 | F2: ='1850'!F2 -> 44286 | G2: ='1850'!G2 -> 44316 | H2: ='1850'!H2 -> 44348 | I2: ='1850'!I2 -> 44379 | J2: ='1850'!J2 -> 44410 | ... O2: ='1850'!O2 -> 44562 | P2: voda | Q2: teplo | R2: elektr | Y2: spotřeby po měsících
A3: byt č. | C3: prosinec | D3: leden | E3: únor | F3: březen | G3: duben | H3: květen | I3: červen | J3: červenec | K3: srpen | L3: září | M3: říjen | N3: listopad | O3: prosinec | P3: m3 | Q3: GJ | R3: KWh | T3: byt | U3: leden | V3: únor | W3: březen | X3: duben | Y3: květen | Z3: červen | AA3: červenec | AB3: srpen | AC3: září | AD3: říjen | AE3: listopad | AF3: prosinec
A4: 1 | B4: vodoměr č. 191519259 | C4: 183.174 | D4: 198.851 | E4: 213.97 | F4: 231.036 | G4: 247.368 | H4: 266.761 | I4: 282.674 | J4: 296.255 | K4: 307.945 | L4: 321.815 | M4: 336.012 | N4: 349.73 | O4: 363.842 | P4: =O4-C4 -> 180.668 | T4: 1 | U4: =D4-C4 -> 15.677 | V4: =E4-D4 -> 15.119 | W4: =F4-E4 -> 17.066 | X4: =G4-F4 -> 16.332 | Y4: =H4-G4 -> 19.393 | Z4: =I4-H4 -> 15.913 | AA4: =J4-I4 -> 13.581 | AB4: =K4-J4 -> 11.69 | ... AF4: =O4-N4 -> 14.112
B5: kalorimetr č. SN 34672816 | C5: 118.241 | D5: 127.175 | E5: 135.469 | F5: 142.954 | G5: 149.639 | H5: 155.099 | I5: 156.343 | J5: 157.238 | K5: 158.663 | L5: 160.152 | M5: 164.921 | N5: 6.069 | O5: 14.103 | Q5: =O5+M5-C5 -> 60.783 | T5: teplo | U5: =D5-C5 -> 8.934 | V5: =E5-D5 -> 8.294 | W5: =F5-E5 -> 7.485 | X5: =G5-F5 -> 6.685 | Y5: =H5-G5 -> 5.46 | Z5: =I5-H5 -> 1.244 | AA5: =J5-I5 -> 0.895 | AB5: =K5-J5 -> 1.425 | ... AD5: =M5-L5 -> 4.769 | AE5: =N5 -> 6.069 | AF5: =O5 -> 14.103
A6: 2 | B6: vodoměr č. 191519283 | C6: 233.734 | D6: 255.691 | E6: 274.665 | F6: 295.486 | G6: 317.129 | H6: 337.879 | I6: 353.981 | J6: 359.023 | K6: 378.094 | L6: 393.582 | M6: 411.545 | N6: 428.318 | O6: 442.615 | P6: =O6-C6 -> 208.881 | T6: 2 | U6: =D6-C6 -> 21.957 | V6: =E6-D6 -> 18.974 | W6: =F6-E6 -> 20.821 | X6: =G6-F6 -> 21.643 | Y6: =H6-G6 -> 20.75 | Z6: =I6-H6 -> 16.102 | AA6: =J6-I6 -> 5.042 | AB6: =K6-J6 -> 19.071 | ... AF6: =O6-N6 -> 14.297
B7: kalorimetr č. SN 34672822 | C7: 135.148 | D7: 142.378 | E7: 149.181 | F7: 155.122 | G7: 160.096 | H7: 163.241 | I7: 164.41 | J7: 164.862 | K7: 166.025 | L7: 167.144 | M7: 169.806 | N7: 4.048 | O7: 9.68 | Q7: =O7+M7-C7 -> 44.338 | U7: =D7-C7 -> 7.23 | V7: =E7-D7 -> 6.803 | W7: =F7-E7 -> 5.941 | X7: =G7-F7 -> 4.974 | Y7: =H7-G7 -> 3.145 | Z7: =I7-H7 -> 1.169 | AA7: =J7-I7 -> 0.452 | AB7: =K7-J7 -> 1.163 | ... AD7: =M7-L7 -> 2.662 | AE7: =N7 -> 4.048 | AF7: =O7 -> 9.68
A8: 3 | B8: vodoměr č. 190907001 | C8: 63.121 | D8: 66.65 | E8: 70.412 | F8: 74.866 | G8: 79.214 | H8: 83.787 | I8: 87.993 | J8: 91.719 | K8: 95.609 | L8: 99.912 | M8: 104.358 | N8: 108.636 | O8: 110.651 | P8: =O8-C8 -> 47.53 | T8: 3 | U8: =D8-C8 -> 3.529 | V8: =E8-D8 -> 3.762 | W8: =F8-E8 -> 4.454 | X8: =G8-F8 -> 4.348 | Y8: =H8-G8 -> 4.573 | Z8: =I8-H8 -> 4.206 | AA8: =J8-I8 -> 3.726 | AB8: =K8-J8 -> 3.89 | ... AF8: =O8-N8 -> 2.015
B9: kalorimetr č. SN 34672827 | C9: 92.497 | D9: 96.87 | E9: 100.974 | F9: 104.207 | G9: 106.62 | H9: 107.337 | I9: 107.647 | J9: 107.922 | K9: 108.235 | L9: 108.584 | M9: 109.74 | N9: 2.511 | O9: 4.502 | Q9: =O9+M9-C9 -> 21.745 | U9: =D9-C9 -> 4.373 | V9: =E9-D9 -> 4.104 | W9: =F9-E9 -> 3.233 | X9: =G9-F9 -> 2.413 | Y9: =H9-G9 -> 0.717 | Z9: =I9-H9 -> 0.31 | AA9: =J9-I9 -> 0.275 | AB9: =K9-J9 -> 0.313 | ... AD9: =M9-L9 -> 1.156 | AE9: =N9 -> 2.511 | AF9: =O9 -> 4.502
A10: 4 | B10: vodoměr č. 190907005 | C10: 14.175 | D10: 14.995 | E10: 15.884 | F10: 17.031 | G10: 17.83 | H10: 18.683 | I10: 19.715 | J10: 20.622 | K10: 21.607 | L10: 22.765 | M10: 24.027 | N10: 25.042 | O10: 25.942 | P10: =O10-C10 -> 11.767 | T10: 4 | U10: =D10-C10 -> 0.82 | V10: =E10-D10 -> 0.889 | W10: =F10-E10 -> 1.147 | X10: =G10-F10 -> 0.799 | Y10: =H10-G10 -> 0.853 | Z10: =I10-H10 -> 1.032 | AA10: =J10-I10 -> 0.907 | AB10: =K10-J10 -> 0.985 | ... AF10: =O10-N10 -> 0.9
B11: kalorimetr č. SN 34672837 | C11: 10.086 | D11: 10.711 | E11: 11.145 | F11: 11.174 | G11: 11.189 | H11: 11.199 | I11: 11.214 | J11: 11.225 | K11: 11.235 | L11: 11.246 | M11: 11.266 | N11: 0.131 | O11: 0.493 | Q11: =O11+M11-C11 -> 1.673 | U11: =D11-C11 -> 0.625 | V11: =E11-D11 -> 0.434 | W11: =F11-E11 -> 0.029 | X11: =G11-F11 -> 0.015 | Y11: =H11-G11 -> 0.01 | Z11: =I11-H11 -> 0.015 | AA11: =J11-I11 -> 0.011 | AB11: =K11-J11 -> 0.01 | ... AD11: =M11-L11 -> 0.02 | AE11: =N11 -> 0.131 | AF11: =O11 -> 0.493
