Workbook

Sheet 1850
A2: 1850 | C2: 44562 | D2: 44593 | E2: 44622 | F2: 44652 | G2: 44683 | H2: 44713 | I2: 44743 | J2: 44774 | K2: 44805 | L2: 44834 | M2: 44866 | N2: 44896 | O2: 44927 | P2: voda | Q2: teplo | Y2: spotřeby po měsících
A3: byt č. | C3: prosinec | D3: leden | E3: únor | F3: březen | G3: duben | H3: květen | I3: červen | J3: červenec | K3: srpen | L3: září | M3: říjen | N3: listopad | O3: prosinec | P3: m3 | Q3: GJ | T3: byt | U3: leden | V3: únor | W3: březen | X3: duben | Y3: květen | Z3: červen | AA3: červenec | AB3: srpen | AC3: září | AD3: říjen | AE3: listopad | AF3: prosinec
A4: 1 | B4: vodoměr č. 190834092 | C4: 29.98 | D4: 30.566 | E4: 31.354 | F4: 32.377 | G4: 33.192 | H4: 33.391 | I4: 34.526 | J4: 35.627 | K4: 36.484 | L4: 37.126 | M4: 37.937 | N4: 38.634 | O4: 39.227 | P4: =O4-C4 -> 9.247 | T4: 1 | U4: =D4-C4 -> 0.586 | V4: =E4-D4 -> 0.788 | W4: =F4-E4 -> 1.023 | X4: =G4-F4 -> 0.815 | Y4: =H4-G4 -> 0.199 | Z4: =I4-H4 -> 1.135 | AA4: =J4-I4 -> 1.101 | AB4: =K4-J4 -> 0.857 | ... AF4: =O4-N4 -> 0.593
B5: kalorimetr č. SN 34582391 | C5: 4.385 | D5: 7.535 | E5: 10.846 | F5: 13.857 | G5: 15.401 | H5: 15.61 | I5: 15.827 | J5: 16.063 | K5: 16.269 | L5: 16.472 | M5: 16.72 | N5: 18.654 | O5: 22.65 | Q5: =O5-C5 -> 18.265
A6: 2 | B6: vodoměr č. 190834090 | C6: 419.04 | D6: 432.829 | E6: 447.37 | F6: 462.529 | G6: 477.847 | H6: 492.391 | I6: 503.618 | J6: 511.411 | K6: 522.863 | L6: 534.27 | M6: 547.746 | N6: 562.797 | O6: 578.873 | P6: =O6-C6 -> 159.833 | R6: =P6*120 -> 19179.96 | T6: 2 | U6: =D6-C6 -> 13.789 | V6: =E6-D6 -> 14.541 | W6: =F6-E6 -> 15.159 | X6: =G6-F6 -> 15.318 | Y6: =H6-G6 -> 14.544 | Z6: =I6-H6 -> 11.227 | AA6: =J6-I6 -> 7.793 | AB6: =K6-J6 -> 11.452 | ... AF6: =O6-N6 -> 16.076
B7: kalorimetr č. SN 34582401 | C7: 9.432 | D7: 14.973 | E7: 19.083 | F7: 23.377 | G7: 26.625 | H7: 27.468 | I7: 27.978 | J7: 28.269 | K7: 28.683 | L7: 29.225 | M7: 29.989 | N7: 32.323 | O7: 36.202 | Q7: =O7-C7 -> 26.77 | R7: =Q7*1720 -> 46044.4
A8: 3 | B8: vodoměr č. 190834097 | C8: 159.808 | D8: 165.652 | E8: 170.928 | F8: 176.257 | G8: 182.291 | H8: 188.251 | I8: 193.211 | J8: 198.745 | K8: 204.187 | L8: 210.099 | M8: 216.283 | N8: 222.231 | O8: 228.181 | P8: =O8-C8 -> 68.373 | R8: =R7+R6 -> 65224.36 | T8: 3 | U8: =D8-C8 -> 5.844 | V8: =E8-D8 -> 5.276 | W8: =F8-E8 -> 5.329 | X8: =G8-F8 -> 6.034 | Y8: =H8-G8 -> 5.96 | Z8: =I8-H8 -> 4.96 | AA8: =J8-I8 -> 5.534 | AB8: =K8-J8 -> 5.442 | ... AF8: =O8-N8 -> 5.95
B9: kalorimetr č. SN 34582385 | C9: 5.553 | D9: 9.326 | E9: 11.679 | F9: 13.423 | G9: 15.288 | H9: 15.797 | I9: 16.188 | J9: 16.569 | K9: 16.919 | L9: 17.363 | M9: 18.452 | N9: 21.255 | O9: 24.945 | Q9: =O9-C9 -> 19.392
A10: 4 | B10: vodoměr č. 190834098 | C10: 227.481 | D10: 238.851 | E10: 249.246 | F10: 260.35 | G10: 272.403 | H10: 281.797 | I10: 290.922 | J10: 298.762 | K10: 307.852 | L10: 316.389 | M10: 326.558 | N10: 336.366 | O10: 346.182 | P10: =O10-C10 -> 118.701 | T10: 4 | U10: =D10-C10 -> 11.37 | V10: =E10-D10 -> 10.395 | W10: =F10-E10 -> 11.104 | X10: =G10-F10 -> 12.053 | Y10: =H10-G10 -> 9.394 | Z10: =I10-H10 -> 9.125 | AA10: =J10-I10 -> 7.84 | AB10: =K10-J10 -> 9.09 | ... AF10: =O10-N10 -> 9.816
B11: kalorimetr č. SN 34582414 | C11: 4.205 | D11: 6.299 | E11: 7.811 | F11: 9.178 | G11: 10.429 | H11: 11.262 | I11: 11.962 | J11: 12.509 | K11: 13.133 | L11: 13.825 | M11: 14.796 | N11: 16.476 | O11: 18.402 | Q11: =O11-C11 -> 14.197
A12: 5 | B12: vodoměr č. 190834095 | C12: 170.846 | D12: 178.037 | E12: 185.448 | F12: 192.596 | G12: 200.595 | H12: 210.914 | I12: 220.496 | J12: 228.036 | K12: 237.156 | L12: 242.343 | M12: 249.471 | N12: 257.172 | O12: 262.861 | P12: =O12-C12 -> 92.015 | T12: 5 | U12: =D12-C12 -> 7.191 | V12: =E12-D12 -> 7.411 | W12: =F12-E12 -> 7.148 | X12: =G12-F12 -> 7.999 | Y12: =H12-G12 -> 10.319 | Z12: =I12-H12 -> 9.582 | AA12: =J12-I12 -> 7.54 | AB12: =K12-J12 -> 9.12 | ... AF12: =O12-N12 -> 5.689
B13: kalorimetr č. SN 34582396 | C13: 5.129 | D13: 7.488 | E13: 9.425 | F13: 11.01 | G13: 12.231 | H13: 12.844 | I13: 13.366 | J13: 13.812 | K13: 14.198 | L13: 14.64 | M13: 15.298 | N13: 17.753 | O13: 20.438 | Q13: =O13-C13 -> 15.309
A14: 6 | B14: vodoměr č. 190834099 | C14: 196.918 | D14: 208.418 | E14: 218.461 | F14: 231.365 | G14: 243.044 | H14: 253.485 | I14: 261.521 | J14: 268.178 | K14: 273.236 | L14: 281.276 | M14: 290.012 | N14: 296.348 | O14: 304.032 | P14: =O14-C14 -> 107.114 | T14: 6 | U14: =D14-C14 -> 11.5 | V14: =E14-D14 -> 10.043 | W14: =F14-E14 -> 12.904 | X14: =G14-F14 -> 11.679 | Y14: =H14-G14 -> 10.441 | Z14: =I14-H14 -> 8.036 | AA14: =J14-I14 -> 6.657 | AB14: =K14-J14 -> 5.058 | ... AF14: =O14-N14 -> 7.684
B15: kalorimetr č. SN 34582416 | C15: 9.852 | D15: 16.478 | E15: 20.712 | F15: 23.067 | G15: 24.956 | H15: 25.886 | I15: 26.461 | J15: 26.995 | K15: 27.409 | L15: 27.975 | M15: 28.691 | N15: 30.949 | O15: 36.339 | Q15: =O15-C15 -> 26.487
A16: 7 | B16: vodoměr č. 190834102 | C16: 39.303 | D16: 40.51 | E16: 41.984 | F16: 43.545 | G16: 44.863 | H16: 46.056 | I16: 47.163 | J16: 48.036 | K16: 48.938 | L16: 49.754 | M16: 50.614 | N16: 51.478 | O16: 52.604 | P16: =O16-C16 -> 13.301 | T16: 7 | U16: =D16-C16 -> 1.207 | V16: =E16-D16 -> 1.474 | W16: =F16-E16 -> 1.561 | X16: =G16-F16 -> 1.318 | Y16: =H16-G16 -> 1.193 | Z16: =I16-H16 -> 1.107 | AA16: =J16-I16 -> 0.873 | AB16: =K16-J16 -> 0.902 | ... AF16: =O16-N16 -> 1.126
B17: kalorimetr č. SN 34582423 | C17: 2.484 | D17: 4.169 | E17: 5.264 | F17: 5.717 | G17: 6.227 | H17: 6.368 | I17: 6.493 | J17: 6.578 | K17: 6.675 | L17: 6.753 | M17: 6.879 | N17: 7.626 | O17: 9.35 | Q17: =O17-C17 -> 6.866
A18: 8 | B18: vodoměr č. 200015742 | C18: 32.864 | D18: 36.446 | E18: 39.173 | F18: 42.819 | G18: 45.486 | H18: 47.349 | I18: 48.873 | J18: 50.936 | K18: 51.501 | L18: 53.732 | M18: 56.972 | N18: 57.637 | O18: 58.755 | P18: =O18-C18 -> 25.891 | T18: 8 | U18: =D18-C18 -> 3.582 | V18: =E18-D18 -> 2.727 | W18: =F18-E18 -> 3.646 | X18: =G18-F18 -> 2.667 | Y18: =H18-G18 -> 1.863 | Z18: =I18-H18 -> 1.524 | AA18: =J18-I18 -> 2.063 | AB18: =K18-J18 -> 0.565 | ... AF18: =O18-N18 -> 1.118
B19: kalorimetr č. SN 34582408 | C19: 6.075 | D19: 10.405 | E19: 13.59 | F19: 16.141 | G19: 17.827 | H19: 18.058 | I19: 18.243 | J19: 18.456 | K19: 18.599 | L19: 19.311 | M19: 21.843 | N19: 24.805 | O19: 29.061 | Q19: =O19-C19 -> 22.986
A20: 9 | B20: vodoměr č. 190834109 | C20: 2.223 | D20: 2.255 | E20: 2.268 | F20: 2.286 | G20: 2.3 | H20: 2.321 | I20: 2.339 | J20: 2.363 | K20: 2.386 | L20: 2.407 | M20: 2.453 | N20: 2.468 | O20: 2.493 | P20: =O20-C20 -> 0.27 | T20: 9 | U20: =D20-C20 -> 0.032 | V20: =E20-D20 -> 0.013 | W20: =F20-E20 -> 0.018 | X20: =G20-F20 -> 0.014 | Y20: =H20-G20 -> 0.021 | Z20: =I20-H20 -> 0.018 | AA20: =J20-I20 -> 0.024 | AB20: =K20-J20 -> 0.023 | ... AF20: =O20-N20 -> 0.025
B21: kalorimetr č. SN 34582410 | C21: 0.387 | D21: 0.563 | E21: 0.725 | F21: 0.897 | G21: 1.075 | H21: 1.233 | I21: 1.378 | J21: 1.535 | K21: 1.691 | L21: 1.858 | M21: 2.053 | N21: 2.22 | O21: 2.389 | Q21: =O21-C21 -> 2.002
A22: 10 | B22: vodoměr č. 191519263 | C22: 186.401 | D22: 194.649 | E22: 202.192 | F22: 209.862 | G22: 213.986 | H22: 220.99 | I22: 226.914 | J22: 232.67 | K22: 240.401 | L22: 247.057 | M22: 254.66 | N22: 261.563 | O22: 268.31 | P22: =O22-C22 -> 81.909 | T22: 10 | U22: =D22-C22 -> 8.248 | V22: =E22-D22 -> 7.543 | W22: =F22-E22 -> 7.67 | X22: =G22-F22 -> 4.124 | Y22: =H22-G22 -> 7.004 | Z22: =I22-H22 -> 5.924 | AA22: =J22-I22 -> 5.756 | AB22: =K22-J22 -> 7.731 | ... AF22: =O22-N22 -> 6.747
B23: kalorimetr č. SN 34582413 | C23: 7.061 | D23: 10.775 | E23: 13.738 | F23: 15.848 | G23: 17.241 | H23: 17.665 | I23: 17.972 | J23: 18.265 | K23: 18.583 | L23: 18.947 | M23: 19.443 | N23: 22.411 | O23: 26.403 | Q23: =O23-C23 -> 19.342
P24: =SUM(P4:P23) -> 676.654 | Q24: =SUM(Q4:Q23) -> 171.616
A25: spol.spotř. | B25: elektroměr č. 18972503 | C25: 76098 | D25: 76304 | E25: 145 | F25: 375 | G25: 594 | H25: 837 | I25: 1069 | J25: 1298 | K25: 1514 | L25: 1730 | M25: 1970 | N25: 2219 | O25: 2438 | R25: =O25+E34-C25 -> 2725
B26: patní vodoměr č. 190976787 | C26: 1705.8 | D26: 1776.8 | E26: 1844.6 | F26: 1918.7 | G26: 1988.1 | H26: 2056.6 | I26: 2116 | J26: 2167.7 | K26: 2224.8 | L26: 2280.4 | M26: 2345.9 | N26: 2406.5 | O26: 2467.9 | P26: =O26-C26 -> 762.1
B27: patní kalorimetr č./MWh | C27: 132.72 | D27: 142.74 | E27: 150.1 | F27: 155.75 | G27: 159.94 | H27: 160.87 | I27: 161.49 | J27: 161.97 | K27: 162.44 | L27: 163.27 | M27: 165.36 | N27: 171.41 | O27: 181.1 | Q27: =(O27-C27)*3.6 -> 174.168 | R27: GJ
B28: patní kalorimetr č./kub.m | C28: 5092 | D28: 5380 | E28: 5594 | F28: 5745 | G28: 5870 | H28: 5902 | I28: 5926 | J28: 5946 | K28: 5967 | L28: 6000 | M28: 6083 | N28: 6257 | O28: 6557 | Q28: =O28-C28 -> 1465 | R28: m3
A29: fakturační vodoměr č. 63796 | C29: 16304 | D29: 16653.4 | E29: 16977.5 | F29: 17322.7 | G29: 17680.1 | H29: 18036.6 | I29: 18355.9 | J29: 18672 | K29: 18979.4 | L29: 19283.1 | M29: 19628 | N29: 19942.6 | O29: 20281.1 | P29: =O29-C29 -> 3977.1
C31: číslo | E31: stav
B32: Výměna fakturač. vodoměru | C32: 110109308 | D32: starý | E32: 12875 | H32: Dne 17.6.2019 odpojen kalor. (cejchování), | L32: stav: | M32: 236.93 | N32: MWh
B33: dne 14.2.2019 | C33: 63796 | D33: nový | E33: 4174 | H33: Dne 20.6.2019 zapojen znovuzapojení, | L33: stav: | M33: 0 | N33: MWh
B34: Výměna elekroměru | C34: 18972503 | D34: starý | E34: 76385
B35: dne 13.2.2022 | C35: 1025291034 | D35: nový | E35: 0
B37: Změna vlastnictví Taufer-Slavíkovi | D37: voda | E37: teplo | N37: Odečet vodárny 30.11.2021 | O37: 15951
B38: do 31.5. a od 1.6.2022 | C38: stav | D38: 274.519 | E38: 10.65 | N38: Dohad 1.12.-31.12.2021 | O38: 353
B39: Taufer 1.1.-31.5.2022 | C39: spotřeba | D39: =D38-C10 -> 47.038 | E39: =E38-C11 -> 6.445 | N39: Odečet vodárny 31.12.2022 | O39: 20281
B40: Slavíkovi 1.6.-31.12.2022 | C40: spotřeba | D40: =O10-D38 -> 71.663 | E40: =O11-E39 -> 11.957
N41: spotřeba | O41: =O39-O37-O38 -> 3977
C42: =(D6-C6)*120 -> 1654.68 | D42: =(E6-D6)*120 -> 1744.92 | E42: =(F6-E6)*120 -> 1819.08 | F42: =(G6-F6)*120 -> 1838.16 | G42: =(H6-G6)*120 -> 1745.28 | H42: =(I6-H6)*120 -> 1347.24 | I42: =(J6-I6)*120 -> 935.16 | J42: =(K6-J6)*120 -> 1374.24 | ... N42: =(O6-N6)*120 -> 1929.12
C43: =(D7-C7)*1700 -> 9419.7 | D43: =(E7-D7)*1700 -> 6987 | E43: =(F7-E7)*1700 -> 7299.8 | F43: =(G7-F7)*1700 -> 5521.6 | G43: =(H7-G7)*1700 -> 1433.1 | H43: =(I7-H7)*1700 -> 867 | I43: =(J7-I7)*1700 -> 494.7 | J43: =(K7-J7)*1700 -> 703.8 | ... N43: =(O7-N7)*1700 -> 6594.3

Sheet 1851
AE1: Vytipování vadných vodoměrů
A2: Nové | B2: 1851 | D2: ='1850'!C2 -> 44562 | E2: ='1850'!D2 -> 44593 | F2: ='1850'!E2 -> 44622 | G2: ='1850'!F2 -> 44652 | H2: ='1850'!G2 -> 44683 | I2: ='1850'!H2 -> 44713 | J2: ='1850'!I2 -> 44743 | K2: ='1850'!J2 -> 44774 | ... P2: ='1850'!O2 -> 44927 | Q2: voda | R2: teplo | Z2: spotřeby po měsících | AH2: předloňský
A3: číslování | B3: byt č. | D3: prosinec | E3: leden | F3: únor | G3: březen | H3: duben | I3: květen | J3: červen | K3: červenec | L3: srpen | M3: září | N3: říjen | O3: listopad | P3: prosinec | Q3: m3 | R3: GJ | U3: byt | V3: leden | W3: únor | X3: březen | Y3: duben | Z3: květen | AA3: červen | AB3: červenec | AC3: srpen | AD3: září | AE3: říjen | AF3: listopad | AG3: prosinec | AH3: průměr
A4: 1 | B4: 1 | C4: vodoměr č. 190834116 | D4: 391.196 | E4: 403.323 | F4: 414.092 | G4: 426.447 | H4: 439.704 | I4: 452.943 | J4: 463.367 | K4: 474.888 | L4: 486.236 | M4: 497.23 | N4: 509.794 | O4: 522.243 | P4: 536.77 | Q4: =P4-D4 -> 145.574 | U4: 1 | V4: =E4-D4 -> 12.127 | W4: =F4-E4 -> 10.769 | X4: =G4-F4 -> 12.355 | Y4: =H4-G4 -> 13.257 | Z4: =I4-H4 -> 13.239 | AA4: =J4-I4 -> 10.424 | AB4: =K4-J4 -> 11.521 | AC4: =L4-K4 -> 11.348 | ... AG4: =P4-O4 -> 14.527 | AH4: 11.905222
C5: kalorimetr č. SN 34582402 | D5: 9.87 | E5: 15.187 | F5: 19.111 | G5: 22.76 | H5: 25.929 | I5: 26.947 | J5: 27.664 | K5: 28.419 | L5: 29.048 | M5: 29.809 | N5: 31.18 | O5: 34.425 | P5: 39.364 | R5: =P5-D5 -> 29.494 | U5: xx
A6: 2 | B6: 2 | C6: vodoměr SV č. 190834120 | D6: 143.997 | E6: 148.281 | F6: 152.157 | G6: 156.049 | H6: 161.178 | I6: 165.519 | J6: 169.707 | K6: 175.45 | L6: 180.946 | M6: 185.833 | N6: 191.258 | O6: 196.183 | P6: 201.144 | Q6: =P6-D6 -> 57.147 | U6: 2 | V6: =E6-D6 -> 4.284 | W6: =F6-E6 -> 3.876 | X6: =G6-F6 -> 3.892 | Y6: =H6-G6 -> 5.129 | Z6: =I6-H6 -> 4.341 | AA6: =J6-I6 -> 4.188 | AB6: =K6-J6 -> 5.743 | AC6: =L6-K6 -> 5.496 | ... AG6: =P6-O6 -> 4.961 | AH6: 4.9828889
A7: 2 a 3 | C7: kalorimetr č. SN 34582400 | D7: 11.013 | E7: 18.272 | F7: 23.089 | G7: 27.412 | H7: 30.255 | I7: 31.571 | J7: 32.548 | K7: 33.416 | L7: 34.196 | M7: 35.541 | N7: 37.416 | O7: 41.15 | P7: 46.893 | R7: =P7-D7 -> 35.88 | U7: TV | V7: =V40 -> 2.904 | W7: =W40 -> 2.42 | X7: =X40 -> 2.092 | Y7: =Y40 -> 2.542 | Z7: =Z40 -> 2.327 | AA7: =AA40 -> 1.687 | AB7: =AB40 -> 1.785 | AC7: =AC40 -> 1.836 | ... AG7: =AG40 -> 2.829 | AH7: 4.43
A8: 5 | B8: 3 | C8: vodoměr SV č. 190834093 | D8: 17.464 | E8: 18.224 | F8: 18.798 | G8: 19.414 | H8: 20.043 | I8: 20.614 | J8: 21.154 | K8: 21.551 | L8: 21.956 | M8: 22.323 | N8: 22.799 | O8: 0.044 | P8: 1.058 | Q8: =P8-I54+I53-D8 -> 6.804 | U8: 5 | V8: =E8-D8 -> 0.76 | W8: =F8-E8 -> 0.574 | X8: =G8-F8 -> 0.616 | Y8: =H8-G8 -> 0.629 | Z8: =I8-H8 -> 0.571 | AA8: =J8-I8 -> 0.54 | AB8: =K8-J8 -> 0.397 | AC8: =L8-K8 -> 0.405 | ... AE8: =N8-M8 -> 0.476 | AF8: =O8-I54+I53-N8 -> 0.455 | AG8: =P8-J54+J53-O8 -> 1.014 | AH8: 0.94022222
A9: 5 a 6 | C9: kalorimetr č. SN 34582398 | D9: 11.368 | E9: 18.67 | F9: 24.342 | G9: 28.771 | H9: 32.099 | I9: 33.69 | J9: 35.155 | K9: 36.744 | L9: 38.27 | M9: 39.955 | N9: 41.98 | O9: 45.741 | P9: 51.338 | R9: =P9-D9 -> 39.97 | U9: TV | V9: =V42 -> 0.66 | W9: =W42 -> 0.42 | X9: =X42 -> 0.428 | Y9: =Y42 -> 0.4 | Z9: =Z42 -> 0.337 | AA9: =AA42 -> 0.324 | AB9: =AB42 -> 0.335 | AC9: =AC42 -> 0.291 | ... AG9: =AG42 -> 0.341 | AH9: 0.37122222
A10: 4 | B10: 4 | C10: vodoměr č. 190834126 | D10: 109.346 | E10: 109.346 | F10: 109.353 | G10: 109.359 | H10: 109.367 | I10: 109.805 | J10: 109.838 | K10: 109.84 | L10: 110.825 | M10: 110.948 | N10: 111.139 | O10: 112.878 | P10: 116.497 | Q10: =P10-D10 -> 7.151 | U10: 4 | V10: =E10-D10 -> 0 | W10: =F10-E10 -> 0.007 | X10: =G10-F10 -> 0.006 | Y10: =H10-G10 -> 0.008 | Z10: =I10-H10 -> 0.438 | AA10: =J10-I10 -> 0.033 | AB10: =K10-J10 -> 0.002 | AC10: =L10-K10 -> 0.985 | ... AG10: =P10-O10 -> 3.619 | AH10: 5.9373333
C11: kalorimetr č. SN 34582419 | D11: 0 | E11: 0 | F11: 0 | G11: 0.001 | H11: 0.002 | I11: 0.021 | J11: 0.022 | K11: 0.022 | L11: 0.07 | M11: 0.073 | N11: 0.079 | O11: 0.467 | P11: 1.298 | R11: =P11-D11 -> 1.298 | U11: xx
A12: 9 | B12: 5 | C12: vodoměr SV č. 190834122 | D12: 115.676 | E12: 119.51 | F12: 123.178 | G12: 127.577 | H12: 132.369 | I12: 137.336 | J12: 142.762 | K12: 147.657 | L12: 152.683 | M12: 157.159 | N12: 162.357 | O12: 167.375 | P12: 172.088 | Q12: =P12-D12 -> 56.412 | U12: 9 | V12: =E12-D12 -> 3.834 | W12: =F12-E12 -> 3.668 | X12: =G12-F12 -> 4.399 | Y12: =H12-G12 -> 4.792 | Z12: =I12-H12 -> 4.967 | AA12: =J12-I12 -> 5.426 | AB12: =K12-J12 -> 4.895 | AC12: =L12-K12 -> 5.026 | ... AG12: =P12-O12 -> 4.713 | AH12: 4.7323333
A13: 8 a 9 | C13: kalorimetr č. SN 34582384 | D13: 8.304 | E13: 12.942 | F13: 16.757 | G13: 20.907 | H13: 24.983 | I13: 26.177 | J13: 26.964 | K13: 27.696 | L13: 28.353 | M13: 29.054 | N13: 30.507 | O13: 34.036 | P13: 38.609 | R13: =P13-D13 -> 30.305 | U13: TV | V13: =V44 -> 2.283 | W13: =W44 -> 2.059 | X13: =X44 -> 2.067 | Y13: =Y44 -> 2.073 | Z13: =Z44 -> 1.652 | AA13: =AA44 -> 1.438 | AB13: =AB44 -> 1.226 | AC13: =AC44 -> 1.334 | ... AG13: =AG44 -> 1.996 | AH13: 4.7182222
A14: 15 | B14: 6 | C14: vodoměr SV č. 200015757 | D14: 95.075 | E14: 100.796 | F14: 105.002 | G14: 109.469 | H14: 114.161 | I14: 118.939 | J14: 123.899 | K14: 129.483 | L14: 136.078 | M14: 141.583 | N14: 145.597 | O14: 149.19 | P14: 153.431 | Q14: =P14-D14 -> 58.356 | U14: 15 | V14: =E14-D14 -> 5.721 | W14: =F14-E14 -> 4.206 | X14: =G14-F14 -> 4.467 | Y14: =H14-G14 -> 4.692 | Z14: =I14-H14 -> 4.778 | AA14: =J14-I14 -> 4.96 | AB14: =K14-J14 -> 5.584 | AC14: =L14-K14 -> 6.595 | ... AG14: =P14-O14 -> 4.241 | AH14: 1.6821111
A15: 11 a 15 | C15: kalorimetr č. SN 34582397 | D15: 5.474 | E15: 8.381 | F15: 10.515 | G15: 12.321 | H15: 13.944 | I15: 14.728 | J15: 15.328 | K15: 15.878 | L15: 16.394 | M15: 17.219 | N15: 17.953 | O15: 19.908 | P15: 22.332 | R15: =P15-D15 -> 16.858 | U15: TV | V15: =V46 -> 4.197 | W15: =W46 -> 4.183 | X15: =X46 -> 3.959 | Y15: =Y46 -> 3.882 | Z15: =Z46 -> 3.125 | AA15: =AA46 -> 3.021 | AB15: =AB46 -> 2.633 | AC15: =AC46 -> 2.26 | ... AG15: =AG46 -> 3.442 | AH15: 0.73344444
A16: 7 | B16: 7 | C16: vodoměr č. 190834119 | D16: 167.571 | E16: 174.584 | F16: 180.401 | G16: 185.5 | H16: 192.116 | I16: 198.385 | J16: 203.608 | K16: 208.063 | L16: 210.311 | M16: 215.292 | N16: 220.473 | O16: 224.838 | P16: 230.537 | Q16: =P16-D16 -> 62.966 | U16: 7 | V16: =E16-D16 -> 7.013 | W16: =F16-E16 -> 5.817 | X16: =G16-F16 -> 5.099 | Y16: =H16-G16 -> 6.616 | Z16: =I16-H16 -> 6.269 | AA16: =J16-I16 -> 5.223 | AB16: =K16-J16 -> 4.455 | AC16: =L16-K16 -> 2.248 | ... AG16: =P16-O16 -> 5.699 | AH16: 6.2735556
C17: kalorimetr č. SN 34582417 | D17: 1.141 | E17: 1.77 | F17: 2.262 | G17: 2.828 | H17: 3.344 | I17: 3.787 | J17: 4.072 | K17: 4.303 | L17: 4.416 | M17: 4.684 | N17: 5.016 | O17: 5.323 | P17: 5.776 | R17: =P17-D17 -> 4.635 | U17: xx
A18: 13 | B18: 8 | C18: vodoměr SV č. 190834112 | D18: 81.12 | E18: 81.936 | F18: 84.352 | G18: 86.72 | H18: 89.263 | I18: 91.925 | J18: 94.869 | K18: 97.014 | L18: 99.636 | M18: 101.882 | N18: 104.479 | O18: 106.569 | P18: 108.811 | Q18: =P18-D18 -> 27.691 | U18: 13 | V18: =E18-D18 -> 0.816 | W18: =F18-E18 -> 2.416 | X18: =G18-F18 -> 2.368 | Y18: =H18-G18 -> 2.543 | Z18: =I18-H18 -> 2.662 | AA18: =J18-I18 -> 2.944 | AB18: =K18-J18 -> 2.145 | AC18: =L18-K18 -> 2.622 | ... AG18: =P18-O18 -> 2.242 | AH18: 2.5207778
A19: 12 a 13 | C19: kalorimetr č. SN 34582392 | D19: 10.751 | E19: 15.615 | F19: 20.187 | G19: 23.4 | H19: 24.965 | I19: 25.593 | J19: 26.169 | K19: 26.487 | L19: 26.929 | M19: 27.445 | N19: 28.324 | O19: 31.245 | P19: 36.685 | R19: =P19-D19 -> 25.934 | U19: TV | V19: =V48 -> 0.552 | W19: =W48 -> 2.417 | X19: =X48 -> 2.612 | Y19: =Y48 -> 2.504 | Z19: =Z48 -> 2.279 | AA19: =AA48 -> 2.291 | AB19: =AB48 -> 1.353 | AC19: =AC48 -> 1.811 | ... AG19: =AG48 -> 1.958 | AH19: 1.2623333
A20: 14 | B20: 9 | C20: vodoměr č. 190834124 | D20: 254.696 | E20: 265.573 | F20: 274.426 | G20: 284.748 | H20: 295.017 | I20: 305.917 | J20: 312.99 | K20: 320.698 | L20: 329.244 | M20: 339.04 | N20: 348.198 | O20: 357.055 | P20: 366.117 | Q20: =P20-D20 -> 111.421 | U20: 14 | V20: =E20-D20 -> 10.877 | W20: =F20-E20 -> 8.853 | X20: =G20-F20 -> 10.322 | Y20: =H20-G20 -> 10.269 | Z20: =I20-H20 -> 10.9 | AA20: =J20-I20 -> 7.073 | AB20: =K20-J20 -> 7.708 | AC20: =L20-K20 -> 8.546 | ... AG20: =P20-O20 -> 9.062 | AH20: 6.9983333
C21: kalorimetr č. SN 34582418 | D21: 9.502 | E21: 14.708 | F21: 18.176 | G21: 20.689 | H21: 22.973 | I21: 23.424 | J21: 23.795 | K21: 24.147 | L21: 24.508 | M21: 25.067 | N21: 26.386 | O21: 29.984 | P21: 35.137 | R21: =P21-D21 -> 25.635 | U21: xx
A22: 10 | B22: 10 | C22: vodoměr č. 190834091 | D22: 50.705 | E22: 52.598 | F22: 54.307 | G22: 56.003 | H22: 58.034 | I22: 59.718 | J22: 61.219 | K22: 63.021 | L22: 64.369 | M22: 65.91 | N22: 68.882 | O22: 69.54 | P22: 72.127 | Q22: =P22-D22 -> 21.422 | U22: 10 | V22: =E22-D22 -> 1.893 | W22: =F22-E22 -> 1.709 | X22: =G22-F22 -> 1.696 | Y22: =H22-G22 -> 2.031 | Z22: =I22-H22 -> 1.684 | AA22: =J22-I22 -> 1.501 | AB22: =K22-J22 -> 1.802 | AC22: =L22-K22 -> 1.348 | ... AG22: =P22-O22 -> 2.587 | AH22: 2.9007778
C23: kalorimetr č. SN 34582411 | D23: 6.162 | E23: 9.764 | F23: 11.912 | G23: 13.668 | H23: 14.576 | I23: 14.801 | J23: 15.001 | K23: 15.209 | L23: 15.407 | M23: 15.623 | N23: 16.164 | O23: 18.21 | P23: 21.182 | R23: =P23-D23 -> 15.02 | U23: xx
B24: spol.spotř. | C24: elektroměr č. 2080200096 | D24: 5432 | E24: 5790 | F24: 6035 | G24: 6284 | H24: 6537 | I24: 6795 | J24: 7029 | K24: 7288 | L24: 7553 | M24: 7882 | N24: 8301 | O24: 8847 | P24: 9091 | Q24: =SUM(Q4:Q23)+SUM(Q33:Q49) -> 928.197 | R24: =SUM(R4:R23) -> 225.029 | S24: =P24-D24 -> 3659 | U24: kWh
C26: patní vodoměr č. 190976791 | D26: 2853.6 | E26: 2947.2 | F26: 3029 | G26: 3112.3 | H26: 3204.2 | I26: 3291.3 | J26: 3368.6 | K26: 3445.1 | L26: 3524.5 | M26: 3600.3 | N26: 3683.1 | O26: 3761.5 | P26: 3852.3 | Q26: =P26-D26 -> 998.7
C27: patní kalorimetr č. /MWh | D27: 217.78 | E27: 230.62 | F27: 240.26 | G27: 248.61 | H27: 255.23 | I27: 258.3 | J27: 260.87 | K27: 263.42 | L27: 265.88 | M27: 268.69 | N27: 272.62 | O27: 280.72 | P27: 292.51 | R27: =(P27-D27)*3.6 -> 269.028 | S27: GJ
C28: patní kalorimetr č./kub.m | D28: 23652 | E28: 24223 | F28: 24648 | G28: 25022 | H28: 25394 | I28: 25631 | J28: 25890 | K28: 26196 | L28: 26509 | M28: 26778 | N28: 27119 | O28: 27506 | P28: 28066 | R28: =P28-D28 -> 4414 | S28: m3
B29: ='1850'!A29 -> fakturační vodoměr č. 63796 | D29: ='1850'!C29 -> 16304 | E29: ='1850'!D29 -> 16653.4 | F29: ='1850'!E29 -> 16977.5 | G29: ='1850'!F29 -> 17322.7 | H29: ='1850'!G29 -> 17680.1 | I29: ='1850'!H29 -> 18036.6 | J29: ='1850'!I29 -> 18355.9 | K29: ='1850'!J29 -> 18672 | ... P29: ='1850'!O29 -> 20281.1 | Q29: =P29-D29 -> 3977.1 | V29: studená voda
U31: byt | V31: leden | W31: únor | X31: březen | Y31: duben | Z31: květen | AA31: červen | AB31: červenec | AC31: srpen | AD31: září | AE31: říjen | AF31: listopad | AG31: prosinec
A33: 3 | B33: 2B | C33: vodoměr SV č. 200015745 | D33: 174.759 | E33: 181.916 | F33: 186.357 | G33: 190.222 | H33: 194.138 | I33: 197.488 | J33: 200.813 | K33: 204.5 | L33: 207.887 | M33: 210.828 | N33: 213.831 | O33: 216.348 | P33: 218.777 | Q33: =P33-D33 -> 44.018 | U33: 3 | V33: =E33-D33 -> 7.157 | W33: =F33-E33 -> 4.441 | X33: =G33-F33 -> 3.865 | Y33: =H33-G33 -> 3.916 | Z33: =I33-H33 -> 3.35 | AA33: =J33-I33 -> 3.325 | AB33: =K33-J33 -> 3.687 | AC33: =L33-K33 -> 3.387 | ... AG33: =P33-O33 -> 2.429 | AH33: 7.9723
A34: 6 | B34: 3B | C34: vodoměr SV č. 190834107 | D34: 104.722 | E34: 106.229 | F34: 107.501 | G34: 108.727 | H34: 110.007 | I34: 111.161 | J34: 112.276 | K34: 113.605 | L34: 115.298 | M34: 116.749 | N34: 118.781 | O34: 120.651 | P34: 122.338 | Q34: =P34-D34 -> 17.616 | U34: 6 | V34: =E34-D34 -> 1.507 | W34: =F34-E34 -> 1.272 | X34: =G34-F34 -> 1.226 | Y34: =H34-G34 -> 1.28 | Z34: =I34-H34 -> 1.154 | AA34: =J34-I34 -> 1.115 | AB34: =K34-J34 -> 1.329 | AC34: =L34-K34 -> 1.693 | ... AG34: =P34-O34 -> 1.687 | AH34: 2.9773
A35: 8 | B35: 5B | C35: vodoměr SV č. 190834094 | D35: 177.033 | E35: 183.651 | F35: 189.533 | G35: 195.366 | H35: 201.476 | I35: 207.228 | J35: 213.119 | K35: 219.274 | L35: 224.61 | M35: 228.122 | N35: 232.643 | O35: 236.458 | P35: 241.591 | Q35: =P35-D35 -> 64.558 | U35: 8 | V35: =E35-D35 -> 6.618 | W35: =F35-E35 -> 5.882 | X35: =G35-F35 -> 5.833 | Y35: =H35-G35 -> 6.11 | Z35: =I35-H35 -> 5.752 | AA35: =J35-I35 -> 5.891 | AB35: =K35-J35 -> 6.155 | AC35: =L35-K35 -> 5.336 | ... AG35: =P35-O35 -> 5.133 | AH35: 5.4084
A36: 11 | B36: 6B | C36: vodoměr SV č. 200015744 | D36: 13.701 | E36: 13.982 | F36: 14.204 | G36: 14.504 | H36: 14.885 | I36: 15.59 | J36: 15.692 | K36: 16.224 | L36: 17.457 | M36: 17.882 | N36: 18.053 | O36: 18.432 | P36: 19.042 | Q36: =P36-D36 -> 5.341 | U36: 11 | V36: =E36-D36 -> 0.281 | W36: =F36-E36 -> 0.222 | X36: =G36-F36 -> 0.3 | Y36: =H36-G36 -> 0.381 | Z36: =I36-H36 -> 0.705 | AA36: =J36-I36 -> 0.102 | AB36: =K36-J36 -> 0.532 | AC36: =L36-K36 -> 1.233 | ... AG36: =P36-O36 -> 0.61 | AH36: 0.4723
A37: 12 | B37: 8B | C37: vodoměr SV č. 190834128 | D37: 49.424 | E37: 50.922 | F37: 52.37 | G37: 53.793 | H37: 57.812 | I37: 60.969 | J37: 64.435 | K37: 66.421 | L37: 70.892 | M37: 74.039 | N37: 77.964 | O37: 81.041 | P37: 84.883 | Q37: =P37-D37 -> 35.459 | U37: 12 | V37: =E37-D37 -> 1.498 | W37: =F37-E37 -> 1.448 | X37: =G37-F37 -> 1.423 | Y37: =H37-G37 -> 4.019 | Z37: =I37-H37 -> 3.157 | AA37: =J37-I37 -> 3.466 | AB37: =K37-J37 -> 1.986 | AC37: =L37-K37 -> 4.471 | ... AG37: =P37-O37 -> 3.842 | AH37: 2.1434
C39: VODOMĚRY TEPLÁ VODA | V39: teplá voda
A40: 2 | B40: 2 | C40: vodoměr TUV č. 200105142 | D40: 56.786 | E40: 59.69 | F40: 62.11 | G40: 64.202 | H40: 66.744 | I40: 69.071 | J40: 70.758 | K40: 72.543 | L40: 74.379 | M40: 76.603 | N40: 79.565 | O40: 82.373 | P40: 85.202 | Q40: =P40-D40 -> 28.416 | U40: 2 | V40: =E40-D40 -> 2.904 | W40: =F40-E40 -> 2.42 | X40: =G40-F40 -> 2.092 | Y40: =H40-G40 -> 2.542 | Z40: =I40-H40 -> 2.327 | AA40: =J40-I40 -> 1.687 | AB40: =K40-J40 -> 1.785 | AC40: =L40-K40 -> 1.836 | ... AG40: =P40-O40 -> 2.829 | AH40: 4.0477
A41: 3 | B41: 2B | C41: vodoměr TUV č. 200105133 | D41: 111.664 | E41: 117.156 | F41: 120.549 | G41: 123.2 | H41: 125.604 | I41: 127.612 | J41: 129.559 | K41: 131.356 | L41: 132.882 | M41: 134.61 | N41: 136.297 | O41: 137.83 | P41: 139.535 | Q41: =P41-D41 -> 27.871 | U41: 3 | V41: =E41-D41 -> 5.492 | W41: =F41-E41 -> 3.393 | X41: =G41-F41 -> 2.651 | Y41: =H41-G41 -> 2.404 | Z41: =I41-H41 -> 2.008 | AA41: =J41-I41 -> 1.947 | AB41: =K41-J41 -> 1.797 | AC41: =L41-K41 -> 1.526 | ... AG41: =P41-O41 -> 1.705 | AH41: 4.1811
A42: 5 | B42: 3 | C42: vodoměr TUV č. 190049448 | D42: 12.609 | E42: 13.269 | F42: 13.689 | G42: 14.117 | H42: 14.517 | I42: 14.854 | J42: 15.178 | K42: 15.513 | L42: 15.804 | M42: 16.124 | N42: 16.489 | O42: 16.899 | P42: 17.24 | Q42: =P42-D42 -> 4.631 | U42: 5 | V42: =E42-D42 -> 0.66 | W42: =F42-E42 -> 0.42 | X42: =G42-F42 -> 0.428 | Y42: =H42-G42 -> 0.4 | Z42: =I42-H42 -> 0.337 | AA42: =J42-I42 -> 0.324 | AB42: =K42-J42 -> 0.335 | AC42: =L42-K42 -> 0.291 | ... AG42: =P42-O42 -> 0.341 | AH42: 0.3771
A43: 6 | B43: 3B | C43: vodoměr TUV č. 190049255 | D43: 82.099 | E43: 84.301 | F43: 86.059 | G43: 86.921 | H43: 88.092 | I43: 88.965 | J43: 89.585 | K43: 90.361 | L43: 90.98 | M43: 91.8 | N43: 93.07 | O43: 94.663 | P43: 96.178 | Q43: =P43-D43 -> 14.079 | U43: 6 | V43: =E43-D43 -> 2.202 | W43: =F43-E43 -> 1.758 | X43: =G43-F43 -> 0.862 | Y43: =H43-G43 -> 1.171 | Z43: =I43-H43 -> 0.873 | AA43: =J43-I43 -> 0.62 | AB43: =K43-J43 -> 0.776 | AC43: =L43-K43 -> 0.619 | ... AG43: =P43-O43 -> 1.515 | AH43: 1.5876
A44: 9 | B44: 5 | C44: vodoměr TUV č. 200105131 | D44: 37.255 | E44: 39.538 | F44: 41.597 | G44: 43.664 | H44: 45.737 | I44: 47.389 | J44: 48.827 | K44: 50.053 | L44: 51.387 | M44: 52.649 | N44: 54.198 | O44: 56.11 | P44: 58.106 | Q44: =P44-D44 -> 20.851 | U44: 9 | V44: =E44-D44 -> 2.283 | W44: =F44-E44 -> 2.059 | X44: =G44-F44 -> 2.067 | Y44: =H44-G44 -> 2.073 | Z44: =I44-H44 -> 1.652 | AA44: =J44-I44 -> 1.438 | AB44: =K44-J44 -> 1.226 | AC44: =L44-K44 -> 1.334 | ... AG44: =P44-O44 -> 1.996 | AH44: 4.4403
...

Sheet 1852
A2: 1852 | C2: ='1850'!C2 -> 44562 | D2: ='1850'!D2 -> 44593 | E2: ='1850'!E2 -> 44622 | F2: ='1850'!F2 -> 44652 | G2: ='1850'!G2 -> 44683 | H2: ='1850'!H2 -> 44713 | I2: ='1850'!I2 -> 44743 | J2: ='1850'!J2 -> 44774 | ... O2: ='1850'!O2 -> 44927 | P2: voda | Q2: teplo | Y2: spotřeby po měsících
A3: byt č. | C3: prosinec | D3: leden | E3: únor | F3: březen | G3: duben | H3: květen | I3: červen | J3: červenec | K3: srpen | L3: září | M3: říjen | N3: listopad | O3: prosinec | P3: m3 | Q3: GJ | T3: byt | U3: leden | V3: únor | W3: březen | X3: duben | Y3: květen | Z3: červen | AA3: červenec | AB3: srpen | AC3: září | AD3: říjen | AE3: listopad | AF3: prosinec
A4: 1 | B4: vodoměr č. 190834115 | C4: 317.269 | D4: 326.505 | E4: 337.162 | F4: 348.559 | G4: 361.034 | H4: 371.339 | I4: 381.692 | J4: 393.421 | K4: 403.431 | L4: 414.272 | M4: 425.64 | N4: 435.605 | O4: 445.719 | P4: =O4-C4 -> 128.45 | T4: 1 | U4: =D4-C4 -> 9.236 | V4: =E4-D4 -> 10.657 | W4: =F4-E4 -> 11.397 | X4: =G4-F4 -> 12.475 | Y4: =H4-G4 -> 10.305 | Z4: =I4-H4 -> 10.353 | AA4: =J4-I4 -> 11.729 | AB4: =K4-J4 -> 10.01 | ... AF4: =O4-N4 -> 10.114
B5: kalorimetr č. SN 34582388 | C5: 7.696 | D5: 11.985 | E5: 15.113 | F5: 18.093 | G5: 20.569 | H5: 21.192 | I5: 21.83 | J5: 22.405 | K5: 22.94 | L5: 23.516 | M5: 24.224 | N5: 27.03 | O5: 30.733 | Q5: =O5-C5 -> 23.037
A6: 2 | B6: vodoměr č. 190834121 | C6: 149.209 | D6: 155.582 | E6: 162.014 | F6: 169.727 | G6: 179.151 | H6: 186.984 | I6: 194.158 | J6: 200.217 | K6: 206.45 | L6: 213.676 | M6: 221.521 | N6: 228.753 | O6: 235.605 | P6: =O6-C6 -> 86.396 | T6: 2 | U6: =D6-C6 -> 6.373 | V6: =E6-D6 -> 6.432 | W6: =F6-E6 -> 7.713 | X6: =G6-F6 -> 9.424 | Y6: =H6-G6 -> 7.833 | Z6: =I6-H6 -> 7.174 | AA6: =J6-I6 -> 6.059 | AB6: =K6-J6 -> 6.233 | ... AF6: =O6-N6 -> 6.852
B7: kalorimetr č. SN 34582394 | C7: 4.266 | D7: 6.632 | E7: 8.705 | F7: 10.198 | G7: 11.295 | H7: 11.996 | I7: 12.527 | J7: 12.977 | K7: 13.404 | L7: 13.858 | M7: 14.427 | N7: 15.169 | O7: 16.116 | Q7: =O7-C7 -> 11.85
A8: 3 | B8: vodoměr č. 200015760 | C8: 203.867 | D8: 215.073 | E8: 225.261 | F8: 236.637 | G8: 249.917 | H8: 260.146 | I8: 268.121 | J8: 281.695 | K8: 290.071 | L8: 301.016 | M8: 311.822 | N8: 324.507 | O8: 338.053 | P8: =O8-C8 -> 134.186 | T8: 3 | U8: =D8-C8 -> 11.206 | V8: =E8-D8 -> 10.188 | W8: =F8-E8 -> 11.376 | X8: =G8-F8 -> 13.28 | Y8: =H8-G8 -> 10.229 | Z8: =I8-H8 -> 7.975 | AA8: =J8-I8 -> 13.574 | AB8: =K8-J8 -> 8.376 | ... AF8: =O8-N8 -> 13.546
B9: kalorimetr č. SN 34582389 | C9: 10.111 | D9: 15.425 | E9: 19.536 | F9: 23.513 | G9: 27.119 | H9: 27.83 | I9: 28.302 | J9: 28.932 | K9: 29.318 | L9: 30.692 | M9: 33.116 | N9: 37.454 | O9: 43.311 | Q9: =O9-C9 -> 33.2
A10: 4 | B10: vodoměr č. 190834096 | C10: 310.612 | D10: 318.96 | E10: 325.61 | F10: 333.657 | G10: 341.595 | H10: 349.681 | I10: 356.103 | J10: 364.443 | K10: 371.62 | L10: 380.33 | M10: 389.31 | N10: 398.562 | O10: 407.947 | P10: =O10-C10 -> 97.335 | T10: 4 | U10: =D10-C10 -> 8.348 | V10: =E10-D10 -> 6.65 | W10: =F10-E10 -> 8.047 | X10: =G10-F10 -> 7.938 | Y10: =H10-G10 -> 8.086 | Z10: =I10-H10 -> 6.422 | AA10: =J10-I10 -> 8.34 | AB10: =K10-J10 -> 7.177 | ... AF10: =O10-N10 -> 9.385
B11: kalorimetr č. SN 34582395 | C11: 9.533 | D11: 14.474 | E11: 18.338 | F11: 21.601 | G11: 23.974 | H11: 24.706 | I11: 25.247 | J11: 25.86 | K11: 26.367 | L11: 27.336 | M11: 29.128 | N11: 32.72 | O11: 37.265 | Q11: =O11-C11 -> 27.732
A12: 5 | B12: vodoměr č. 190834110 | C12: 133.155 | D12: 144.367 | E12: 153.875 | F12: 164.915 | G12: 175.966 | H12: 188.222 | I12: 198.363 | J12: 203.37 | K12: 210.77 | L12: 216.303 | M12: 224.132 | N12: 230.225 | O12: 236.272 | P12: =O12-C12 -> 103.117 | T12: 5 | U12: =D12-C12 -> 11.212 | V12: =E12-D12 -> 9.508 | W12: =F12-E12 -> 11.04 | X12: =G12-F12 -> 11.051 | Y12: =H12-G12 -> 12.256 | Z12: =I12-H12 -> 10.141 | AA12: =J12-I12 -> 5.007 | AB12: =K12-J12 -> 7.4 | ... AF12: =O12-N12 -> 6.047
B13: kalorimetr č. SN 34582393 | C13: 4.064 | D13: 6.13 | E13: 7.957 | F13: 9.796 | G13: 11.348 | H13: 12.451 | I13: 13.309 | J13: 13.786 | K13: 14.335 | L13: 14.93 | M13: 15.974 | N13: 17.789 | O13: 20.024 | Q13: =O13-C13 -> 15.96
A14: 6 | B14: vodoměr č. 190834127 | C14: 215.901 | D14: 222.927 | E14: 230.856 | F14: 238.795 | G14: 245.888 | H14: 255.529 | I14: 264.629 | J14: 272.248 | K14: 276.836 | L14: 284.46 | M14: 295.428 | N14: 305.71 | O14: 317.583 | P14: =O14-C14 -> 101.682 | T14: 6 | U14: =D14-C14 -> 7.026 | V14: =E14-D14 -> 7.929 | W14: =F14-E14 -> 7.939 | X14: =G14-F14 -> 7.093 | Y14: =H14-G14 -> 9.641 | Z14: =I14-H14 -> 9.1 | AA14: =J14-I14 -> 7.619 | AB14: =K14-J14 -> 4.588 | ... AF14: =O14-N14 -> 11.873
B15: kalorimetr č. SN 34582399 | C15: 6.688 | D15: 10.92 | E15: 14.606 | F15: 17.682 | G15: 19.364 | H15: 20.205 | I15: 20.868 | J15: 21.353 | K15: 21.694 | L15: 22.211 | M15: 23.476 | N15: 26.119 | O15: 30.804 | Q15: =O15-C15 -> 24.116
A16: 7 | B16: vodoměr č. 190834123 | C16: 29.521 | D16: 30.205 | E16: 30.828 | F16: 31.389 | G16: 31.924 | H16: 32.615 | I16: 33.54 | J16: 34.752 | K16: 35.637 | L16: 36.349 | M16: 37.148 | N16: 37.65 | O16: 38.227 | P16: =O16-C16 -> 8.706 | T16: 7 | U16: =D16-C16 -> 0.684 | V16: =E16-D16 -> 0.623 | W16: =F16-E16 -> 0.561 | X16: =G16-F16 -> 0.535 | Y16: =H16-G16 -> 0.691 | Z16: =I16-H16 -> 0.925 | AA16: =J16-I16 -> 1.212 | AB16: =K16-J16 -> 0.885 | ... AF16: =O16-N16 -> 0.577
B17: kalorimetr č. SN 34582404 | C17: 3.464 | D17: 5.717 | E17: 6.836 | F17: 7.177 | G17: 7.703 | H17: 7.723 | I17: 7.75 | J17: 7.778 | K17: 7.795 | L17: 7.904 | M17: 8.126 | N17: 9.889 | O17: 12.76 | Q17: =O17-C17 -> 9.296
A18: 8 | B18: vodoměr č. 190834118 | C18: 249.053 | D18: 259.341 | E18: 267.363 | F18: 277.845 | G18: 287.833 | H18: 298.144 | I18: 306.303 | J18: 314.792 | K18: 320.637 | L18: 327.084 | M18: 336.817 | N18: 345.823 | O18: 355.342 | P18: =O18-C18 -> 106.289 | T18: 8 | U18: =D18-C18 -> 10.288 | V18: =E18-D18 -> 8.022 | W18: =F18-E18 -> 10.482 | X18: =G18-F18 -> 9.988 | Y18: =H18-G18 -> 10.311 | Z18: =I18-H18 -> 8.159 | AA18: =J18-I18 -> 8.489 | AB18: =K18-J18 -> 5.845 | ... AF18: =O18-N18 -> 9.519
B19: kalorimetr č. SN 34582406 | C19: 5.175 | D19: 8.488 | E19: 10.284 | F19: 11.678 | G19: 12.896 | H19: 13.53 | I19: 14.013 | J19: 14.516 | K19: 14.888 | L19: 15.302 | M19: 15.938 | N19: 17.306 | O19: 19.528 | Q19: =O19-C19 -> 14.353
A20: 9 | B20: vodoměr č. 190834113 | C20: 143.658 | D20: =C20+11.3 -> 154.958 | E20: =D20+10.9 -> 165.858 | F20: =E20+11.3 -> 177.158 | G20: =F20+11.5 -> 188.658 | H20: =G20+11 -> 199.658 | I20: =H20+9.8 -> 209.458 | J20: =I20+8 -> 217.458 | K20: =J20+10.1 -> 227.558 | L20: =K20+10.7 -> 238.258 | M20: =L20+12.6 -> 250.858 | N20: 0.434 | O20: 11.177 | P20: =O20-G33+G32-C20 -> 126.077 | T20: 9 | U20: =D20-C20 -> 11.3 | V20: =E20-D20 -> 10.9 | W20: =F20-E20 -> 11.3 | X20: =G20-F20 -> 11.5 | Y20: =H20-G20 -> 11 | Z20: =I20-H20 -> 9.8 | AA20: =J20-I20 -> 8 | AB20: =K20-J20 -> 10.1 | ... AD20: =M20-L20 -> 12.6 | AE20: =N20+G32-M20 -> 8.134 | AF20: =O20+H32-N20 -> 10.743
B21: kalorimetr č. SN 34582405 | C21: 11.394 | D21: 16.907 | E21: 21.452 | F21: 25.368 | G21: 29.279 | H21: 30.314 | I21: 31.04 | J21: 31.604 | K21: 32.292 | L21: 33.1 | M21: 34.177 | N21: 37.715 | O21: 43.025 | Q21: =O21-C21 -> 31.631
A22: 10 | B22: vodoměr č. 190834129 | C22: 199.254 | D22: 205.614 | E22: 210.528 | F22: 217.336 | G22: 225.373 | H22: 231.403 | I22: 239.138 | J22: 243.989 | K22: 251.802 | L22: 259.086 | M22: 267.636 | N22: 275.302 | O22: 283.974 | P22: =O22-C22 -> 84.72 | T22: 10 | U22: =D22-C22 -> 6.36 | V22: =E22-D22 -> 4.914 | W22: =F22-E22 -> 6.808 | X22: =G22-F22 -> 8.037 | Y22: =H22-G22 -> 6.03 | Z22: =I22-H22 -> 7.735 | AA22: =J22-I22 -> 4.851 | AB22: =K22-J22 -> 7.813 | ... AF22: =O22-N22 -> 8.672
B23: kalorimetr č. SN 34582407 | C23: 6.284 | D23: 10.164 | E23: 12.529 | F23: 14.884 | G23: 16.61 | H23: 17.163 | I23: 17.741 | J23: 18.13 | K23: 18.663 | L23: 19.361 | M23: 20.903 | N23: 24.081 | O23: 28.409 | Q23: =O23-C23 -> 22.125
P24: =SUM(P4:P23) -> 976.958 | Q24: =SUM(Q4:Q23) -> 213.3
A25: spol.spotř. | B25: elektroměr č. 2080200097 | C25: 5389 | D25: 5570 | E25: 5745 | F25: 5933 | G25: 6154 | H25: 6344 | I25: 6534 | J25: 6715 | K25: 6930 | L25: 7119 | M25: 7337 | N25: 7544 | O25: 7868 | R25: =O25-C25 -> 2479
B26: patní vodoměr č. 190976792 | C26: 2353 | D26: 2444.3 | E26: 2528.5 | F26: 2624.6 | G26: 2726.1 | H26: 2822.1 | I26: 2908.5 | J26: 2991.5 | K26: 3067.6 | L26: 3152 | M26: 3251.5 | N26: 3341.2 | O26: 3438.2 | P26: =O26-C26 -> 1085.2
B27: patní kalorimetr č./MWh | C27: 165.58 | D27: 176.79 | E27: 184.79 | F27: 191.59 | G27: 197.05 | H27: 198.51 | I27: 199.6 | J27: 200.39 | K27: 201.07 | L27: 202.47 | M27: 205.26 | N27: 212.76 | O27: 223.61 | Q27: =(O27-C27)*3.6 -> 208.908 | R27: GJ
B28: patní kalorimetr č./kub.m | C28: 7312 | D28: 7617 | E28: 7825 | F28: 8019 | G28: 8164 | H28: 8202 | I28: 8234 | J28: 8260 | K28: 8283 | L28: 8322 | M28: 8399 | N28: 8584 | O28: 8842 | Q28: =O28-C28 -> 1530 | R28: m3
A29: ='1850'!A29 -> fakturační vodoměr č. 63796 | C29: ='1850'!C29 -> 16304 | D29: ='1850'!D29 -> 16653.4 | E29: ='1850'!E29 -> 16977.5 | F29: ='1850'!F29 -> 17322.7 | G29: ='1850'!G29 -> 17680.1 | H29: ='1850'!H29 -> 18036.6 | I29: ='1850'!I29 -> 18355.9 | J29: ='1850'!J29 -> 18672 | ... O29: ='1850'!O29 -> 20281.1 | P29: =O29-C29 -> 3977.1
C31: byt | D31: Reklamace - výměna | F31: číslo | G31: stav
C32: 9 | D32: 43950 | E32: starý | F32: 190834113 | G32: =M20+7.7 -> 258.558
E33: nový | F33: 221525380 | G33: 0
D35: Výměna elektroměru
D36: 43956 | E36: starý
E37: nový
B41: vodoměr č. 190834113 | C41: 143.658 | D41: 145.286 | E41: 146.443 | F41: 147.384 | G41: 148.159 | H41: 148.938 | I41: 149.689 | J41: 150.164 | K41: 150.705 | L41: 151.354 | M41: 152.571 | N41: 0.434 | O41: 11.177 | P41: =O41+N43-C41 -> 20.979 | T41: 9 | U41: =D41-C41 -> 1.628 | V41: =E41-D41 -> 1.157 | W41: =F41-E41 -> 0.941 | X41: =G41-F41 -> 0.775 | Y41: =H41-G41 -> 0.779 | Z41: =I41-H41 -> 0.751 | AA41: =J41-I41 -> 0.475 | AB41: =K41-J41 -> 0.541 | ... AD41: =M41-L41 -> 1.217 | AE41: =N41+N43-M41 -> 1.323 | AF41: =O41+H53-N41 -> 10.743
M43: 44681 | N43: 153.46

Sheet 1853
A2: 1853 | C2: ='1850'!C2 -> 44562 | D2: ='1850'!D2 -> 44593 | E2: ='1850'!E2 -> 44622 | F2: ='1850'!F2 -> 44652 | G2: ='1850'!G2 -> 44683 | H2: ='1850'!H2 -> 44713 | I2: ='1850'!I2 -> 44743 | J2: ='1850'!J2 -> 44774 | ... O2: ='1850'!O2 -> 44927 | P2: Voda | Q2: Teplo | R2: Elektr | Y2: spotřeby po měsících
A3: byt č. | C3: prosinec | D3: leden | E3: únor | F3: březen | G3: duben | H3: květen | I3: červen | J3: červenec | K3: srpen | L3: září | M3: říjen | N3: listopad | O3: prosinec | P3: m3 | Q3: GJ | R3: KWh | T3: byt | U3: leden | V3: únor | W3: březen | X3: duben | Y3: květen | Z3: červen | AA3: červenec | AB3: srpen | AC3: září | AD3: říjen | AE3: listopad | AF3: prosinec
A4: 1 | B4: vodoměr č. 190834100 | C4: 380.509 | D4: 394.372 | E4: 407.693 | F4: 421.132 | G4: 435.601 | H4: 446.898 | I4: 458.172 | J4: 469.845 | K4: 481.991 | L4: 492.673 | M4: 505.612 | N4: 517.252 | O4: 530.581 | P4: =O4-C4 -> 150.072 | T4: 1 | U4: =D4-C4 -> 13.863 | V4: =E4-D4 -> 13.321 | W4: =F4-E4 -> 13.439 | X4: =G4-F4 -> 14.469 | Y4: =H4-G4 -> 11.297 | Z4: =I4-H4 -> 11.274 | AA4: =J4-I4 -> 11.673 | AB4: =K4-J4 -> 12.146 | ... AF4: =O4-N4 -> 13.329
B5: kalorimetr č. SN 34582390 | C5: 9.528 | D5: 15.184 | E5: 20.138 | F5: 24.396 | G5: 27.007 | H5: 27.72 | I5: 28.355 | J5: 28.912 | K5: 29.455 | L5: 30.131 | M5: 30.977 | N5: 33.285 | O5: 37.232 | Q5: =O5-C5 -> 27.704
A6: 2 | B6: vodoměr č. 190906789 | C6: 212.804 | D6: 219.523 | E6: 226.242 | F6: 231.717 | G6: 240.123 | H6: 246.037 | I6: 253.288 | J6: 261.277 | K6: 268.711 | L6: 275.619 | M6: 283.158 | N6: 289.962 | O6: 294.937 | P6: =O6-C6 -> 82.133 | T6: 2 | U6: =D6-C6 -> 6.719 | V6: =E6-D6 -> 6.719 | W6: =F6-E6 -> 5.475 | X6: =G6-F6 -> 8.406 | Y6: =H6-G6 -> 5.914 | Z6: =I6-H6 -> 7.251 | AA6: =J6-I6 -> 7.989 | AB6: =K6-J6 -> 7.434 | ... AF6: =O6-N6 -> 4.975
B7: kalorimetr č. SN 34582422 | C7: 2.426 | D7: 3.62 | E7: 4.768 | F7: 5.584 | G7: 6.281 | H7: 6.52 | I7: 6.855 | J7: 7.207 | K7: 7.5 | L7: 7.834 | M7: 8.256 | N7: 9.047 | O7: 10.275 | Q7: =O7-C7 -> 7.849
A8: 3 | B8: vodoměr č. 190906786 | C8: 93.933 | D8: 100.429 | E8: 107.476 | F8: 115.911 | G8: 124.674 | H8: 132.17 | I8: 137.849 | J8: 142.352 | K8: 146.94 | L8: 152.019 | M8: 158.267 | N8: 165.252 | O8: 173.735 | P8: =O8-C8 -> 79.802 | T8: 3 | U8: =D8-C8 -> 6.496 | V8: =E8-D8 -> 7.047 | W8: =F8-E8 -> 8.435 | X8: =G8-F8 -> 8.763 | Y8: =H8-G8 -> 7.496 | Z8: =I8-H8 -> 5.679 | AA8: =J8-I8 -> 4.503 | AB8: =K8-J8 -> 4.588 | ... AF8: =O8-N8 -> 8.483
B9: kalorimetr č. SN 34582386 | C9: 6.53 | D9: 10.82 | E9: 14.235 | F9: 18.086 | G9: 20.495 | H9: 20.857 | I9: 21.125 | J9: 21.337 | K9: 21.54 | L9: 21.999 | M9: 22.938 | N9: 25.409 | O9: 29.607 | Q9: =O9-C9 -> 23.077
A10: 4 | B10: vodoměr č. 190834105 | C10: 146.769 | D10: 152.192 | E10: 156.441 | F10: 161.376 | G10: 165.999 | H10: 169.322 | I10: 173.204 | J10: 174.966 | K10: 177.5 | L10: 181.871 | M10: 186.895 | N10: 190.746 | O10: 194.525 | P10: =O10-C10 -> 47.756 | T10: 4 | U10: =D10-C10 -> 5.423 | V10: =E10-D10 -> 4.249 | W10: =F10-E10 -> 4.935 | X10: =G10-F10 -> 4.623 | Y10: =H10-G10 -> 3.323 | Z10: =I10-H10 -> 3.882 | AA10: =J10-I10 -> 1.762 | AB10: =K10-J10 -> 2.534 | ... AF10: =O10-N10 -> 3.779
B11: kalorimetr č. SN 34582421 | C11: 3.388 | D11: 5.46 | E11: 6.43 | F11: 7.096 | G11: 7.634 | H11: 8.007 | I11: 8.36 | J11: 8.478 | K11: 8.501 | L11: 8.718 | M11: 9.007 | N11: 10.153 | O11: 12.095 | Q11: =O11-C11 -> 8.707
A12: 5 | B12: vodoměr č. 190906792 | C12: 226.914 | D12: 235.952 | E12: 244.675 | F12: 252.571 | G12: 260.595 | H12: 266.943 | I12: 272.875 | J12: 279.208 | K12: 284.736 | L12: 290.574 | M12: 296.953 | N12: 303.79 | O12: 312.23 | P12: =O12-C12 -> 85.316 | T12: 5 | U12: =D12-C12 -> 9.038 | V12: =E12-D12 -> 8.723 | W12: =F12-E12 -> 7.896 | X12: =G12-F12 -> 8.024 | Y12: =H12-G12 -> 6.348 | Z12: =I12-H12 -> 5.932 | AA12: =J12-I12 -> 6.333 | AB12: =K12-J12 -> 5.528 | ... AF12: =O12-N12 -> 8.44
B13: kalorimetr č. SN 34582387 | C13: 3.187 | D13: 4.59 | E13: 5.892 | F13: 6.398 | G13: 7.091 | H13: 7.399 | I13: 7.654 | J13: 7.936 | K13: 8.158 | L13: 8.441 | M13: 8.873 | N13: 10.013 | O13: 11.632 | Q13: =O13-C13 -> 8.445
A14: 6 | B14: vodoměr č. 190906795 | C14: 126.237 | D14: 130.696 | E14: 135.298 | F14: 139.259 | G14: 143.641 | H14: 148.204 | I14: 152.458 | J14: 156.486 | K14: 159.134 | L14: 161.545 | M14: 165.743 | N14: 169.883 | O14: 173.968 | P14: =O14-C14 -> 47.731 | T14: 6 | U14: =D14-C14 -> 4.459 | V14: =E14-D14 -> 4.602 | W14: =F14-E14 -> 3.961 | X14: =G14-F14 -> 4.382 | Y14: =H14-G14 -> 4.563 | Z14: =I14-H14 -> 4.254 | AA14: =J14-I14 -> 4.028 | AB14: =K14-J14 -> 2.648 | ... AF14: =O14-N14 -> 4.085
B15: kalorimetr č. SN 34582420 | C15: 5.642 | D15: 7.981 | E15: 9.463 | F15: 10.738 | G15: 11.547 | H15: 11.774 | I15: 11.942 | J15: 12.123 | K15: 12.256 | L15: 12.365 | M15: 12.535 | N15: 14.506 | O15: 17.234 | Q15: =O15-C15 -> 11.592
A16: 7 | B16: vodoměr č. 190834103 | C16: 287.97 | D16: 299.51 | E16: 311.64 | F16: 325.426 | G16: 335.817 | H16: 347.682 | I16: 355.078 | J16: 363.852 | K16: 372.927 | L16: 383.84 | M16: 396.382 | N16: 407.592 | O16: 419.101 | P16: =O16-C16 -> 131.131 | T16: 7 | U16: =D16-C16 -> 11.54 | V16: =E16-D16 -> 12.13 | W16: =F16-E16 -> 13.786 | X16: =G16-F16 -> 10.391 | Y16: =H16-G16 -> 11.865 | Z16: =I16-H16 -> 7.396 | AA16: =J16-I16 -> 8.774 | AB16: =K16-J16 -> 9.075 | ... AF16: =O16-N16 -> 11.509
B17: kalorimetr č. SN 34582412 | C17: 8.727 | D17: 13.206 | E17: 16.898 | F17: 19.994 | G17: 22.146 | H17: 23.056 | I17: 23.577 | J17: 24.165 | K17: 24.72 | L17: 25.446 | M17: 26.613 | N17: 29.53 | O17: 33.724 | Q17: =O17-C17 -> 24.997
A18: 8 | B18: vodoměr č. 190834101 | C18: 184.437 | D18: 191.794 | E18: 198.198 | F18: 205.242 | G18: 213.098 | H18: 218.506 | I18: 224.14 | J18: 228.888 | K18: 233.397 | L18: 238.436 | M18: 246.487 | N18: 252.834 | O18: 260.688 | P18: =O18-C18 -> 76.251 | T18: 8 | U18: =D18-C18 -> 7.357 | V18: =E18-D18 -> 6.404 | W18: =F18-E18 -> 7.044 | X18: =G18-F18 -> 7.856 | Y18: =H18-G18 -> 5.408 | Z18: =I18-H18 -> 5.634 | AA18: =J18-I18 -> 4.748 | AB18: =K18-J18 -> 4.509 | ... AF18: =O18-N18 -> 7.854
B19: kalorimetr č. SN 34582403 | C19: 6.768 | D19: 10.201 | E19: 12.462 | F19: 13.939 | G19: 14.935 | H19: 15.201 | I19: 15.424 | J19: 15.638 | K19: 15.837 | L19: 16.144 | M19: 16.728 | N19: 19.354 | O19: 23.2 | Q19: =O19-C19 -> 16.432
A20: 9 | B20: vodoměr č. 190834108 | C20: 103.436 | D20: 107.644 | E20: 111.421 | F20: 115.406 | G20: 119.642 | H20: 123.256 | I20: 127.333 | J20: 131.153 | K20: 134.71 | L20: 137.912 | M20: 141.122 | N20: 144.279 | O20: 147.58 | P20: =O20-C20 -> 44.144 | T20: 9 | U20: =D20-C20 -> 4.208 | V20: =E20-D20 -> 3.777 | W20: =F20-E20 -> 3.985 | X20: =G20-F20 -> 4.236 | Y20: =H20-G20 -> 3.614 | Z20: =I20-H20 -> 4.077 | AA20: =J20-I20 -> 3.82 | AB20: =K20-J20 -> 3.557 | ... AF20: =O20-N20 -> 3.301
B21: kalorimetr č. SN 34582409 | C21: 6.771 | D21: 11.017 | E21: 13.907 | F21: 15.729 | G21: 17.121 | H21: 17.418 | I21: 17.682 | J21: 17.937 | K21: 18.195 | L21: 18.477 | M21: 19.178 | N21: 21.865 | O21: 26.124 | Q21: =O21-C21 -> 19.353
A22: 10 | B22: vodoměr č. 190906953 | C22: 129.324 | D22: 132.334 | E22: 134.89 | F22: 137.456 | G22: 140.283 | H22: 143.23 | I22: 146.032 | J22: 148.345 | K22: 151.514 | L22: 153.553 | M22: 157.095 | N22: 159.52 | O22: 162.723 | P22: =O22-C22 -> 33.399 | T22: 10 | U22: =D22-C22 -> 3.01 | V22: =E22-D22 -> 2.556 | W22: =F22-E22 -> 2.566 | X22: =G22-F22 -> 2.827 | Y22: =H22-G22 -> 2.947 | Z22: =I22-H22 -> 2.802 | AA22: =J22-I22 -> 2.313 | AB22: =K22-J22 -> 3.169 | ... AF22: =O22-N22 -> 3.203
B23: kalorimetr č. SN 34582415 | C23: 7.357 | D23: 11.217 | E23: 14.301 | F23: 16.754 | G23: 18.267 | H23: 18.417 | I23: 18.536 | J23: 18.621 | K23: 18.779 | L23: 19.064 | M23: 20.334 | N23: 23.168 | O23: 27.286 | Q23: =O23-C23 -> 19.929
B24: elektroměr č.2080200105 dům | C24: 4181 | D24: 4360 | E24: 4523 | F24: 4709 | G24: 4891 | H24: 5078 | I24: 5251 | J24: 5431 | K24: 5609 | L24: 5788 | M24: 5974 | N24: 6153 | O24: 6338 | P24: =SUM(P4:P23) -> 777.735 | Q24: =SUM(Q4:Q23) -> 168.085 | R24: =O24-C24 -> 2157
A25: spol.spotř. | B25: elektroměr č. 2080200100 VO | C25: 6580 | D25: 7082 | E25: 7522 | F25: 7895 | G25: 8220 | H25: 8492 | I25: 8737 | J25: 8985 | K25: 9270 | L25: 9585 | M25: 9977 | N25: 10392 | O25: 10842 | R25: =O25-C25 -> 4262 | T25: Zahrada | U25: =D26-C26 -> 0 | V25: =E26-D26 -> 0 | W25: =F26-E26 -> 0 | X25: =G26-F26 -> 0 | Y25: =H26-G26 -> 20.535 | Z25: =I26-H26 -> 18.043 | AA25: =J26-I26 -> 26.683 | AB25: =K26-J26 -> 17.652 | ... AF25: =O26-N26 -> 0
B26: vodoměr areál č.200076532 | C26: 318.911 | D26: 318.911 | E26: 318.911 | F26: 318.911 | G26: 318.911 | H26: 339.446 | I26: 357.489 | J26: 384.172 | K26: 401.824 | L26: 411.836 | M26: 415.488 | N26: 416.747 | O26: 416.747 | P26: =O26-C26 -> 97.836 | Q26: =ROUND(P26,0) -> 98 | R26: zahrada
B27: patní vodoměr č. 190976789 | C27: 2345.2 | D27: 2423.7 | E27: 2500.5 | F27: 2578.3 | G27: 2659 | H27: 2749.6 | I27: 2831.1 | J27: 2919.8 | K27: 2998.4 | L27: 3070.3 | M27: 3151.4 | N27: 3222.3 | O27: 3297.6 | P27: =O27-C27 -> 952.4 | Q27: =P27-Q26 -> 854.4 | R27: byty
B28: patní kalorimetr č./ MWh | C28: 155.36 | D28: 165.29 | E28: 172.88 | F28: 179.21 | G28: 183.71 | H28: 185.44 | I28: 187.01 | J28: 188.06 | K28: 188.61 | L28: 189.49 | M28: 191.3 | N28: 197.49 | O28: 206.92 | Q28: =(O28-C28)*3.6 -> 185.616 | R28: GJ
B29: patní kalorimetr č. /kub.m | C29: 11759 | D29: 12063 | E29: 12297 | F29: 12508 | G29: 12680 | H29: 12787 | I29: 12907 | J29: 12979 | K29: 12996 | L29: 13022 | M29: 13069 | N29: 13220 | O29: 13450 | Q29: =O29-C29 -> 1691 | R29: m3
A30: ='1850'!A29 -> fakturační vodoměr č. 63796 | C30: ='1850'!C29 -> 16304 | D30: ='1850'!D29 -> 16653.4 | E30: ='1850'!E29 -> 16977.5 | F30: ='1850'!F29 -> 17322.7 | G30: ='1850'!G29 -> 17680.1 | H30: ='1850'!H29 -> 18036.6 | I30: ='1850'!I29 -> 18355.9 | J30: ='1850'!J29 -> 18672 | ... O30: ='1850'!O29 -> 20281.1 | P30: =O30-C30 -> 3977.1
A32: 11 | B32: vodoměr SV č. 11717149 | C32: 9.369 | D32: 9.644 | E32: 9.908 | F32: 10.296 | G32: 10.618 | H32: 11.084 | I32: 11.542 | J32: 11.908 | K32: 12.288 | L32: 12.796 | M32: 13.195 | N32: 13.667 | O32: 13.972 | P32: =O32-C32 -> 4.603 | S32: SV | T32: 11 | U32: =D32-C32 -> 0.275 | V32: =E32-D32 -> 0.264 | W32: =F32-E32 -> 0.388 | X32: =G32-F32 -> 0.322 | Y32: =H32-G32 -> 0.466 | Z32: =I32-H32 -> 0.458 | AA32: =J32-I32 -> 0.366 | AB32: =K32-J32 -> 0.38 | ... AF32: =O32-N32 -> 0.305
B33: vodoměr TV č. 11683196 | C33: 0.594 | D33: 0.613 | E33: 0.622 | F33: 0.627 | G33: 0.633 | H33: 0.662 | I33: 0.675 | J33: 0.699 | K33: 0.701 | L33: 0.715 | M33: 0.735 | N33: 0.751 | O33: 0.76 | P33: =O33-C33 -> 0.166 | S33: TV | U33: =D33-C33 -> 0.019 | V33: =E33-D33 -> 0.009 | W33: =F33-E33 -> 0.005 | X33: =G33-F33 -> 0.006 | Y33: =H33-G33 -> 0.029 | Z33: =I33-H33 -> 0.013 | AA33: =J33-I33 -> 0.024 | AB33: =K33-J33 -> 0.002 | ... AF33: =O33-N33 -> 0.009
D35: Výměna elektroměru DŮM
D36: 43956 | E36: starý
E37: nový
D38: Výměna elektroměru AREÁL
D39: 43956 | E39: starý
E40: nový

Sheet 1854
A2: 1854 | C2: ='1850'!C2 -> 44562 | D2: ='1850'!D2 -> 44593 | E2: ='1850'!E2 -> 44622 | F2: ='1850'!F2 -> 44652 | G2: ='1850'!G2 -> 44683 | H2: ='1850'!H2 -> 44713 | I2: ='1850'!I2 -> 44743 | J2: ='1850'!J2 -> 44774 | ... O2: ='1850'!O2 -> 44927 | P2: voda | Q2: teplo | Y2: spotřeby po měsících
A3: byt č. | C3: prosinec | D3: leden | E3: únor | F3: březen | G3: duben | H3: květen | I3: červen | J3: červenec | K3: srpen | L3: září | M3: říjen | N3: listopad | O3: prosinec | P3: m3 | Q3: GJ | T3: byt | U3: leden | V3: únor | W3: březen | X3: duben | Y3: květen | Z3: červen | AA3: červenec | AB3: srpen | AC3: září | AD3: říjen | AE3: listopad | AF3: prosinec
A4: 1 | B4: vodoměr č. 190906992 | C4: 190.77 | D4: 198.964 | E4: 205.613 | F4: 215.274 | G4: 222.737 | H4: 230.268 | I4: 235.797 | J4: 238.097 | K4: 243.088 | L4: 250.11 | M4: 257.155 | N4: 264.354 | O4: 270.752 | P4: =O4-C4 -> 79.982 | T4: 1 | U4: =D4-C4 -> 8.194 | V4: =E4-D4 -> 6.649 | W4: =F4-E4 -> 9.661 | X4: =G4-F4 -> 7.463 | Y4: =H4-G4 -> 7.531 | Z4: =I4-H4 -> 5.529 | AA4: =J4-I4 -> 2.3 | AB4: =K4-J4 -> 4.991 | ... AF4: =O4-N4 -> 6.398
B5: kalorimetr č. SN 34672835 | C5: 6.792 | D5: 10.999 | E5: 14.319 | F5: 17.305 | G5: 19.445 | H5: 19.967 | I5: 20.251 | J5: 20.451 | K5: 20.726 | L5: 21.145 | M5: 22.543 | N5: 25.621 | O5: 29.809 | Q5: =O5-C5 -> 23.017
A6: 2 | B6: vodoměr č. 190906991 | C6: 130.154 | D6: 135.875 | E6: 140.738 | F6: 147.232 | G6: 153.132 | H6: 158.748 | I6: 163.806 | J6: 169.224 | K6: 175.724 | L6: 181.555 | M6: 186.962 | N6: 192.432 | O6: 199.445 | P6: =O6-C6 -> 69.291 | T6: 2 | U6: =D6-C6 -> 5.721 | V6: =E6-D6 -> 4.863 | W6: =F6-E6 -> 6.494 | X6: =G6-F6 -> 5.9 | Y6: =H6-G6 -> 5.616 | Z6: =I6-H6 -> 5.058 | AA6: =J6-I6 -> 5.418 | AB6: =K6-J6 -> 6.5 | ... AF6: =O6-N6 -> 7.013
B7: kalorimetr č. SN 34672801 | C7: 9.411 | D7: 14.899 | E7: 18.884 | F7: 22.264 | G7: 25.186 | H7: 25.813 | I7: 26.204 | J7: 26.563 | K7: 26.938 | L7: 27.906 | M7: 29.721 | N7: 34.365 | O7: 40.553 | Q7: =O7-C7 -> 31.142
A8: 3 | B8: vodoměr č. 190906988 | C8: 190.74 | D8: 198.066 | E8: 205.087 | F8: 212.007 | G8: 219.641 | H8: 227.219 | I8: 234.728 | J8: 242.841 | K8: 250.473 | L8: 256.939 | M8: 263.22 | N8: 269.182 | O8: 275.92 | P8: =O8-C8 -> 85.18 | T8: 3 | U8: =D8-C8 -> 7.326 | V8: =E8-D8 -> 7.021 | W8: =F8-E8 -> 6.92 | X8: =G8-F8 -> 7.634 | Y8: =H8-G8 -> 7.578 | Z8: =I8-H8 -> 7.509 | AA8: =J8-I8 -> 8.113 | AB8: =K8-J8 -> 7.632 | ... AF8: =O8-N8 -> 6.738
B9: kalorimetr č. SN 34672802 | C9: 11.59 | D9: 17.634 | E9: 22.681 | F9: 26.76 | G9: 30.672 | H9: 31.287 | I9: 31.575 | J9: 31.881 | K9: 32.14 | L9: 32.682 | M9: 34.515 | N9: 38.298 | O9: 43.799 | Q9: =O9-C9 -> 32.209
A10: 4 | B10: vodoměr č. 190906987 | C10: 125.285 | D10: 134.466 | E10: 142.333 | F10: 151.151 | G10: 161.107 | H10: 169.355 | I10: 176.913 | J10: 185.535 | K10: 194.771 | L10: 203.531 | M10: 213.631 | N10: 223.977 | O10: 233.497 | P10: =O10-C10 -> 108.212 | T10: 4 | U10: =D10-C10 -> 9.181 | V10: =E10-D10 -> 7.867 | W10: =F10-E10 -> 8.818 | X10: =G10-F10 -> 9.956 | Y10: =H10-G10 -> 8.248 | Z10: =I10-H10 -> 7.558 | AA10: =J10-I10 -> 8.622 | AB10: =K10-J10 -> 9.236 | ... AF10: =O10-N10 -> 9.52
B11: kalorimetr č. SN 69067316 | C11: 3.734 | D11: 5.696 | E11: 7.204 | F11: 8.422 | G11: 9.858 | H11: 10.483 | I11: 10.881 | J11: 11.287 | K11: 11.713 | L11: 12.171 | M11: 12.775 | N11: 14.078 | O11: 15.755 | Q11: =O11-C11 -> 12.021
A12: 5 | B12: vodoměr č. 190907002 | C12: 0.5 | D12: 0.511 | E12: 0.535 | F12: 0.535 | G12: 0.535 | H12: 0.551 | I12: 0.551 | J12: 0.565 | K12: 0.581 | L12: 0.585 | M12: 0.602 | N12: 0.022 | O12: 0.111 | P12: =O12-G40+G39-C12 -> 0.193 | T12: 5 | U12: =D12-C12 -> 0.011 | V12: =E12-D12 -> 0.024 | W12: =F12-E12 -> 0 | X12: =G12-F12 -> 0 | Y12: =H12-G12 -> 0.016 | Z12: =I12-H12 -> 0 | AA12: =J12-I12 -> 0.014 | AB12: =K12-J12 -> 0.016 | ... AD12: =M12-L12 -> 0.017 | AE12: =N12-G40+G39-M12 -> 0.002 | AF12: =O12-H40+H39-N12 -> 0.089
B13: kalorimetr č. SN 34672814 | C13: 1.731 | D13: 1.847 | E13: 2.168 | F13: 4.169 | G13: 4.171 | H13: 4.173 | I13: 4.173 | J13: 4.175 | K13: 4.177 | L13: 4.178 | M13: 4.18 | N13: 4.204 | O13: 4.916 | Q13: =O13-C13 -> 3.185
A14: 6 | B14: vodoměr č. 190906994 | C14: 233.669 | D14: 242.713 | E14: 252.162 | F14: 259.675 | G14: 260.158 | H14: 268.151 | I14: 275.288 | J14: 282.247 | K14: 291.04 | L14: 299.289 | M14: 308.548 | N14: 313.523 | O14: 323.594 | P14: =O14-C14 -> 89.925 | T14: 6 | U14: =D14-C14 -> 9.044 | V14: =E14-D14 -> 9.449 | W14: =F14-E14 -> 7.513 | X14: =G14-F14 -> 0.483 | Y14: =H14-G14 -> 7.993 | Z14: =I14-H14 -> 7.137 | AA14: =J14-I14 -> 6.959 | AB14: =K14-J14 -> 8.793 | ... AF14: =O14-N14 -> 10.071
B15: kalorimetr č. SN 34672815 | C15: 2.625 | D15: 4.85 | E15: 6.346 | F15: 7.037 | G15: 7.109 | H15: 7.562 | I15: 7.93 | J15: 8.273 | K15: 8.671 | L15: 9.103 | M15: 9.675 | N15: 10.306 | O15: 12.884 | Q15: =O15-C15 -> 10.259
A16: 7 | B16: vodoměr č. 190906986 | C16: 101.134 | D16: 105.37 | E16: 107.915 | F16: 109.353 | G16: 111.611 | H16: 115.126 | I16: 118.34 | J16: 119.386 | K16: 120.843 | L16: 122.624 | M16: 123.061 | N16: 123.42 | O16: 124.062 | P16: =O16-C16 -> 22.928 | T16: 7 | U16: =D16-C16 -> 4.236 | V16: =E16-D16 -> 2.545 | W16: =F16-E16 -> 1.438 | X16: =G16-F16 -> 2.258 | Y16: =H16-G16 -> 3.515 | Z16: =I16-H16 -> 3.214 | AA16: =J16-I16 -> 1.046 | AB16: =K16-J16 -> 1.457 | ... AF16: =O16-N16 -> 0.642
B17: kalorimetr č. SN 34672806 | C17: 2.488 | D17: 4.028 | E17: 4.973 | F17: 5.418 | G17: 5.943 | H17: 6.444 | I17: 6.871 | J17: 7.113 | K17: 7.39 | L17: 7.698 | M17: 7.933 | N17: 8.33 | O17: 9.096 | Q17: =O17-C17 -> 6.608
A18: 8 | B18: vodoměr č. 191519281 | C18: 175.044 | D18: 181.75 | E18: 187.756 | F18: 193.76 | G18: 200.808 | H18: 207.473 | I18: 213.543 | J18: 219.988 | K18: 225.963 | L18: 231.634 | M18: 237.715 | N18: 243.816 | O18: 249.7 | P18: =O18-C18 -> 74.656 | T18: 8 | U18: =D18-C18 -> 6.706 | V18: =E18-D18 -> 6.006 | W18: =F18-E18 -> 6.004 | X18: =G18-F18 -> 7.048 | Y18: =H18-G18 -> 6.665 | Z18: =I18-H18 -> 6.07 | AA18: =J18-I18 -> 6.445 | AB18: =K18-J18 -> 5.975 | ... AF18: =O18-N18 -> 5.884
B19: kalorimetr č. SN 34672809 | C19: 9.78 | D19: 15.601 | E19: 19.777 | F19: 22.598 | G19: 24.929 | H19: 25.322 | I19: 25.624 | J19: 25.942 | K19: 26.227 | L19: 26.61 | M19: 27.805 | N19: 30.144 | O19: 34.484 | Q19: =O19-C19 -> 24.704
A20: 9 | B20: vodoměr č. 190906990 | C20: 327.76 | D20: 340.09 | E20: 352.8 | F20: 364.961 | G20: 378.434 | H20: 388.121 | I20: 401.867 | J20: 415.937 | K20: 430.278 | L20: 440.701 | M20: 451.906 | N20: 460.658 | O20: 473.534 | P20: =O20-C20 -> 145.774 | T20: 9 | U20: =D20-C20 -> 12.33 | V20: =E20-D20 -> 12.71 | W20: =F20-E20 -> 12.161 | X20: =G20-F20 -> 13.473 | Y20: =H20-G20 -> 9.687 | Z20: =I20-H20 -> 13.746 | AA20: =J20-I20 -> 14.07 | AB20: =K20-J20 -> 14.341 | ... AF20: =O20-N20 -> 12.876
B21: kalorimetr č. SN 34672804 | C21: 9.923 | D21: 15.831 | E21: 20.555 | F21: 24.141 | G21: 26.881 | H21: 27.463 | I21: 28.062 | J21: 28.632 | K21: 29.177 | L21: 29.651 | M21: 30.413 | N21: 34.555 | O21: 40.387 | Q21: =O21-C21 -> 30.464
A22: 10 | B22: vodoměr č. 190906995 | C22: 0.325 | D22: 0.326 | E22: 0.326 | F22: 0.327 | G22: 0.327 | H22: 0.328 | I22: 0.332 | J22: 0.333 | K22: 0.335 | L22: 0.337 | M22: 0.337 | N22: 0.337 | O22: 0.337 | P22: =O22-C22 -> 0.012 | T22: 10 | U22: =D22-C22 -> 0.001 | V22: =E22-D22 -> 0 | W22: =F22-E22 -> 0.001 | X22: =G22-F22 -> 0 | Y22: =H22-G22 -> 0.001 | Z22: =I22-H22 -> 0.004 | AA22: =J22-I22 -> 0.001 | AB22: =K22-J22 -> 0.002 | ... AF22: =O22-N22 -> 0
B23: kalorimetr č. SN 34672829 | C23: 0.004 | D23: 0.011 | E23: 0.02 | F23: 0.034 | G23: 0.046 | H23: 0.052 | I23: 0.054 | J23: 0.055 | K23: 0.055 | L23: 0.061 | M23: 0.076 | N23: 0.086 | O23: 0.092 | Q23: =O23-C23 -> 0.088
P24: =SUM(P4:P23) -> 676.153 | Q24: =SUM(Q4:Q23) -> 173.697
A25: spol.spotř. | B25: elektroměr č. 72370871 | C25: 52736 | D25: 52933 | E25: 53109 | F25: 53294 | G25: 53503 | H25: 53700 | I25: 53890 | J25: 54083 | K25: 54279 | L25: 54465 | M25: 54656 | N25: 54831 | O25: 55126 | R25: =O25-C25 -> 2390
B26: patní vodoměr č. 190976793 | C26: 1618.4 | D26: 1687.5 | E26: 1750 | F26: 1814.5 | G26: 1874 | H26: 1936.7 | I26: 1998.2 | J26: 2056 | K26: 2121.5 | L26: 2181.1 | M26: 2242.7 | N26: 2298.5 | O26: 2361.6 | P26: =O26-C26 -> 743.2
B27: patní kalorimetr č. 70465263/ GJ | C27: 313.67 | D27: 349.04 | E27: 376.43 | F27: 399.14 | G27: 416.19 | H27: 419.83 | I27: 422.16 | J27: 424.71 | K27: 427.81 | L27: 431.9 | M27: 440.79 | N27: 462.56 | O27: 496.85 | Q27: =O27-C27 -> 183.18 | R27: GJ
B28: patní kalorimetr č. / kub.m | C28: 2751 | D28: 3014 | E28: 3212 | F28: 3367 | G28: 3492 | H28: 3527 | I28: 3554 | J28: 3589 | K28: 3635 | L28: 3683 | M28: 3766 | N28: 3918 | O28: 4150 | Q28: =O28-C28 -> 1399 | R28: m3
A29: Fakturační vodoměr: 42012114941 | C29: 4605 | D29: 4905.6 | E29: 5169.8 | F29: 5453.5 | G29: 5740.1 | H29: 6002.3 | I29: 6257.5 | J29: 6498.9 | K29: 6755.3 | L29: 7009 | M29: 7290.8 | N29: 7559.6 | O29: 7844.6 | P29: =O29-C29 -> 3239.6
E32: Výměna kalorimetru pata | H32: MWh | I32: m3 | K32: Výměna faktur.vodoměru výr.č. | N32: m3
D33: demontáž | E33: 43984 | F33: starý | K33: 44095 | L33: starý
G34: výr.č. | H34: GJ | I34: m3 | M34: výr.č. | N34: m3
D35: montáž | E35: 43986 | F35: nový | K35: 44095 | L35: nový
C38: byt | D38: Reklamace - výměna | F38: číslo | G38: stav | N38: Odečet vodárny 30.11.2021 | O38: 4300
C39: 5 | D39: 43950 | E39: starý | F39: 190907002 | G39: 0.602 | N39: Dohad 1.12.-31.12.2021 | O39: 305
E40: nový | F40: 221525395 | G40: 0.02 | N40: Odečet vodárny 31.12.2022 | O40: 7844

Sheet 1855
A2: 1855 | C2: ='1850'!C2 -> 44562 | D2: ='1850'!D2 -> 44593 | E2: ='1850'!E2 -> 44622 | F2: ='1850'!F2 -> 44652 | G2: ='1850'!G2 -> 44683 | H2: ='1850'!H2 -> 44713 | I2: ='1850'!I2 -> 44743 | J2: ='1850'!J2 -> 44774 | ... O2: ='1850'!O2 -> 44927 | P2: voda | Q2: teplo | R2: elektr | Y2: spotřeby po měsících
A3: byt č. | C3: prosinec | D3: leden | E3: únor | F3: březen | G3: duben | H3: květen | I3: červen | J3: červenec | K3: srpen | L3: září | M3: říjen | N3: listopad | O3: prosinec | P3: m3 | Q3: GJ | R3: KWh | T3: byt | U3: leden | V3: únor | W3: březen | X3: duben | Y3: květen | Z3: červen | AA3: červenec | AB3: srpen | AC3: září | AD3: říjen | AE3: listopad | AF3: prosinec
A4: 1 | B4: vodoměr č. 191519259 | C4: 363.842 | D4: 379.037 | E4: 391.154 | F4: 405.315 | G4: 420.059 | H4: 434.307 | I4: 447.536 | J4: 459.657 | K4: 469.844 | L4: 482.626 | M4: 495.495 | N4: 507.597 | O4: 520.504 | P4: =O4-C4 -> 156.662 | T4: 1 | U4: =D4-C4 -> 15.195 | V4: =E4-D4 -> 12.117 | W4: =F4-E4 -> 14.161 | X4: =G4-F4 -> 14.744 | Y4: =H4-G4 -> 14.248 | Z4: =I4-H4 -> 13.229 | AA4: =J4-I4 -> 12.121 | AB4: =K4-J4 -> 10.187 | ... AF4: =O4-N4 -> 12.907
B5: kalorimetr č. SN 34672816 | C5: 14.103 | D5: 22.427 | E5: 29.05 | F5: 35.001 | G5: 39.989 | H5: 41.414 | I5: 42.397 | J5: 43.269 | K5: 43.919 | L5: 45.027 | M5: 46.981 | N5: 50.747 | O5: 56.527 | Q5: =O5-C5 -> 42.424 | T5: teplo | U5: =D5-C5 -> 8.324 | V5: =E5-D5 -> 6.623 | W5: =F5-E5 -> 5.951 | X5: =G5-F5 -> 4.988 | Y5: =H5-G5 -> 1.425 | Z5: =I5-H5 -> 0.983 | AA5: =J5-I5 -> 0.872 | AB5: =K5-J5 -> 0.65 | ... AF5: =O5-N5 -> 5.78
A6: 2 | B6: vodoměr č. 191519283 | C6: 442.615 | D6: 459.633 | E6: 470.743 | F6: 489.988 | G6: 505.762 | H6: 521.158 | I6: 534.78 | J6: 542.788 | K6: 554.273 | L6: 568.101 | M6: 583.64 | N6: 602.887 | O6: 619.368 | P6: =O6-C6 -> 176.753 | T6: 2 | U6: =D6-C6 -> 17.018 | V6: =E6-D6 -> 11.11 | W6: =F6-E6 -> 19.245 | X6: =G6-F6 -> 15.774 | Y6: =H6-G6 -> 15.396 | Z6: =I6-H6 -> 13.622 | AA6: =J6-I6 -> 8.008 | AB6: =K6-J6 -> 11.485 | ... AF6: =O6-N6 -> 16.481
B7: kalorimetr č. SN 34672822 | C7: 9.68 | D7: 15.479 | E7: 20.291 | F7: 24.805 | G7: 28.324 | H7: 29.57 | I7: 30.461 | J7: 30.961 | K7: 31.626 | L7: 32.552 | M7: 34.249 | N7: 38.196 | O7: 43.285 | Q7: =O7-C7 -> 33.605 | U7: =D7-C7 -> 5.799 | V7: =E7-D7 -> 4.812 | W7: =F7-E7 -> 4.514 | X7: =G7-F7 -> 3.519 | Y7: =H7-G7 -> 1.246 | Z7: =I7-H7 -> 0.891 | AA7: =J7-I7 -> 0.5 | AB7: =K7-J7 -> 0.665 | ... AF7: =O7-N7 -> 5.089
