Workbook

Sheet 1850
A2: 1850 | C2: 43466 | D2: 43497 | E2: 43526 | F2: 43556 | G2: 43588 | H2: 43620 | I2: 43647 | J2: 43678 | K2: 43679 | L2: 43739 | M2: 43742 | N2: 43770 | O2: 43798 | P2: 43804 | Q2: 43804 | R2: 43831 | S2: voda | T2: teplo | AA2: spotřeby po měsících starý vodoměr | AG2: spotřeby nový vodoměr
A3: byt č. | C3: prosinec | D3: leden | E3: únor | F3: březen | G3: duben | H3: květen | I3: červen | J3: červenec | K3: srpen | L3: září | M3: nový vod. | N3: říjen | O3: listopad | P3: výměna | Q3: nový vod. | R3: prosinec | S3: m3 | T3: GJ | V3: byt | W3: leden | X3: únor | Y3: březen | Z3: duben | AA3: květen | AB3: červen | AC3: červenec | AD3: srpen | AE3: září | AF3: říjen | AG3: listopad | AH3: prosinec
A4: 1 | B4: vodoměr č. 190834092 | C4: 175.254 | D4: 177.467 | E4: 178.66 | F4: 180.493 | G4: 182.101 | H4: 183.598 | I4: 185.403 | J4: 186.784 | K4: 188.368 | L4: 190.297 | M4: 0.01 | N4: 1.482 | O4: 2.843 | P4: 3.12 | Q4: 3.12 | R4: 4.304 | S4: =R4-M4+L4-C4 -> 19.337 | V4: 1 | W4: =D4-C4 -> 2.213 | X4: =E4-D4 -> 1.193 | Y4: =F4-E4 -> 1.833 | Z4: =G4-F4 -> 1.608 | AA4: =H4-G4 -> 1.497 | AB4: =I4-H4 -> 1.805 | AC4: =J4-I4 -> 1.381 | AD4: =K4-J4 -> 1.584 | AE4: =L4-K4 -> 1.929 | AF4: =N4-M4 -> 1.472 | AG4: =O4-N4 -> 1.361 | AH4: =R4-Q4 -> 1.184
B5: kalorimetr č. SN 34582391 | C5: 13.76 | D5: 18.892 | E5: 21.087 | F5: 23.087 | G5: 23.583 | H5: 23.923 | I5: 24.125 | J5: 24.322 | K5: 24.531 | L5: 24.734 | N5: 25.044 | O5: 27.231 | R5: 30.541 | T5: =R5-C5 -> 16.781
A6: 2 | B6: vodoměr č. 190834090 | C6: 373.825 | D6: 387.744 | E6: 402.145 | F6: 415.597 | G6: 433.189 | H6: 448.464 | I6: 461.572 | J6: 470.444 | K6: 481.046 | L6: 497.636 | M6: 0.01 | N6: 13.278 | O6: 29.182 | P6: 32.055 | Q6: 32.055 | R6: 45.39 | S6: =R6-M6+L6-C6 -> 169.191 | V6: 2 | W6: =D6-C6 -> 13.919 | X6: =E6-D6 -> 14.401 | Y6: =F6-E6 -> 13.452 | Z6: =G6-F6 -> 17.592 | AA6: =H6-G6 -> 15.275 | AB6: =I6-H6 -> 13.108 | AC6: =J6-I6 -> 8.872 | AD6: =K6-J6 -> 10.602 | AE6: =L6-K6 -> 16.59 | AF6: =N6-M6 -> 13.268 | AG6: =O6-N6 -> 15.904 | AH6: =R6-Q6 -> 13.335
B7: kalorimetr č. SN 34582401 | C7: 39.697 | D7: 44.624 | E7: 49.731 | F7: 52.946 | G7: 54.717 | H7: 55.634 | I7: 56.083 | J7: 56.304 | K7: 56.581 | L7: 57.129 | N7: 58.239 | O7: 61.064 | R7: 64.938 | T7: =R7-C7 -> 25.241
A8: 3 | B8: vodoměr č. 190834097 | C8: 191.484 | D8: 198.757 | E8: 205.998 | F8: 211.22 | G8: 218.546 | H8: 224.282 | I8: 230.78 | J8: 237.245 | K8: 242.462 | L8: 249.597 | M8: 0.01 | N8: 5.261 | O8: 10.754 | P8: 12.434 | Q8: 12.434 | R8: 17.889 | S8: =R8-M8+L8-C8 -> 75.992 | V8: 3 | W8: =D8-C8 -> 7.273 | X8: =E8-D8 -> 7.241 | Y8: =F8-E8 -> 5.222 | Z8: =G8-F8 -> 7.326 | AA8: =H8-G8 -> 5.736 | AB8: =I8-H8 -> 6.498 | AC8: =J8-I8 -> 6.465 | AD8: =K8-J8 -> 5.217 | AE8: =L8-K8 -> 7.135 | AF8: =N8-M8 -> 5.251 | AG8: =O8-N8 -> 5.493 | AH8: =R8-Q8 -> 5.455
B9: kalorimetr č. SN 34582385 | C9: 30.742 | D9: 34.789 | E9: 38.153 | F9: 40.468 | G9: 41.649 | H9: 42.881 | I9: 43.296 | J9: 43.75 | K9: 44.134 | L9: 44.645 | N9: 45.681 | O9: 48.024 | R9: 51.991 | T9: =R9-C9 -> 21.249
A10: 4 | B10: vodoměr č. 190834098 | C10: 314.132 | D10: 321.426 | E10: 328.303 | F10: 335.384 | G10: 342.256 | H10: 350.058 | I10: 356.521 | J10: 362.345 | K10: 369.312 | L10: 376.912 | M10: 0.03 | N10: 7.299 | O10: 14.347 | P10: 15.707 | Q10: 15.707 | R10: 22.895 | S10: =R10-M10+L10-C10 -> 85.645 | V10: 4 | W10: =D10-C10 -> 7.294 | X10: =E10-D10 -> 6.877 | Y10: =F10-E10 -> 7.081 | Z10: =G10-F10 -> 6.872 | AA10: =H10-G10 -> 7.802 | AB10: =I10-H10 -> 6.463 | AC10: =J10-I10 -> 5.824 | AD10: =K10-J10 -> 6.967 | AE10: =L10-K10 -> 7.6 | AF10: =N10-M10 -> 7.269 | AG10: =O10-N10 -> 7.048 | AH10: =R10-Q10 -> 7.188
B11: kalorimetr č. SN 34582414 | C11: 18.881 | D11: 20.576 | E11: 21.9 | F11: 22.851 | G11: 23.544 | H11: 24.269 | I11: 24.687 | J11: 25.077 | K11: 25.551 | L11: 26.119 | N11: 26.89 | O11: 27.891 | R11: 29.628 | T11: =R11-C11 -> 10.747
A12: 5 | B12: vodoměr č. 190834095 | C12: 305.997 | D12: 310.015 | E12: 310.656 | F12: 311.374 | G12: 314.137 | H12: 321.878 | I12: 327.035 | J12: 333.407 | K12: 341.287 | L12: 346.382 | M12: 0.01 | N12: 5.497 | O12: 11.533 | P12: 13.242 | Q12: 13.242 | R12: 17.328 | S12: =R12-M12+L12-C12 -> 57.703 | V12: 5 | W12: =D12-C12 -> 4.018 | X12: =E12-D12 -> 0.641 | Y12: =F12-E12 -> 0.718 | Z12: =G12-F12 -> 2.763 | AA12: =H12-G12 -> 7.741 | AB12: =I12-H12 -> 5.157 | AC12: =J12-I12 -> 6.372 | AD12: =K12-J12 -> 7.88 | AE12: =L12-K12 -> 5.095 | AF12: =N12-M12 -> 5.487 | AG12: =O12-N12 -> 6.036 | AH12: =R12-Q12 -> 4.086
B13: kalorimetr č. SN 34582396 | C13: 38.17 | D13: 40.139 | E13: 40.277 | F13: 40.438 | G13: 40.768 | H13: 41.493 | I13: 41.772 | J13: 42.126 | K13: 42.532 | L13: 42.863 | N13: 43.642 | O13: 45.249 | R13: 47.614 | T13: =R13-C13 -> 9.444
A14: 6 | B14: vodoměr č. 190834099 | C14: 417.208 | D14: 427.773 | E14: 437.434 | F14: 446.484 | G14: 454.515 | H14: 463.863 | I14: 470.451 | J14: 475.448 | K14: 475.899 | L14: 479.795 | M14: 0.04 | N14: 6 | O14: 11.401 | P14: 12.045 | Q14: 12.045 | R14: 16.014 | S14: =R14-M14+L14-C14 -> 78.561 | V14: 6 | W14: =D14-C14 -> 10.565 | X14: =E14-D14 -> 9.661 | Y14: =F14-E14 -> 9.05 | Z14: =G14-F14 -> 8.031 | AA14: =H14-G14 -> 9.348 | AB14: =I14-H14 -> 6.588 | AC14: =J14-I14 -> 4.997 | AD14: =K14-J14 -> 0.451 | AE14: =L14-K14 -> 3.896 | AF14: =N14-M14 -> 5.96 | AG14: =O14-N14 -> 5.401 | AH14: =R14-Q14 -> 3.969
B15: kalorimetr č. SN 34582416 | C15: 45.094 | D15: 51.147 | E15: 54.938 | F15: 58.169 | G15: 59.961 | H15: 60.881 | I15: 61.331 | J15: 61.67 | K15: 61.764 | L15: 62.033 | N15: 63.326 | O15: 66.078 | R15: 69.496 | T15: =R15-C15 -> 24.402
A16: 7 | B16: vodoměr č. 190834102 | C16: 160.267 | D16: 163.231 | E16: 165.95 | F16: 168.634 | G16: 171.664 | H16: 174.647 | I16: 176.965 | J16: 180.076 | K16: 182.82 | L16: 185.68 | M16: 0.02 | N16: 2.348 | O16: 4.327 | P16: 4.707 | Q16: 4.707 | R16: 6.197 | S16: =R16-M16+L16-C16 -> 31.59 | V16: 7 | W16: =D16-C16 -> 2.964 | X16: =E16-D16 -> 2.719 | Y16: =F16-E16 -> 2.684 | Z16: =G16-F16 -> 3.03 | AA16: =H16-G16 -> 2.983 | AB16: =I16-H16 -> 2.318 | AC16: =J16-I16 -> 3.111 | AD16: =K16-J16 -> 2.744 | AE16: =L16-K16 -> 2.86 | AF16: =N16-M16 -> 2.328 | AG16: =O16-N16 -> 1.979 | AH16: =R16-Q16 -> 1.49
B17: kalorimetr č. SN 34582423 | C17: 9.55 | D17: 11.201 | E17: 12.29 | F17: 13.048 | G17: 13.292 | H17: 13.577 | I17: 13.668 | J17: 13.798 | K17: 13.901 | L17: 14.028 | N17: 14.214 | O17: 14.837 | R17: 15.908 | T17: =R17-C17 -> 6.358
A18: 8 | B18: vodoměr č. 190834104 | C18: 361.082 | D18: 370.204 | E18: 375.533 | F18: 383.627 | G18: 390.811 | H18: 398.234 | I18: 405.032 | J18: 409.72 | K18: 412.736 | L18: 413.049 | M18: 0.09 | N18: 0.793 | O18: 1.517 | P18: 1.657 | Q18: 1.657 | R18: 1.897 | S18: =R18-M18+L18-C18 -> 53.774 | V18: 8 | W18: =D18-C18 -> 9.122 | X18: =E18-D18 -> 5.329 | Y18: =F18-E18 -> 8.094 | Z18: =G18-F18 -> 7.184 | AA18: =H18-G18 -> 7.423 | AB18: =I18-H18 -> 6.798 | AC18: =J18-I18 -> 4.688 | AD18: =K18-J18 -> 3.016 | AE18: =L18-K18 -> 0.313 | AF18: =N18-M18 -> 0.703 | AG18: =O18-N18 -> 0.724 | AH18: =R18-Q18 -> 0.24
B19: kalorimetr č. SN 34582408 | C19: 28.884 | D19: 33.296 | E19: 34.64 | F19: 36.615 | G19: 37.716 | H19: 38.842 | I19: 39.228 | J19: 39.533 | K19: 39.68 | L19: 39.711 | N19: 40.098 | O19: 42.214 | R19: 46.048 | T19: =R19-C19 -> 17.164
A20: 9 | B20: vodoměr č. 190834109 | C20: 5.049 | D20: 5.101 | E20: 5.232 | F20: 5.511 | G20: 6.038 | H20: 6.073 | I20: 6.108 | J20: 6.137 | K20: 6.163 | L20: 6.322 | M20: 0.01 | N20: 0.032 | O20: 0.049 | P20: 0.055 | Q20: 0.055 | R20: 0.07 | S20: =R20-M20+L20-C20 -> 1.333 | V20: 9 | W20: =D20-C20 -> 0.052 | X20: =E20-D20 -> 0.131 | Y20: =F20-E20 -> 0.279 | Z20: =G20-F20 -> 0.527 | AA20: =H20-G20 -> 0.035 | AB20: =I20-H20 -> 0.035 | AC20: =J20-I20 -> 0.029 | AD20: =K20-J20 -> 0.026 | AE20: =L20-K20 -> 0.159 | AF20: =N20-M20 -> 0.022 | AG20: =O20-N20 -> 0.017 | AH20: =R20-Q20 -> 0.015
B21: kalorimetr č. SN 34582410 | C21: 2.71 | D21: 3.427 | E21: 3.628 | F21: 3.826 | G21: 4.03 | H21: 4.214 | I21: 4.335 | J21: 4.481 | K21: 4.642 | L21: 4.808 | N21: 4.998 | O21: 5.181 | R21: 5.485 | T21: =R21-C21 -> 2.775
A22: 10 | B22: vodoměr č. 191519263 | C22: 98.599 | D22: 106.557 | E22: 112.685 | F22: 120.256 | G22: 123.882 | H22: 130.603 | I22: 136.288 | J22: 142.323 | K22: 149.228 | L22: 156.732 | M22: 0.03 | N22: 3.971 | O22: 5.614 | P22: 5.838 | Q22: 0.024 | R22: 7.188 | S22: =R22-Q22+P22-M22+L22-C22 -> 71.105 | V22: 10 | W22: =D22-C22 -> 7.958 | X22: =E22-D22 -> 6.128 | Y22: =F22-E22 -> 7.571 | Z22: =G22-F22 -> 3.626 | AA22: =H22-G22 -> 6.721 | AB22: =I22-H22 -> 5.685 | AC22: =J22-I22 -> 6.035 | AD22: =K22-J22 -> 6.905 | AE22: =L22-K22 -> 7.504 | AF22: =N22-M22 -> 3.941 | AG22: =O22-N22 -> 1.643 | AH22: =R22-Q22 -> 7.164
B23: kalorimetr č. SN 34582413 | C23: 26.443 | D23: 30.237 | E23: 33.432 | F23: 34.911 | G23: 35.544 | H23: 36.136 | I23: 36.395 | J23: 36.674 | K23: 36.971 | L23: 37.338 | N23: 37.839 | O23: 39.352 | R23: 41.987 | T23: =R23-C23 -> 15.544
S24: =SUM(S4:S23) -> 644.231 | T24: =SUM(T4:T23) -> 149.705
A25: spol.spotř. | B25: elektroměr č. 18972503 | C25: 66129 | D25: 66665 | E25: 67172 | F25: 67452 | G25: 67745 | H25: 68037 | I25: 68314 | J25: 68585 | K25: 68860 | L25: 69156 | N25: 69418 | O25: 69655 | R25: 69969 | U25: =R25-C25 -> 3840 | V25: kWh
B26: patní vodoměr č. 190976787 | C26: 2548.7 | D26: 2618.6 | E26: 2676.3 | F26: 2736.4 | G26: 2799.9 | H26: 2870.3 | I26: 2928.3 | J26: 2980.9 | K26: 3030.4 | L26: 3087.5 | M26: 0 | N26: 54 | O26: 114.1 | P26: 127.4 | Q26: 127.4 | R26: 179.6 | S26: =R26+L26-C26 -> 718.4
B27: patní kalorimetr č./MWh | C27: 206.07 | D27: 217.15 | E27: 224.44 | F27: 230.07 | G27: 233.37 | H27: 236.19 | I27: 0.49 | J27: 1.91 | K27: 3.29 | L27: 4.8 | N27: 7.45 | O27: 13.54 | R27: 22.27 | T27: =(R27-M33+M32-C27)*3.6 -> 191.268 | U27: GJ
B28: patní kalorimetr č./kub.m | C28: 10345 | D28: 10815 | E28: 11098 | F28: 11335 | G28: 11502 | H28: 11650 | I28: 32 | J28: 129 | K28: 228 | L28: 327 | N28: 471 | O28: 761 | R28: 1071
A29: fakturační vodoměr č. 110109308 | C29: 12400 | D29: 12741.6 | E29: 4358.2 | F29: 4677.5 | G29: 5038.2 | H29: 5389.7 | I29: 5691.3 | J29: 6012.6 | K29: 6313.8 | L29: 6605.1 | N29: 6922.5 | O29: 7232.3 | R29: 7593.2 | S29: =R29-E33+E32-C29 -> 3894.2
D31: modře - žádný nárůst
B32: Výměna fakturač. vodoměru | C32: 110109308 | D32: starý | E32: 12875 | H32: Dne 17.6.2019 odpojen kalor. (cejchování), | L32: stav: | M32: 236.93 | N32: MWh
B33: dne 14.2.2019 | C33: 63796 | D33: nový | E33: 4174 | H33: Dne 20.6.2019 zapojen znovuzapojení, | L33: stav: | M33: 0 | N33: MWh
H34: Dne 4.10.2019 výměna vodoměrů - byty + pata
H35: Odečty vody za září jsou ze dne výměny 4.10.
H36: Dne 5.12.2019 výměna vadných vodoměrů

Sheet 1851
AE1: Vytipování vadných vodoměrů
A2: Nové | B2: 1851 | D2: ='1850'!C2 -> 43466 | E2: ='1850'!D2 -> 43497 | F2: ='1850'!E2 -> 43526 | G2: ='1850'!F2 -> 43556 | H2: ='1850'!G2 -> 43588 | I2: ='1850'!H2 -> 43620 | J2: ='1850'!I2 -> 43647 | K2: ='1850'!J2 -> 43678 | ... P2: ='1850'!O2 -> 43798 | Q2: ='1850'!R2 -> 43831 | R2: voda | S2: teplo | Z2: spotřeby po měsících starý vodoměr SV | AF2: spotřeby nový vodoměr
A3: číslování | B3: byt č. | D3: prosinec | E3: leden | F3: únor | G3: březen | H3: duben | I3: květen | J3: červen | K3: červenec | L3: srpen | M3: září | N3: nový vod. | O3: říjen | P3: listopad | Q3: prosinec | R3: m3 | S3: GJ | U3: byt | V3: leden | W3: únor | X3: březen | Y3: duben | Z3: květen | AA3: červen | AB3: červenec | AC3: srpen | AD3: září | AE3: říjen | AF3: listopad | AG3: prosinec
A4: 1 | B4: 1 | C4: vodoměr č. 190834116 | D4: 154.068 | E4: 166.163 | F4: 177.797 | G4: 188.778 | H4: 201.256 | I4: 214.268 | J4: 224.42 | K4: 237.35 | L4: 248.394 | M4: 261.215 | N4: 0.01 | O4: 11.76 | P4: 24.046 | Q4: 38.561 | R4: =Q4-N4+M4-D4 -> 145.698 | U4: 1 | V4: =E4-D4 -> 12.095 | W4: =F4-E4 -> 11.634 | X4: =G4-F4 -> 10.981 | Y4: =H4-G4 -> 12.478 | Z4: =I4-H4 -> 13.012 | AA4: =J4-I4 -> 10.152 | AB4: =K4-J4 -> 12.93 | AC4: =L4-K4 -> 11.044 | AD4: =M4-L4 -> 12.821 | AE4: =O4-N4 -> 11.75 | AF4: =P4-O4 -> 12.286 | AG4: =Q4-P4 -> 14.515
C5: kalorimetr č. SN 34582402 | D5: 39.425 | E5: 45.014 | F5: 48.781 | G5: 51.14 | H5: 52.317 | I5: 53.301 | J5: 53.678 | K5: 54.133 | L5: 54.524 | M5: 55.177 | O5: 56.925 | P5: 60.107 | Q5: 64.528 | S5: =Q5-D5 -> 25.103 | U5: xx
A6: 2 | B6: 2 | C6: vodoměr SV č. 190834120 | D6: 310.179 | E6: 315.243 | F6: 319.625 | G6: 324.787 | H6: 330.63 | I6: 335.912 | J6: 339.899 | K6: 344.085 | L6: 349.535 | M6: 355.025 | N6: 0.08 | O6: 5.738 | P6: 10.043 | Q6: 14.612 | R6: =Q6-N6+M6-D6 -> 59.378 | U6: 2 | V6: =E6-D6 -> 5.064 | W6: =F6-E6 -> 4.382 | X6: =G6-F6 -> 5.162 | Y6: =H6-G6 -> 5.843 | Z6: =I6-H6 -> 5.282 | AA6: =J6-I6 -> 3.987 | AB6: =K6-J6 -> 4.186 | AC6: =L6-K6 -> 5.45 | AD6: =M6-L6 -> 5.49 | AE6: =O6-N6 -> 5.658 | AF6: =P6-O6 -> 4.305 | AG6: =Q6-P6 -> 4.569
A7: 2 a 3 | C7: kalorimetr č. SN 34582400 | D7: 66.535 | E7: 76.097 | F7: 84.32 | G7: 91.127 | H7: 97.289 | I7: 101.965 | J7: 102.967 | K7: 104.239 | L7: 105.661 | M7: 108.044 | O7: 111.716 | P7: 116.329 | Q7: 122.646 | S7: =Q7-D7 -> 56.111 | U7: TV | V7: 5.984 | W7: 5.226 | X7: 4.879 | Y7: 5.985 | Z7: 5.112 | AA7: 2.632 | AB7: 2.896 | AC7: 3.117 | AD7: 4.039 | AE7: 1.757 | AF7: 0.999 | AG7: 0.607
A8: 5 | B8: 3 | C8: vodoměr SV č. 190834093 | D8: 5.9 | E8: 6.715 | F8: 7.707 | G8: 8.503 | H8: 9.398 | I8: 10.398 | J8: 11.103 | K8: 12.093 | L8: 13.196 | M8: 14.362 | N8: 0.01 | O8: 1.033 | P8: 1.887 | Q8: 2.74 | R8: =Q8-N8+M8-D8 -> 11.192 | U8: 5 | V8: =E8-D8 -> 0.815 | W8: =F8-E8 -> 0.992 | X8: =G8-F8 -> 0.796 | Y8: =H8-G8 -> 0.895 | Z8: =I8-H8 -> 1 | AA8: =J8-I8 -> 0.705 | AB8: =K8-J8 -> 0.99 | AC8: =L8-K8 -> 1.103 | AD8: =M8-L8 -> 1.166 | AE8: =O8-N8 -> 1.023 | AF8: =P8-O8 -> 0.854 | AG8: =Q8-P8 -> 0.853
A9: 5 a 6 | C9: kalorimetr č. SN 34582398 | D9: 36.186 | E9: 42.293 | F9: 46.884 | G9: 51.059 | H9: 53.236 | I9: 55.037 | J9: 55.8 | K9: 56.763 | L9: 57.805 | M9: 58.698 | O9: 60.208 | P9: 63.485 | Q9: 69.353 | S9: =Q9-D9 -> 33.167 | U9: TV | V9: 0.404 | W9: 0.43 | X9: 0.402 | Y9: 0.4 | Z9: 0.37 | AA9: 0.262 | AB9: 0.318 | AC9: 0.323 | AD9: 0.432 | AE9: 0.423 | AF9: 0.388 | AG9: 0.43
A10: 4 | B10: 4 | C10: vodoměr č. 190834126 | D10: 241.55 | E10: 246.558 | F10: 251.388 | G10: 257.474 | H10: 263.726 | I10: 270.407 | J10: 276.628 | K10: 282.716 | L10: 289.123 | M10: 294.986 | N10: 0.01 | O10: 4.918 | P10: 9.427 | Q10: 15.637 | R10: =Q10-N10+M10-D10 -> 69.063 | U10: 4 | V10: =E10-D10 -> 5.008 | W10: =F10-E10 -> 4.83 | X10: =G10-F10 -> 6.086 | Y10: =H10-G10 -> 6.252 | Z10: =I10-H10 -> 6.681 | AA10: =J10-I10 -> 6.221 | AB10: =K10-J10 -> 6.088 | AC10: =L10-K10 -> 6.407 | AD10: =M10-L10 -> 5.863 | AE10: =O10-N10 -> 4.908 | AF10: =P10-O10 -> 4.509 | AG10: =Q10-P10 -> 6.21
C11: kalorimetr č. SN 34582419 | D11: 5.797 | E11: 6.946 | F11: 7.635 | G11: 8.14 | H11: 8.526 | I11: 8.916 | J11: 9.164 | K11: 9.384 | L11: 9.642 | M11: 9.863 | O11: 10.163 | P11: 10.648 | Q11: 11.452 | S11: =Q11-D11 -> 5.655 | U11: xx
A12: 9 | B12: 5 | C12: vodoměr SV č. 190834122 | D12: 64.252 | E12: 69.076 | F12: 73.173 | G12: 77.987 | H12: 83.571 | I12: 87.531 | J12: 90.06 | K12: 95.92 | L12: 100.447 | M12: 106.843 | N12: 0.01 | O12: 5.278 | P12: 9.495 | Q12: 14.348 | R12: =Q12-N12+M12-D12 -> 56.929 | U12: 9 | V12: =E12-D12 -> 4.824 | W12: =F12-E12 -> 4.097 | X12: =G12-F12 -> 4.814 | Y12: =H12-G12 -> 5.584 | Z12: =I12-H12 -> 3.96 | AA12: =J12-I12 -> 2.529 | AB12: =K12-J12 -> 5.86 | AC12: =L12-K12 -> 4.527 | AD12: =M12-L12 -> 6.396 | AE12: =O12-N12 -> 5.268 | AF12: =P12-O12 -> 4.217 | AG12: =Q12-P12 -> 4.853
A13: 8 a 9 | C13: kalorimetr č. SN 34582384 | D13: 33.709 | E13: 40.175 | F13: 44.967 | G13: 48.255 | H13: 50.898 | I13: 52.533 | J13: 53.183 | K13: 54.336 | L13: 55.13 | M13: 56.415 | O13: 58.024 | P13: 61.345 | Q13: 65.843 | S13: =Q13-D13 -> 32.134 | U13: TV | V13: 12.761 | W13: 10.679 | X13: 3.111 | Y13: 3.355 | Z13: 1.856 | AA13: 0.959 | AB13: 3.41 | AC13: 2.595 | AD13: 3.738 | AE13: 2.132 | AF13: 1.996 | AG13: 1.939
A14: 15 | B14: 6 | C14: vodoměr SV č. 190834125 | D14: 126.174 | E14: 127.507 | F14: 128.382 | G14: 129.07 | H14: 131.445 | I14: 133.437 | J14: 134.95 | K14: 138.039 | L14: 140.617 | M14: 141.313 | N14: 0.02 | O14: 1.17 | P14: 1.598 | Q14: 2.529 | R14: =Q14-N14+M14-D14 -> 17.648 | U14: 15 | V14: =E14-D14 -> 1.333 | W14: =F14-E14 -> 0.875 | X14: =G14-F14 -> 0.688 | Y14: =H14-G14 -> 2.375 | Z14: =I14-H14 -> 1.992 | AA14: =J14-I14 -> 1.513 | AB14: =K14-J14 -> 3.089 | AC14: =L14-K14 -> 2.578 | AD14: =M14-L14 -> 0.696 | AE14: =O14-N14 -> 1.15 | AF14: =P14-O14 -> 0.428 | AG14: =Q14-P14 -> 0.931
A15: 11 a 15 | C15: kalorimetr č. SN 34582397 | D15: 27.5 | E15: 30.45 | F15: 32.171 | G15: 33.533 | H15: 34.127 | I15: 34.475 | J15: 34.665 | K15: 34.985 | L15: 35.305 | O15: 37.211 | P15: 39.072 | Q15: 43.561 | S15: =Q15-D15 -> 16.061 | U15: TV | V15: 0.694 | W15: 0.393 | X15: 0.463 | Y15: 1.272 | Z15: 0.93 | AA15: 0.492 | AB15: 1.006 | AC15: 0.94 | AD15: 0.411 | AE15: 1.032 | AF15: 0.644 | AG15: 3.06
A16: 7 | B16: 7 | C16: vodoměr č. 190834119 | D16: 372.778 | E16: 380.666 | F16: 387.531 | G16: 394.199 | H16: 400.324 | I16: 406.731 | J16: 412.935 | K16: 417.78 | L16: 421.71 | M16: 429.24 | N16: 0.03 | O16: 5.773 | P16: 12.331 | Q16: 20.11 | R16: =Q16-N16+M16-D16 -> 76.542 | U16: 7 | V16: =E16-D16 -> 7.888 | W16: =F16-E16 -> 6.865 | X16: =G16-F16 -> 6.668 | Y16: =H16-G16 -> 6.125 | Z16: =I16-H16 -> 6.407 | AA16: =J16-I16 -> 6.204 | AB16: =K16-J16 -> 4.845 | AC16: =L16-K16 -> 3.93 | AD16: =M16-L16 -> 7.53 | AE16: =O16-N16 -> 5.743 | AF16: =P16-O16 -> 6.558 | AG16: =Q16-P16 -> 7.779
C17: kalorimetr č. SN 34582417 | D17: 5.693 | E17: 6.532 | F17: 7.234 | G17: 7.905 | H17: 8.508 | I17: 9.072 | J17: 9.481 | K17: 9.791 | L17: 10.069 | M17: 10.546 | O17: 11.089 | P17: 11.628 | Q17: 12.307 | S17: =Q17-D17 -> 6.614 | U17: xx
A18: 13 | B18: 8 | C18: vodoměr SV č. 190834112 | D18: 44.54 | E18: 47.288 | F18: 49.811 | G18: 52.139 | H18: 54.378 | I18: 57.176 | J18: 59.766 | K18: 61.115 | L18: 64.44 | M18: 67.227 | N18: 0.08 | O18: 2.596 | P18: 5.281 | Q18: 9.147 | R18: =Q18-N18+M18-D18 -> 31.754 | U18: 13 | V18: =E18-D18 -> 2.748 | W18: =F18-E18 -> 2.523 | X18: =G18-F18 -> 2.328 | Y18: =H18-G18 -> 2.239 | Z18: =I18-H18 -> 2.798 | AA18: =J18-I18 -> 2.59 | AB18: =K18-J18 -> 1.349 | AC18: =L18-K18 -> 3.325 | AD18: =M18-L18 -> 2.787 | AE18: =O18-N18 -> 2.516 | AF18: =P18-O18 -> 2.685 | AG18: =Q18-P18 -> 3.866
A19: 12 a 13 | C19: kalorimetr č. SN 34582392 | D19: 42.133 | E19: 47.494 | F19: 51.055 | G19: 54.313 | H19: 56.337 | I19: 57.825 | J19: 58.218 | K19: 58.513 | L19: 59.198 | M19: 59.507 | O19: 61.169 | P19: 64.594 | Q19: 69.751 | S19: =Q19-D19 -> 27.618 | U19: TV | V19: 1.869 | W19: 1.608 | X19: 1.249 | Y19: 1.303 | Z19: 1.605 | AA19: 0.851 | AB19: 0.312 | AC19: 1.201 | AD19: 1.363 | AE19: 1.303 | AF19: 1.392 | AG19: 1.892
A20: 14 | B20: 9 | C20: vodoměr č. 190834124 | D20: 215.44 | E20: 221.206 | F20: 228.962 | G20: 235.23 | H20: 244.279 | I20: 252.751 | J20: 259.729 | K20: 263.819 | L20: 270.84 | M20: 278.425 | N20: 0.03 | O20: 6.363 | P20: 13.869 | Q20: 22.085 | R20: =Q20-N20+M20-D20 -> 85.04 | U20: 14 | V20: =E20-D20 -> 5.766 | W20: =F20-E20 -> 7.756 | X20: =G20-F20 -> 6.268 | Y20: =H20-G20 -> 9.049 | Z20: =I20-H20 -> 8.472 | AA20: =J20-I20 -> 6.978 | AB20: =K20-J20 -> 4.09 | AC20: =L20-K20 -> 7.021 | AD20: =M20-L20 -> 7.585 | AE20: =O20-N20 -> 6.333 | AF20: =P20-O20 -> 7.506 | AG20: =Q20-P20 -> 8.216
C21: kalorimetr č. SN 34582418 | D21: 37.831 | E21: 42.725 | F21: 46.437 | G21: 48.715 | H21: 49.995 | I21: 51.184 | J21: 51.517 | K21: 51.802 | L21: 52.189 | M21: 52.577 | O21: 53.781 | P21: 56.948 | Q21: 61.354 | S21: =Q21-D21 -> 23.523 | U21: xx
A22: 10 | B22: 10 | C22: vodoměr č. 190834091 | D22: 196.393 | E22: 199.719 | F22: 202.527 | G22: 205.374 | H22: 207.936 | I22: 210.484 | J22: 213.397 | K22: 216.116 | L22: 218.12 | M22: 222.5 | N22: 0.01 | O22: 1.777 | P22: 3.736 | Q22: 5.619 | R22: =Q22-N22+M22-D22 -> 31.716 | U22: 10 | V22: =E22-D22 -> 3.326 | W22: =F22-E22 -> 2.808 | X22: =G22-F22 -> 2.847 | Y22: =H22-G22 -> 2.562 | Z22: =I22-H22 -> 2.548 | AA22: =J22-I22 -> 2.913 | AB22: =K22-J22 -> 2.719 | AC22: =L22-K22 -> 2.004 | AD22: =M22-L22 -> 4.38 | AE22: =O22-N22 -> 1.767 | AF22: =P22-O22 -> 1.959 | AG22: =Q22-P22 -> 1.883
C23: kalorimetr č. SN 34582411 | D23: 23.343 | E23: 27.011 | F23: 28.815 | G23: 29.914 | H23: 30.425 | I23: 30.764 | J23: 31.011 | K23: 31.298 | L23: 31.562 | M23: 31.909 | O23: 32.769 | P23: 34.853 | Q23: 38.191 | S23: =Q23-D23 -> 14.848 | U23: xx
B24: spol.spotř. | C24: elektroměr č. 72350116 | D24: 53946 | E24: 54207 | F24: 54499 | G24: 54773 | H24: 55043 | I24: 55297 | J24: 55723 | K24: 56017 | L24: 56321 | M24: 56589 | O24: 56898 | P24: 57243 | Q24: 57596 | R24: =SUM(R4:R23)+SUM(R33:R49) -> 1046.561 | S24: =SUM(S4:S23) -> 240.834 | T24: =Q24-D24 -> 3650 | U24: kWh
C26: patní vodoměr č. 190976791 | D26: 3412.3 | E26: 3523.6 | F26: 3621.9 | G26: 3715.9 | H26: 3821.3 | I26: 3921.5 | J26: 3995.1 | K26: 4084.1 | L26: 4174.1 | M26: 4274.5 | N26: 0 | O26: 82.4 | P26: 171.3 | Q26: 286.5 | R26: =Q26-N26+M26-D26 -> 1148.7
C27: patní kalorimetr č. /MWh | D27: 239.7 | E27: 253.91 | F27: 264.35 | G27: 272.76 | H27: 278.95 | I27: 284.01 | J27: 0.97 | K27: 3.71 | L27: 6.51 | M27: 9.84 | O27: 15.14 | P27: 23.57 | Q27: 36.19 | S27: =(Q27-N52+N51-D27)*3.6 -> 293.832 | T27: GJ
C28: patní kalorimetr č./kub.m | D28: 22298 | E28: 24176 | F28: 25585 | G28: 26966 | H28: 28362 | I28: 29733 | J28: 440 | K28: 1657 | L28: 2887 | M28: 4004 | O28: 5308 | P28: 6451 | Q28: 7699
B29: ='1850'!A29 -> fakturační vodoměr č. 110109308 | D29: ='1850'!C29 -> 12400 | E29: ='1850'!D29 -> 12741.6 | F29: ='1850'!E29 -> 4358.2 | G29: ='1850'!F29 -> 4677.5 | H29: ='1850'!G29 -> 5038.2 | I29: ='1850'!H29 -> 5389.7 | J29: ='1850'!I29 -> 5691.3 | K29: ='1850'!J29 -> 6012.6 | ... M29: ='1850'!L29 -> 6605.1 | O29: ='1850'!N29 -> 6922.5 | P29: ='1850'!O29 -> 7232.3 | Q29: ='1850'!R29 -> 7593.2 | R29: ='1850'!S29 -> 3894.2 | V29: studená voda
E31: modře - žádný nárůst | U31: byt | V31: leden | W31: únor | X31: březen | Y31: duben | Z31: květen | AA31: červen | AB31: červenec | AC31: srpen | AD31: září | AE31: říjen | AF31: listopad | AG31: prosinec
A33: 3 | B33: 2B | C33: vodoměr SV č. 190834114 | D33: 328.415 | E33: 336.214 | F33: 343.523 | G33: 350.737 | H33: 358.76 | I33: 367.002 | J33: 372.332 | K33: 380.472 | L33: 390.859 | M33: 400.813 | N33: 0.02 | O33: 5.853 | P33: 13.174 | Q33: 20.499 | R33: =Q33-N33+M33-D33 -> 92.877 | U33: 3 | V33: =E33-D33 -> 7.799 | W33: =F33-E33 -> 7.309 | X33: =G33-F33 -> 7.214 | Y33: =H33-G33 -> 8.023 | Z33: =I33-H33 -> 8.242 | AA33: =J33-I33 -> 5.33 | AB33: =K33-J33 -> 8.14 | AC33: =L33-K33 -> 10.387 | AD33: =M33-L33 -> 9.954 | AE33: =O33-N33 -> 5.833 | AF33: =P33-O33 -> 7.321 | AG33: =Q33-P33 -> 7.325
A34: 6 | B34: 3B | C34: vodoměr SV č. 190834107 | D34: 109.497 | E34: 113.895 | F34: 116.347 | G34: 120.486 | H34: 124.799 | I34: 128.459 | J34: 129.023 | K34: 131.153 | L34: 133.734 | M34: 134.027 | N34: 0.03 | O34: 0.14 | P34: 1.148 | Q34: 6.391 | R34: =Q34-N34+M34-D34 -> 30.891 | U34: 6 | V34: =E34-D34 -> 4.398 | W34: =F34-E34 -> 2.452 | X34: =G34-F34 -> 4.139 | Y34: =H34-G34 -> 4.313 | Z34: =I34-H34 -> 3.66 | AA34: =J34-I34 -> 0.564 | AB34: =K34-J34 -> 2.13 | AC34: =L34-K34 -> 2.581 | AD34: =M34-L34 -> 0.293 | AE34: =O34-N34 -> 0.11 | AF34: =P34-O34 -> 1.008 | AG34: =Q34-P34 -> 5.243
A35: 8 | B35: 5B | C35: vodoměr SV č. 190834094 | D35: 88.561 | E35: 93.88 | F35: 98.164 | G35: 103.197 | H35: 108.667 | I35: 114.359 | J35: 119.51 | K35: 125.858 | L35: 130.087 | M35: 136.07 | N35: 0.01 | O35: 4.482 | P35: 10.331 | Q35: 16.906 | R35: =Q35-N35+M35-D35 -> 64.405 | U35: 8 | V35: =E35-D35 -> 5.319 | W35: =F35-E35 -> 4.284 | X35: =G35-F35 -> 5.033 | Y35: =H35-G35 -> 5.47 | Z35: =I35-H35 -> 5.692 | AA35: =J35-I35 -> 5.151 | AB35: =K35-J35 -> 6.348 | AC35: =L35-K35 -> 4.229 | AD35: =M35-L35 -> 5.983 | AE35: =O35-N35 -> 4.472 | AF35: =P35-O35 -> 5.849 | AG35: =Q35-P35 -> 6.575
A36: 11 | B36: 6B | C36: vodoměr SV č. 190834111 | D36: 6.406 | E36: 6.62 | F36: 6.905 | G36: 7.194 | H36: 7.416 | I36: 7.623 | J36: 7.871 | K36: 8.949 | L36: 9.72 | M36: 10.315 | N36: 0.01 | O36: 0.65 | P36: 1.171 | Q36: 1.985 | R36: =Q36-N36+M36-D36 -> 5.884 | U36: 11 | V36: =E36-D36 -> 0.214 | W36: =F36-E36 -> 0.285 | X36: =G36-F36 -> 0.289 | Y36: =H36-G36 -> 0.222 | Z36: =I36-H36 -> 0.207 | AA36: =J36-I36 -> 0.248 | AB36: =K36-J36 -> 1.078 | AC36: =L36-K36 -> 0.771 | AD36: =M36-L36 -> 0.595 | AE36: =O36-N36 -> 0.64 | AF36: =P36-O36 -> 0.521 | AG36: =Q36-P36 -> 0.814
A37: 12 | B37: 8B | C37: vodoměr SV č. 190834128 | D37: 130.086 | E37: 132.336 | F37: 134.166 | G37: 136.195 | H37: 138.489 | I37: 140.622 | J37: 142.826 | K37: 145.045 | L37: 146.855 | M37: 149.302 | N37: 0.04 | O37: 1.835 | P37: 3.651 | Q37: 5.869 | R37: =Q37-N37+M37-D37 -> 25.045 | U37: 12 | V37: =E37-D37 -> 2.25 | W37: =F37-E37 -> 1.83 | X37: =G37-F37 -> 2.029 | Y37: =H37-G37 -> 2.294 | Z37: =I37-H37 -> 2.133 | AA37: =J37-I37 -> 2.204 | AB37: =K37-J37 -> 2.219 | AC37: =L37-K37 -> 1.81 | AD37: =M37-L37 -> 2.447 | AE37: =O37-N37 -> 1.795 | AF37: =P37-O37 -> 1.816 | AG37: =Q37-P37 -> 2.218
C39: VODOMĚRY TEPLÁ VODA | V39: teplá voda
A40: 2 | B40: 2 | C40: vodoměr TUV č. 190049257 | D40: 181.039 | E40: 187.023 | F40: 192.249 | G40: 197.128 | H40: 203.113 | I40: 208.225 | J40: 210.857 | K40: 213.753 | L40: 216.87 | M40: 220.909 | N40: 0.01 | O40: 1.767 | P40: 2.766 | Q40: 3.373 | R40: =Q40-N40+M40-D40 -> 43.233 | U40: 2 | V40: =E40-D40 -> 5.984 | W40: =F40-E40 -> 5.226 | X40: =G40-F40 -> 4.879 | Y40: =H40-G40 -> 5.985 | Z40: =I40-H40 -> 5.112 | AA40: =J40-I40 -> 2.632 | AB40: =K40-J40 -> 2.896 | AC40: =L40-K40 -> 3.117 | AD40: =M40-L40 -> 4.039 | AE40: =O40-N40 -> 1.757 | AF40: =P40-O40 -> 0.999 | AG40: =Q40-P40 -> 0.607
A41: 3 | B41: 2B | C41: vodoměr TUV č. 190049252 | D41: 220.129 | E41: 225.252 | F41: 230.48 | G41: 235.529 | H41: 241.055 | I41: 246.046 | J41: 248.091 | K41: 251.655 | L41: 255.718 | M41: 260.218 | N41: 0.01 | O41: 3.068 | P41: 5.832 | Q41: 7.554 | R41: =Q41-N41+M41-D41 -> 47.633 | U41: 3 | V41: =E41-D41 -> 5.123 | W41: =F41-E41 -> 5.228 | X41: =G41-F41 -> 5.049 | Y41: =H41-G41 -> 5.526 | Z41: =I41-H41 -> 4.991 | AA41: =J41-I41 -> 2.045 | AB41: =K41-J41 -> 3.564 | AC41: =L41-K41 -> 4.063 | AD41: =M41-L41 -> 4.5 | AE41: =O41-N41 -> 3.058 | AF41: =P41-O41 -> 2.764 | AG41: =Q41-P41 -> 1.722
A42: 5 | B42: 3 | C42: vodoměr TUV č. 190049448 | D42: 2.776 | E42: 3.18 | F42: 3.61 | G42: 4.012 | H42: 4.412 | I42: 4.782 | J42: 5.044 | K42: 5.362 | L42: 5.685 | M42: 6.117 | N42: 0.01 | O42: 0.433 | P42: 0.821 | Q42: 1.251 | R42: =Q42-N42+M42-D42 -> 4.582 | U42: 5 | V42: =E42-D42 -> 0.404 | W42: =F42-E42 -> 0.43 | X42: =G42-F42 -> 0.402 | Y42: =H42-G42 -> 0.4 | Z42: =I42-H42 -> 0.37 | AA42: =J42-I42 -> 0.262 | AB42: =K42-J42 -> 0.318 | AC42: =L42-K42 -> 0.323 | AD42: =M42-L42 -> 0.432 | AE42: =O42-N42 -> 0.423 | AF42: =P42-O42 -> 0.388 | AG42: =Q42-P42 -> 0.43
A43: 6 | B43: 3B | C43: vodoměr TUV č. 190049255 | D43: 56.51 | E43: 58.84 | F43: 60.285 | G43: 62.378 | H43: 64.074 | I43: 65.411 | J43: 65.591 | K43: 66.435 | L43: 67.578 | M43: 67.699 | N43: 0.01 | O43: 0.14 | P43: 0.773 | Q43: 5.46 | R43: =Q43-N43+M43-D43 -> 16.639 | U43: 6 | V43: =E43-D43 -> 2.33 | W43: =F43-E43 -> 1.445 | X43: =G43-F43 -> 2.093 | Y43: =H43-G43 -> 1.696 | Z43: =I43-H43 -> 1.337 | AA43: =J43-I43 -> 0.18 | AB43: =K43-J43 -> 0.844 | AC43: =L43-K43 -> 1.143 | AD43: =M43-L43 -> 0.121 | AE43: =O43-N43 -> 0.13 | AF43: =P43-O43 -> 0.633 | AG43: =Q43-P43 -> 4.687
A44: 9 | B44: 5 | C44: vodoměr TUV č. 190049254 | D44: 55.226 | E44: 67.987 | F44: 78.666 | G44: 81.777 | H44: 85.132 | I44: 86.988 | J44: 87.947 | K44: 91.357 | L44: 93.952 | M44: 97.69 | N44: 0.01 | O44: 2.142 | P44: 4.138 | Q44: 6.077 | R44: =Q44-N44+M44-D44 -> 48.531 | U44: 9 | V44: =E44-D44 -> 12.761 | W44: =F44-E44 -> 10.679 | X44: =G44-F44 -> 3.111 | Y44: =H44-G44 -> 3.355 | Z44: =I44-H44 -> 1.856 | AA44: =J44-I44 -> 0.959 | AB44: =K44-J44 -> 3.41 | AC44: =L44-K44 -> 2.595 | AD44: =M44-L44 -> 3.738 | AE44: =O44-N44 -> 2.132 | AF44: =P44-O44 -> 1.996 | AG44: =Q44-P44 -> 1.939
...

Sheet 1852
A2: 1852 | C2: ='1850'!C2 -> 43466 | D2: ='1850'!D2 -> 43497 | E2: ='1850'!E2 -> 43526 | F2: ='1850'!F2 -> 43556 | G2: ='1850'!G2 -> 43588 | H2: ='1850'!H2 -> 43620 | I2: ='1850'!I2 -> 43647 | J2: ='1850'!J2 -> 43678 | ... O2: ='1850'!O2 -> 43798 | P2: ='1850'!R2 -> 43831 | Q2: voda | R2: teplo | Y2: spotřeby po měsících starý vodoměr | AE2: spotřeby nový vodoměr
A3: byt č. | C3: prosinec | D3: leden | E3: únor | F3: březen | G3: duben | H3: květen | I3: červen | J3: červenec | K3: srpen | L3: září | M3: nový vod. | N3: říjen | O3: listopad | P3: prosinec | Q3: m3 | R3: GJ | T3: byt | U3: leden | V3: únor | W3: březen | X3: duben | Y3: květen | Z3: červen | AA3: červenec | AB3: srpen | AC3: září | AD3: říjen | AE3: listopad | AF3: prosinec
A4: 1 | B4: vodoměr č. 190834115 | C4: 150.122 | D4: 161.988 | E4: 174.722 | F4: 184.196 | G4: 195.424 | H4: 204.124 | I4: 211.184 | J4: 215.703 | K4: 220.132 | L4: 221.617 | M4: 0.04 | N4: 11.192 | O4: 22.304 | P4: 35.466 | Q4: =P4-M4+L4-C4 -> 106.921 | T4: 1 | U4: =D4-C4 -> 11.866 | V4: =E4-D4 -> 12.734 | W4: =F4-E4 -> 9.474 | X4: =G4-F4 -> 11.228 | Y4: =H4-G4 -> 8.7 | Z4: =I4-H4 -> 7.06 | AA4: =J4-I4 -> 4.519 | AB4: =K4-J4 -> 4.429 | AC4: =L4-K4 -> 1.485 | AD4: =N4-M4 -> 11.152 | AE4: =O4-N4 -> 11.112 | AF4: =P4-O4 -> 13.162
B5: kalorimetr č. SN 34582388 | C5: 23.478 | D5: 27.993 | E5: 31.939 | F5: 34.979 | G5: 36.96 | H5: 38.266 | I5: 38.959 | J5: 39.653 | K5: 40.395 | L5: 41.152 | N5: 43.062 | O5: 46.131 | P5: 51.01 | R5: =P5-C5 -> 27.532
A6: 2 | B6: vodoměr č. 190834121 | C6: 303.408 | D6: 310.543 | E6: 317.569 | F6: 324.967 | G6: 332.308 | H6: 338.601 | I6: 345.262 | J6: 345.703 | K6: 347.351 | L6: 349.32 | M6: 0.03 | N6: 0.906 | O6: 2.241 | P6: 4.361 | Q6: =P6-M6+L6-C6 -> 50.243 | T6: 2 | U6: =D6-C6 -> 7.135 | V6: =E6-D6 -> 7.026 | W6: =F6-E6 -> 7.398 | X6: =G6-F6 -> 7.341 | Y6: =H6-G6 -> 6.293 | Z6: =I6-H6 -> 6.661 | AA6: =J6-I6 -> 0.441 | AB6: =K6-J6 -> 1.648 | AC6: =L6-K6 -> 1.969 | AD6: =N6-M6 -> 0.876 | AE6: =O6-N6 -> 1.335 | AF6: =P6-O6 -> 2.12
B7: kalorimetr č. SN 34582394 | C7: 29.867 | D7: 33.272 | E7: 35.974 | F7: 37.677 | G7: 38.913 | H7: 40.049 | I7: 40.444 | J7: 40.766 | K7: 41.016 | L7: 41.273 | N7: 41.595 | O7: 43.19 | P7: 45.521 | R7: =P7-C7 -> 15.654
A8: 3 | B8: vodoměr č. 190834117 | C8: 425.877 | D8: 433.536 | E8: 440.637 | F8: 450.442 | G8: 459.746 | H8: 469.987 | I8: 478.441 | J8: 491.684 | K8: 499.915 | L8: 510.366 | M8: 0.03 | N8: 5.615 | O8: 10.707 | P8: 16.535 | Q8: =P8-M8+L8-C8 -> 100.994 | T8: 3 | U8: =D8-C8 -> 7.659 | V8: =E8-D8 -> 7.101 | W8: =F8-E8 -> 9.805 | X8: =G8-F8 -> 9.304 | Y8: =H8-G8 -> 10.241 | Z8: =I8-H8 -> 8.454 | AA8: =J8-I8 -> 13.243 | AB8: =K8-J8 -> 8.231 | AC8: =L8-K8 -> 10.451 | AD8: =N8-M8 -> 5.585 | AE8: =O8-N8 -> 5.092 | AF8: =P8-O8 -> 5.828
B9: kalorimetr č. SN 34582389 | C9: 35.464 | D9: 40.722 | E9: 44.925 | F9: 48.267 | G9: 50.368 | H9: 51.233 | I9: 51.647 | J9: 52.201 | K9: 52.597 | L9: 53.482 | N9: 55.128 | O9: 58.238 | P9: 63.801 | R9: =P9-C9 -> 28.337
A10: 4 | B10: vodoměr č. 190834096 | C10: 270.277 | D10: 282.066 | E10: 294.316 | F10: 306.341 | G10: 317.993 | H10: 329.428 | I10: 338.481 | J10: 342.834 | K10: 345.441 | L10: 358.565 | M10: 0.01 | N10: 12.567 | O10: 24.829 | P10: 40.108 | Q10: =P10-M10+L10-C10 -> 128.386 | T10: 4 | U10: =D10-C10 -> 11.789 | V10: =E10-D10 -> 12.25 | W10: =F10-E10 -> 12.025 | X10: =G10-F10 -> 11.652 | Y10: =H10-G10 -> 11.435 | Z10: =I10-H10 -> 9.053 | AA10: =J10-I10 -> 4.353 | AB10: =K10-J10 -> 2.607 | AC10: =L10-K10 -> 13.124 | AD10: =N10-M10 -> 12.557 | AE10: =O10-N10 -> 12.262 | AF10: =P10-O10 -> 15.279
B11: kalorimetr č. SN 34582395 | C11: 49.415 | D11: 55.182 | E11: 59.449 | F11: 62.282 | G11: 63.7 | H11: 65.408 | I11: 65.971 | J11: 66.278 | K11: 66.54 | L11: 67.44 | N11: 69.55 | O11: 73.129 | P11: 77.768 | R11: =P11-C11 -> 28.353
A12: 5 | B12: vodoměr č. 190834110 | C12: 362.584 | D12: 362.855 | E12: 363.442 | F12: 364.019 | G12: 365.091 | H12: 365.36 | I12: 365.439 | J12: 365.45 | K12: 365.539 | L12: 365.61 | M12: 0.01 | N12: 0.026 | O12: 0.035 | P12: 0.247 | Q12: =P12-M12+L12-C12 -> 3.263 | T12: 5 | U12: =D12-C12 -> 0.271 | V12: =E12-D12 -> 0.587 | W12: =F12-E12 -> 0.577 | X12: =G12-F12 -> 1.072 | Y12: =H12-G12 -> 0.269 | Z12: =I12-H12 -> 0.079 | AA12: =J12-I12 -> 0.011 | AB12: =K12-J12 -> 0.089 | AC12: =L12-K12 -> 0.071 | AD12: =N12-M12 -> 0.016 | AE12: =O12-N12 -> 0.009 | AF12: =P12-O12 -> 0.212
B13: kalorimetr č. SN 34582393 | C13: 13.955 | D13: 14.129 | E13: 14.319 | F13: 14.466 | G13: 14.658 | H13: 14.838 | I13: 14.966 | J13: 15.114 | K13: 15.276 | L13: 15.446 | N13: 15.619 | O13: 15.777 | P13: 15.984 | R13: =P13-C13 -> 2.029
A14: 6 | B14: vodoměr č. 190834127 | C14: 186.038 | D14: 194.162 | E14: 201.71 | F14: 210.23 | G14: 221.467 | H14: 229.359 | I14: 236.596 | J14: 243.085 | K14: 249.649 | L14: 259.685 | M14: 0.04 | N14: 7.17 | O14: 12.179 | P14: 21.617 | Q14: =P14-M14+L14-C14 -> 95.224 | T14: 6 | U14: =D14-C14 -> 8.124 | V14: =E14-D14 -> 7.548 | W14: =F14-E14 -> 8.52 | X14: =G14-F14 -> 11.237 | Y14: =H14-G14 -> 7.892 | Z14: =I14-H14 -> 7.237 | AA14: =J14-I14 -> 6.489 | AB14: =K14-J14 -> 6.564 | AC14: =L14-K14 -> 10.036 | AD14: =N14-M14 -> 7.13 | AE14: =O14-N14 -> 5.009 | AF14: =P14-O14 -> 9.438
B15: kalorimetr č. SN 34582399 | C15: 70.872 | D15: 76.12 | E15: 81.016 | F15: 84.797 | G15: 87.609 | H15: 89.696 | I15: 90.443 | J15: 91.176 | K15: 92.003 | L15: 93.423 | N15: 95.925 | O15: 100.227 | P15: 105.191 | R15: =P15-C15 -> 34.319
A16: 7 | B16: vodoměr č. 190834123 | C16: 70.861 | D16: 71.552 | E16: 72.382 | F16: 73.019 | G16: 75.209 | H16: 75.892 | I16: 76.315 | J16: 79.423 | K16: 82.857 | L16: 83.687 | M16: 0.03 | N16: 1.091 | O16: 1.916 | P16: 2.368 | Q16: =P16-M16+L16-C16 -> 15.164 | T16: 7 | U16: =D16-C16 -> 0.691 | V16: =E16-D16 -> 0.83 | W16: =F16-E16 -> 0.637 | X16: =G16-F16 -> 2.19 | Y16: =H16-G16 -> 0.683 | Z16: =I16-H16 -> 0.423 | AA16: =J16-I16 -> 3.108 | AB16: =K16-J16 -> 3.434 | AC16: =L16-K16 -> 0.83 | AD16: =N16-M16 -> 1.061 | AE16: =O16-N16 -> 0.825 | AF16: =P16-O16 -> 0.452
B17: kalorimetr č. SN 34582404 | C17: 18.161 | D17: 21.532 | E17: 22.74 | F17: 23.56 | G17: 23.739 | H17: 23.883 | I17: 23.887 | J17: 23.941 | K17: 24.005 | L17: 24.027 | N17: 24.582 | O17: 26.215 | P17: 29.122 | R17: =P17-C17 -> 10.961
A18: 8 | B18: vodoměr č. 190834118 | C18: 73.238 | D18: 81.477 | E18: 88.047 | F18: 97.629 | G18: 104.911 | H18: 112.354 | I18: 118.181 | J18: 127.159 | K18: 133.3 | L18: 138.281 | M18: 0.02 | N18: 7.237 | O18: 14.352 | P18: 21.516 | Q18: =P18-M18+L18-C18 -> 86.539 | T18: 8 | U18: =D18-C18 -> 8.239 | V18: =E18-D18 -> 6.57 | W18: =F18-E18 -> 9.582 | X18: =G18-F18 -> 7.282 | Y18: =H18-G18 -> 7.443 | Z18: =I18-H18 -> 5.827 | AA18: =J18-I18 -> 8.978 | AB18: =K18-J18 -> 6.141 | AC18: =L18-K18 -> 4.981 | AD18: =N18-M18 -> 7.217 | AE18: =O18-N18 -> 7.115 | AF18: =P18-O18 -> 7.164
B19: kalorimetr č. SN 34582406 | C19: 12.081 | D19: 17.082 | E19: 20.425 | F19: 22.184 | G19: 23.077 | H19: 23.941 | I19: 24.293 | J19: 24.804 | K19: 25.208 | L19: 25.545 | N19: 26.263 | O19: 29.256 | P19: 32.916 | R19: =P19-C19 -> 20.835
A20: 9 | B20: vodoměr č. 190834113 | C20: 402.999 | D20: 413.769 | E20: 424.913 | F20: 434.923 | G20: 443.842 | H20: 452.956 | I20: 459.258 | J20: 465.19 | K20: 472.358 | L20: 476.65 | M20: 0.01 | N20: 6.332 | O20: 14.502 | P20: 23.265 | Q20: =P20-M20+L20-C20 -> 96.906 | T20: 9 | U20: =D20-C20 -> 10.77 | V20: =E20-D20 -> 11.144 | W20: =F20-E20 -> 10.01 | X20: =G20-F20 -> 8.919 | Y20: =H20-G20 -> 9.114 | Z20: =I20-H20 -> 6.302 | AA20: =J20-I20 -> 5.932 | AB20: =K20-J20 -> 7.168 | AC20: =L20-K20 -> 4.292 | AD20: =N20-M20 -> 6.322 | AE20: =O20-N20 -> 8.17 | AF20: =P20-O20 -> 8.763
B21: kalorimetr č. SN 34582405 | C21: 42.544 | D21: 48.626 | E21: 52.829 | F21: 55.862 | G21: 57.477 | H21: 59.138 | I21: 59.542 | J21: 59.936 | K21: 60.41 | L21: 62.095 | N21: 63.82 | O21: 67.8 | P21: 74.263 | R21: =P21-C21 -> 31.719
A22: 10 | B22: vodoměr č. 190834129 | C22: 121.043 | D22: 126.056 | E22: 129.652 | F22: 135.184 | G22: 141.327 | H22: 147.362 | I22: 152.704 | J22: 158.529 | K22: 163.983 | L22: 170.751 | M22: 0.01 | N22: 6.267 | O22: 12.955 | P22: 19.413 | Q22: =P22-M22+L22-C22 -> 69.111 | T22: 10 | U22: =D22-C22 -> 5.013 | V22: =E22-D22 -> 3.596 | W22: =F22-E22 -> 5.532 | X22: =G22-F22 -> 6.143 | Y22: =H22-G22 -> 6.035 | Z22: =I22-H22 -> 5.342 | AA22: =J22-I22 -> 5.825 | AB22: =K22-J22 -> 5.454 | AC22: =L22-K22 -> 6.768 | AD22: =N22-M22 -> 6.257 | AE22: =O22-N22 -> 6.688 | AF22: =P22-O22 -> 6.458
B23: kalorimetr č. SN 34582407 | C23: 18.304 | D23: 20.658 | E23: 22.128 | F23: 23.471 | G23: 24.156 | H23: 24.648 | I23: 24.987 | J23: 25.352 | K23: 25.81 | L23: 26.266 | N23: 27.151 | O23: 29.248 | P23: 32.152 | R23: =P23-C23 -> 13.848
Q24: =SUM(Q4:Q23) -> 752.751 | R24: =SUM(R4:R23) -> 213.587
A25: spol.spotř. | B25: elektroměr č. 723 50117 | C25: 59017 | D25: 59288 | E25: 59509 | F25: 59730 | G25: 59975 | H25: 60202 | I25: 60430 | J25: 60650 | K25: 60886 | L25: 61108 | N25: 61350 | O25: 61566 | P25: 61952 | S25: =P25-C25 -> 2935
B26: patní vodoměr č. 190976792 | C26: 2584.9 | D26: 2664.1 | E26: 2739.7 | F26: 2824.7 | G26: 2911.9 | H26: 2991.5 | I26: 3059.6 | J26: 3125 | K26: 3187.6 | L26: 3259.2 | M26: 0 | N26: 67 | O26: 135.8 | P26: 218.7 | Q26: =P26-M26+L26-C26 -> 893
B27: patní kalorimetr č./MWh | C27: 216.39 | D27: 228.75 | E27: 238.01 | F27: 244.88 | G27: 249.13 | H27: 252.85 | I27: 0.75 | J27: 2.73 | K27: 4.74 | L27: 7.5 | N27: 11.69 | O27: 19.4 | P27: 30.68 | R27: =(P27-M32+M31-C27)*3.6 -> 245.052 | S27: GJ
B28: patní kalorimetr č./kub.m | C28: 13941 | D28: 14909 | E28: 15538 | F28: 16064 | G28: 16392 | H28: 16879 | I28: 181 | J28: 670 | K28: 1168 | L28: 1654 | N28: 1989 | O28: 2319 | P28: 2747
A29: ='1850'!A29 -> fakturační vodoměr č. 110109308 | C29: ='1850'!C29 -> 12400 | D29: ='1850'!D29 -> 12741.6 | E29: ='1850'!E29 -> 4358.2 | F29: ='1850'!F29 -> 4677.5 | G29: ='1850'!G29 -> 5038.2 | H29: ='1850'!H29 -> 5389.7 | I29: ='1850'!I29 -> 5691.3 | J29: ='1850'!J29 -> 6012.6 | ... L29: ='1850'!L29 -> 6605.1 | N29: ='1850'!N29 -> 6922.5 | O29: ='1850'!O29 -> 7232.3 | P29: ='1850'!R29 -> 7593.2 | Q29: ='1850'!S29 -> 3894.2
D31: modře - žádný nárůst | H31: Dne 17.6.2019 odpojen kalor. (cejchování), | L31: stav: | M31: 253.78 | N31: MWh
B32: Výměna fakturač. vodoměru | C32: 110109308 | D32: starý | E32: 12875 | H32: Dne 20.6.2019 zapojen znovuzapojení, | L32: stav: | M32: 0 | N32: MWh
B33: dne 14.2.2019 | C33: 63796 | D33: nový | E33: 4174 | H33: Dne 4.10.2019 výměna vodoměrů - byty + pata
H34: Odečty vody za září jsou ze dne výměny 4.10.

Sheet 1853
A2: 1853 | C2: ='1850'!C2 -> 43466 | D2: ='1850'!D2 -> 43497 | E2: ='1850'!E2 -> 43526 | F2: ='1850'!F2 -> 43556 | G2: ='1850'!G2 -> 43588 | H2: ='1850'!H2 -> 43620 | I2: ='1850'!I2 -> 43647 | J2: ='1850'!J2 -> 43678 | ... O2: ='1850'!O2 -> 43798 | P2: ='1850'!R2 -> 43831 | Q2: Voda | R2: Teplo | S2: Elektr | Y2: spotřeby po měsících starý vodoměr | AE2: spotřeby nový vodoměr
A3: byt č. | C3: prosinec | D3: leden | E3: únor | F3: březen | G3: duben | H3: květen | I3: červen | J3: červenec | K3: srpen | L3: září | M3: nový vod. | N3: říjen | O3: listopad | P3: prosinec | Q3: m3 | R3: GJ | S3: KWh | T3: byt | U3: leden | V3: únor | W3: březen | X3: duben | Y3: květen | Z3: červen | AA3: červenec | AB3: srpen | AC3: září | AD3: říjen | AE3: listopad | AF3: prosinec
A4: 1 | B4: vodoměr č. 190834100 | C4: 198.054 | D4: 210.55 | E4: 222.067 | F4: 233.708 | G4: 246.728 | H4: 260.85 | I4: 270.446 | J4: 282.653 | K4: 297.135 | L4: 309.135 | M4: 0.03 | N4: 13.225 | O4: 26.066 | P4: 40.011 | Q4: =P4-M4+L4-C4 -> 151.062 | T4: 1 | U4: =D4-C4 -> 12.496 | V4: =E4-D4 -> 11.517 | W4: =F4-E4 -> 11.641 | X4: =G4-F4 -> 13.02 | Y4: =H4-G4 -> 14.122 | Z4: =I4-H4 -> 9.596 | AA4: =J4-I4 -> 12.207 | AB4: =K4-J4 -> 14.482 | AC4: =L4-K4 -> 12 | AD4: =N4-M4 -> 13.195 | AE4: =O4-N4 -> 12.841 | AF4: =P4-O4 -> 13.945
B5: kalorimetr č. SN 34582390 | C5: 56.023 | D5: 62.737 | E5: 68.158 | F5: 72.67 | G5: 75.286 | H5: 77.03 | I5: 77.694 | J5: 78.528 | K5: 79.534 | L5: 80.54 | N5: 82.368 | O5: 85.023 | P5: 89.812 | R5: =P5-C5 -> 33.789
A6: 2 | B6: vodoměr č. 190906789 | C6: 405.487 | D6: 413.831 | E6: 421.36 | F6: 428.694 | G6: 437.347 | H6: 446.908 | I6: 452.459 | J6: 459.796 | K6: 467.755 | L6: 475.257 | M6: 0.01 | N6: 6.843 | O6: 10.087 | P6: 19.397 | Q6: =P6-M6+L6-C6 -> 89.157 | T6: 2 | U6: =D6-C6 -> 8.344 | V6: =E6-D6 -> 7.529 | W6: =F6-E6 -> 7.334 | X6: =G6-F6 -> 8.653 | Y6: =H6-G6 -> 9.561 | Z6: =I6-H6 -> 5.551 | AA6: =J6-I6 -> 7.337 | AB6: =K6-J6 -> 7.959 | AC6: =L6-K6 -> 7.502 | AD6: =N6-M6 -> 6.833 | AE6: =O6-N6 -> 3.244 | AF6: =P6-O6 -> 9.31
B7: kalorimetr č. SN 34582422 | C7: 14.737 | D7: 17.045 | E7: 18.755 | F7: 19.968 | G7: 20.698 | H7: 21.402 | I7: 21.761 | J7: 22.277 | K7: 22.745 | L7: 23.234 | N7: 23.808 | O7: 24.466 | P7: 26.576 | R7: =P7-C7 -> 11.839
A8: 3 | B8: vodoměr č. 190906786 | C8: 44.09 | D8: 45.156 | E8: 46.059 | F8: 47.481 | G8: 48.445 | H8: 49.455 | I8: 50.339 | J8: 51.344 | K8: 52.635 | L8: 54.63 | M8: 0.01 | N8: 0.922 | O8: 1.522 | P8: 2.407 | Q8: =P8-M8+L8-C8 -> 12.937 | T8: 3 | U8: =D8-C8 -> 1.066 | V8: =E8-D8 -> 0.903 | W8: =F8-E8 -> 1.422 | X8: =G8-F8 -> 0.964 | Y8: =H8-G8 -> 1.01 | Z8: =I8-H8 -> 0.884 | AA8: =J8-I8 -> 1.005 | AB8: =K8-J8 -> 1.291 | AC8: =L8-K8 -> 1.995 | AD8: =N8-M8 -> 0.912 | AE8: =O8-N8 -> 0.6 | AF8: =P8-O8 -> 0.885
B9: kalorimetr č. SN 34582386 | C9: 10.391 | D9: 13.032 | E9: 15.04 | F9: 15.938 | G9: 15.967 | H9: 15.983 | I9: 16.006 | J9: 16.029 | K9: 16.054 | L9: 16.081 | N9: 16.094 | O9: 16.401 | P9: 17.361 | R9: =P9-C9 -> 6.97
A10: 4 | B10: vodoměr č. 190834105 | C10: 107.926 | D10: 117.365 | E10: 126.842 | F10: 136.492 | G10: 144.354 | H10: 152.207 | I10: 156.755 | J10: 161.873 | K10: 167.548 | L10: 171.26 | M10: 0.04 | N10: 9.608 | O10: 17.795 | P10: 23.053 | Q10: =P10-M10+L10-C10 -> 86.347 | T10: 4 | U10: =D10-C10 -> 9.439 | V10: =E10-D10 -> 9.477 | W10: =F10-E10 -> 9.65 | X10: =G10-F10 -> 7.862 | Y10: =H10-G10 -> 7.853 | Z10: =I10-H10 -> 4.548 | AA10: =J10-I10 -> 5.118 | AB10: =K10-J10 -> 5.675 | AC10: =L10-K10 -> 3.712 | AD10: =N10-M10 -> 9.568 | AE10: =O10-N10 -> 8.187 | AF10: =P10-O10 -> 5.258
B11: kalorimetr č. SN 34582421 | C11: 28.359 | D11: 32.476 | E11: 34.833 | F11: 36.308 | G11: 36.854 | H11: 37.336 | I11: 37.564 | J11: 37.813 | K11: 38.099 | L11: 38.26 | N11: 39.125 | O11: 40.684 | P11: 42.628 | R11: =P11-C11 -> 14.269
A12: 5 | B12: vodoměr č. 190906792 | C12: 283.13 | D12: 296.614 | E12: 311.206 | F12: 315.479 | G12: 323.783 | H12: 331.953 | I12: 339.429 | J12: 347.223 | K12: 353.342 | L12: 359.83 | M12: 0.01 | N12: 7.031 | O12: 14.98 | P12: 24.351 | Q12: =P12-M12+L12-C12 -> 101.041 | T12: 5 | U12: =D12-C12 -> 13.484 | V12: =E12-D12 -> 14.592 | W12: =F12-E12 -> 4.273 | X12: =G12-F12 -> 8.304 | Y12: =H12-G12 -> 8.17 | Z12: =I12-H12 -> 7.476 | AA12: =J12-I12 -> 7.794 | AB12: =K12-J12 -> 6.119 | AC12: =L12-K12 -> 6.488 | AD12: =N12-M12 -> 7.021 | AE12: =O12-N12 -> 7.949 | AF12: =P12-O12 -> 9.371
B13: kalorimetr č. SN 34582387 | C13: 21.785 | D13: 24.501 | E13: 26.415 | F13: 27.165 | G13: 27.773 | H13: 28.362 | I13: 28.674 | J13: 29.052 | K13: 29.269 | L13: 29.526 | N13: 30.045 | O13: 32.179 | P13: 34.753 | R13: =P13-C13 -> 12.968
A14: 6 | B14: vodoměr č. 190906795 | C14: 306.416 | D14: 311.347 | E14: 316.121 | F14: 320.16 | G14: 324.479 | H14: 329.227 | I14: 333.532 | J14: 337.27 | K14: 340.919 | L14: 345.45 | M14: 0.01 | N14: 3.882 | O14: 7.955 | P14: 13.147 | Q14: =P14-M14+L14-C14 -> 52.171 | T14: 6 | U14: =D14-C14 -> 4.931 | V14: =E14-D14 -> 4.774 | W14: =F14-E14 -> 4.039 | X14: =G14-F14 -> 4.319 | Y14: =H14-G14 -> 4.748 | Z14: =I14-H14 -> 4.305 | AA14: =J14-I14 -> 3.738 | AB14: =K14-J14 -> 3.649 | AC14: =L14-K14 -> 4.531 | AD14: =N14-M14 -> 3.872 | AE14: =O14-N14 -> 4.073 | AF14: =P14-O14 -> 5.192
B15: kalorimetr č. SN 34582420 | C15: 38.582 | D15: 41.668 | E15: 43.31 | F15: 44.197 | G15: 44.738 | H15: 45.231 | I15: 45.332 | J15: 45.414 | K15: 45.507 | L15: 45.601 | N15: 46.263 | O15: 48.009 | P15: 50.337 | R15: =P15-C15 -> 11.755
A16: 7 | B16: vodoměr č. 190834103 | C16: 33.134 | D16: 45.347 | E16: 54.18 | F16: 62.238 | G16: 70.933 | H16: 79.531 | I16: 86.322 | J16: 91.548 | K16: 98.542 | L16: 108.673 | M16: 0.05 | N16: 9.012 | O16: 17.613 | P16: 27.944 | Q16: =P16-M16+L16-C16 -> 103.433 | T16: 7 | U16: =D16-C16 -> 12.213 | V16: =E16-D16 -> 8.833 | W16: =F16-E16 -> 8.058 | X16: =G16-F16 -> 8.695 | Y16: =H16-G16 -> 8.598 | Z16: =I16-H16 -> 6.791 | AA16: =J16-I16 -> 5.226 | AB16: =K16-J16 -> 6.994 | AC16: =L16-K16 -> 10.131 | AD16: =N16-M16 -> 8.962 | AE16: =O16-N16 -> 8.601 | AF16: =P16-O16 -> 10.331
B17: kalorimetr č. SN 34582412 | C17: 20.053 | D17: 24.544 | E17: 27.323 | F17: 29.141 | G17: 30.22 | H17: 31.364 | I17: 31.813 | J17: 32.182 | K17: 32.663 | L17: 33.31 | N17: 34.282 | O17: 36.978 | P17: 40.87 | R17: =P17-C17 -> 20.817
A18: 8 | B18: vodoměr č. 190834101 | C18: 34.36 | D18: 40.868 | E18: 47.973 | F18: 54.286 | G18: 60.886 | H18: 67.83 | I18: 73.377 | J18: 79.469 | K18: 83.792 | L18: 90.976 | M18: 0.01 | N18: 5.87 | O18: 12.04 | P18: 19.689 | Q18: =P18-M18+L18-C18 -> 76.295 | T18: 8 | U18: =D18-C18 -> 6.508 | V18: =E18-D18 -> 7.105 | W18: =F18-E18 -> 6.313 | X18: =G18-F18 -> 6.6 | Y18: =H18-G18 -> 6.944 | Z18: =I18-H18 -> 5.547 | AA18: =J18-I18 -> 6.092 | AB18: =K18-J18 -> 4.323 | AC18: =L18-K18 -> 7.184 | AD18: =N18-M18 -> 5.86 | AE18: =O18-N18 -> 6.17 | AF18: =P18-O18 -> 7.649
B19: kalorimetr č. SN 34582403 | C19: 10.563 | D19: 15.605 | E19: 18.59 | F19: 20.594 | G19: 21.508 | H19: 22.237 | I19: 22.452 | J19: 22.738 | K19: 22.951 | L19: 23.281 | N19: 24.316 | O19: 27.257 | P19: 31.264 | R19: =P19-C19 -> 20.701
A20: 9 | B20: vodoměr č. 190834108 | C20: 130.44 | D20: 134.015 | E20: 137.277 | F20: 140.916 | G20: 145.336 | H20: 149.546 | I20: 153.197 | J20: 156.776 | K20: 160.31 | L20: 163.56 | M20: 0.07 | N20: 3.22 | O20: 6.518 | P20: 10.416 | Q20: =P20-M20+L20-C20 -> 43.466 | T20: 9 | U20: =D20-C20 -> 3.575 | V20: =E20-D20 -> 3.262 | W20: =F20-E20 -> 3.639 | X20: =G20-F20 -> 4.42 | Y20: =H20-G20 -> 4.21 | Z20: =I20-H20 -> 3.651 | AA20: =J20-I20 -> 3.579 | AB20: =K20-J20 -> 3.534 | AC20: =L20-K20 -> 3.25 | AD20: =N20-M20 -> 3.15 | AE20: =O20-N20 -> 3.298 | AF20: =P20-O20 -> 3.898
B21: kalorimetr č. SN 34582409 | C21: 33.065 | D21: 37.776 | E21: 40.696 | F21: 42.877 | G21: 43.697 | H21: 44.639 | I21: 44.918 | J21: 45.215 | K21: 45.512 | L21: 45.8 | N21: 46.584 | O21: 49.057 | P21: 52.977 | R21: =P21-C21 -> 19.912
A22: 10 | B22: vodoměr č. 190906953 | C22: 325.426 | D22: 330.743 | E22: 336.555 | F22: 342.738 | G22: 347.096 | H22: 352.902 | I22: 356.703 | J22: 362.214 | K22: 367.09 | L22: 373.696 | M22: 0.01 | N22: 5.041 | O22: 10.269 | P22: 17.996 | Q22: =P22-M22+L22-C22 -> 66.256 | T22: 10 | U22: =D22-C22 -> 5.317 | V22: =E22-D22 -> 5.812 | W22: =F22-E22 -> 6.183 | X22: =G22-F22 -> 4.358 | Y22: =H22-G22 -> 5.806 | Z22: =I22-H22 -> 3.801 | AA22: =J22-I22 -> 5.511 | AB22: =K22-J22 -> 4.876 | AC22: =L22-K22 -> 6.606 | AD22: =N22-M22 -> 5.031 | AE22: =O22-N22 -> 5.228 | AF22: =P22-O22 -> 7.727
B23: kalorimetr č. SN 34582415 | C23: 37.373 | D23: 41.192 | E23: 44.471 | F23: 47.12 | G23: 48.94 | H23: 50.293 | I23: 50.381 | J23: 50.535 | K23: 50.637 | L23: 50.937 | N23: 52.43 | O23: 55.327 | P23: 59.152 | R23: =P23-C23 -> 21.779
B24: elektroměr č. 72350114 dům | C24: 47097 | D24: 47423 | E24: 47693 | F24: 47934 | G24: 48250 | H24: 48524 | I24: 48741 | J24: 49037 | K24: 49257 | L24: 49494 | N24: 49862 | O24: 50127 | P24: 50383 | Q24: =SUM(Q4:Q23) -> 782.165 | R24: =SUM(R4:R23) -> 174.799 | S24: =P24-C24 -> 3286
A25: spol.spotř. | B25: elektroměr č. 72325367 VO | C25: 40137 | D25: 40582 | E25: 40964 | F25: 41310 | G25: 41628 | H25: 41902 | I25: 42109 | J25: 42354 | K25: 42653 | L25: 42973 | N25: 43391 | O25: 43833 | P25: 44564 | S25: =P25-C25 -> 4427
B26: vodoměr areál č.10282180 | C26: 527 | D26: 527 | E26: 527 | F26: 527 | G26: 542.426 | H26: 551.438 | I26: 583.556 | J26: 614.16 | K26: 632.318 | L26: 641.817 | N26: 643.691 | O26: 655.348 | P26: 655.348 | Q26: =P26-C26 -> 128.348
B27: patní vodoměr č. 190976789 | C27: 2431.3 | D27: 2514.5 | E27: 2593.4 | F27: 2661.2 | G27: 2749.4 | H27: 2834.9 | I27: 2924.9 | J27: 3016.4 | K27: 3097.7 | L27: 3174.4 | M27: 0 | N27: 71.7 | O27: 149.5 | P27: 230.5 | Q27: =P27-M27+L27-C27 -> 973.6
B28: patní kalorimetr č./ MWh | C28: 188.01 | D28: 200.55 | E28: 209.52 | F28: 215.91 | G28: 219.87 | H28: 223.36 | I28: 0.62 | J28: 2.44 | K28: 4.33 | L28: 6.28 | N28: 9.88 | O28: 16.7 | P28: 26.72 | R28: =(P28-M33+M32-C28)*3.6 -> 226.404 | S28: GJ
B29: patní kalorimetr č. /kub.m | C29: 9883 | D29: 10839 | E29: 11613 | F29: 12360 | G29: 13086 | H29: 13789 | I29: 218 | J29: 812 | K29: 1404 | L29: 1937 | N29: 2604 | O29: 3212 | P29: 3872
A30: ='1850'!A29 -> fakturační vodoměr č. 110109308 | C30: ='1850'!C29 -> 12400 | D30: ='1850'!D29 -> 12741.6 | E30: ='1850'!E29 -> 4358.2 | F30: ='1850'!F29 -> 4677.5 | G30: ='1850'!G29 -> 5038.2 | H30: ='1850'!H29 -> 5389.7 | I30: ='1850'!I29 -> 5691.3 | J30: ='1850'!J29 -> 6012.6 | ... L30: ='1850'!L29 -> 6605.1 | N30: ='1850'!N29 -> 6922.5 | O30: ='1850'!O29 -> 7232.3 | P30: ='1850'!R29 -> 7593.2 | Q30: ='1850'!S29 -> 3894.2
D32: modře - žádný nárůst | H32: Dne 17.6.2019 odpojen kalor. (cejchování), | L32: stav: | M32: 224.18 | N32: MWh
B33: Výměna fakturač. vodoměru | C33: 110109308 | D33: starý | E33: 12875 | H33: Dne 20.6.2019 zapojen znovuzapojení, | L33: stav: | M33: 0 | N33: MWh
B34: dne 14.2.2019 | C34: 63796 | D34: nový | E34: 4174 | H34: Dne 4.10.2019 výměna vodoměrů - byty + pata
H35: Odečty vody za září jsou ze dne výměny 4.10.

Sheet 1854
A2: 1854 | C2: ='1850'!C2 -> 43466 | D2: ='1850'!D2 -> 43497 | E2: ='1850'!E2 -> 43526 | F2: ='1850'!F2 -> 43556 | G2: ='1850'!G2 -> 43588 | H2: ='1850'!H2 -> 43620 | I2: ='1850'!I2 -> 43647 | J2: ='1850'!J2 -> 43678 | ... R2: ='1850'!R2 -> 43831 | S2: voda | T2: teplo | AA2: spotřeby po měsících starý vodoměr | AG2: spotřeby nový vodoměr
A3: byt č. | C3: prosinec | D3: leden | E3: únor | F3: březen | G3: duben | H3: květen | I3: červen | J3: červenec | K3: srpen | L3: září | M3: nový vod. | N3: říjen | O3: listopad | P3: výměna | Q3: nový vod. | R3: prosinec | S3: m3 | T3: GJ | V3: byt | W3: leden | X3: únor | Y3: březen | Z3: duben | AA3: květen | AB3: červen | AC3: červenec | AD3: srpen | AE3: září | AF3: říjen | AG3: listopad | AH3: prosinec
A4: 1 | B4: vodoměr č. 190906992 | C4: 36.996 | D4: 41.875 | E4: 48.538 | F4: 56.049 | G4: 61.1 | H4: 68.297 | I4: 72.546 | J4: 77.14 | K4: 82.606 | L4: 89.54 | M4: 0.01 | N4: 7.251 | O4: 14.459 | P4: 16.087 | Q4: 16.087 | R4: 21.315 | S4: =R4-M4+L4-C4 -> 73.849 | V4: 1 | W4: =D4-C4 -> 4.879 | X4: =E4-D4 -> 6.663 | Y4: =F4-E4 -> 7.511 | Z4: =G4-F4 -> 5.051 | AA4: =H4-G4 -> 7.197 | AB4: =I4-H4 -> 4.249 | AC4: =J4-I4 -> 4.594 | AD4: =K4-J4 -> 5.466 | AE4: =L4-K4 -> 6.934 | AF4: =N4-M4 -> 7.241 | AG4: =O4-N4 -> 7.208 | AH4: =R4-Q4 -> 5.228
B5: kalorimetr č. SN 34672835 | C5: 10.937 | D5: 15.779 | E5: 19.433 | F5: 22.365 | G5: 23.857 | H5: 25.115 | I5: 25.373 | J5: 25.651 | K5: 25.981 | L5: 26.367 | N5: 27.694 | O5: 30.342 | R5: 34.212 | T5: =R5-C5 -> 23.275
A6: 2 | B6: vodoměr č. 190906991 | C6: 138.59 | D6: 143.059 | E6: 147.736 | F6: 153.427 | G6: 158.725 | H6: 164.119 | I6: 168.708 | J6: 174.561 | K6: 177.641 | L6: 182.34 | M6: 0.01 | N6: 4.795 | O6: 9.481 | P6: 10.473 | Q6: 10.473 | R6: 13.675 | S6: =R6-M6+L6-C6 -> 57.415 | V6: 2 | W6: =D6-C6 -> 4.469 | X6: =E6-D6 -> 4.677 | Y6: =F6-E6 -> 5.691 | Z6: =G6-F6 -> 5.298 | AA6: =H6-G6 -> 5.394 | AB6: =I6-H6 -> 4.589 | AC6: =J6-I6 -> 5.853 | AD6: =K6-J6 -> 3.08 | AE6: =L6-K6 -> 4.699 | AF6: =N6-M6 -> 4.785 | AG6: =O6-N6 -> 4.686 | AH6: =R6-Q6 -> 3.202
B7: kalorimetr č. SN 34672801 | C7: 58.263 | D7: 65.114 | E7: 70.327 | F7: 74.451 | G7: 77.513 | H7: 79.797 | I7: 80.118 | J7: 80.501 | K7: 80.785 | L7: 81.183 | N7: 82.591 | O7: 86.247 | R7: 91.287 | T7: =R7-C7 -> 33.024
A8: 3 | B8: vodoměr č. 190906988 | C8: 212.784 | D8: 219.228 | E8: 226.474 | F8: 232.422 | G8: 239.232 | H8: 246.965 | I8: 254.201 | J8: 260.309 | K8: 268.083 | L8: 274.89 | M8: 0.01 | N8: 5.963 | O8: 12.108 | P8: 13.379 | Q8: 13.379 | R8: 18.036 | S8: =R8-M8+L8-C8 -> 80.132 | V8: 3 | W8: =D8-C8 -> 6.444 | X8: =E8-D8 -> 7.246 | Y8: =F8-E8 -> 5.948 | Z8: =G8-F8 -> 6.81 | AA8: =H8-G8 -> 7.733 | AB8: =I8-H8 -> 7.236 | AC8: =J8-I8 -> 6.108 | AD8: =K8-J8 -> 7.774 | AE8: =L8-K8 -> 6.807 | AF8: =N8-M8 -> 5.953 | AG8: =O8-N8 -> 6.145 | AH8: =R8-Q8 -> 4.657
B9: kalorimetr č. SN 34672802 | C9: 50.313 | D9: 56.107 | E9: 60.783 | F9: 64.885 | G9: 67.768 | H9: 70.123 | I9: 70.38 | J9: 70.558 | K9: 70.789 | L9: 71.678 | N9: 73.772 | O9: 77.453 | R9: 83.194 | T9: =R9-C9 -> 32.881
A10: 4 | B10: vodoměr č. 190906987 | C10: 214.857 | D10: 220.083 | E10: 224.596 | F10: 228.69 | G10: 233.716 | H10: 238.217 | I10: 241.996 | J10: 247.323 | K10: 251.005 | L10: 255.83 | M10: 0.01 | N10: 4.191 | O10: 8.355 | P10: 9.396 | Q10: 9.396 | R10: 14.048 | S10: =R10-M10+L10-C10 -> 55.011 | V10: 4 | W10: =D10-C10 -> 5.226 | X10: =E10-D10 -> 4.513 | Y10: =F10-E10 -> 4.094 | Z10: =G10-F10 -> 5.026 | AA10: =H10-G10 -> 4.501 | AB10: =I10-H10 -> 3.779 | AC10: =J10-I10 -> 5.327 | AD10: =K10-J10 -> 3.682 | AE10: =L10-K10 -> 4.825 | AF10: =N10-M10 -> 4.181 | AG10: =O10-N10 -> 4.164 | AH10: =R10-Q10 -> 4.652
B11: kalorimetr č. SN 69067316 | C11: 15.817 | D11: 20.15 | E11: 23.696 | F11: 26.217 | G11: 27.913 | H11: 29.106 | I11: 29.452 | J11: 29.833 | K11: 30.125 | L11: 30.797 | N11: 31.751 | O11: 33.379 | R11: 35.905 | T11: =R11-C11 -> 20.088
A12: 5 | B12: vodoměr č. 190907002 | C12: 3.306 | D12: 3.332 | E12: 3.335 | F12: 3.335 | G12: 3.335 | H12: 3.335 | I12: 3.335 | J12: 3.335 | K12: 3.335 | L12: 3.335 | M12: 0.01 | N12: 0.071 | O12: 0.091 | P12: 0.091 | Q12: 0.091 | R12: 0.116 | S12: =R12-M12+L12-C12 -> 0.135 | V12: 5 | W12: =D12-C12 -> 0.026 | X12: =E12-D12 -> 0.003 | Y12: =F12-E12 -> 0 | Z12: =G12-F12 -> 0 | AA12: =H12-G12 -> 0 | AB12: =I12-H12 -> 0 | AC12: =J12-I12 -> 0 | AD12: =K12-J12 -> 0 | AE12: =L12-K12 -> 0 | AF12: =N12-M12 -> 0.061 | AG12: =O12-N12 -> 0.02 | AH12: =R12-Q12 -> 0.025
B13: kalorimetr č. SN 34672814 | C13: 6.899 | D13: 8.571 | E13: 9.161 | F13: 9.937 | G13: 10.093 | H13: 10.825 | I13: 10.957 | J13: 11.089 | K13: 11.223 | L13: 11.353 | N13: 11.661 | O13: 11.787 | R13: 11.969 | T13: =R13-C13 -> 5.07
A14: 6 | B14: vodoměr č. 190906994 | C14: 332.309 | D14: 340.852 | E14: 350.129 | F14: 359.191 | G14: 369.095 | H14: 380 | I14: 388.595 | J14: 395.392 | K14: 404.039 | L14: 412.15 | M14: 0.01 | N14: 7.142 | O14: 14.146 | P14: 16.214 | Q14: 16.214 | R14: 24.468 | S14: =R14-M14+L14-C14 -> 104.299 | V14: 6 | W14: =D14-C14 -> 8.543 | X14: =E14-D14 -> 9.277 | Y14: =F14-E14 -> 9.062 | Z14: =G14-F14 -> 9.904 | AA14: =H14-G14 -> 10.905 | AB14: =I14-H14 -> 8.595 | AC14: =J14-I14 -> 6.797 | AD14: =K14-J14 -> 8.647 | AE14: =L14-K14 -> 8.111 | AF14: =N14-M14 -> 7.132 | AG14: =O14-N14 -> 7.004 | AH14: =R14-Q14 -> 8.254
B15: kalorimetr č. SN 34672815 | C15: 44.447 | D15: 49.274 | E15: 51.79 | F15: 53.374 | G15: 54.542 | H15: 55.856 | I15: 56.307 | J15: 56.684 | K15: 57.114 | L15: 57.802 | N15: 58.812 | O15: 60.942 | R15: 63.795 | T15: =R15-C15 -> 19.348
A16: 7 | B16: vodoměr č. 190906986 | C16: 80.791 | D16: 82.363 | E16: 84.154 | F16: 86.37 | G16: 89.326 | H16: 91.446 | I16: 93.96 | J16: 97.419 | K16: 100.678 | L16: 104.21 | M16: 0.02 | N16: 3.43 | O16: 6.275 | P16: 7.098 | Q16: 7.098 | R16: 9.679 | S16: =R16-M16+L16-C16 -> 33.078 | V16: 7 | W16: =D16-C16 -> 1.572 | X16: =E16-D16 -> 1.791 | Y16: =F16-E16 -> 2.216 | Z16: =G16-F16 -> 2.956 | AA16: =H16-G16 -> 2.12 | AB16: =I16-H16 -> 2.514 | AC16: =J16-I16 -> 3.459 | AD16: =K16-J16 -> 3.259 | AE16: =L16-K16 -> 3.532 | AF16: =N16-M16 -> 3.41 | AG16: =O16-N16 -> 2.845 | AH16: =R16-Q16 -> 2.581
B17: kalorimetr č. SN 34672806 | C17: 8.655 | D17: 9.397 | E17: 9.836 | F17: 10.164 | G17: 10.591 | H17: 10.903 | I17: 11.165 | J17: 11.439 | K17: 11.694 | L17: 12.013 | N17: 12.445 | O17: 12.952 | R17: 13.728 | T17: =R17-C17 -> 5.073
A18: 8 | B18: vodoměr č. 191519281 | C18: 167 | D18: 172.665 | E18: 178.201 | F18: 184.605 | G18: 190.851 | H18: 197.39 | I18: 203.256 | J18: 210.107 | K18: 217.397 | L18: 225.27 | M18: 0.01 | N18: 0.568 | O18: 0.622 | P18: 0.63 | Q18: 0.085 | R18: 5.763 | S18: =R18-Q18+P18-M18+L18-C18 -> 64.568 | V18: 8 | W18: =D18-C18 -> 5.665 | X18: =E18-D18 -> 5.536 | Y18: =F18-E18 -> 6.404 | Z18: =G18-F18 -> 6.246 | AA18: =H18-G18 -> 6.539 | AB18: =I18-H18 -> 5.866 | AC18: =J18-I18 -> 6.851 | AD18: =K18-J18 -> 7.29 | AE18: =L18-K18 -> 7.873 | AF18: =N18-M18 -> 0.558 | AG18: =O18-N18 -> 0.054 | AH18: =R18-Q18 -> 5.678
B19: kalorimetr č. SN 34672809 | C19: 41.639 | D19: 47.233 | E19: 51.353 | F19: 53.822 | G19: 55.037 | H19: 55.944 | I19: 56.315 | J19: 56.748 | K19: 57.214 | L19: 57.686 | N19: 59.225 | O19: 63.059 | R19: 68.834 | T19: =R19-C19 -> 27.195
A20: 9 | B20: vodoměr č. 190906990 | C20: 625.147 | D20: 635.562 | E20: 647.02 | F20: 657.54 | G20: 671.301 | H20: 682.728 | I20: 694.865 | J20: 706.618 | K20: 718.636 | L20: 731.5 | M20: 0.01 | N20: 9.936 | O20: 20.51 | P20: 21.341 | Q20: 21.341 | R20: 30.728 | S20: =R20-M20+L20-C20 -> 137.071 | V20: 9 | W20: =D20-C20 -> 10.415 | X20: =E20-D20 -> 11.458 | Y20: =F20-E20 -> 10.52 | Z20: =G20-F20 -> 13.761 | AA20: =H20-G20 -> 11.427 | AB20: =I20-H20 -> 12.137 | AC20: =J20-I20 -> 11.753 | AD20: =K20-J20 -> 12.018 | AE20: =L20-K20 -> 12.864 | AF20: =N20-M20 -> 9.926 | AG20: =O20-N20 -> 10.574 | AH20: =R20-Q20 -> 9.387
B21: kalorimetr č. SN 34672804 | C21: 48.294 | D21: 55.206 | E21: 60.2 | F21: 64.386 | G21: 66.753 | H21: 68.391 | I21: 69.044 | J21: 69.739 | K21: 70.501 | L21: 71.205 | N21: 72.774 | O21: 76.818 | R21: 82.401 | T21: =R21-C21 -> 34.107
A22: 10 | B22: vodoměr č. 190906995 | C22: 4.122 | D22: 4.26 | E22: 4.4 | F22: 4.522 | G22: 4.663 | H22: 4.824 | I22: 4.839 | J22: 4.855 | K22: 4.87 | L22: 4.92 | M22: 0.01 | N22: 0.024 | O22: 0.038 | P22: 0.04 | Q22: 0.04 | R22: 0.048 | S22: =R22-M22+L22-C22 -> 0.836 | V22: 10 | W22: =D22-C22 -> 0.138 | X22: =E22-D22 -> 0.14 | Y22: =F22-E22 -> 0.122 | Z22: =G22-F22 -> 0.141 | AA22: =H22-G22 -> 0.161 | AB22: =I22-H22 -> 0.015 | AC22: =J22-I22 -> 0.016 | AD22: =K22-J22 -> 0.015 | AE22: =L22-K22 -> 0.05 | AF22: =N22-M22 -> 0.014 | AG22: =O22-N22 -> 0.014 | AH22: =R22-Q22 -> 0.008
B23: kalorimetr č. SN 34672829 | C23: 0.441 | D23: 0.52 | E23: 0.568 | F23: 0.614 | G23: 0.672 | H23: 0.729 | I23: 0.746 | J23: 0.749 | K23: 0.754 | L23: 0.792 | N23: 0.866 | O23: 0.909 | R23: 0.96 | T23: =R23-C23 -> 0.519
S24: =SUM(S4:S23) -> 606.394 | T24: =SUM(T4:T23) -> 200.58
A25: spol.spotř. | B25: elektroměr č. 72370871 | C25: 44119 | D25: 44428 | E25: 44828 | F25: 45102 | G25: 45403 | H25: 45694 | I25: 45951 | J25: 46226 | K25: 46546 | L25: 46809 | N25: 47075 | O25: 47303 | R25: 47567 | U25: =R25-C25 -> 3448
B26: patní vodoměr č. 190976793 | C26: 2122.8 | D26: 2174.3 | E26: 2228.8 | F26: 2283.7 | G26: 2342.7 | H26: 2402.8 | I26: 2455.1 | J26: 2509.2 | K26: 2564 | L26: 2624.1 | M26: 0 | N26: 54 | O26: 106.4 | P26: 117.2 | Q26: 117.2 | R26: 163.9 | S26: =R26-M26+L26-C26 -> 665.2
B27: patní kalorimetr č. / MWh | C27: 152.54 | D27: 165.19 | E27: 174.31 | F27: 181.43 | G27: 186.18 | H27: 190.22 | I27: 191.44 | J27: 192.81 | K27: 194.22 | L27: 195.98 | N27: 199.56 | O27: 206.42 | R27: 216.31 | T27: =(R27-C27)*3.6 -> 229.572
B28: patní kalorimetr č. / kub.m | C28: 6779 | D28: 7316 | E28: 7645 | F28: 7882 | G28: 8072 | H28: 8249 | I28: 8324 | J28: 8407 | K28: 8492 | L28: 8584 | N28: 8727 | O28: 8942 | R28: 9249
