Workbook

Sheet 1850
A2: 1850 | C2: 45658 | D2: 45688 | E2: 45716 | F2: 45748 | G2: 45779 | H2: 45810 | I2: 45839 | J2: 45870 | K2: 45901 | L2: 45931 | M2: 45961 | N2: 45992 | O2: 46022 | P2: voda | Q2: teplo | R2: Elektr | Y2: spotřeby po měsících
A3: byt č. | C3: prosinec | D3: leden | E3: únor | F3: březen | G3: duben | H3: květen | I3: červen | J3: červenec | K3: srpen | L3: září | M3: říjen | N3: listopad | O3: prosinec | P3: m3 | Q3: GJ | R3: KWh | T3: byt | U3: leden | V3: únor | W3: březen | X3: duben | Y3: květen | Z3: červen | AA3: červenec | AB3: srpen | AC3: září | AD3: říjen | AE3: listopad | AF3: prosinec
A4: 1 | B4: vodoměr č. 241345698 | C4: 3.829 | D4: 13.067 | E4: 21.617 | F4: 30.906 | G4: 46.883 | H4: 55.949 | I4: 63.595 | J4: 71.439 | K4: 84.327 | L4: 96.543 | M4: 107.006 | N4: 118.761 | O4: 131.765 | P4: =O4-C4 -> 127.936 | T4: 1 | U4: =D4-C4 -> 9.238 | V4: =E4-D4 -> 8.55 | W4: =F4-E4 -> 9.289 | X4: =G4-F4 -> 15.977 | Y4: =H4-G4 -> 9.066 | Z4: =I4-H4 -> 7.646 | AA4: =J4-I4 -> 7.844 | AB4: =K4-J4 -> 12.888 | ... AF4: =O4-N4 -> 13.004
B5: kalorimetr č. 71182278 | C5: 67.779 | D5: 71.836 | E5: 75.085 | F5: 77.27 | G5: 78.283 | H5: 78.93 | I5: 79.435 | J5: 79.948 | K5: 80.759 | L5: 81.492 | M5: 82.21 | N5: 84.678 | O5: 88.237 | Q5: =O5-C5 -> 20.458 | Z5: =I5-H5 -> 0.505 | AA5: =J5-I5 -> 0.513 | AB5: =K5-J5 -> 0.811 | AC5: =L5-K5 -> 0.733 | AD5: =M5-L5 -> 0.718 | AE5: =N5-M5 -> 2.468 | AF5: =O5-N5 -> 3.559
A6: 2 | B6: vodoměr č. 241345701 | C6: 19.095 | D6: 34.634 | E6: 49.155 | F6: 65.991 | G6: 85.821 | H6: 104.238 | I6: 119.742 | J6: 131.547 | K6: 147.885 | L6: 159.79 | M6: 175.486 | N6: 192.984 | O6: 209.272 | P6: =O6-C6 -> 190.177 | T6: 2 | U6: =D6-C6 -> 15.539 | V6: =E6-D6 -> 14.521 | W6: =F6-E6 -> 16.836 | X6: =G6-F6 -> 19.83 | Y6: =H6-G6 -> 18.417 | Z6: =I6-H6 -> 15.504 | AA6: =J6-I6 -> 11.805 | AB6: =K6-J6 -> 16.338 | ... AF6: =O6-N6 -> 16.288
B7: kalorimetr č. 71182225 | C7: 83.238 | D7: 89.067 | E7: 94.211 | F7: 98.132 | G7: 100.154 | H7: 101.433 | I7: 102.307 | J7: 102.816 | K7: 103.576 | L7: 104.461 | M7: 106.776 | N7: 111.421 | O7: 116.53 | Q7: =O7-C7 -> 33.292 | Z7: =I7-H7 -> 0.874 | AA7: =J7-I7 -> 0.509 | AB7: =K7-J7 -> 0.76 | AC7: =L7-K7 -> 0.885 | AD7: =M7-L7 -> 2.315 | AE7: =N7-M7 -> 4.645 | AF7: =O7-N7 -> 5.109
A8: 3 | B8: vodoměr č. 241345691 | C8: 6.06 | D8: 10.586 | E8: 15.712 | F8: 22.185 | G8: 28.001 | H8: 34.163 | I8: 39.272 | J8: 44.503 | K8: 50.636 | L8: 54.84 | M8: 59.946 | N8: 65.403 | O8: 70.033 | P8: =O8-C8 -> 63.973 | T8: 3 | U8: =D8-C8 -> 4.526 | V8: =E8-D8 -> 5.126 | W8: =F8-E8 -> 6.473 | X8: =G8-F8 -> 5.816 | Y8: =H8-G8 -> 6.162 | Z8: =I8-H8 -> 5.109 | AA8: =J8-I8 -> 5.231 | AB8: =K8-J8 -> 6.133 | ... AF8: =O8-N8 -> 4.63
B9: kalorimetr č. 71182284 | C9: 60.193 | D9: 64.04 | E9: 66.994 | F9: 68.858 | G9: 69.675 | H9: 70.158 | I9: 70.547 | J9: 70.918 | K9: 71.333 | L9: 71.704 | M9: 73.561 | N9: 77.239 | O9: 79.838 | Q9: =O9-C9 -> 19.645 | Z9: =I9-H9 -> 0.389 | AA9: =J9-I9 -> 0.371 | AB9: =K9-J9 -> 0.415 | AC9: =L9-K9 -> 0.371 | AD9: =M9-L9 -> 1.857 | AE9: =N9-M9 -> 3.678 | AF9: =O9-N9 -> 2.599
A10: 4 | B10: vodoměr č. 241345696 | C10: 12.77 | D10: 23.715 | E10: 33.722 | F10: 45.952 | G10: 56.661 | H10: 68.487 | I10: 78.897 | J10: 89.086 | K10: 96.756 | L10: 104.896 | M10: 105.56 | N10: 116.667 | O10: 125.385 | P10: =O10-C10 -> 112.615 | T10: 4 | U10: =D10-C10 -> 10.945 | V10: =E10-D10 -> 10.007 | W10: =F10-E10 -> 12.23 | X10: =G10-F10 -> 10.709 | Y10: =H10-G10 -> 11.826 | Z10: =I10-H10 -> 10.41 | AA10: =J10-I10 -> 10.189 | AB10: =K10-J10 -> 7.67 | ... AF10: =O10-N10 -> 8.718
B11: kalorimetr č. 71182235 | C11: 40.877 | D11: 42.716 | E11: 44.31 | F11: 45.574 | G11: 46.514 | H11: 47.442 | I11: 48.155 | J11: 48.764 | K11: 49.302 | L11: 49.901 | M11: 50.063 | N11: 51.918 | O11: 54.863 | Q11: =O11-C11 -> 13.986 | Z11: =I11-H11 -> 0.713 | AA11: =J11-I11 -> 0.609 | AB11: =K11-J11 -> 0.538 | AC11: =L11-K11 -> 0.599 | AD11: =M11-L11 -> 0.162 | AE11: =N11-M11 -> 1.855 | AF11: =O11-N11 -> 2.945
A12: 5 | B12: vodoměr č. 241345690 | C12: 9.296 | D12: 18.066 | E12: 27.681 | F12: 37.874 | G12: 48.914 | H12: 58.539 | I12: 68.217 | J12: 76.309 | K12: 85.602 | L12: 93.595 | M12: 101.752 | N12: 110.222 | O12: 118.4 | P12: =O12-C12 -> 109.104 | T12: 5 | U12: =D12-C12 -> 8.77 | V12: =E12-D12 -> 9.615 | W12: =F12-E12 -> 10.193 | X12: =G12-F12 -> 11.04 | Y12: =H12-G12 -> 9.625 | Z12: =I12-H12 -> 9.678 | AA12: =J12-I12 -> 8.092 | AB12: =K12-J12 -> 9.293 | ... AF12: =O12-N12 -> 8.178
B13: kalorimetr č. 71182238 | C13: 57.859 | D13: 61.682 | E13: 65.146 | F13: 67.502 | G13: 68.697 | H13: 69.392 | I13: 70.049 | J13: 70.58 | K13: 71.118 | L13: 71.618 | M13: 72.757 | N13: 75.358 | O13: 78.234 | Q13: =O13-C13 -> 20.375 | Z13: =I13-H13 -> 0.657 | AA13: =J13-I13 -> 0.531 | AB13: =K13-J13 -> 0.538 | AC13: =L13-K13 -> 0.5 | AD13: =M13-L13 -> 1.139 | AE13: =N13-M13 -> 2.601 | AF13: =O13-N13 -> 2.876
A14: 6 | B14: vodoměr č. 241345700 | C14: 7.545 | D14: 12.112 | E14: 16.18 | F14: 21.108 | G14: 26.199 | H14: 31.703 | I14: 39.531 | J14: 45.604 | K14: 50.014 | L14: 55.236 | M14: 59.401 | N14: 64.139 | O14: 70.558 | P14: =O14-C14 -> 63.013 | T14: 6 | U14: =D14-C14 -> 4.567 | V14: =E14-D14 -> 4.068 | W14: =F14-E14 -> 4.928 | X14: =G14-F14 -> 5.091 | Y14: =H14-G14 -> 5.504 | Z14: =I14-H14 -> 7.828 | AA14: =J14-I14 -> 6.073 | AB14: =K14-J14 -> 4.41 | ... AF14: =O14-N14 -> 6.419
B15: kalorimetr č. 71182269 | C15: 91.113 | D15: 97.679 | E15: 102.992 | F15: 106.63 | G15: 107.786 | H15: 108.588 | I15: 109.166 | J15: 109.651 | K15: 110.013 | L15: 110.453 | M15: 110.988 | N15: 112.747 | O15: 116.546 | Q15: =O15-C15 -> 25.433 | Z15: =I15-H15 -> 0.578 | AA15: =J15-I15 -> 0.485 | AB15: =K15-J15 -> 0.362 | AC15: =L15-K15 -> 0.44 | AD15: =M15-L15 -> 0.535 | AE15: =N15-M15 -> 1.759 | AF15: =O15-N15 -> 3.799
A16: 7 | B16: vodoměr č. 241345702 | C16: 4.463 | D16: 7.81 | E16: 11.208 | F16: 14.709 | G16: 18.341 | H16: 21.451 | I16: 25.129 | J16: 28.95 | K16: 31.632 | L16: 35.336 | M16: 39.078 | N16: 43.9 | O16: 47.513 | P16: =O16-C16 -> 43.05 | T16: 7 | U16: =D16-C16 -> 3.347 | V16: =E16-D16 -> 3.398 | W16: =F16-E16 -> 3.501 | X16: =G16-F16 -> 3.632 | Y16: =H16-G16 -> 3.11 | Z16: =I16-H16 -> 3.678 | AA16: =J16-I16 -> 3.821 | AB16: =K16-J16 -> 2.682 | ... AF16: =O16-N16 -> 3.613
B17: kalorimetr č. 71182265 | C17: 21.004 | D17: 22.427 | E17: 23.199 | F17: 23.475 | G17: 23.626 | H17: 23.732 | I17: 23.85 | J17: 23.96 | K17: 24.032 | L17: 24.123 | M17: 24.316 | N17: 25.303 | O17: 26.122 | Q17: =O17-C17 -> 5.118 | Z17: =I17-H17 -> 0.118 | AA17: =J17-I17 -> 0.11 | AB17: =K17-J17 -> 0.072 | AC17: =L17-K17 -> 0.091 | AD17: =M17-L17 -> 0.193 | AE17: =N17-M17 -> 0.987 | AF17: =O17-N17 -> 0.819
A18: 8 | B18: vodoměr č. 241345699 | C18: 0.446 | D18: 1.927 | E18: 2.259 | F18: 3.094 | G18: 3.166 | H18: 3.457 | I18: 4.09 | J18: 4.579 | K18: 4.798 | L18: 6.387 | M18: 8.469 | N18: 9.218 | O18: 9.297 | P18: =O18-C18 -> 8.851 | T18: 8 | U18: =D18-C18 -> 1.481 | V18: =E18-D18 -> 0.332 | W18: =F18-E18 -> 0.835 | X18: =G18-F18 -> 0.072 | Y18: =H18-G18 -> 0.291 | Z18: =I18-H18 -> 0.633 | AA18: =J18-I18 -> 0.489 | AB18: =K18-J18 -> 0.219 | ... AF18: =O18-N18 -> 0.079
B19: kalorimetr č. 71182245 | C19: 62.224 | D19: 65.897 | E19: 68.595 | F19: 70.176 | G19: 70.29 | H19: 70.445 | I19: 70.591 | J19: 70.728 | K19: 70.857 | L19: 71.059 | M19: 72.09 | N19: 74.581 | O19: 77.412 | Q19: =O19-C19 -> 15.188 | Z19: =I19-H19 -> 0.146 | AA19: =J19-I19 -> 0.137 | AB19: =K19-J19 -> 0.129 | AC19: =L19-K19 -> 0.202 | AD19: =M19-L19 -> 1.031 | AE19: =N19-M19 -> 2.491 | AF19: =O19-N19 -> 2.831
A20: 9 | B20: vodoměr č. 241345692 | C20: 0.073 | D20: 0.098 | E20: 0.115 | F20: 0.141 | G20: 0.16 | H20: 0.182 | I20: 0.206 | J20: 0.225 | K20: 0.25 | L20: 0.279 | M20: 0.286 | N20: 6.015 | O20: 15.707 | P20: =O20-C20 -> 15.634 | T20: 9 | U20: =D20-C20 -> 0.025 | V20: =E20-D20 -> 0.017 | W20: =F20-E20 -> 0.026 | X20: =G20-F20 -> 0.019 | Y20: =H20-G20 -> 0.022 | Z20: =I20-H20 -> 0.024 | AA20: =J20-I20 -> 0.019 | AB20: =K20-J20 -> 0.025 | ... AF20: =O20-N20 -> 9.692
B21: kalorimetr č. 71182280 | C21: 12.012 | D21: 12.139 | E21: 12.27 | F21: 12.44 | G21: 12.613 | H21: 12.783 | I21: 12.927 | J21: 13.072 | K21: 13.222 | L21: 13.375 | M21: 13.54 | N21: 15.759 | O21: 18.462 | Q21: =O21-C21 -> 6.45 | Z21: =I21-H21 -> 0.144 | AA21: =J21-I21 -> 0.145 | AB21: =K21-J21 -> 0.15 | AC21: =L21-K21 -> 0.153 | AD21: =M21-L21 -> 0.165 | AE21: =N21-M21 -> 2.219 | AF21: =O21-N21 -> 2.703
A22: 10 | B22: vodoměr č. 241345695 | C22: 8.359 | D22: 17.322 | E22: 23.559 | F22: 34.052 | G22: 43.289 | H22: 51.926 | I22: 61.184 | J22: 68.196 | K22: 77.196 | L22: 86.021 | M22: 95.876 | N22: 106.827 | O22: 114.433 | P22: =O22-C22 -> 106.074 | T22: 10 | U22: =D22-C22 -> 8.963 | V22: =E22-D22 -> 6.237 | W22: =F22-E22 -> 10.493 | X22: =G22-F22 -> 9.237 | Y22: =H22-G22 -> 8.637 | Z22: =I22-H22 -> 9.258 | AA22: =J22-I22 -> 7.012 | AB22: =K22-J22 -> 9 | ... AF22: =O22-N22 -> 7.606
B23: kalorimetr č. 71182243 | C23: 68.947 | D23: 73.782 | E23: 77.406 | F23: 80.095 | G23: 81.133 | H23: 81.636 | I23: 82.077 | J23: 82.403 | K23: 82.816 | L23: 83.263 | M23: 85.486 | N23: 90.434 | O23: 95.253 | Q23: =O23-C23 -> 26.306 | Z23: =I23-H23 -> 0.441 | AA23: =J23-I23 -> 0.326 | AB23: =K23-J23 -> 0.413 | AC23: =L23-K23 -> 0.447 | AD23: =M23-L23 -> 2.223 | AE23: =N23-M23 -> 4.948 | AF23: =O23-N23 -> 4.819
P24: =SUM(P4:P23) -> 840.427 | Q24: =SUM(Q4:Q23) -> 186.251
A25: spol.spotř. | B25: elektroměr č. 1025291034 | C25: 7220 | D25: 7401 | E25: 7599 | F25: 7791 | G25: 7978 | H25: 8198 | I25: 8392 | J25: 8563 | K25: 8742 | L25: 8925 | M25: 9097 | N25: 9283 | O25: 9472 | R25: =O25-C25 -> 2252
B26: patní vodoměr č. 241175202 | C26: 79.1 | D26: 152.6 | E26: 220.9 | F26: 302.5 | G26: 390.4 | H26: 469.6 | I26: 545.6 | J26: 611.9 | K26: 687.6 | L26: 757.4 | M26: 823.2 | N26: 911.2 | O26: 996.6 | P26: =O26-C26 -> 917.5
B27: patní kalorimetr č./ GJ | C27: 227.97 | D27: 264.11 | E27: 293.69 | F27: 311.71 | G27: 317.94 | H27: 321.29 | I27: 324.04 | J27: 326.14 | K27: 328.2 | L27: 330.86 | M27: 339.44 | N27: 367.16 | O27: 399.83 | Q27: =(O27-C27) -> 171.86 | R27: GJ
B28: patní kalorimetr č./kub.m | C28: 1970 | D28: 2274 | E28: 2509 | F28: 2650 | G28: 2700 | H28: 2729 | I28: 2754 | J28: 2778 | K28: 2798 | L28: 2823 | M28: 2905 | N28: 3111 | O28: 3333 | Q28: =O28-C28 -> 1363 | R28: m3
A29: fakturační vodoměr č. 63796 | C29: 28101 | D29: 28433.6 | E29: 28750.9 | F29: 29123.3 | G29: 29498.8 | H29: 29863 | I29: 30199 | J29: 30525.8 | K29: 30885.6 | L29: 31236.6 | M29: 31568.3 | N29: 31933 | O29: 65454 | P29: =O29-E33+E32-C29 -> 4178
C31: číslo | E31: stav
B32: Výměna fakturač. vodoměru | C32: 63796 | D32: starý | E32: 31933 | H32: Dne 31.7.2023 odpojen kalor. (cejchování), | L32: stav: | M32: 210.8 | N32: MWh
B33: dne 1.12.2025 | C33: 203623 | D33: nový | E33: 65108 | H33: Dne 3.8.2023 zapojen znovuzapojení, | L33: stav: | M33: 0 | N33: GJ
B34: Výměna elekroměru | C34: 18972503 | D34: starý
B35: dne 13.2.2022 | C35: 1025291034 | D35: nový
N37: Odečet vodárny 31.12.2024 | O37: =C29 -> 28101
N39: Odečet vodárny 31.12.2025 | O39: =O29 -> 65454
N41: spotřeba | O41: =O39-O37-O38 -> 37353

Sheet 1851
AE1: Vytipování vadných vodoměrů
A2: Nové | B2: 1851 | D2: ='1850'!C2 -> 45658 | E2: ='1850'!D2 -> 45688 | F2: ='1850'!E2 -> 45716 | G2: ='1850'!F2 -> 45748 | H2: ='1850'!G2 -> 45779 | I2: ='1850'!H2 -> 45810 | J2: ='1850'!I2 -> 45839 | K2: ='1850'!J2 -> 45870 | ... P2: ='1850'!O2 -> 46022 | Q2: voda | R2: teplo | S2: Elektr | Z2: spotřeby po měsících | AK2: Podíl teplé vody na celkové spotřebě vody u dělených bytů (%) | AV2: CELKOVÝ | AW2: =(AW6+AW12+AW14+AW18+AW54+AW56+AW58+AW60+AW62)/9 -> 0.31126519
A3: číslování | B3: byt č. | D3: prosinec | E3: leden | F3: únor | G3: březen | H3: duben | I3: květen | J3: červen | K3: červenec | L3: srpen | M3: září | N3: říjen | O3: listopad | P3: prosinec | Q3: m3 | R3: GJ | S3: KWh | U3: byt | V3: leden | W3: únor | X3: březen | Y3: duben | Z3: květen | AA3: červen | AB3: červenec | AC3: srpen | AD3: září | AE3: říjen | AF3: listopad | AG3: prosinec | AK3: 1. | AL3: 2. | AM3: 3. | AN3: 4. | AO3: 5. | AP3: 6. | AQ3: 7. | AR3: 8. | AS3: 9. | AT3: 10. | AU3: 11. | AV3: 12. | AW3: Průměr
A4: 1 | B4: 1 | C4: vodoměr č. 241010644 | D4: 15.011 | E4: 28.037 | F4: 43.089 | G4: 60.307 | H4: 76.864 | I4: 92.991 | J4: 106.245 | K4: 122.097 | L4: 141.502 | M4: 159.22 | N4: 173.646 | O4: 187.745 | P4: 199.73 | Q4: =P4-D4 -> 184.719 | U4: 1 | V4: =E4-D4 -> 13.026 | W4: =F4-E4 -> 15.052 | X4: =G4-F4 -> 17.218 | Y4: =H4-G4 -> 16.557 | Z4: =I4-H4 -> 16.127 | AA4: =J4-I4 -> 13.254 | AB4: =K4-J4 -> 15.852 | AC4: =L4-K4 -> 19.405 | ... AG4: =P4-O4 -> 11.985
C5: kalorimetr č. 71182262 | D5: 91.799 | E5: 96.551 | F5: 101.424 | G5: 105.055 | H5: 107.005 | I5: 108.389 | J5: 109.244 | K5: 110.095 | L5: 111.092 | M5: 112.199 | N5: 114.626 | O5: 118.546 | P5: 122.956 | R5: =P5-D5 -> 31.157 | U5: xx
A6: 2 | B6: 2 | C6: vodoměr SV č. 241010636 | D6: 7.346 | E6: 12.976 | F6: 18.9 | G6: 25.565 | H6: 31.982 | I6: 38.645 | J6: 45.224 | K6: 51.937 | L6: 59.309 | M6: 67.745 | N6: 76.055 | O6: 82.937 | P6: 90.242 | Q6: =P6-D6 -> 82.896 | U6: 2 | V6: =E6-D6 -> 5.63 | W6: =F6-E6 -> 5.924 | X6: =G6-F6 -> 6.665 | Y6: =H6-G6 -> 6.417 | Z6: =I6-H6 -> 6.663 | AA6: =J6-I6 -> 6.579 | AB6: =K6-J6 -> 6.713 | AC6: =L6-K6 -> 7.372 | ... AG6: =P6-O6 -> 7.305 | AJ6: byt 2 | AK6: =V7/(V6+V7) -> 0.37080912 | AL6: =W7/(W6+W7) -> 0.34374654 | AM6: =X7/(X6+X7) -> 0.35479187 | AN6: =Y7/(Y6+Y7) -> 0.3387263 | AO6: =Z7/(Z6+Z7) -> 0.3392503 | AP6: =AA7/(AA6+AA7) -> 0.25953855 | AQ6: =AB7/(AB6+AB7) -> 0.245476 | AR6: =AC7/(AC6+AC7) -> 0.25648008 | ... AV6: =AG7/(AG6+AG7) -> 0.30388794 | AW6: =SUM(AK6:AV6)/12 -> 0.30475394
A7: 2 a 3 | C7: kalorimetr č. 71182271 | D7: 111.032 | E7: 117.933 | F7: 124.626 | G7: 128.932 | H7: 131.033 | I7: 132.518 | J7: 133.527 | K7: 134.453 | L7: 135.203 | M7: 136.455 | N7: 139.75 | O7: 144.249 | P7: 148.721 | R7: =P7-D7 -> 37.689 | U7: TV | V7: =V40 -> 3.318 | W7: =W40 -> 3.103 | X7: =X40 -> 3.665 | Y7: =Y40 -> 3.287 | Z7: =Z40 -> 3.421 | AA7: =AA40 -> 2.306 | AB7: =AB40 -> 2.184 | AC7: =AC40 -> 2.543 | ... AG7: =AG40 -> 3.189
A8: 5 | B8: 3 | C8: vodoměr SV č. 241010648 | D8: 1.227 | E8: 2.16 | F8: 3.144 | G8: 4.548 | H8: 5.93 | I8: 7.35 | J8: 8.626 | K8: 10.044 | L8: 11.541 | M8: 12.849 | N8: 14.083 | O8: 15.509 | P8: 17.065 | Q8: =P8-D8 -> 15.838 | U8: 5 | V8: =E8-D8 -> 0.933 | W8: =F8-E8 -> 0.984 | X8: =G8-F8 -> 1.404 | Y8: =H8-G8 -> 1.382 | Z8: =I8-H8 -> 1.42 | AA8: =J8-I8 -> 1.276 | AB8: =K8-J8 -> 1.418 | AC8: =L8-K8 -> 1.497 | ... AG8: =P8-O8 -> 1.556 | AJ8: byt 5 | AK8: =V9/(V8+V9) -> 0.26303318 | AL8: =W9/(W8+W9) -> 0.24015444 | AM8: =X9/(X8+X9) -> 0.20990433 | AN8: =Y9/(Y8+Y9) -> 0.20665901 | AO8: =Z9/(Z8+Z9) -> 0.21111111 | AP8: =AA9/(AA8+AA9) -> 0.21185917 | AQ8: =AB9/(AB8+AB9) -> 0.20247469 | AR8: =AC9/(AC8+AC9) -> 0.18641304 | ... AV8: =AG9/(AG8+AG9) -> 0.22587065 | AW8: =SUM(AK8:AV8)/12 -> 0.22334596
A9: 5 a 6 | C9: kalorimetr č. 71182241 | D9: 124.131 | E9: 129.177 | F9: 133.02 | G9: 135.046 | H9: 135.803 | I9: 136.056 | J9: 136.251 | K9: 136.419 | L9: 136.595 | M9: 136.885 | N9: 137.734 | O9: 140.62 | P9: 144.359 | R9: =P9-D9 -> 20.228 | U9: TV | V9: =V42 -> 0.333 | W9: =W42 -> 0.311 | X9: =X42 -> 0.373 | Y9: =Y42 -> 0.36 | Z9: =Z42 -> 0.38 | AA9: =AA42 -> 0.343 | AB9: =AB42 -> 0.36 | AC9: =AC42 -> 0.343 | ... AG9: =AG42 -> 0.454
A10: 4 | B10: 4 | C10: vodoměr č. 241010642 | D10: 9.465 | E10: 18.038 | F10: 24.604 | G10: 33.764 | H10: 41.563 | I10: 49.768 | J10: 56.173 | K10: 62.815 | L10: 71.301 | M10: 79.546 | N10: 87.438 | O10: 96.62 | P10: 104.28 | Q10: =P10-D10 -> 94.815 | U10: 4 | V10: =E10-D10 -> 8.573 | W10: =F10-E10 -> 6.566 | X10: =G10-F10 -> 9.16 | Y10: =H10-G10 -> 7.799 | Z10: =I10-H10 -> 8.205 | AA10: =J10-I10 -> 6.405 | AB10: =K10-J10 -> 6.642 | AC10: =L10-K10 -> 8.486 | ... AG10: =P10-O10 -> 7.66
C11: kalorimetr č. 71182237 | D11: 19.687 | E11: 21.612 | F11: 22.952 | G11: 23.701 | H11: 24.396 | I11: 24.913 | J11: 25.242 | K11: 25.512 | L11: 25.89 | M11: 26.31 | N11: 26.848 | O11: 28.629 | P11: 30.653 | R11: =P11-D11 -> 10.966 | U11: xx | AZ11: originál
A12: 9 | B12: 5 | C12: vodoměr SV č. 241010637 | D12: 1.517 | E12: 1.517 | F12: 1.568 | G12: 1.568 | H12: 1.575 | I12: 1.575 | J12: 1.575 | K12: 1.575 | L12: 1.575 | M12: 1.575 | N12: 1.576 | O12: 1.576 | P12: 1.588 | Q12: =P12-D12 -> 0.071 | U12: 9 | V12: =E12-D12 -> 0 | W12: =F12-E12 -> 0.051 | X12: =G12-F12 -> 0 | Y12: =H12-G12 -> 0.007 | Z12: =I12-H12 -> 0 | AA12: =J12-I12 -> 0 | AB12: =K12-J12 -> 0 | AC12: =L12-K12 -> 0 | ... AG12: =P12-O12 -> 0.012 | AJ12: byt 9 | AW12: =SUM(AK12:AV12)/12 -> 0 | AZ12: byt 9 | BA12: =AL13/(AL12+AL13) -> #DIV/0! | BB12: =AM13/(AM12+AM13) -> #DIV/0! | BC12: =AN13/(AN12+AN13) -> #DIV/0! | BD12: =AO13/(AO12+AO13) -> #DIV/0! | BE12: =AP13/(AP12+AP13) -> #DIV/0! | BF12: =AQ13/(AQ12+AQ13) -> #DIV/0! | BG12: =AR13/(AR12+AR13) -> #DIV/0! | BH12: =AS13/(AS12+AS13) -> #DIV/0! | ... BL12: =AW13/(AW12+AW13) -> #DIV/0! | BM12: =SUM(BA12:BL12)/12 -> #DIV/0!
A13: 8 a 9 | C13: kalorimetr č. 71182221 | D13: 95.26 | E13: 98.466 | F13: 101.186 | G13: 103.647 | H13: 105.168 | I13: 106.343 | J13: 106.945 | K13: 107.401 | L13: 107.815 | M13: 108.426 | N13: 110.417 | O13: 114.26 | P13: 118.131 | R13: =P13-D13 -> 22.871 | U13: TV | V13: =V44 -> 0 | W13: =W44 -> 0.001 | X13: =X44 -> 0 | Y13: =Y44 -> 0 | Z13: =Z44 -> 0 | AA13: =AA44 -> 0 | AB13: =AB44 -> 0 | AC13: =AC44 -> 0 | ... AG13: =AG44 -> 0.002
A14: 15 | B14: 6 | C14: vodoměr SV č. 241010633 | D14: 2.171 | E14: 3.81 | F14: 5.682 | G14: 7.377 | H14: 9 | I14: 10.841 | J14: 12.976 | K14: 15.117 | L14: 17.395 | M14: 19.172 | N14: 21.023 | O14: 23.529 | P14: 25.973 | Q14: =P14-D14 -> 23.802 | U14: 15 | V14: =E14-D14 -> 1.639 | W14: =F14-E14 -> 1.872 | X14: =G14-F14 -> 1.695 | Y14: =H14-G14 -> 1.623 | Z14: =I14-H14 -> 1.841 | AA14: =J14-I14 -> 2.135 | AB14: =K14-J14 -> 2.141 | AC14: =L14-K14 -> 2.278 | ... AG14: =P14-O14 -> 2.444 | AJ14: byt 15 | AK14: =V15/(V14+V15) -> 0.42652204 | AL14: =W15/(W14+W15) -> 0.38843515 | AM14: =X15/(X14+X15) -> 0.37706725 | AN14: =Y15/(Y14+Y15) -> 0.40440367 | AO14: =Z15/(Z14+Z15) -> 0.3176427 | AP14: =AA15/(AA14+AA15) -> 0.29163902 | AQ14: =AB15/(AB14+AB15) -> 0.35628382 | AR14: =AC15/(AC14+AC15) -> 0.38878455 | ... AV14: =AG15/(AG14+AG15) -> 0.39891786 | AW14: =SUM(AK14:AV14)/12 -> 0.38294388
A15: 11 a 15 | C15: kalorimetr č. 71182276 | D15: 52.481 | E15: 54.425 | F15: 57.467 | G15: 58.745 | H15: 59.288 | I15: 59.615 | J15: 60.027 | K15: 60.446 | L15: 61.035 | M15: 61.516 | N15: 62.9 | O15: 65.748 | P15: 69.055 | R15: =P15-D15 -> 16.574 | U15: TV | V15: =V46 -> 1.219 | W15: =W46 -> 1.189 | X15: =X46 -> 1.026 | Y15: =Y46 -> 1.102 | Z15: =Z46 -> 0.857 | AA15: =AA46 -> 0.879 | AB15: =AB46 -> 1.185 | AC15: =AC46 -> 1.449 | ... AG15: =AG46 -> 1.622
A16: 7 | B16: 7 | C16: vodoměr č. 241010643 | D16: 6.863 | E16: 12.859 | F16: 18.007 | G16: 24.676 | H16: 35.707 | I16: 45.17 | J16: 54.014 | K16: 62.629 | L16: 70.667 | M16: 78.902 | N16: 88.11 | O16: 100.046 | P16: 108.226 | Q16: =P16-D16 -> 101.363 | U16: 7 | V16: =E16-D16 -> 5.996 | W16: =F16-E16 -> 5.148 | X16: =G16-F16 -> 6.669 | Y16: =H16-G16 -> 11.031 | Z16: =I16-H16 -> 9.463 | AA16: =J16-I16 -> 8.844 | AB16: =K16-J16 -> 8.615 | AC16: =L16-K16 -> 8.038 | ... AG16: =P16-O16 -> 8.18
C17: kalorimetr č. 71182256 | D17: 13.934 | E17: 15.131 | F17: 15.96 | G17: 16.645 | H17: 17.408 | I17: 17.97 | J17: 18.421 | K17: 18.784 | L17: 19.113 | M17: 19.475 | N17: 19.937 | O17: 20.635 | P17: 21.263 | R17: =P17-D17 -> 7.329 | U17: xx
A18: 13 | B18: 8 | C18: vodoměr SV č. 241010631 | D18: 2.59 | E18: 4.997 | F18: 6.688 | G18: 8.99 | H18: 10.914 | I18: 13.047 | J18: 15.05 | K18: 18.114 | L18: 21.404 | M18: 23.306 | N18: 25.665 | O18: 27.685 | P18: 29.93 | Q18: =P18-D18 -> 27.34 | U18: 13 | V18: =E18-D18 -> 2.407 | W18: =F18-E18 -> 1.691 | X18: =G18-F18 -> 2.302 | Y18: =H18-G18 -> 1.924 | Z18: =I18-H18 -> 2.133 | AA18: =J18-I18 -> 2.003 | AB18: =K18-J18 -> 3.064 | AC18: =L18-K18 -> 3.29 | ... AG18: =P18-O18 -> 2.245 | AJ18: byt 13 | AK18: =V19/(V18+V19) -> 0.44321073 | AL18: =W19/(W18+W19) -> 0.48819613 | AM18: =X19/(X18+X19) -> 0.43244576 | AN18: =Y19/(Y18+Y19) -> 0.4431259 | AO18: =Z19/(Z18+Z19) -> 0.40979524 | AP18: =AA19/(AA18+AA19) -> 0.37929966 | AQ18: =AB19/(AB18+AB19) -> 0.36352306 | AR18: =AC19/(AC18+AC19) -> 0.38389513 | ... AV18: =AG19/(AG18+AG19) -> 0.39373481 | AW18: =SUM(AK18:AV18)/12 -> 0.41451599
A19: 12 a 13 | C19: kalorimetr č. 71182279 | D19: 83.883 | E19: 89.259 | F19: 94.22 | G19: 96.699 | H19: 98.319 | I19: 98.832 | J19: 99.065 | K19: 99.316 | L19: 99.626 | M19: 99.802 | N19: 101.151 | O19: 103.914 | P19: 107.747 | R19: =P19-D19 -> 23.864 | U19: TV | V19: =V48 -> 1.916 | W19: =W48 -> 1.613 | X19: =X48 -> 1.754 | Y19: =Y48 -> 1.531 | Z19: =Z48 -> 1.481 | AA19: =AA48 -> 1.224 | AB19: =AB48 -> 1.75 | AC19: =AC48 -> 2.05 | ... AG19: =AG48 -> 1.458
A20: 14 | B20: 9 | C20: vodoměr č. 241010632 | D20: 9.871 | E20: 17.148 | F20: 26.287 | G20: 36.47 | H20: 46.895 | I20: 55.571 | J20: 65.248 | K20: 74.057 | L20: 83.226 | M20: 92.23 | N20: 100.75 | O20: 111.195 | P20: 120.691 | Q20: =P20-D20 -> 110.82 | U20: 14 | V20: =E20-D20 -> 7.277 | W20: =F20-E20 -> 9.139 | X20: =G20-F20 -> 10.183 | Y20: =H20-G20 -> 10.425 | Z20: =I20-H20 -> 8.676 | AA20: =J20-I20 -> 9.677 | AB20: =K20-J20 -> 8.809 | AC20: =L20-K20 -> 9.169 | ... AG20: =P20-O20 -> 9.496
C21: kalorimetr č. 71182252 | D21: 87.236 | E21: 92.407 | F21: 96.954 | G21: 99.864 | H21: 101.028 | I21: 101.631 | J21: 102.1 | K21: 102.541 | L21: 102.982 | M21: 103.419 | N21: 105.233 | O21: 109.349 | P21: 113.934 | R21: =P21-D21 -> 26.698 | U21: xx
A22: 10 | B22: 10 | C22: vodoměr č. 241010635 | D22: 2.516 | E22: 4.717 | F22: 7.148 | G22: 9.529 | H22: 12.145 | I22: 14.709 | J22: 17.004 | K22: 19.752 | L22: 21.96 | M22: 24.92 | N22: 27.163 | O22: 29.568 | P22: 32.06 | Q22: =P22-D22 -> 29.544 | U22: 10 | V22: =E22-D22 -> 2.201 | W22: =F22-E22 -> 2.431 | X22: =G22-F22 -> 2.381 | Y22: =H22-G22 -> 2.616 | Z22: =I22-H22 -> 2.564 | AA22: =J22-I22 -> 2.295 | AB22: =K22-J22 -> 2.748 | AC22: =L22-K22 -> 2.208 | ... AG22: =P22-O22 -> 2.492
C23: kalorimetr č. 71182234 | D23: 51.809 | E23: 55.686 | F23: 59.048 | G23: 60.841 | H23: 61.502 | I23: 61.763 | J23: 61.992 | K23: 62.197 | L23: 62.411 | M23: 62.849 | N23: 64.257 | O23: 67.492 | P23: 71.66 | R23: =P23-D23 -> 19.851 | U23: xx
B24: spol.spotř. | C24: elektroměr č. 2080200096 | D24: 14724 | E24: 14906 | F24: 15089 | G24: 15287 | H24: 15489 | I24: 15678 | J24: 15859 | K24: 16035 | L24: 16225 | M24: 16417 | N24: 16618 | O24: 16806 | P24: 16972 | Q24: =SUM(Q4:Q23)+SUM(Q33:Q49) -> 952.79 | R24: =SUM(R4:R23) -> 217.227 | S24: =P24-D24 -> 2248 | U24: kWh | AK24: Podíl teplé vody na celkové spotřebě vody u dělených bytů po měsících (%)
AJ25: CELKEM | AK25: 1. | AL25: 2. | AM25: 3. | AN25: 4. | AO25: 5. | AP25: 6. | AQ25: 7. | AR25: 8. | AS25: 9. | AT25: 10. | AU25: 11. | AV25: 12. | AW25: Průměr | BF25: originál | BG25: 1. | BH25: 2. | BI25: 3. | BJ25: 4. | BK25: 5. | BL25: 6. | BM25: 7. | BN25: 8. | BO25: 9. | BP25: 10. | BQ25: 11. | BR25: 12. | BS25: Průměr
C26: patní vodoměr č. 241175208 | D26: 101.3 | E26: 181.8 | F26: 263.3 | G26: 357.9 | H26: 449.7 | I26: 538.4 | J26: 618.8 | K26: 705 | L26: 795.4 | M26: 880.8 | N26: 964.4 | O26: 1056.4 | P26: 1140.1 | Q26: =P26-D26 -> 1038.8 | AJ26: Průměr po měsících | AK26: =(AK6+AK8+AK12+AK14+AK18+AK54+AK56+AK58+AK60+AK62)/9 -> 0.39174175 | AL26: =(AL6+AL8+AL12+AL14+AL18+AL54+AL56+AL58+AL60+AL62)/9 -> 0.38795801 | AM26: =(AM6+AM8+AM12+AM14+AM18+AM54+AM56+AM58+AM60+AM62)/9 -> 0.36120606 | AN26: =(AN6+AN8+AN12+AN14+AN18+AN54+AN56+AN58+AN60+AN62)/9 -> 0.3629718 | AO26: =(AO6+AO8+AO12+AO14+AO18+AO54+AO56+AO58+AO60+AO62)/9 -> 0.34750286 | AP26: =(AP6+AP8+AP12+AP14+AP18+AP54+AP56+AP58+AP60+AP62)/9 -> 0.30662998 | AQ26: =(AQ6+AQ8+AQ12+AQ14+AQ18+AQ54+AQ56+AQ58+AQ60+AQ62)/9 -> 0.28853529 | AR26: =(AR6+AR8+AR12+AR14+AR18+AR54+AR56+AR58+AR60+AR62)/9 -> 0.28646744 | AS26: =(AS6+AS8+AS12+AS14+AS18+AS56+AS58+AS60+AS62)/8 -> 0.29011946 | AT26: =(AT6+AT8+AT12+AT14+AT18+AT56+AT58+AT60+AT62)/8 -> 0.33387956 | AU26: =(AU6+AU8+AU12+AU14+AU18+AU56+AU58+AU60+AU62)/8 -> 0.34397001 | AV26: =(AV6+AV8+AV12+AV14+AV18+AV56+AV58+AV60+AV62)/8 -> 0.3199757 | AW26: =(AW6+AW8+AW12+AW14+AW18+AW54+AW56+AW58+AW60+AW62)/9 -> 0.33608141 | AZ26: Podíl TV po bytech | BF26: Průměr po měsících | BG26: =(BG6+BG8+BG12+BG14+BG18+BG54+BG56+BG58+BG60+BG62)/10 -> #DIV/0! | BH26: =(BH6+BH8+BH12+BH14+BH18+BH54+BH56+BH58+BH60+BH62)/10 -> #DIV/0! | BI26: =(BI6+BI8+BI12+BI14+BI18+BI54+BI56+BI58+BI60+BI62)/10 -> #DIV/0! | BJ26: =(BJ6+BJ8+BJ12+BJ14+BJ18+BJ54+BJ56+BJ58+BJ60+BJ62)/10 -> #DIV/0! | BK26: =(BK6+BK8+BK12+BK14+BK18+BK54+BK56+BK58+BK60+BK62)/10 -> #DIV/0! | BL26: =(BL6+BL8+BL12+BL14+BL18+BL54+BL56+BL58+BL60+BL62)/10 -> #DIV/0! | BM26: =(BM6+BM8+BM12+BM14+BM18+BM54+BM56+BM58+BM60+BM62)/10 -> #DIV/0! | BN26: =(BN6+BN8+BN12+BN14+BN18+BN54+BN56+BN58+BN60+BN62)/10 -> #DIV/0! | ... BS26: =(BS6+BS8+BS12+BS14+BS18+BS54+BS56+BS58+BS60+BS62)/10 -> 0
C27: patní kalorimetr č. / GJ | D27: 337.39 | E27: 380 | F27: 419.54 | G27: 442.64 | H27: 455.22 | I27: 463.64 | J27: 469.9 | K27: 475.28 | L27: 479.59 | M27: 486.89 | N27: 502.48 | O27: 533.44 | P27: 570.14 | R27: =(P27-D27) -> 232.75 | S27: GJ
C28: patní kalorimetr č./kub.m | D28: 5081 | E28: 5505 | F28: 5903 | G28: 6107 | H28: 6264 | I28: 6402 | J28: 6516.1 | K28: 6611 | L28: 6680 | M28: 6848 | N28: 7032 | O28: 7307 | P28: 7626 | R28: =P28-D28 -> 2545 | S28: m3
B29: ='1850'!A29 -> fakturační vodoměr č. 63796 | D29: ='1850'!C29 -> 28101 | E29: ='1850'!D29 -> 28433.6 | F29: ='1850'!E29 -> 28750.9 | G29: ='1850'!F29 -> 29123.3 | H29: ='1850'!G29 -> 29498.8 | I29: ='1850'!H29 -> 29863 | J29: ='1850'!I29 -> 30199 | K29: ='1850'!J29 -> 30525.8 | ... P29: ='1850'!O29 -> 65454 | Q29: =P29-D29 -> 37353 | V29: studená voda
U31: byt | V31: leden | W31: únor | X31: březen | Y31: duben | Z31: květen | AA31: červen | AB31: červenec | AC31: srpen | AD31: září | AE31: říjen | AF31: listopad | AG31: prosinec
A33: 3 | B33: 2B | C33: vodoměr SV č. 241010630 | D33: 2.112 | E33: 4.421 | F33: 7.006 | G33: 10.571 | H33: 12.961 | I33: 15.374 | J33: 17.775 | K33: 21.299 | L33: 21.353 | M33: 21.353 | N33: 21.354 | O33: 21.354 | P33: 21.355 | Q33: =P33-D33 -> 19.243 | U33: 3 | V33: =E33-D33 -> 2.309 | W33: =F33-E33 -> 2.585 | X33: =G33-F33 -> 3.565 | Y33: =H33-G33 -> 2.39 | Z33: =I33-H33 -> 2.413 | AA33: =J33-I33 -> 2.401 | AB33: =K33-J33 -> 3.524 | AC33: =L33-K33 -> 0.054 | ... AG33: =P33-O33 -> 0.001
A34: 6 | B34: 3B | C34: vodoměr SV č. 241010640 | D34: 1.782 | E34: 3.45 | F34: 4.422 | G34: 5.874 | H34: 7.072 | I34: 8.337 | J34: 9.782 | K34: 10.83 | L34: 12.143 | M34: 14.112 | N34: 16.189 | O34: 18.636 | P34: 20.181 | Q34: =P34-D34 -> 18.399 | U34: 6 | V34: =E34-D34 -> 1.668 | W34: =F34-E34 -> 0.972 | X34: =G34-F34 -> 1.452 | Y34: =H34-G34 -> 1.198 | Z34: =I34-H34 -> 1.265 | AA34: =J34-I34 -> 1.445 | AB34: =K34-J34 -> 1.048 | AC34: =L34-K34 -> 1.313 | ... AG34: =P34-O34 -> 1.545
A35: 8 | B35: 5B | C35: vodoměr SV č. 241010650 | D35: 5.744 | E35: 9.533 | F35: 13.824 | G35: 19.306 | H35: 24.44 | I35: 28.965 | J35: 33.823 | K35: 38.849 | L35: 42.615 | M35: 46.82 | N35: 51.666 | O35: 56.637 | P35: 61.995 | Q35: =P35-D35 -> 56.251 | U35: 8 | V35: =E35-D35 -> 3.789 | W35: =F35-E35 -> 4.291 | X35: =G35-F35 -> 5.482 | Y35: =H35-G35 -> 5.134 | Z35: =I35-H35 -> 4.525 | AA35: =J35-I35 -> 4.858 | AB35: =K35-J35 -> 5.026 | AC35: =L35-K35 -> 3.766 | ... AG35: =P35-O35 -> 5.358
A36: 11 | B36: 6B | C36: vodoměr SV č. 241010639 | D36: 1.937 | E36: 2.294 | F36: 3.175 | G36: 3.692 | H36: 3.907 | I36: 4.3921 | J36: 6.455 | K36: 9.212 | L36: 13.856 | M36: 16.751 | N36: 18.558 | O36: 20.778 | P36: 24.088 | Q36: =P36-D36 -> 22.151 | U36: 11 | V36: =E36-D36 -> 0.357 | W36: =F36-E36 -> 0.881 | X36: =G36-F36 -> 0.517 | Y36: =H36-G36 -> 0.215 | Z36: =I36-H36 -> 0.4851 | AA36: =J36-I36 -> 2.0629 | AB36: =K36-J36 -> 2.757 | AC36: =L36-K36 -> 4.644 | ... AG36: =P36-O36 -> 3.31
A37: 12 | B37: 8B | C37: vodoměr SV č. 241010641 | D37: 4.145 | E37: 7.898 | F37: 11.03 | G37: 14.167 | H37: 17.408 | I37: 20.026 | J37: 20.703 | K37: 21.058 | L37: 21.665 | M37: 21.859 | N37: 22.345 | O37: 22.557 | P37: 22.68 | Q37: =P37-D37 -> 18.535 | U37: 12 | V37: =E37-D37 -> 3.753 | W37: =F37-E37 -> 3.132 | X37: =G37-F37 -> 3.137 | Y37: =H37-G37 -> 3.241 | Z37: =I37-H37 -> 2.618 | AA37: =J37-I37 -> 0.677 | AB37: =K37-J37 -> 0.355 | AC37: =L37-K37 -> 0.607 | ... AG37: =P37-O37 -> 0.123
C39: VODOMĚRY TEPLÁ VODA | V39: teplá voda
A40: 2 | B40: 2 | C40: vodoměr TUV č. 240093441 | D40: 3.844 | E40: 7.162 | F40: 10.265 | G40: 13.93 | H40: 17.217 | I40: 20.638 | J40: 22.944 | K40: 25.128 | L40: 27.671 | M40: 30.551 | N40: 33.668 | O40: 36.863 | P40: 40.052 | Q40: =P40-D40 -> 36.208 | U40: 2 | V40: =E40-D40 -> 3.318 | W40: =F40-E40 -> 3.103 | X40: =G40-F40 -> 3.665 | Y40: =H40-G40 -> 3.287 | Z40: =I40-H40 -> 3.421 | AA40: =J40-I40 -> 2.306 | AB40: =K40-J40 -> 2.184 | AC40: =L40-K40 -> 2.543 | ... AG40: =P40-O40 -> 3.189
A41: 3 | B41: 2B | C41: vodoměr TUV č. 240093452 | D41: 1.277 | E41: 3.112 | F41: 4.874 | G41: 6.749 | H41: 8.091 | I41: 9.488 | J41: 10.749 | K41: 12.184 | L41: 12.201 | M41: 12.202 | N41: 12.202 | O41: 12.202 | P41: 12.203 | Q41: =P41-D41 -> 10.926 | U41: 3 | V41: =E41-D41 -> 1.835 | W41: =F41-E41 -> 1.762 | X41: =G41-F41 -> 1.875 | Y41: =H41-G41 -> 1.342 | Z41: =I41-H41 -> 1.397 | AA41: =J41-I41 -> 1.261 | AB41: =K41-J41 -> 1.435 | AC41: =L41-K41 -> 0.017 | ... AG41: =P41-O41 -> 0.001
A42: 5 | B42: 3 | C42: vodoměr TUV č. 240093448 | D42: 0.411 | E42: 0.744 | F42: 1.055 | G42: 1.428 | H42: 1.788 | I42: 2.168 | J42: 2.511 | K42: 2.871 | L42: 3.214 | M42: 3.563 | N42: 3.968 | O42: 4.482 | P42: 4.936 | Q42: =P42-D42 -> 4.525 | U42: 5 | V42: =E42-D42 -> 0.333 | W42: =F42-E42 -> 0.311 | X42: =G42-F42 -> 0.373 | Y42: =H42-G42 -> 0.36 | Z42: =I42-H42 -> 0.38 | AA42: =J42-I42 -> 0.343 | AB42: =K42-J42 -> 0.36 | AC42: =L42-K42 -> 0.343 | ... AG42: =P42-O42 -> 0.454
A43: 6 | B43: 3B | C43: vodoměr TUV č. 240093431 | D43: 1.286 | E43: 2.655 | F43: 3.567 | G43: 4.705 | H43: 5.464 | I43: 6.394 | J43: 7.08 | K43: 7.713 | L43: 8.391 | M43: 9.545 | N43: 10.91 | O43: 12.79 | P43: 14.064 | Q43: =P43-D43 -> 12.778 | U43: 6 | V43: =E43-D43 -> 1.369 | W43: =F43-E43 -> 0.912 | X43: =G43-F43 -> 1.138 | Y43: =H43-G43 -> 0.759 | Z43: =I43-H43 -> 0.93 | AA43: =J43-I43 -> 0.686 | AB43: =K43-J43 -> 0.633 | AC43: =L43-K43 -> 0.678 | ... AG43: =P43-O43 -> 1.274
...

Sheet 1852
A2: 1852 | C2: ='1850'!C2 -> 45658 | D2: ='1850'!D2 -> 45688 | E2: ='1850'!E2 -> 45716 | F2: ='1850'!F2 -> 45748 | G2: ='1850'!G2 -> 45779 | H2: ='1850'!H2 -> 45810 | I2: ='1850'!I2 -> 45839 | J2: ='1850'!J2 -> 45870 | ... O2: ='1850'!O2 -> 46022 | P2: voda | Q2: teplo | R2: Elektr | Y2: spotřeby po měsících
A3: byt č. | C3: prosinec | D3: leden | E3: únor | F3: březen | G3: duben | H3: květen | I3: červen | J3: červenec | K3: srpen | L3: září | M3: říjen | N3: listopad | O3: prosinec | P3: m3 | Q3: GJ | R3: KWh | T3: byt | U3: leden | V3: únor | W3: březen | X3: duben | Y3: květen | Z3: červen | AA3: červenec | AB3: srpen | AC3: září | AD3: říjen | AE3: listopad | AF3: prosinec
A4: 1 | B4: vodoměr č. 241345697 | C4: 12.545 | D4: 22.7 | E4: 33.384 | F4: 45.361 | G4: 56.855 | H4: 66.478 | I4: 75.42 | J4: 84.431 | K4: 95.788 | L4: 106.596 | M4: 114.091 | N4: 122.075 | O4: 132.855 | P4: =O4-C4 -> 120.31 | T4: 1 | U4: =D4-C4 -> 10.155 | V4: =E4-D4 -> 10.684 | W4: =F4-E4 -> 11.977 | X4: =G4-F4 -> 11.494 | Y4: =H4-G4 -> 9.623 | Z4: =I4-H4 -> 8.942 | AA4: =J4-I4 -> 9.011 | AB4: =K4-J4 -> 11.357 | ... AF4: =O4-N4 -> 10.78
B5: kalorimetr č. 71182233 | C5: 76.346 | D5: 80.653 | E5: 84.683 | F5: 87.673 | G5: 89.168 | H5: 89.873 | I5: 90.432 | J5: 90.942 | K5: 91.554 | L5: 92.241 | M5: 94.08 | N5: 97.757 | O5: 101.954 | Q5: =O5-C5 -> 25.608
A6: 2 | B6: vodoměr č. 241345687 | C6: 5.285 | D6: 11.658 | E6: 17.63 | F6: 23.555 | G6: 29.837 | H6: 35.683 | I6: 40.609 | J6: 45.702 | K6: 49.01 | L6: 55.906 | M6: 62.781 | N6: 69.21 | O6: 70.296 | P6: =O6-C6 -> 65.011 | T6: 2 | U6: =D6-C6 -> 6.373 | V6: =E6-D6 -> 5.972 | W6: =F6-E6 -> 5.925 | X6: =G6-F6 -> 6.282 | Y6: =H6-G6 -> 5.846 | Z6: =I6-H6 -> 4.926 | AA6: =J6-I6 -> 5.093 | AB6: =K6-J6 -> 3.308 | ... AF6: =O6-N6 -> 1.086
B7: kalorimetr č. 71182270 | C7: 35.462 | D7: 37.934 | E7: 40.466 | F7: 41.454 | G7: 42.072 | H7: 42.617 | I7: 42.933 | J7: 43.228 | K7: 43.414 | L7: 43.875 | M7: 45.145 | N7: 48.511 | O7: 53.346 | Q7: =O7-C7 -> 17.884
A8: 3 | B8: vodoměr č. 241345688 | C8: 12.117 | D8: 22.845 | E8: 33.358 | F8: 45.983 | G8: 54.61 | H8: 66.85 | I8: 73.49 | J8: 86.549 | K8: 99.606 | L8: 112.388 | M8: 125.045 | N8: 137.677 | O8: 150.035 | P8: =O8-C8 -> 137.918 | T8: 3 | U8: =D8-C8 -> 10.728 | V8: =E8-D8 -> 10.513 | W8: =F8-E8 -> 12.625 | X8: =G8-F8 -> 8.627 | Y8: =H8-G8 -> 12.24 | Z8: =I8-H8 -> 6.64 | AA8: =J8-I8 -> 13.059 | AB8: =K8-J8 -> 13.057 | ... AF8: =O8-N8 -> 12.358
B9: kalorimetr č. 71182274 | C9: 106.363 | D9: 112.752 | E9: 118.247 | F9: 123.254 | G9: 126.64 | H9: 127.367 | I9: 127.743 | J9: 128.31 | K9: 129.018 | L9: 130.116 | M9: 133.075 | N9: 137.881 | O9: 142.691 | Q9: =O9-C9 -> 36.328
A10: 4 | B10: vodoměr č. 241345693 | C10: 6.82 | D10: =9.094+6 -> 15.094 | E10: =9.199+6+7.8 -> 22.999 | F10: 1.806 | G10: 9.352 | H10: 18.145 | I10: 24.243 | J10: 29.564 | K10: 35.832 | L10: 44.261 | M10: 52.894 | N10: 62.803 | O10: 71.464 | P10: =O10-G33+G32-C10 -> 94.44 | T10: 4 | U10: =D10-C10 -> 8.274 | V10: =E10-D10 -> 7.905 | W10: =F10-G33+G32-E10 -> 8.603 | X10: =G10-F10 -> 7.546 | Y10: =H10-G10 -> 8.793 | Z10: =I10-H10 -> 6.098 | AA10: =J10-I10 -> 5.321 | AB10: =K10-J10 -> 6.268 | AC10: =L10-K10 -> 8.429 | AD10: =M10-L10 -> 8.633 | AE10: =N10-M10 -> 9.909 | AF10: =O10-N10 -> 8.661
B11: kalorimetr č. 71182244 | C11: 82.226 | D11: 86.669 | E11: 90.514 | F11: 92.471 | G11: 93.336 | H11: 94.154 | I11: 94.598 | J11: 94.955 | K11: 95.408 | L11: 96.233 | M11: 97.763 | N11: 101.702 | O11: 104.88 | Q11: =O11-C11 -> 22.654
A12: 5 | B12: vodoměr č. 241345689 | C12: 5.789 | D12: 12.765 | E12: 19.989 | F12: 26.992 | G12: 34.43 | H12: 41.265 | I12: 48.735 | J12: 54.952 | K12: 62.392 | L12: 67.757 | M12: 75.968 | N12: 83.041 | O12: 89.153 | P12: =O12-C12 -> 83.364 | T12: 5 | U12: =D12-C12 -> 6.976 | V12: =E12-D12 -> 7.224 | W12: =F12-E12 -> 7.003 | X12: =G12-F12 -> 7.438 | Y12: =H12-G12 -> 6.835 | Z12: =I12-H12 -> 7.47 | AA12: =J12-I12 -> 6.217 | AB12: =K12-J12 -> 7.44 | ... AF12: =O12-N12 -> 6.112
B13: kalorimetr č. 71182251 | C13: 42.479 | D13: 44.338 | E13: 46.103 | F13: 47.006 | G13: 47.8 | H13: 48.316 | I13: 48.82 | J13: 49.221 | K13: 49.679 | L13: 50.125 | M13: 50.881 | N13: 52.355 | O13: 54.095 | Q13: =O13-C13 -> 11.616
A14: 6 | B14: vodoměr č. 241345694 | C14: 0.043 | D14: 2.085 | E14: 8.567 | F14: 15.265 | G14: 22.844 | H14: 30.704 | I14: 37.566 | J14: 44.455 | K14: 50.587 | L14: 56.956 | M14: 61.993 | N14: 69.298 | O14: 75.263 | P14: =O14-C14 -> 75.22 | T14: 6 | U14: =D14-C14 -> 2.042 | V14: =E14-D14 -> 6.482 | W14: =F14-E14 -> 6.698 | X14: =G14-F14 -> 7.579 | Y14: =H14-G14 -> 7.86 | Z14: =I14-H14 -> 6.862 | AA14: =J14-I14 -> 6.889 | AB14: =K14-J14 -> 6.132 | ... AF14: =O14-N14 -> 5.965
B15: kalorimetr č. 71182283 | C15: 60.997 | D15: 62.882 | E15: 65.819 | F15: 67.293 | G15: 68.037 | H15: 68.742 | I15: 69.273 | J15: 69.762 | K15: 70.229 | L15: 70.69 | M15: 71.072 | N15: 73.53 | O15: 76.675 | Q15: =O15-C15 -> 15.678
A16: 7 | B16: vodoměr č. 241345686 | C16: 0.757 | D16: 1.589 | E16: 2.546 | F16: 3.165 | G16: 4.171 | H16: 4.617 | I16: 5.005 | J16: 5.978 | K16: 6.854 | L16: 8.543 | M16: 9.809 | N16: 11.684 | O16: 13.325 | P16: =O16-C16 -> 12.568 | T16: 7 | U16: =D16-C16 -> 0.832 | V16: =E16-D16 -> 0.957 | W16: =F16-E16 -> 0.619 | X16: =G16-F16 -> 1.006 | Y16: =H16-G16 -> 0.446 | Z16: =I16-H16 -> 0.388 | AA16: =J16-I16 -> 0.973 | AB16: =K16-J16 -> 0.876 | ... AF16: =O16-N16 -> 1.641
B17: kalorimetr č. 71182277 | C17: 33.49 | D17: 36.433 | E17: 38.342 | F17: 39.336 | G17: 39.472 | H17: 39.627 | I17: 39.633 | J17: 39.65 | K17: 39.674 | L17: 39.737 | M17: 40.853 | N17: 44.77 | O17: 49.633 | Q17: =O17-C17 -> 16.143
A18: 8 | B18: vodoměr č. 241345685 | C18: 13.38 | D18: 25.387 | E18: 34.833 | F18: 46.262 | G18: 59.924 | H18: 71.247 | I18: 82.285 | J18: 94.667 | K18: 103.617 | L18: 116.722 | M18: 129.46 | N18: 142.608 | O18: 154.038 | P18: =O18-C18 -> 140.658 | T18: 8 | U18: =D18-C18 -> 12.007 | V18: =E18-D18 -> 9.446 | W18: =F18-E18 -> 11.429 | X18: =G18-F18 -> 13.662 | Y18: =H18-G18 -> 11.323 | Z18: =I18-H18 -> 11.038 | AA18: =J18-I18 -> 12.382 | AB18: =K18-J18 -> 8.95 | ... AF18: =O18-N18 -> 11.43
B19: kalorimetr č. 71182246 | C19: 47.794 | D19: 51.181 | E19: 53.311 | F19: 54.412 | G19: 55.372 | H19: 56.017 | I19: 56.569 | J19: 57.122 | K19: 57.575 | L19: 58.177 | M19: 59.301 | N19: 61.91 | O19: 64.559 | Q19: =O19-C19 -> 16.765
A20: 9 | B20: vodoměr č. 241345704 | C20: 13.636 | D20: 28.695 | E20: 38.048 | F20: 47.909 | G20: 56.973 | H20: 65.777 | I20: 73.321 | J20: 76.92 | K20: 84.075 | L20: 94.195 | M20: 102.121 | N20: 108.038 | O20: 108.135 | P20: =O20-C20 -> 94.499 | T20: 9 | U20: =D20-C20 -> 15.059 | V20: =E20-D20 -> 9.353 | W20: =F20-E20 -> 9.861 | X20: =G20-F20 -> 9.064 | Y20: =H20-G20 -> 8.804 | Z20: =I20-H20 -> 7.544 | AA20: =J20-I20 -> 3.599 | AB20: =K20-J20 -> 7.155 | ... AF20: =O20-N20 -> 0.097
B21: kalorimetr č. 71182282 | C21: 118.749 | D21: 125.249 | E21: 130.642 | F21: 133.148 | G21: 134.248 | H21: 135.054 | I21: 135.703 | J21: 136.018 | K21: 136.592 | L21: 137.364 | M21: 138.589 | N21: 140.278 | O21: 140.442 | Q21: =O21-C21 -> 21.693
A22: 10 | B22: vodoměr č. 241345703 | C22: 6.461 | D22: 13.775 | E22: 18.475 | F22: 24.006 | G22: 32.446 | H22: 39.624 | I22: 46.516 | J22: 54.125 | K22: 60.885 | L22: 66 | M22: 73.307 | N22: 79.559 | O22: 87.056 | P22: =O22-C22 -> 80.595 | T22: 10 | U22: =D22-C22 -> 7.314 | V22: =E22-D22 -> 4.7 | W22: =F22-E22 -> 5.531 | X22: =G22-F22 -> 8.44 | Y22: =H22-G22 -> 7.178 | Z22: =I22-H22 -> 6.892 | AA22: =J22-I22 -> 7.609 | AB22: =K22-J22 -> 6.76 | ... AF22: =O22-N22 -> 7.497
B23: kalorimetr č. 71182240 | C23: 68.613 | D23: 73.048 | E23: 76.22 | F23: 77.643 | G23: 78.476 | H23: 79.08 | I23: 79.603 | J23: 80.12 | K23: 80.592 | L23: 81.09 | M23: 82.255 | N23: 85.397 | O23: 89.435 | Q23: =O23-C23 -> 20.822
P24: =SUM(P4:P23) -> 904.583 | Q24: =SUM(Q4:Q23) -> 205.191
A25: spol.spotř. | B25: elektroměr č. 2080200097 | C25: 12333 | D25: 12519 | E25: 12680 | F25: 12859 | G25: 13096 | H25: 13273 | I25: 13436 | J25: 13604 | K25: 13784 | L25: 13952 | M25: 14128 | N25: 14328 | O25: 14615 | R25: =O25-C25 -> 2282
B26: patní vodoměr č. 240826415 | C26: 85.5 | D26: 173.2 | E26: 253.6 | F26: 341.5 | G26: 430.4 | H26: 517.3 | I26: 590.1 | J26: 666.3 | K26: 744.9 | L26: 834 | M26: 920.2 | N26: 1007 | O26: 1079.3 | P26: =O26-C26 -> 993.8
B27: patní kalorimetr č./ GJ | C27: 258.05 | D27: 296.39 | E27: 330.32 | F27: 349.89 | G27: 358.61 | H27: 363.55 | I27: 366.88 | J27: 369.83 | K27: 373.04 | L27: 377.85 | M27: 389.69 | N27: 420.1 | O27: 453.82 | Q27: =(O27-C27) -> 195.77 | R27: GJ
B28: patní kalorimetr č./kub.m | C28: 1803 | D28: 2032 | E28: 2246 | F28: 2410 | G28: 2480 | H28: 2512 | I28: 2535 | J28: 2558 | K28: 2581 | L28: 2614 | M28: 2705 | N28: 2897 | O28: 3092 | Q28: =O28-C28 -> 1289 | R28: m3
A29: ='1850'!A29 -> fakturační vodoměr č. 63796 | C29: ='1850'!C29 -> 28101 | D29: ='1850'!D29 -> 28433.6 | E29: ='1850'!E29 -> 28750.9 | F29: ='1850'!F29 -> 29123.3 | G29: ='1850'!G29 -> 29498.8 | H29: ='1850'!H29 -> 29863 | I29: ='1850'!I29 -> 30199 | J29: ='1850'!J29 -> 30525.8 | ... O29: ='1850'!O29 -> 65454 | P29: =O29-C29 -> 37353
B31: Vodoměr | C31: byt | D31: Reklamace - výměna | F31: číslo | G31: stav | I31: Dne 31.7.2023 odpojen kalor. (cejchování), | M31: stav: | N31: 257.22 | O31: MWh
C32: 4 | D32: 45741 | E32: starý | F32: 241345693 | G32: =9.996+6+7.8+6 -> 29.796 | I32: Dne 3.8.2023 zapojen znovuzapojení, | M32: stav: | N32: 0 | O32: GJ
E33: nový | F33: 250434729 | G33: 0
D35: Výměna elektroměru
D36: 43956 | E36: starý
E37: nový

Sheet 1853
A2: 1853 | C2: ='1850'!C2 -> 45658 | D2: ='1850'!D2 -> 45688 | E2: ='1850'!E2 -> 45716 | F2: ='1850'!F2 -> 45748 | G2: ='1850'!G2 -> 45779 | H2: ='1850'!H2 -> 45810 | I2: ='1850'!I2 -> 45839 | J2: ='1850'!J2 -> 45870 | ... O2: ='1850'!O2 -> 46022 | P2: Voda | Q2: Teplo | R2: Elektr | Y2: spotřeby po měsících
A3: byt č. | C3: prosinec | D3: leden | E3: únor | F3: březen | G3: duben | H3: květen | I3: červen | J3: červenec | K3: srpen | L3: září | M3: říjen | N3: listopad | O3: prosinec | P3: m3 | Q3: GJ | R3: KWh | T3: byt | U3: leden | V3: únor | W3: březen | X3: duben | Y3: květen | Z3: červen | AA3: červenec | AB3: srpen | AC3: září | AD3: říjen | AE3: listopad | AF3: prosinec
A4: 1 | B4: vodoměr č. 241010646 | C4: 15.692 | D4: 28.592 | E4: 40.715 | F4: 53.926 | G4: 70.367 | H4: 84.931 | I4: 95.837 | J4: 107.08 | K4: 119.526 | L4: 133.414 | M4: 149.417 | N4: 162.854 | O4: 175.815 | P4: =O4-C4 -> 160.123 | T4: 1 | U4: =D4-C4 -> 12.9 | V4: =E4-D4 -> 12.123 | W4: =F4-E4 -> 13.211 | X4: =G4-F4 -> 16.441 | Y4: =H4-G4 -> 14.564 | Z4: =I4-H4 -> 10.906 | AA4: =J4-I4 -> 11.243 | AB4: =K4-J4 -> 12.446 | ... AF4: =O4-N4 -> 12.961
B5: kalorimetr č. 71182275 | C5: 95.658 | D5: 101.566 | E5: 107.813 | F5: 112.101 | G5: 114.761 | H5: 115.846 | I5: 116.52 | J5: 117.105 | K5: 117.809 | L5: 118.804 | M5: 121.177 | N5: 125.152 | O5: 129.64 | Q5: =O5-C5 -> 33.982
A6: 2 | B6: vodoměr č. 241010634 | C6: 7.571 | D6: 13.879 | E6: 19.942 | F6: 26.695 | G6: 32.243 | H6: 38.66 | I6: 45.283 | J6: 50.997 | K6: 56.147 | L6: 61.75 | M6: 67.209 | N6: 74.087 | O6: 81.341 | P6: =O6-C6 -> 73.77 | T6: 2 | U6: =D6-C6 -> 6.308 | V6: =E6-D6 -> 6.063 | W6: =F6-E6 -> 6.753 | X6: =G6-F6 -> 5.548 | Y6: =H6-G6 -> 6.417 | Z6: =I6-H6 -> 6.623 | AA6: =J6-I6 -> 5.714 | AB6: =K6-J6 -> 5.15 | ... AF6: =O6-N6 -> 7.254
B7: kalorimetr č. 71182253 | C7: 27.501 | D7: 29.628 | E7: 31.468 | F7: 32.524 | G7: 32.916 | H7: 33.279 | I7: 33.527 | J7: 33.731 | K7: 33.945 | L7: 34.178 | M7: 34.81 | N7: 36.497 | O7: 38.242 | Q7: =O7-C7 -> 10.741
A8: 3 | B8: vodoměr č. 241010645 | C8: 6.239 | D8: 12.475 | E8: 20.733 | F8: 34.419 | G8: 45.572 | H8: 51.992 | I8: 58.94 | J8: 66.359 | K8: 73.437 | L8: 79.96 | M8: 86.479 | N8: 92.418 | O8: 100.236 | P8: =O8-C8 -> 93.997 | T8: 3 | U8: =D8-C8 -> 6.236 | V8: =E8-D8 -> 8.258 | W8: =F8-E8 -> 13.686 | X8: =G8-F8 -> 11.153 | Y8: =H8-G8 -> 6.42 | Z8: =I8-H8 -> 6.948 | AA8: =J8-I8 -> 7.419 | AB8: =K8-J8 -> 7.078 | ... AF8: =O8-N8 -> 7.818
B9: kalorimetr č. 71182217 | C9: 62.257 | D9: 65.95 | E9: 69.772 | F9: 72.153 | G9: 73.425 | H9: 74.032 | I9: 74.423 | J9: 74.768 | K9: 75.138 | L9: 75.761 | M9: 77.309 | N9: 80.311 | O9: 83.978 | Q9: =O9-C9 -> 21.721
A10: 4 | B10: vodoměr č. 241010647 | C10: 3.377 | D10: 6.635 | E10: 9.071 | F10: 13.371 | G10: 17.291 | H10: 20.45 | I10: 25.362 | J10: 28.865 | K10: 34.399 | L10: 41.599 | M10: 45.731 | N10: 49.478 | O10: 54.349 | P10: =O10-C10 -> 50.972 | T10: 4 | U10: =D10-C10 -> 3.258 | V10: =E10-D10 -> 2.436 | W10: =F10-E10 -> 4.3 | X10: =G10-F10 -> 3.92 | Y10: =H10-G10 -> 3.159 | Z10: =I10-H10 -> 4.912 | AA10: =J10-I10 -> 3.503 | AB10: =K10-J10 -> 5.534 | ... AF10: =O10-N10 -> 4.871
B11: kalorimetr č. 71182254 | C11: 31.791 | D11: 34.198 | E11: 35.922 | F11: 36.831 | G11: 37.115 | H11: 37.373 | I11: 37.692 | J11: 37.902 | K11: 38.202 | L11: 38.517 | M11: 39.385 | N11: 41.72 | O11: 43.999 | Q11: =O11-C11 -> 12.208
A12: 5 | B12: vodoměr č. 241010638 | C12: 7.298 | D12: 14.1 | E12: 20.634 | F12: 28.574 | G12: 34.768 | H12: 41.01 | I12: 46.812 | J12: 53.903 | K12: 59.83 | L12: 66.958 | M12: 73.652 | N12: 80.555 | O12: 88.007 | P12: =O12-C12 -> 80.709 | T12: 5 | U12: =D12-C12 -> 6.802 | V12: =E12-D12 -> 6.534 | W12: =F12-E12 -> 7.94 | X12: =G12-F12 -> 6.194 | Y12: =H12-G12 -> 6.242 | Z12: =I12-H12 -> 5.802 | AA12: =J12-I12 -> 7.091 | AB12: =K12-J12 -> 5.927 | ... AF12: =O12-N12 -> 7.452
B13: kalorimetr č. 71182267 | C13: 28.57 | D13: 30.015 | E13: 31.264 | F13: 31.979 | G13: 32.372 | H13: 32.714 | I13: 33.023 | J13: 33.369 | K13: 33.617 | L13: 33.947 | M13: 34.411 | N13: 35.527 | O13: 36.796 | Q13: =O13-C13 -> 8.226
A14: 6 | B14: vodoměr č. 241010623 | C14: 6.274 | D14: 12.725 | E14: 19.468 | F14: 25.789 | G14: 32.378 | H14: 38.521 | I14: 43.982 | J14: 49.717 | K14: 56.352 | L14: 63.698 | M14: 70.772 | N14: 78.443 | O14: 84.296 | P14: =O14-C14 -> 78.022 | T14: 6 | U14: =D14-C14 -> 6.451 | V14: =E14-D14 -> 6.743 | W14: =F14-E14 -> 6.321 | X14: =G14-F14 -> 6.589 | Y14: =H14-G14 -> 6.143 | Z14: =I14-H14 -> 5.461 | AA14: =J14-I14 -> 5.735 | AB14: =K14-J14 -> 6.635 | ... AF14: =O14-N14 -> 5.853
B15: kalorimetr č. 71182261 | C15: 43.35 | D15: 46.914 | E15: 49.757 | F15: 51.491 | G15: 52.22 | H15: 52.519 | I15: 52.747 | J15: 52.945 | K15: 53.177 | L15: 53.462 | M15: 54.336 | N15: 57.247 | O15: 60.341 | Q15: =O15-C15 -> 16.991
A16: 7 | B16: vodoměr č. 241010627 | C16: 14.626 | D16: 26.53 | E16: 35.24 | F16: 49.208 | G16: 59.911 | H16: 73.735 | I16: 83.074 | J16: 89.216 | K16: 101.462 | L16: 112.106 | M16: 122.799 | N16: 135.931 | O16: 148.233 | P16: =O16-C16 -> 133.607 | T16: 7 | U16: =D16-C16 -> 11.904 | V16: =E16-D16 -> 8.71 | W16: =F16-E16 -> 13.968 | X16: =G16-F16 -> 10.703 | Y16: =H16-G16 -> 13.824 | Z16: =I16-H16 -> 9.339 | AA16: =J16-I16 -> 6.142 | AB16: =K16-J16 -> 12.246 | ... AF16: =O16-N16 -> 12.302
B17: kalorimetr č. 71182272 | C17: 76.723 | D17: 80.554 | E17: 83.262 | F17: 85.186 | G17: 86.333 | H17: 87.357 | I17: 87.994 | J17: 88.412 | K17: 89.156 | L17: 89.976 | M17: 91.593 | N17: 94.278 | O17: 97.447 | Q17: =O17-C17 -> 20.724
A18: 8 | B18: vodoměr č. 241010626 | C18: 11.299 | D18: 20.96 | E18: 30.66 | F18: 42.252 | G18: 52.752 | H18: 63.557 | I18: 71.867 | J18: 78.055 | K18: 88.64 | L18: 98.392 | M18: 108.646 | N18: 119.148 | O18: 129.38 | P18: =O18-C18 -> 118.081 | T18: 8 | U18: =D18-C18 -> 9.661 | V18: =E18-D18 -> 9.7 | W18: =F18-E18 -> 11.592 | X18: =G18-F18 -> 10.5 | Y18: =H18-G18 -> 10.805 | Z18: =I18-H18 -> 8.31 | AA18: =J18-I18 -> 6.188 | AB18: =K18-J18 -> 10.585 | ... AF18: =O18-N18 -> 10.232
B19: kalorimetr č. 71182249 | C19: 58.519 | D19: 62.814 | E19: 66.022 | F19: 67.282 | G19: 67.992 | H19: 68.635 | I19: 69.003 | J19: 69.258 | K19: 69.696 | L19: 70.186 | M19: 71.037 | N19: 73.753 | O19: 77.098 | Q19: =O19-C19 -> 18.579
A20: 9 | B20: vodoměr č. 241010624 | C20: 3.939 | D20: 7.425 | E20: 10.436 | F20: 14.473 | G20: 17.666 | H20: 21.307 | I20: 24.215 | J20: 27.21 | K20: 30.433 | L20: 33.722 | M20: 37.125 | N20: 40.833 | O20: 44.594 | P20: =O20-C20 -> 40.655 | T20: 9 | U20: =D20-C20 -> 3.486 | V20: =E20-D20 -> 3.011 | W20: =F20-E20 -> 4.037 | X20: =G20-F20 -> 3.193 | Y20: =H20-G20 -> 3.641 | Z20: =I20-H20 -> 2.908 | AA20: =J20-I20 -> 2.995 | AB20: =K20-J20 -> 3.223 | ... AF20: =O20-N20 -> 3.761
B21: kalorimetr č. 71182281 | C21: 68.216 | D21: 72.825 | E21: 76.572 | F21: 78.704 | G21: 79.386 | H21: 79.827 | I21: 80.144 | J21: 80.445 | K21: 80.782 | L21: 81.157 | M21: 82.656 | N21: 86.101 | O21: 89.992 | Q21: =O21-C21 -> 21.776
A22: 10 | B22: vodoměr č. 241010628 | C22: 3.745 | D22: 6.603 | E22: 9.202 | F22: 11.977 | G22: 14.4 | H22: 16.594 | I22: 18.812 | J22: 21.025 | K22: 23.492 | L22: 26.591 | M22: 29.003 | N22: 31.341 | O22: 34.131 | P22: =O22-C22 -> 30.386 | T22: 10 | U22: =D22-C22 -> 2.858 | V22: =E22-D22 -> 2.599 | W22: =F22-E22 -> 2.775 | X22: =G22-F22 -> 2.423 | Y22: =H22-G22 -> 2.194 | Z22: =I22-H22 -> 2.218 | AA22: =J22-I22 -> 2.213 | AB22: =K22-J22 -> 2.467 | ... AF22: =O22-N22 -> 2.79
B23: kalorimetr č. 71182268 | C23: 64.113 | D23: 68.001 | E23: 71.216 | F23: 73.175 | G23: 73.964 | H23: 74.07 | I23: 74.146 | J23: 74.221 | K23: 74.304 | L23: 74.503 | M23: 76.019 | N23: 78.955 | O23: 82.508 | Q23: =O23-C23 -> 18.395
B24: elektroměr č.2080200105 dům | C24: 10800 | D24: 10976 | E24: 11136 | F24: 11316 | G24: 11493 | H24: 11660 | I24: 11833 | J24: 12046 | K24: 12216 | L24: 12422 | M24: 12596 | N24: 12777 | O24: 12933 | P24: =SUM(P4:P23) -> 860.322 | Q24: =SUM(Q4:Q23) -> 183.343 | R24: =O24-C24 -> 2133
A25: spol.spotř. | B25: elektroměr č. 2080200100 VO | C25: 18016 | D25: 18390 | E25: 18698 | F25: 19014 | G25: 19279 | H25: 19507 | I25: 19705 | J25: 19931 | K25: 20184 | L25: 20472 | M25: 20801 | N25: 21180 | O25: 21566 | R25: =O25-C25 -> 3550 | T25: Zahrada | U25: =D26-C26 -> 0 | V25: =E26-D26 -> 0 | W25: =F26-E26 -> 0 | X25: =G26-F26 -> 8.566 | Y25: =H26-G26 -> 15.412 | Z25: =I26-H26 -> 24 | AA25: =J26-I26 -> 19.966 | AB25: =K26-J26 -> 23.906 | ... AF25: =O26-N26 -> 0
B26: vodoměr areál č.200076532 | C26: 640.722 | D26: 640.722 | E26: 640.722 | F26: 640.722 | G26: 649.288 | H26: 664.7 | I26: 688.7 | J26: 708.666 | K26: 732.572 | L26: 743.401 | M26: 744.598 | N26: 746.371 | O26: 746.371 | P26: =O26-C26 -> 105.649 | Q26: =ROUND(P26,0) -> 106 | R26: zahrada
B27: patní vodoměr č. 241175207 | C27: 90.7 | D27: 170.6 | E27: 246.7 | F27: 343.2 | G27: 438.2 | H27: 536 | I27: 631.4 | J27: 716.7 | K27: 820.7 | L27: 916.6 | M27: 999.8 | N27: 1086.3 | O27: 1173.1 | P27: =O27-C27 -> 1082.4 | Q27: =P27-Q26 -> 976.4 | R27: byty | U27: =(D27-C27)-(D26-C26) -> 79.9 | V27: =(E27-D27)-(E26-D26) -> 76.1 | W27: =(F27-E27)-(F26-E26) -> 96.5 | X27: =(G27-F27)-(G26-F26) -> 86.434 | Y27: =(H27-G27)-(H26-G26) -> 82.388 | Z27: =(I27-H27)-(I26-H26) -> 71.4 | AA27: =(J27-I27)-(J26-I26) -> 65.334 | AB27: =(K27-J27)-(K26-J26) -> 80.094 | ... AF27: =(O27-N27)-(O26-N26) -> 86.8
B28: patní kalorimetr č./ GJ | C28: 232.37 | D28: 269.02 | E28: 301.41 | F28: 320.06 | G28: 328.68 | H28: 333.18 | I28: 336.12 | J28: 338.48 | K28: 341.59 | L28: 345.68 | M28: 357.85 | N28: 385.18 | O28: 416.82 | Q28: =(O28-C28) -> 184.45 | R28: GJ | U28: =(D28-C28) -> 36.65 | V28: =(E28-D28) -> 32.39 | W28: =(F28-E28) -> 18.65 | X28: =(G28-F28) -> 8.62 | Y28: =(H28-G28) -> 4.5 | Z28: =(I28-H28) -> 2.94 | AA28: =(J28-I28) -> 2.36 | AB28: =(K28-J28) -> 3.11 | ... AF28: =(O28-N28) -> 31.64
B29: patní kalorimetr č. /kub.m | C29: 1649 | D29: 1880 | E29: 2097 | F29: 2233 | G29: 2297 | H29: 2330 | I29: 2352 | J29: 2374 | K29: 2397 | L29: 2429 | M29: 2530 | N29: 2702 | O29: 2894 | Q29: =O29-C29 -> 1245 | R29: m3
A30: ='1850'!A29 -> fakturační vodoměr č. 63796 | C30: ='1850'!C29 -> 28101 | D30: ='1850'!D29 -> 28433.6 | E30: ='1850'!E29 -> 28750.9 | F30: ='1850'!F29 -> 29123.3 | G30: ='1850'!G29 -> 29498.8 | H30: ='1850'!H29 -> 29863 | I30: ='1850'!I29 -> 30199 | J30: ='1850'!J29 -> 30525.8 | ... O30: ='1850'!O29 -> 65454 | P30: =O30-C30 -> 37353
A32: 11 | B32: vodoměr SV č. 11717149 | C32: 23.853 | D32: 24.085 | E32: 24.312 | F32: 24.582 | G32: 24.828 | H32: 25.099 | I32: 25.411 | J32: 25.626 | K32: 25.793 | L32: 25.993 | M32: 26.359 | N32: 26.628 | O32: 26.83 | P32: =O32-C32 -> 2.977 | S32: SV | T32: 11 | U32: =D32-C32 -> 0.232 | V32: =E32-D32 -> 0.227 | W32: =F32-E32 -> 0.27 | X32: =G32-F32 -> 0.246 | Y32: =H32-G32 -> 0.271 | Z32: =I32-H32 -> 0.312 | AA32: =J32-I32 -> 0.215 | AB32: =K32-J32 -> 0.167 | ... AF32: =O32-N32 -> 0.202
B33: vodoměr TV č. 11683196 | C33: 1.05 | D33: 1.05 | E33: 1.05 | F33: 1.05 | G33: 1.051 | H33: 1.058 | I33: 1.063 | J33: 1.064 | K33: 1.066 | L33: 1.068 | M33: 1.073 | N33: 1.074 | O33: 1.074 | P33: =O33-C33 -> 0.024 | S33: TV | U33: =D33-C33 -> 0 | V33: =E33-D33 -> 0 | W33: =F33-E33 -> 0 | X33: =G33-F33 -> 0.001 | Y33: =H33-G33 -> 0.007 | Z33: =I33-H33 -> 0.005 | AA33: =J33-I33 -> 0.001 | AB33: =K33-J33 -> 0.002 | ... AF33: =O33-N33 -> 0
D35: Výměna elektroměru DŮM
D36: 43956 | E36: starý | O36: spotřeba SV byt č.3 pro vyúčt. | P36: =P8-P32-P33 -> 90.996
E37: nový | O37: spotřeba SV sklad č.11 pro vyúčt. | P37: =P32+P33 -> 3.001
D38: Výměna elektroměru AREÁL | O38: CELKEM : | P38: =SUM(P36:P37) -> 93.997
D39: 43956 | E39: starý
E40: nový | J40: Dne 31.7.2023 odpojen kalor. (cejchování), | N40: stav: | O40: 234.86 | P40: MWh
J41: Dne 3.8.2023 zapojen znovuzapojení, | N41: stav: | O41: 0 | P41: GJ
D42: Výměna vodoměru ZAHRADA | G42: Příští výměna 2026
D43: 43874 | E43: starý | F43: 10282180 | H43: 655.348
...

Sheet 1854
A2: 1854 | C2: ='1850'!C2 -> 45658 | D2: ='1850'!D2 -> 45688 | E2: ='1850'!E2 -> 45716 | F2: ='1850'!F2 -> 45748 | G2: ='1850'!G2 -> 45779 | H2: ='1850'!H2 -> 45810 | I2: ='1850'!I2 -> 45839 | J2: ='1850'!J2 -> 45870 | ... O2: ='1850'!O2 -> 46022 | P2: voda | Q2: teplo | R2: Elektr | Y2: spotřeby po měsících
A3: byt č. | C3: prosinec | D3: leden | E3: únor | F3: březen | G3: duben | H3: květen | I3: červen | J3: červenec | K3: srpen | L3: září | M3: říjen | N3: listopad | O3: prosinec | P3: m3 | Q3: GJ | R3: KWh | T3: byt | U3: leden | V3: únor | W3: březen | X3: duben | Y3: květen | Z3: červen | AA3: červenec | AB3: srpen | AC3: září | AD3: říjen | AE3: listopad | AF3: prosinec
A4: 1 | B4: vodoměr č. 241010657 | C4: 2.875 | D4: 5.601 | E4: 8.586 | F4: 11.769 | G4: 14.679 | H4: 17.784 | I4: 20.428 | J4: 22.024 | K4: 24.696 | L4: 27.325 | M4: 30.502 | N4: 33.554 | O4: 36.432 | P4: =O4-C4 -> 33.557 | T4: 1 | U4: =D4-C4 -> 2.726 | V4: =E4-D4 -> 2.985 | W4: =F4-E4 -> 3.183 | X4: =G4-F4 -> 2.91 | Y4: =H4-G4 -> 3.105 | Z4: =I4-H4 -> 2.644 | AA4: =J4-I4 -> 1.596 | AB4: =K4-J4 -> 2.672 | ... AF4: =O4-N4 -> 2.878
B5: kalorimetr č. 71182259 | C5: 69.398 | D5: 73.494 | E5: 77.223 | F5: 78.868 | G5: 79.345 | H5: 79.567 | I5: 79.773 | J5: 79.928 | K5: 80.138 | L5: 80.421 | M5: 81.352 | N5: 83.858 | O5: 87.096 | Q5: =O5-C5 -> 17.698
A6: 2 | B6: vodoměr č. 241010655 | C6: 5.8 | D6: 9.925 | E6: 15.534 | F6: 22.284 | G6: 27.925 | H6: 33.205 | I6: 38.949 | J6: 44.914 | K6: 50.273 | L6: 56.502 | M6: 62.022 | N6: 67.975 | O6: 74.11 | P6: =O6-C6 -> 68.31 | T6: 2 | U6: =D6-C6 -> 4.125 | V6: =E6-D6 -> 5.609 | W6: =F6-E6 -> 6.75 | X6: =G6-F6 -> 5.641 | Y6: =H6-G6 -> 5.28 | Z6: =I6-H6 -> 5.744 | AA6: =J6-I6 -> 5.965 | AB6: =K6-J6 -> 5.359 | ... AF6: =O6-N6 -> 6.135
B7: kalorimetr č. 71182248 | C7: 102.543 | D7: 108.68 | E7: 115.127 | F7: 121.944 | G7: 125.286 | H7: 126.266 | I7: 126.786 | J7: 127.172 | K7: 127.601 | L7: 129.308 | M7: 133.129 | N7: 137.547 | O7: 141.336 | Q7: =O7-C7 -> 38.793
A8: 3 | B8: vodoměr č. 241345683 | C8: 5.638 | D8: 10.79 | E8: 15.473 | F8: 20.543 | G8: 26.192 | H8: 31.867 | I8: 38.029 | J8: 44.39 | K8: 51.151 | L8: 56.601 | M8: 61.034 | N8: 66.184 | O8: 71.285 | P8: =O8-C8 -> 65.647 | T8: 3 | U8: =D8-C8 -> 5.152 | V8: =E8-D8 -> 4.683 | W8: =F8-E8 -> 5.07 | X8: =G8-F8 -> 5.649 | Y8: =H8-G8 -> 5.675 | Z8: =I8-H8 -> 6.162 | AA8: =J8-I8 -> 6.361 | AB8: =K8-J8 -> 6.761 | ... AF8: =O8-N8 -> 5.101
B9: kalorimetr č. 71182258 | C9: 117.96 | D9: 125.015 | E9: 131.101 | F9: 136.25 | G9: 139.458 | H9: 142.104 | I9: 142.481 | J9: 142.778 | K9: 143.093 | L9: 143.88 | M9: 146.762 | N9: 152.102 | O9: 158.203 | Q9: =O9-C9 -> 40.243
A10: 4 | B10: vodoměr č. 241010651 | C10: 7.666 | D10: 14.605 | E10: 21.576 | F10: 27.922 | G10: 34.25 | H10: 41.101 | I10: 46.875 | J10: 53.603 | K10: 61.313 | L10: 68.396 | M10: 74.833 | N10: 81.988 | O10: 88.761 | P10: =O10-C10 -> 81.095 | T10: 4 | U10: =D10-C10 -> 6.939 | V10: =E10-D10 -> 6.971 | W10: =F10-E10 -> 6.346 | X10: =G10-F10 -> 6.328 | Y10: =H10-G10 -> 6.851 | Z10: =I10-H10 -> 5.774 | AA10: =J10-I10 -> 6.728 | AB10: =K10-J10 -> 7.71 | ... AF10: =O10-N10 -> 6.773
B11: kalorimetr č. 71182242 | C11: 31.658 | D11: 32.959 | E11: 34.07 | F11: 34.418 | G11: 34.783 | H11: 35.138 | I11: 35.492 | J11: 35.83 | K11: 36.195 | L11: 36.53 | M11: 36.887 | N11: 37.79 | O11: 38.633 | Q11: =O11-C11 -> 6.975
A12: 5 | B12: vodoměr č. 241345677 | C12: 0.057 | D12: 0.08 | E12: 0.23 | F12: 0.324 | G12: 4.216 | H12: 5.6 | I12: 5.725 | J12: 5.765 | K12: 5.823 | L12: 6.088 | M12: 11.062 | N12: 16.02 | O12: 18.231 | P12: =O12-C12 -> 18.174 | T12: 5 | U12: =D12-C12 -> 0.023 | V12: =E12-D12 -> 0.15 | W12: =F12-E12 -> 0.094 | X12: =G12-F12 -> 3.892 | Y12: =H12-G12 -> 1.384 | Z12: =I12-H12 -> 0.125 | AA12: =J12-I12 -> 0.04 | AB12: =K12-J12 -> 0.058 | ... AF12: =O12-N12 -> 2.211
B13: kalorimetr č. 71182255 | C13: 6.73 | D13: 6.73 | E13: 6.878 | F13: 6.879 | G13: 7.255 | H13: 7.323 | I13: 7.324 | J13: 7.325 | K13: 7.325 | L13: 7.41 | M13: 10.019 | N13: 15.489 | O13: 20.766 | Q13: =O13-C13 -> 14.036
A14: 6 | B14: vodoměr č. 241010629 | C14: 14.895 | D14: 27.334 | E14: 40.661 | F14: 52.141 | G14: 64.718 | H14: 72.662 | I14: 79.489 | J14: 90.609 | K14: 104.13 | L14: 116.603 | M14: 123.739 | N14: 140.637 | O14: 150.001 | P14: =O14-C14 -> 135.106 | T14: 6 | U14: =D14-C14 -> 12.439 | V14: =E14-D14 -> 13.327 | W14: =F14-E14 -> 11.48 | X14: =G14-F14 -> 12.577 | Y14: =H14-G14 -> 7.944 | Z14: =I14-H14 -> 6.827 | AA14: =J14-I14 -> 11.12 | AB14: =K14-J14 -> 13.521 | ... AF14: =O14-N14 -> 9.364
B15: kalorimetr č. 71182230 | C15: 34.229 | D15: 36.894 | E15: 38.844 | F15: 39.852 | G15: 40.936 | H15: 41.641 | I15: 42.21 | J15: 42.949 | K15: 43.892 | L15: 44.73 | M15: 45.291 | N15: 46.961 | O15: 48.317 | Q15: =O15-C15 -> 14.088
A16: 7 | B16: vodoměr č. 241010659 | C16: 4.367 | D16: 8.475 | E16: 12.25 | F16: 16.69 | G16: 21.018 | H16: 25.07 | I16: 29.011 | J16: 33.909 | K16: 38.006 | L16: 41.935 | M16: 45.884 | N16: 49.17 | O16: 52.297 | P16: =O16-C16 -> 47.93 | T16: 7 | U16: =D16-C16 -> 4.108 | V16: =E16-D16 -> 3.775 | W16: =F16-E16 -> 4.44 | X16: =G16-F16 -> 4.328 | Y16: =H16-G16 -> 4.052 | Z16: =I16-H16 -> 3.941 | AA16: =J16-I16 -> 4.898 | AB16: =K16-J16 -> 4.097 | ... AF16: =O16-N16 -> 3.127
B17: kalorimetr č. 71182247 | C17: 24.471 | D17: 26.531 | E17: 27.809 | F17: 28.492 | G17: 29.068 | H17: 29.583 | I17: 30.02 | J17: 30.497 | K17: 30.943 | L17: 31.529 | M17: 33.549 | N17: 36.123 | O17: 37.54 | Q17: =O17-C17 -> 13.069
A18: 8 | B18: vodoměr č. 241010622 | C18: 6.421 | D18: 11.555 | E18: 16.648 | F18: 22.288 | G18: 29.074 | H18: 34.468 | I18: 39.821 | J18: 47.082 | K18: 52.859 | L18: 58.744 | M18: 64.375 | N18: 69.961 | O18: 75.76 | P18: =O18-C18 -> 69.339 | T18: 8 | U18: =D18-C18 -> 5.134 | V18: =E18-D18 -> 5.093 | W18: =F18-E18 -> 5.64 | X18: =G18-F18 -> 6.786 | Y18: =H18-G18 -> 5.394 | Z18: =I18-H18 -> 5.353 | AA18: =J18-I18 -> 7.261 | AB18: =K18-J18 -> 5.777 | ... AF18: =O18-N18 -> 5.799
B19: kalorimetr č. 71182232 | C19: 82.638 | D19: 88.155 | E19: 92.797 | F19: 95.496 | G19: 96.504 | H19: 96.964 | I19: 97.172 | J19: 97.398 | K19: 97.594 | L19: 97.918 | M19: 99.237 | N19: 102.29 | O19: 105.695 | Q19: =O19-C19 -> 23.057
A20: 9 | B20: vodoměr č. 241010625 | C20: 12.707 | D20: 24.99 | E20: 36.786 | F20: 50.952 | G20: 63.642 | H20: 75.663 | I20: 85.799 | J20: 96.807 | K20: 109.19 | L20: 120.562 | M20: 131.012 | N20: 139.337 | O20: 153.01 | P20: =O20-C20 -> 140.303 | T20: 9 | U20: =D20-C20 -> 12.283 | V20: =E20-D20 -> 11.796 | W20: =F20-E20 -> 14.166 | X20: =G20-F20 -> 12.69 | Y20: =H20-G20 -> 12.021 | Z20: =I20-H20 -> 10.136 | AA20: =J20-I20 -> 11.008 | AB20: =K20-J20 -> 12.383 | ... AF20: =O20-N20 -> 13.673
B21: kalorimetr č. 71182228 | C21: 97.755 | D21: 102.802 | E21: 107.477 | F21: 110.913 | G21: 112.101 | H21: 112.723 | I21: 113.214 | J21: 113.655 | K21: 114.161 | L21: 114.647 | M21: 117.471 | N21: 122.26 | O21: 127.65 | Q21: =O21-C21 -> 29.895
A22: 10 | B22: vodoměr č. 241010621 | C22: 0.057 | D22: 0.092 | E22: 0.112 | F22: 0.131 | G22: 0.165 | H22: 0.186 | I22: 0.205 | J22: 0.228 | K22: 0.25 | L22: 0.32 | M22: 0.333 | N22: 0.345 | O22: 0.371 | P22: =O22-C22 -> 0.314 | T22: 10 | U22: =D22-C22 -> 0.035 | V22: =E22-D22 -> 0.02 | W22: =F22-E22 -> 0.019 | X22: =G22-F22 -> 0.034 | Y22: =H22-G22 -> 0.021 | Z22: =I22-H22 -> 0.019 | AA22: =J22-I22 -> 0.023 | AB22: =K22-J22 -> 0.022 | ... AF22: =O22-N22 -> 0.026
B23: kalorimetr č. 71182263 | C23: 0.15 | D23: 0.15 | E23: 0.151 | F23: 0.153 | G23: 0.153 | H23: 0.154 | I23: 0.154 | J23: 0.155 | K23: 0.155 | L23: 0.159 | M23: 0.161 | N23: 0.161 | O23: 0.161 | Q23: =O23-C23 -> 0.011
P24: =SUM(P4:P23) -> 659.775 | Q24: =SUM(Q4:Q23) -> 197.865
