Workbook

Sheet 1850
A2: 1850 | C2: 44927 | D2: 44958 | E2: 44986 | F2: 45017 | G2: 45047 | H2: 45078 | I2: 45111 | J2: 45139 | K2: 45170 | L2: 45201 | M2: 45231 | N2: 45261 | O2: 45292 | P2: voda | Q2: teplo | R2: Elektr | Y2: spotřeby po měsících
A3: byt č. | C3: prosinec | D3: leden | E3: únor | F3: březen | G3: duben | H3: květen | I3: červen | J3: červenec | K3: srpen | L3: září | M3: říjen | N3: listopad | O3: prosinec | P3: m3 | Q3: GJ | R3: KWh | T3: byt | U3: leden | V3: únor | W3: březen | X3: duben | Y3: květen | Z3: červen | AA3: červenec | AB3: srpen | AC3: září | AD3: říjen | AE3: listopad | AF3: prosinec
A4: 1 | B4: vodoměr č. 190834092 | C4: 39.227 | D4: 40.223 | E4: 40.773 | F4: 41.702 | G4: 43.002 | H4: 44.232 | I4: 45.192 | J4: 45.843 | K4: 46.564 | L4: 47.082 | M4: 48.091 | N4: 48.753 | O4: 49.332 | P4: =O4-C4 -> 10.105 | T4: 1 | U4: =D4-C4 -> 0.996 | V4: =E4-D4 -> 0.55 | W4: =F4-E4 -> 0.929 | X4: =G4-F4 -> 1.3 | Y4: =H4-G4 -> 1.23 | Z4: =I4-H4 -> 0.96 | AA4: =J4-I4 -> 0.651 | AB4: =K4-J4 -> 0.721 | ... AF4: =O4-N4 -> 0.579
B5: kalorimetr č. 71182278 | C5: 22.65 | D5: 27.016 | E5: 30.764 | F5: 33.454 | G5: 35.818 | H5: 36.098 | I5: 36.324 | J5: 36.492 | K5: 36.67 | L5: 36.876 | M5: 37.159 | N5: 40.161 | O5: 44.448 | Q5: =O5-C5 -> 21.798
A6: 2 | B6: vodoměr č. 190834090 | C6: 578.873 | D6: 592.362 | E6: 606.454 | F6: 622.004 | G6: 636.66 | H6: 648.853 | I6: 664.53 | J6: 671.838 | K6: 682.518 | L6: 694.912 | M6: 708.928 | N6: 722.705 | O6: 739.504 | P6: =O6-C6 -> 160.631 | T6: 2 | U6: =D6-C6 -> 13.489 | V6: =E6-D6 -> 14.092 | W6: =F6-E6 -> 15.55 | X6: =G6-F6 -> 14.656 | Y6: =H6-G6 -> 12.193 | Z6: =I6-H6 -> 15.677 | AA6: =J6-I6 -> 7.308 | AB6: =K6-J6 -> 10.68 | ... AF6: =O6-N6 -> 16.799
B7: kalorimetr č. 71182225 | C7: 36.202 | D7: 39.783 | E7: 43.194 | F7: 46.29 | G7: 47.866 | H7: 48.645 | I7: 49.471 | J7: 49.7 | K7: 50.03 | L7: 50.502 | M7: 51.281 | N7: 53.585 | O7: 57.354 | Q7: =O7-C7 -> 21.152
A8: 3 | B8: vodoměr č. 190834097 | C8: 228.181 | D8: 232.665 | E8: 238.142 | F8: 244.605 | G8: 250.567 | H8: 255.566 | I8: 261.191 | J8: 265.898 | K8: 271.425 | L8: 275.382 | M8: 280.638 | N8: 286.218 | O8: 291.679 | P8: =O8-C8 -> 63.498 | T8: 3 | U8: =D8-C8 -> 4.484 | V8: =E8-D8 -> 5.477 | W8: =F8-E8 -> 6.463 | X8: =G8-F8 -> 5.962 | Y8: =H8-G8 -> 4.999 | Z8: =I8-H8 -> 5.625 | AA8: =J8-I8 -> 4.707 | AB8: =K8-J8 -> 5.527 | ... AF8: =O8-N8 -> 5.461
B9: kalorimetr č. 71182284 | C9: 24.945 | D9: 28.477 | E9: 31.366 | F9: 34.132 | G9: 35.142 | H9: 35.556 | I9: 35.984 | J9: 36.285 | K9: 36.603 | L9: 36.914 | M9: 37.778 | N9: 40.102 | O9: 43.117 | Q9: =O9-C9 -> 18.172
A10: 4 | B10: vodoměr č. 190834098 | C10: 346.182 | D10: 355.512 | E10: 364.629 | F10: 373.855 | G10: 381.77 | H10: 390.246 | I10: 397.679 | J10: 401.115 | K10: 408.557 | L10: 416.041 | M10: 425.516 | N10: 434.38 | O10: 443.676 | P10: =O10-C10 -> 97.494 | T10: 4 | U10: =D10-C10 -> 9.33 | V10: =E10-D10 -> 9.117 | W10: =F10-E10 -> 9.226 | X10: =G10-F10 -> 7.915 | Y10: =H10-G10 -> 8.476 | Z10: =I10-H10 -> 7.433 | AA10: =J10-I10 -> 3.436 | AB10: =K10-J10 -> 7.442 | ... AF10: =O10-N10 -> 9.296
B11: kalorimetr č. 71182235 | C11: 18.402 | D11: 20.053 | E11: 21.769 | F11: 23.179 | G11: 24.183 | H11: 25.07 | I11: 25.605 | J11: 25.856 | K11: 26.31 | L11: 26.812 | M11: 27.585 | N11: 28.571 | O11: 29.642 | Q11: =O11-C11 -> 11.24
A12: 5 | B12: vodoměr č. 190834095 | C12: 262.861 | D12: 270.84 | E12: 278.268 | F12: 286.909 | G12: 293.502 | H12: 302.7 | I12: 312.13 | J12: 315.978 | K12: 323.69 | L12: 330.52 | M12: 339.726 | N12: 349.25 | O12: 357.076 | P12: =O12-C12 -> 94.215 | T12: 5 | U12: =D12-C12 -> 7.979 | V12: =E12-D12 -> 7.428 | W12: =F12-E12 -> 8.641 | X12: =G12-F12 -> 6.593 | Y12: =H12-G12 -> 9.198 | Z12: =I12-H12 -> 9.43 | AA12: =J12-I12 -> 3.848 | AB12: =K12-J12 -> 7.712 | ... AF12: =O12-N12 -> 7.826
B13: kalorimetr č. 71182238 | C13: 20.438 | D13: 23.405 | E13: 25.959 | F13: 28.095 | G13: 29.54 | H13: 30.187 | I13: 30.813 | J13: 31.078 | K13: 31.463 | L13: 31.921 | M13: 32.77 | N13: 34.996 | O13: 37.944 | Q13: =O13-C13 -> 17.506
A14: 6 | B14: vodoměr č. 190834099 | C14: 304.032 | D14: 311.117 | E14: 317.102 | F14: 324.063 | G14: 329.126 | H14: 334.665 | I14: 341.323 | J14: 347.259 | K14: 353.092 | L14: 359.684 | M14: 366.125 | N14: 370.643 | O14: 375.966 | P14: =O14-C14 -> 71.934 | T14: 6 | U14: =D14-C14 -> 7.085 | V14: =E14-D14 -> 5.985 | W14: =F14-E14 -> 6.961 | X14: =G14-F14 -> 5.063 | Y14: =H14-G14 -> 5.539 | Z14: =I14-H14 -> 6.658 | AA14: =J14-I14 -> 5.936 | AB14: =K14-J14 -> 5.833 | ... AF14: =O14-N14 -> 5.323
B15: kalorimetr č. 71182269 | C15: 36.339 | D15: 41.109 | E15: 45.095 | F15: 48.459 | G15: 50.694 | H15: 51.202 | I15: 51.725 | J15: 52.116 | K15: 52.46 | L15: 52.891 | M15: 53.816 | N15: 57.839 | O15: 63.645 | Q15: =O15-C15 -> 27.306
A16: 7 | B16: vodoměr č. 190834102 | C16: 52.604 | D16: 53.712 | E16: 54.892 | F16: 56.126 | G16: 57.385 | H16: 58.69 | I16: 60.203 | J16: 61.207 | K16: 62.383 | L16: 63.644 | M16: 65.174 | N16: 66.787 | O16: 68.381 | P16: =O16-C16 -> 15.777 | T16: 7 | U16: =D16-C16 -> 1.108 | V16: =E16-D16 -> 1.18 | W16: =F16-E16 -> 1.234 | X16: =G16-F16 -> 1.259 | Y16: =H16-G16 -> 1.305 | Z16: =I16-H16 -> 1.513 | AA16: =J16-I16 -> 1.004 | AB16: =K16-J16 -> 1.176 | ... AF16: =O16-N16 -> 1.594
B17: kalorimetr č. 71182265 | C17: 9.35 | D17: 10.616 | E17: 11.963 | F17: 12.631 | G17: 12.978 | H17: 13.108 | I17: 13.258 | J17: 13.348 | K17: 13.462 | L17: 13.587 | M17: 13.765 | N17: 14.541 | O17: 16.056 | Q17: =O17-C17 -> 6.706
A18: 8 | B18: vodoměr č. 200015742 | C18: 58.755 | D18: 59.55 | E18: 61.261 | F18: 62.261 | G18: 63.497 | H18: 66.01 | I18: 67.54 | J18: 68.719 | K18: 70.304 | L18: 72.519 | M18: 73.094 | N18: 74.368 | O18: 74.952 | P18: =O18-C18 -> 16.197 | T18: 8 | U18: =D18-C18 -> 0.795 | V18: =E18-D18 -> 1.711 | W18: =F18-E18 -> 1 | X18: =G18-F18 -> 1.236 | Y18: =H18-G18 -> 2.513 | Z18: =I18-H18 -> 1.53 | AA18: =J18-I18 -> 1.179 | AB18: =K18-J18 -> 1.585 | ... AF18: =O18-N18 -> 0.584
B19: kalorimetr č. 71182245 | C19: 29.061 | D19: 32.272 | E19: 35.642 | F19: 38.008 | G19: 39.575 | H19: 40.214 | I19: 40.414 | J19: 40.548 | K19: 40.709 | L19: 40.92 | M19: 41.572 | N19: 44.03 | O19: 47.294 | Q19: =O19-C19 -> 18.233
A20: 9 | B20: vodoměr č. 190834109 | C20: 2.493 | D20: 2.507 | E20: 2.517 | F20: 2.532 | G20: 2.545 | H20: 2.569 | I20: 2.593 | J20: 2.614 | K20: 2.638 | L20: 2.656 | M20: 2.676 | N20: 2.69 | O20: 2.702 | P20: =O20-C20 -> 0.209 | T20: 9 | U20: =D20-C20 -> 0.014 | V20: =E20-D20 -> 0.01 | W20: =F20-E20 -> 0.015 | X20: =G20-F20 -> 0.013 | Y20: =H20-G20 -> 0.024 | Z20: =I20-H20 -> 0.024 | AA20: =J20-I20 -> 0.021 | AB20: =K20-J20 -> 0.024 | ... AF20: =O20-N20 -> 0.012
B21: kalorimetr č. 71182280 | C21: 2.389 | D21: 2.548 | E21: 2.692 | F21: 2.859 | G21: 3.024 | H21: 3.188 | I21: 3.352 | J21: 3.476 | K21: 3.598 | L21: 3.743 | M21: 3.911 | N21: 4.073 | O21: 4.222 | Q21: =O21-C21 -> 1.833
A22: 10 | B22: vodoměr č. 191519263 | C22: 268.31 | D22: 275.789 | E22: 282.352 | F22: 290.317 | G22: 297.533 | H22: 303.561 | I22: 311.521 | J22: 319.58 | K22: 330.192 | L22: 337.991 | M22: 344.998 | N22: 351.368 | O22: 357.404 | P22: =O22-C22 -> 89.094 | T22: 10 | U22: =D22-C22 -> 7.479 | V22: =E22-D22 -> 6.563 | W22: =F22-E22 -> 7.965 | X22: =G22-F22 -> 7.216 | Y22: =H22-G22 -> 6.028 | Z22: =I22-H22 -> 7.96 | AA22: =J22-I22 -> 8.059 | AB22: =K22-J22 -> 10.612 | ... AF22: =O22-N22 -> 6.036
B23: kalorimetr č. 71182243 | C23: 26.403 | D23: 30.637 | E23: 34.649 | F23: 37.614 | G23: 39.449 | H23: 39.816 | I23: 40.164 | J23: 40.404 | K23: 40.665 | L23: 40.975 | M23: 41.554 | N23: 44.441 | O23: 48.342 | Q23: =O23-C23 -> 21.939
P24: =SUM(P4:P23) -> 619.154 | Q24: =SUM(Q4:Q23) -> 165.885
A25: spol.spotř. | B25: elektroměr č. 1025291034 | C25: 2438 | D25: 2643 | E25: 2829 | F25: 3063 | G25: 3275 | H25: 3488 | I25: 3711 | J25: 3921 | K25: 4187 | L25: 4365 | M25: 4547 | N25: 4715 | O25: 4886 | R25: =O25-C25 -> 2448
B26: patní vodoměr č. 190976787 | C26: 2467.9 | D26: 2528 | E26: 2586.6 | F26: 2651.8 | G26: 2710.1 | H26: 2768.1 | I26: 2832.8 | J26: 2875.1 | K26: 2933.5 | L26: 2999.7 | M26: 3051.3 | N26: 3110.5 | O26: 3172 | P26: =O26-C26 -> 704.1
B27: patní kalorimetr č./MWh | C27: 181.1 | D27: 190.12 | E27: 198.32 | F27: 204.73 | G27: 208.7 | H27: 209.76 | I27: 210.49 | J27: 210.8 | K27: 1.64 | L27: 3.68 | M27: 10.21 | N27: 33.9 | O27: 67.3 | Q27: =(J27-C27)*3.6+O27 -> 174.22 | R27: GJ
B28: patní kalorimetr č./kub.m | C28: 6557 | D28: 6799 | E28: 7036 | F28: 7212 | G28: 7334 | H28: 7377 | I28: 7406 | J28: 7421 | K28: 20 | L28: 42 | M28: 108 | N28: 295 | O28: 564 | Q28: =J28-C28+O28 -> 1428 | R28: m3
A29: fakturační vodoměr č. 63796 | C29: 20281.1 | D29: 20614.3 | E29: 20910.1 | F29: 21247.4 | G29: 21572.2 | H29: 21932.7 | I29: 22298.9 | J29: 22571.5 | K29: 22887.6 | L29: 23211.6 | M29: 23544 | N29: 23869.2 | O29: 24212 | P29: =O29-C29 -> 3930.9
C31: číslo | E31: stav
B32: Výměna fakturač. vodoměru | C32: 110109308 | D32: starý | E32: 12875 | H32: Dne 31.7.2023 odpojen kalor. (cejchování), | L32: stav: | M32: 210.8 | N32: MWh
B33: dne 14.2.2019 | C33: 63796 | D33: nový | E33: 4174 | H33: Dne 3.8.2023 zapojen znovuzapojení, | L33: stav: | M33: 0 | N33: GJ
B34: Výměna elekroměru | C34: 18972503 | D34: starý
B35: dne 13.2.2022 | C35: 1025291034 | D35: nový
B37: Změna vlastnictví Taufer-Slavíkovi | D37: voda | E37: teplo | N37: Odečet vodárny 31.12.2022 | O37: 20281
B38: do 31.5. a od 1.6.2022 | C38: stav | D38: 274.519 | E38: 10.65
B39: Taufer 1.1.-31.5.2022 | C39: spotřeba | D39: =D38-C10 -> -71.663 | E39: =E38-C11 -> -7.752 | N39: Odečet vodárny 31.12.2023 | O39: 24212
B40: Slavíkovi 1.6.-31.12.2022 | C40: spotřeba | D40: =O10-D38 -> 169.157 | E40: =O11-E39 -> 37.394
N41: spotřeba | O41: =O39-O37-O38 -> 3931

Sheet 1851
AE1: Vytipování vadných vodoměrů
A2: Nové | B2: 1851 | D2: ='1850'!C2 -> 44927 | E2: ='1850'!D2 -> 44958 | F2: ='1850'!E2 -> 44986 | G2: ='1850'!F2 -> 45017 | H2: ='1850'!G2 -> 45047 | I2: ='1850'!H2 -> 45078 | J2: ='1850'!I2 -> 45111 | K2: ='1850'!J2 -> 45139 | ... P2: ='1850'!O2 -> 45292 | Q2: voda | R2: teplo | S2: Elektr | Z2: spotřeby po měsících | AH2: předloňský | AK2: Podíl teplé vody na celkové spotřebě vody u dělených bytů (%) | AV2: CELKOVÝ | AW2: =(AW6+AW12+AW14+AW18+AW54+AW56+AW58+AW60+AW62)/9 -> 0.35991695
A3: číslování | B3: byt č. | D3: prosinec | E3: leden | F3: únor | G3: březen | H3: duben | I3: květen | J3: červen | K3: červenec | L3: srpen | M3: září | N3: říjen | O3: listopad | P3: prosinec | Q3: m3 | R3: GJ | S3: KWh | U3: byt | V3: leden | W3: únor | X3: březen | Y3: duben | Z3: květen | AA3: červen | AB3: červenec | AC3: srpen | AD3: září | AE3: říjen | AF3: listopad | AG3: prosinec | AH3: průměr | AK3: 1. | AL3: 2. | AM3: 3. | AN3: 4. | AO3: 5. | AP3: 6. | AQ3: 7. | AR3: 8. | AS3: 9. | AT3: 10. | AU3: 11. | AV3: 12. | AW3: Průměr
A4: 1 | B4: 1 | C4: vodoměr č. 190834116 | D4: 536.77 | E4: 551.647 | F4: 562.368 | G4: 574.768 | H4: 585.116 | I4: 597.078 | J4: 607.972 | K4: 616.911 | L4: 628.671 | M4: 641.315 | N4: 653.944 | O4: 666.821 | P4: 682.225 | Q4: =P4-D4 -> 145.455 | U4: 1 | V4: =E4-D4 -> 14.877 | W4: =F4-E4 -> 10.721 | X4: =G4-F4 -> 12.4 | Y4: =H4-G4 -> 10.348 | Z4: =I4-H4 -> 11.962 | AA4: =J4-I4 -> 10.894 | AB4: =K4-J4 -> 8.939 | AC4: =L4-K4 -> 11.76 | ... AG4: =P4-O4 -> 15.404 | AH4: 11.905222
C5: kalorimetr č. 71182262 | D5: 39.364 | E5: 43.734 | F5: 47.276 | G5: 50.347 | H5: 52.093 | I5: 53.195 | J5: 53.962 | K5: 54.496 | L5: 55.123 | M5: 55.888 | N5: 57.157 | O5: 60.357 | P5: 64.751 | R5: =P5-D5 -> 25.387 | U5: xx
A6: 2 | B6: 2 | C6: vodoměr SV č. 190834120 | D6: 201.144 | E6: 206.112 | F6: 210.649 | G6: 215.891 | H6: 220.924 | I6: 225.614 | J6: 231.181 | K6: 235.64 | L6: 240.643 | M6: 246.092 | N6: 250.655 | O6: 255.35 | P6: 261.012 | Q6: =P6-D6 -> 59.868 | U6: 2 | V6: =E6-D6 -> 4.968 | W6: =F6-E6 -> 4.537 | X6: =G6-F6 -> 5.242 | Y6: =H6-G6 -> 5.033 | Z6: =I6-H6 -> 4.69 | AA6: =J6-I6 -> 5.567 | AB6: =K6-J6 -> 4.459 | AC6: =L6-K6 -> 5.003 | ... AG6: =P6-O6 -> 5.662 | AH6: 4.9828889 | AJ6: byt 2 | AK6: =V7/(V6+V7) -> 0.34597156 | AL6: =W7/(W6+W7) -> 0.35027925 | AM6: =X7/(X6+X7) -> 0.35712534 | AN6: =Y7/(Y6+Y7) -> 0.3668386 | AO6: =Z7/(Z6+Z7) -> 0.36475687 | AP6: =AA7/(AA6+AA7) -> 0.31330949 | AQ6: =AB7/(AB6+AB7) -> 0.27613636 | AR6: =AC7/(AC6+AC7) -> 0.28292963 | ... AV6: =AG7/(AG6+AG7) -> 0.36800982 | AW6: =SUM(AK6:AV6)/12 -> 0.33918136
A7: 2 a 3 | C7: kalorimetr č. 71182271 | D7: 46.893 | E7: 51.423 | F7: 56.612 | G7: 61.177 | H7: 63.3 | I7: 64.216 | J7: 64.974 | K7: 65.653 | L7: 66.286 | M7: 67.014 | N7: 68.822 | O7: 72.827 | P7: 78.034 | R7: =P7-D7 -> 31.141 | U7: TV | V7: =V40 -> 2.628 | W7: =W40 -> 2.446 | X7: =X40 -> 2.912 | Y7: =Y40 -> 2.916 | Z7: =Z40 -> 2.693 | AA7: =AA40 -> 2.54 | AB7: =AB40 -> 1.701 | AC7: =AC40 -> 1.974 | ... AG7: =AG40 -> 3.297 | AH7: 4.43
A8: 5 | B8: 3 | C8: vodoměr SV č. 221525378 | D8: 1.058 | E8: 2.172 | F8: 3.164 | G8: 4.259 | H8: 5.271 | I8: 6.291 | J8: 7.524 | K8: 8.629 | L8: 9.843 | M8: 10.911 | N8: 11.945 | O8: 13.048 | P8: 14.203 | Q8: =P8-I54+I53-D8 -> 36.355 | U8: 5 | V8: =E8-D8 -> 1.114 | W8: =F8-E8 -> 0.992 | X8: =G8-F8 -> 1.095 | Y8: =H8-G8 -> 1.012 | Z8: =I8-H8 -> 1.02 | AA8: =J8-I8 -> 1.233 | AB8: =K8-J8 -> 1.105 | AC8: =L8-K8 -> 1.214 | ... AG8: =P8-O8 -> 1.155 | AH8: 0.94022222 | AJ8: byt 5 | AK8: =V9/(V8+V9) -> 0.25832224 | AL8: =W9/(W8+W9) -> 0.26897568 | AM8: =X9/(X8+X9) -> 0.25611413 | AN8: =Y9/(Y8+Y9) -> 0.26666667 | AO8: =Z9/(Z8+Z9) -> 0.23994039 | AP8: =AA9/(AA8+AA9) -> 0.21113244 | AQ8: =AB9/(AB8+AB9) -> 0.18690213 | AR8: =AC9/(AC8+AC9) -> 0.21474774 | ... AV8: =AG9/(AG8+AG9) -> 0.25291074 | AW8: =SUM(AK8:AV8)/12 -> 0.23605879
A9: 5 a 6 | C9: kalorimetr č. 71182241 | D9: 51.338 | E9: 56.038 | F9: 60.893 | G9: 70.006 | H9: 77.695 | I9: 83.397 | J9: 87.178 | K9: 88.517 | L9: 89.678 | M9: 90.756 | N9: 92.24 | O9: 95.573 | P9: 100 | R9: =P9-D9 -> 48.662 | U9: TV | V9: =V42 -> 0.388 | W9: =W42 -> 0.365 | X9: =X42 -> 0.377 | Y9: =Y42 -> 0.368 | Z9: =Z42 -> 0.322 | AA9: =AA42 -> 0.33 | AB9: =AB42 -> 0.254 | AC9: =AC42 -> 0.332 | ... AG9: =AG42 -> 0.391 | AH9: 0.37122222
A10: 4 | B10: 4 | C10: vodoměr č. 190834126 | D10: 116.497 | E10: 124.646 | F10: 132.55 | G10: 138.602 | H10: 145.833 | I10: 154.376 | J10: 161.812 | K10: 166.168 | L10: 171.105 | M10: 179.009 | N10: 186.825 | O10: 194.76 | P10: 201.491 | Q10: =P10-D10 -> 84.994 | U10: 4 | V10: =E10-D10 -> 8.149 | W10: =F10-E10 -> 7.904 | X10: =G10-F10 -> 6.052 | Y10: =H10-G10 -> 7.231 | Z10: =I10-H10 -> 8.543 | AA10: =J10-I10 -> 7.436 | AB10: =K10-J10 -> 4.356 | AC10: =L10-K10 -> 4.937 | ... AG10: =P10-O10 -> 6.731 | AH10: 5.9373333
C11: kalorimetr č. 71182237 | D11: 1.298 | E11: 2.899 | F11: 4.455 | G11: 5.28 | H11: 5.996 | I11: 6.464 | J11: 6.807 | K11: 6.952 | L11: 7.124 | M11: 7.463 | N11: 7.853 | O11: 8.873 | P11: 10.27 | R11: =P11-D11 -> 8.972 | U11: xx
A12: 9 | B12: 5 | C12: vodoměr SV č. 190834122 | D12: 172.088 | E12: 176.766 | F12: 181.119 | G12: 185.537 | H12: 189.534 | I12: 194.08 | J12: 199.655 | K12: 203.936 | L12: 208.561 | M12: 213.425 | N12: 218.813 | O12: 223.697 | P12: 229.006 | Q12: =P12-D12 -> 56.918 | U12: 9 | V12: =E12-D12 -> 4.678 | W12: =F12-E12 -> 4.353 | X12: =G12-F12 -> 4.418 | Y12: =H12-G12 -> 3.997 | Z12: =I12-H12 -> 4.546 | AA12: =J12-I12 -> 5.575 | AB12: =K12-J12 -> 4.281 | AC12: =L12-K12 -> 4.625 | ... AG12: =P12-O12 -> 5.309 | AH12: 4.7323333 | AJ12: byt 9 | AK12: =V13/(V12+V13) -> 0.28819233 | AL12: =W13/(W12+W13) -> 0.29801645 | AM12: =X13/(X12+X13) -> 0.25797783 | AN12: =Y13/(Y12+Y13) -> 0.25023448 | AO12: =Z13/(Z12+Z13) -> 0.21090089 | AP12: =AA13/(AA12+AA13) -> 0.16001205 | AQ12: =AB13/(AB12+AB13) -> 0.18472672 | AR12: =AC13/(AC12+AC13) -> 0.18516561 | ... AV12: =AG13/(AG12+AG13) -> 0.22766948 | AW12: =SUM(AK12:AV12)/12 -> 0.22204003
A13: 8 a 9 | C13: kalorimetr č. 71182221 | D13: 38.609 | E13: 43.002 | F13: 45.708 | G13: 47.663 | H13: 49.801 | I13: 50.894 | J13: 51.549 | K13: 51.982 | L13: 52.502 | M13: 53.193 | N13: 55.465 | O13: 59.372 | P13: 64.284 | R13: =P13-D13 -> 25.675 | U13: TV | V13: =V44 -> 1.894 | W13: =W44 -> 1.848 | X13: =X44 -> 1.536 | Y13: =Y44 -> 1.334 | Z13: =Z44 -> 1.215 | AA13: =AA44 -> 1.062 | AB13: =AB44 -> 0.97 | AC13: =AC44 -> 1.051 | ... AG13: =AG44 -> 1.565 | AH13: 4.7182222
A14: 15 | B14: 6 | C14: vodoměr SV č. 200015757 | D14: 153.431 | E14: 158.16 | F14: 161.53 | G14: 165.253 | H14: 169.479 | I14: 173.28 | J14: 178.004 | K14: 182.352 | L14: 186.712 | M14: 186.85 | N14: 187.664 | O14: 188.386 | P14: 189.371 | Q14: =P14-D14 -> 35.94 | U14: 15 | V14: =E14-D14 -> 4.729 | W14: =F14-E14 -> 3.37 | X14: =G14-F14 -> 3.723 | Y14: =H14-G14 -> 4.226 | Z14: =I14-H14 -> 3.801 | AA14: =J14-I14 -> 4.724 | AB14: =K14-J14 -> 4.348 | AC14: =L14-K14 -> 4.36 | ... AG14: =P14-O14 -> 0.985 | AH14: 1.6821111 | AJ14: byt 15 | AK14: =V15/(V14+V15) -> 0.47647515 | AL14: =W15/(W14+W15) -> 0.49791418 | AM14: =X15/(X14+X15) -> 0.48796589 | AN14: =Y15/(Y14+Y15) -> 0.45986708 | AO14: =Z15/(Z14+Z15) -> 0.44984802 | AP14: =AA15/(AA14+AA15) -> 0.37997112 | AQ14: =AB15/(AB14+AB15) -> 0.3184953 | AR14: =AC15/(AC14+AC15) -> 0.27430093 | ... AV14: =AG15/(AG14+AG15) -> 0.59314333 | AW14: =SUM(AK14:AV14)/12 -> 0.42979885
A15: 11 a 15 | C15: kalorimetr č. 71182276 | D15: 22.332 | E15: 25.121 | F15: 27.818 | G15: 30.329 | H15: 32.195 | I15: 32.973 | J15: 33.632 | K15: 34.081 | L15: 34.549 | M15: 34.736 | N15: 35.415 | O15: 36.553 | P15: 39.081 | R15: =P15-D15 -> 16.749 | U15: TV | V15: =V46 -> 4.304 | W15: =W46 -> 3.342 | X15: =X46 -> 3.548 | Y15: =Y46 -> 3.598 | Z15: =Z46 -> 3.108 | AA15: =AA46 -> 2.895 | AB15: =AB46 -> 2.032 | AC15: =AC46 -> 1.648 | ... AG15: =AG46 -> 1.436 | AH15: 0.73344444
A16: 7 | B16: 7 | C16: vodoměr č. 190834119 | D16: 230.537 | E16: 235.137 | F16: 239.791 | G16: 245.797 | H16: 251.135 | I16: 255.92 | J16: 260.93 | K16: 264.786 | L16: 267.634 | M16: 272.1 | N16: 276.665 | O16: 281.702 | P16: 288.419 | Q16: =P16-D16 -> 57.882 | U16: 7 | V16: =E16-D16 -> 4.6 | W16: =F16-E16 -> 4.654 | X16: =G16-F16 -> 6.006 | Y16: =H16-G16 -> 5.338 | Z16: =I16-H16 -> 4.785 | AA16: =J16-I16 -> 5.01 | AB16: =K16-J16 -> 3.856 | AC16: =L16-K16 -> 2.848 | ... AG16: =P16-O16 -> 6.717 | AH16: 6.2735556
C17: kalorimetr č. 71182256 | D17: 5.776 | E17: 6.138 | F17: 6.523 | G17: 7.034 | H17: 7.47 | I17: 7.797 | J17: 8.104 | K17: 8.296 | L17: 8.441 | M17: 8.675 | N17: 8.966 | O17: 9.332 | P17: 9.895 | R17: =P17-D17 -> 4.119 | U17: xx
A18: 13 | B18: 8 | C18: vodoměr SV č. 190834112 | D18: 108.811 | E18: 111.154 | F18: 113.14 | G18: 115.386 | H18: 117.763 | I18: 119.625 | J18: 122.048 | K18: 124.184 | L18: 127.101 | M18: 129.543 | N18: 131.821 | O18: 133.7 | P18: 136.261 | Q18: =P18-D18 -> 27.45 | U18: 13 | V18: =E18-D18 -> 2.343 | W18: =F18-E18 -> 1.986 | X18: =G18-F18 -> 2.246 | Y18: =H18-G18 -> 2.377 | Z18: =I18-H18 -> 1.862 | AA18: =J18-I18 -> 2.423 | AB18: =K18-J18 -> 2.136 | AC18: =L18-K18 -> 2.917 | ... AG18: =P18-O18 -> 2.561 | AH18: 2.5207778 | AJ18: byt 13 | AK18: =V19/(V18+V19) -> 0.46580027 | AL18: =W19/(W18+W19) -> 0.52680486 | AM18: =X19/(X18+X19) -> 0.46650831 | AN18: =Y19/(Y18+Y19) -> 0.44989586 | AO18: =Z19/(Z18+Z19) -> 0.4627813 | AP18: =AA19/(AA18+AA19) -> 0.40830281 | AQ18: =AB19/(AB18+AB19) -> 0.34276923 | AR18: =AC19/(AC18+AC19) -> 0.39216503 | ... AV18: =AG19/(AG18+AG19) -> 0.40400279 | AW18: =SUM(AK18:AV18)/12 -> 0.43639186
A19: 12 a 13 | C19: kalorimetr č. 71182279 | D19: 36.685 | E19: 41.326 | F19: 46.028 | G19: 49.05 | H19: 50.771 | I19: 51.274 | J19: 51.809 | K19: 52.11 | L19: 52.528 | M19: 53.005 | N19: 53.727 | O19: 56.422 | P19: 60.986 | R19: =P19-D19 -> 24.301 | U19: TV | V19: =V48 -> 2.043 | W19: =W48 -> 2.211 | X19: =X48 -> 1.964 | Y19: =Y48 -> 1.944 | Z19: =Z48 -> 1.604 | AA19: =AA48 -> 1.672 | AB19: =AB48 -> 1.114 | AC19: =AC48 -> 1.882 | ... AG19: =AG48 -> 1.736 | AH19: 1.2623333
A20: 14 | B20: 9 | C20: vodoměr č. 190834124 | D20: 366.117 | E20: 374.279 | F20: 380.839 | G20: 390.237 | H20: 399.692 | I20: 409.378 | J20: 420.212 | K20: 426.581 | L20: 433.529 | M20: 443.934 | N20: 453.482 | O20: 462.4 | P20: 470.877 | Q20: =P20-D20 -> 104.76 | U20: 14 | V20: =E20-D20 -> 8.162 | W20: =F20-E20 -> 6.56 | X20: =G20-F20 -> 9.398 | Y20: =H20-G20 -> 9.455 | Z20: =I20-H20 -> 9.686 | AA20: =J20-I20 -> 10.834 | AB20: =K20-J20 -> 6.369 | AC20: =L20-K20 -> 6.948 | ... AG20: =P20-O20 -> 8.477 | AH20: 6.9983333
C21: kalorimetr č. 71182252 | D21: 35.137 | E21: 39.438 | F21: 43.612 | G21: 46.7 | H21: 48.552 | I21: 49.221 | J21: 49.757 | K21: 50.04 | L21: 50.323 | M21: 50.761 | N21: 52.086 | O21: 55.832 | P21: 60.793 | R21: =P21-D21 -> 25.656 | U21: xx
A22: 10 | B22: 10 | C22: vodoměr č. 190834091 | D22: 72.127 | E22: 73.66 | F22: 74.202 | G22: 76.55 | H22: 78.251 | I22: 79.91 | J22: 81.553 | K22: 83.553 | L22: 85.709 | M22: 87.398 | N22: 89.334 | O22: 91.106 | P22: 92.85 | Q22: =P22-D22 -> 20.723 | U22: 10 | V22: =E22-D22 -> 1.533 | W22: =F22-E22 -> 0.542 | X22: =G22-F22 -> 2.348 | Y22: =H22-G22 -> 1.701 | Z22: =I22-H22 -> 1.659 | AA22: =J22-I22 -> 1.643 | AB22: =K22-J22 -> 2 | AC22: =L22-K22 -> 2.156 | ... AG22: =P22-O22 -> 1.744 | AH22: 2.9007778
C23: kalorimetr č. 71182234 | D23: 21.182 | E23: 23.761 | F23: 25.808 | G23: 27.746 | H23: 28.546 | I23: 28.786 | J23: 29.024 | K23: 29.223 | L23: 29.413 | M23: 29.635 | N23: 30.031 | O23: 32.618 | P23: 35.464 | R23: =P23-D23 -> 14.282 | U23: xx
B24: spol.spotř. | C24: elektroměr č. 2080200096 | D24: 9091 | E24: 9291 | F24: 9532 | G24: 9781 | H24: 10063 | I24: 10304 | J24: 10587 | K24: 10797 | L24: 11042 | M24: 11281 | N24: 11552 | O24: 11784 | P24: 12070 | Q24: =SUM(Q4:Q23)+SUM(Q33:Q49) -> 981.325 | R24: =SUM(R4:R23) -> 224.944 | S24: =P24-D24 -> 2979 | U24: kWh | AK24: Podíl teplé vody na celkové spotřebě vody u dělených bytů po měsících (%)
AJ25: CELKEM | AK25: 1. | AL25: 2. | AM25: 3. | AN25: 4. | AO25: 5. | AP25: 6. | AQ25: 7. | AR25: 8. | AS25: 9. | AT25: 10. | AU25: 11. | AV25: 12. | AW25: Průměr
C26: patní vodoměr č. 190976791 | D26: 3852.3 | E26: 3944.9 | F26: 4021.2 | G26: 4113 | H26: 4204.6 | I26: 4302.7 | J26: 4398.4 | K26: 4466.5 | L26: 4542.1 | M26: 4617.8 | N26: 4699.7 | O26: 4786.3 | P26: 4882.6 | Q26: =P26-D26 -> 1030.3 | AJ26: Průměr po měsících | AK26: =(AK6+AK8+AK12+AK14+AK18+AK54+AK56+AK58+AK60+AK62)/10 -> 0.37510111 | AL26: =(AL6+AL8+AL12+AL14+AL18+AL54+AL56+AL58+AL60+AL62)/10 -> 0.38990646 | AM26: =(AM6+AM8+AM12+AM14+AM18+AM54+AM56+AM58+AM60+AM62)/10 -> 0.39816564 | AN26: =(AN6+AN8+AN12+AN14+AN18+AN54+AN56+AN58+AN60+AN62)/10 -> 0.3826926 | AO26: =(AO6+AO8+AO12+AO14+AO18+AO54+AO56+AO58+AO60+AO62)/10 -> 0.35898214 | AP26: =(AP6+AP8+AP12+AP14+AP18+AP54+AP56+AP58+AP60+AP62)/10 -> 0.30614145 | AQ26: =(AQ6+AQ8+AQ12+AQ14+AQ18+AQ54+AQ56+AQ58+AQ60+AQ62)/10 -> 0.31647023 | AR26: =(AR6+AR8+AR12+AR14+AR18+AR54+AR56+AR58+AR60+AR62)/10 -> 0.31520721 | ... AW26: =(AW6+AW8+AW12+AW14+AW18+AW54+AW56+AW58+AW60+AW62)/10 -> 0.34753113 | AZ26: Podíl TV po bytech
C27: patní kalorimetr č. /MWh | D27: 292.51 | E27: 303.2 | F27: 313.14 | G27: 322.61 | H27: 329.28 | I27: 333.52 | J27: 336.96 | K27: 339.11 | L27: 8.21 | M27: 17.44 | N27: 31.73 | O27: 60.68 | P27: 100.05 | R27: =(K27-D27)*3.6+P27 -> 267.81 | S27: GJ
C28: patní kalorimetr č./kub.m | D28: 28066 | E28: 28546 | F28: 28989 | G28: 29361 | H28: 29617 | I28: 29918 | J28: 30230 | K28: 30496 | L28: 345 | M28: 708 | N28: 1051.3 | O28: 1381 | P28: 1827 | R28: =K28-D28+P28 -> 4257 | S28: m3
B29: ='1850'!A29 -> fakturační vodoměr č. 63796 | D29: ='1850'!C29 -> 20281.1 | E29: ='1850'!D29 -> 20614.3 | F29: ='1850'!E29 -> 20910.1 | G29: ='1850'!F29 -> 21247.4 | H29: ='1850'!G29 -> 21572.2 | I29: ='1850'!H29 -> 21932.7 | J29: ='1850'!I29 -> 22298.9 | K29: ='1850'!J29 -> 22571.5 | ... P29: ='1850'!O29 -> 24212 | Q29: =P29-D29 -> 3930.9 | V29: studená voda
U31: byt | V31: leden | W31: únor | X31: březen | Y31: duben | Z31: květen | AA31: červen | AB31: červenec | AC31: srpen | AD31: září | AE31: říjen | AF31: listopad | AG31: prosinec
A33: 3 | B33: 2B | C33: vodoměr SV č. 200015745 | D33: 218.777 | E33: 221.137 | F33: 223.265 | G33: 225.854 | H33: 226.08 | I33: 226.325 | J33: 226.361 | K33: 228.733 | L33: 231.391 | M33: 233.789 | N33: 236.749 | O33: 240.25 | P33: 243.244 | Q33: =P33-D33 -> 24.467 | U33: 3 | V33: =E33-D33 -> 2.36 | W33: =F33-E33 -> 2.128 | X33: =G33-F33 -> 2.589 | Y33: =H33-G33 -> 0.226 | Z33: =I33-H33 -> 0.245 | AA33: =J33-I33 -> 0.036 | AB33: =K33-J33 -> 2.372 | AC33: =L33-K33 -> 2.658 | ... AG33: =P33-O33 -> 2.994 | AH33: 7.9723
A34: 6 | B34: 3B | C34: vodoměr SV č. 190834107 | D34: 122.338 | E34: 124.05 | F34: 125.871 | G34: 130.136 | H34: 136.44 | I34: 145.161 | J34: 152.404 | K34: 154.912 | L34: 155.235 | M34: 155.324 | N34: 156.223 | O34: 158.477 | P34: 160.511 | Q34: =P34-D34 -> 38.173 | U34: 6 | V34: =E34-D34 -> 1.712 | W34: =F34-E34 -> 1.821 | X34: =G34-F34 -> 4.265 | Y34: =H34-G34 -> 6.304 | Z34: =I34-H34 -> 8.721 | AA34: =J34-I34 -> 7.243 | AB34: =K34-J34 -> 2.508 | AC34: =L34-K34 -> 0.323 | ... AG34: =P34-O34 -> 2.034 | AH34: 2.9773
A35: 8 | B35: 5B | C35: vodoměr SV č. 190834094 | D35: 241.591 | E35: 246.764 | F35: 248.787 | G35: 249.291 | H35: 251.565 | I35: 253.856 | J35: 255.927 | K35: 256.925 | L35: 258.597 | M35: 260.595 | N35: 265.799 | O35: 271.794 | P35: 278.202 | Q35: =P35-D35 -> 36.611 | U35: 8 | V35: =E35-D35 -> 5.173 | W35: =F35-E35 -> 2.023 | X35: =G35-F35 -> 0.504 | Y35: =H35-G35 -> 2.274 | Z35: =I35-H35 -> 2.291 | AA35: =J35-I35 -> 2.071 | AB35: =K35-J35 -> 0.998 | AC35: =L35-K35 -> 1.672 | ... AG35: =P35-O35 -> 6.408 | AH35: 5.4084
A36: 11 | B36: 6B | C36: vodoměr SV č. 200015744 | D36: 19.042 | E36: 19.577 | F36: 19.924 | G36: 20.75 | H36: 22.025 | I36: 22.817 | J36: 23.889 | K36: 24.903 | L36: 27.863 | M36: 28.535 | N36: 29.315 | O36: 29.767 | P36: 31.35 | Q36: =P36-D36 -> 12.308 | U36: 11 | V36: =E36-D36 -> 0.535 | W36: =F36-E36 -> 0.347 | X36: =G36-F36 -> 0.826 | Y36: =H36-G36 -> 1.275 | Z36: =I36-H36 -> 0.792 | AA36: =J36-I36 -> 1.072 | AB36: =K36-J36 -> 1.014 | AC36: =L36-K36 -> 2.96 | ... AG36: =P36-O36 -> 1.583 | AH36: 0.4723
A37: 12 | B37: 8B | C37: vodoměr SV č. 190834128 | D37: 84.883 | E37: 87.797 | F37: 90.593 | G37: 94.19 | H37: 98.255 | I37: 103.207 | J37: 106.635 | K37: 109.267 | L37: 112.702 | M37: 116.39 | N37: 119.875 | O37: 123.423 | P37: 127.366 | Q37: =P37-D37 -> 42.483 | U37: 12 | V37: =E37-D37 -> 2.914 | W37: =F37-E37 -> 2.796 | X37: =G37-F37 -> 3.597 | Y37: =H37-G37 -> 4.065 | Z37: =I37-H37 -> 4.952 | AA37: =J37-I37 -> 3.428 | AB37: =K37-J37 -> 2.632 | AC37: =L37-K37 -> 3.435 | ... AG37: =P37-O37 -> 3.943 | AH37: 2.1434
C39: VODOMĚRY TEPLÁ VODA | V39: teplá voda
A40: 2 | B40: 2 | C40: vodoměr TUV č. 200105142 | D40: 85.202 | E40: 87.83 | F40: 90.276 | G40: 93.188 | H40: 96.104 | I40: 98.797 | J40: 101.337 | K40: 103.038 | L40: 105.012 | M40: 107.569 | N40: 110.037 | O40: 112.847 | P40: 116.144 | Q40: =P40-D40 -> 30.942 | U40: 2 | V40: =E40-D40 -> 2.628 | W40: =F40-E40 -> 2.446 | X40: =G40-F40 -> 2.912 | Y40: =H40-G40 -> 2.916 | Z40: =I40-H40 -> 2.693 | AA40: =J40-I40 -> 2.54 | AB40: =K40-J40 -> 1.701 | AC40: =L40-K40 -> 1.974 | ... AG40: =P40-O40 -> 3.297 | AH40: 4.0477
A41: 3 | B41: 2B | C41: vodoměr TUV č. 200105133 | D41: 139.535 | E41: 140.991 | F41: 142.409 | G41: 144.491 | H41: 144.676 | I41: 144.829 | J41: 144.83 | K41: 146.136 | L41: 147.581 | M41: 148.785 | N41: 150.219 | O41: 152.13 | P41: 153.634 | Q41: =P41-D41 -> 14.099 | U41: 3 | V41: =E41-D41 -> 1.456 | W41: =F41-E41 -> 1.418 | X41: =G41-F41 -> 2.082 | Y41: =H41-G41 -> 0.185 | Z41: =I41-H41 -> 0.153 | AA41: =J41-I41 -> 0.001 | AB41: =K41-J41 -> 1.306 | AC41: =L41-K41 -> 1.445 | ... AG41: =P41-O41 -> 1.504 | AH41: 4.1811
A42: 5 | B42: 3 | C42: vodoměr TUV č. 190049448 | D42: 17.24 | E42: 17.628 | F42: 17.993 | G42: 18.37 | H42: 18.738 | I42: 19.06 | J42: 19.39 | K42: 19.644 | L42: 19.976 | M42: 20.255 | N42: 20.563 | O42: 20.912 | P42: 21.303 | Q42: =P42-D42 -> 4.063 | U42: 5 | V42: =E42-D42 -> 0.388 | W42: =F42-E42 -> 0.365 | X42: =G42-F42 -> 0.377 | Y42: =H42-G42 -> 0.368 | Z42: =I42-H42 -> 0.322 | AA42: =J42-I42 -> 0.33 | AB42: =K42-J42 -> 0.254 | AC42: =L42-K42 -> 0.332 | ... AG42: =P42-O42 -> 0.391 | AH42: 0.3771
A43: 6 | B43: 3B | C43: vodoměr TUV č. 190049255 | D43: 96.178 | E43: 97.762 | F43: 99.381 | G43: 104.356 | H43: 110.941 | I43: 120.195 | J43: 127.4 | K43: 130.236 | L43: 130.578 | M43: 130.623 | N43: 130.935 | O43: 131.887 | P43: 132.966 | Q43: =P43-D43 -> 36.788 | U43: 6 | V43: =E43-D43 -> 1.584 | W43: =F43-E43 -> 1.619 | X43: =G43-F43 -> 4.975 | Y43: =H43-G43 -> 6.585 | Z43: =I43-H43 -> 9.254 | AA43: =J43-I43 -> 7.205 | AB43: =K43-J43 -> 2.836 | AC43: =L43-K43 -> 0.342 | ... AG43: =P43-O43 -> 1.079 | AH43: 1.5876
...

Sheet 1852
A2: 1852 | C2: ='1850'!C2 -> 44927 | D2: ='1850'!D2 -> 44958 | E2: ='1850'!E2 -> 44986 | F2: ='1850'!F2 -> 45017 | G2: ='1850'!G2 -> 45047 | H2: ='1850'!H2 -> 45078 | I2: ='1850'!I2 -> 45111 | J2: ='1850'!J2 -> 45139 | ... O2: ='1850'!O2 -> 45292 | P2: voda | Q2: teplo | R2: Elektr | Y2: spotřeby po měsících
A3: byt č. | C3: prosinec | D3: leden | E3: únor | F3: březen | G3: duben | H3: květen | I3: červen | J3: červenec | K3: srpen | L3: září | M3: říjen | N3: listopad | O3: prosinec | P3: m3 | Q3: GJ | R3: KWh | T3: byt | U3: leden | V3: únor | W3: březen | X3: duben | Y3: květen | Z3: červen | AA3: červenec | AB3: srpen | AC3: září | AD3: říjen | AE3: listopad | AF3: prosinec
A4: 1 | B4: vodoměr č. 190834115 | C4: 445.719 | D4: 455.59 | E4: 466.564 | F4: 476.999 | G4: 487.181 | H4: 498.181 | I4: 509.757 | J4: 518.961 | K4: 530.655 | L4: 543.346 | M4: 554.406 | N4: 565.053 | O4: 576.312 | P4: =O4-C4 -> 130.593 | T4: 1 | U4: =D4-C4 -> 9.871 | V4: =E4-D4 -> 10.974 | W4: =F4-E4 -> 10.435 | X4: =G4-F4 -> 10.182 | Y4: =H4-G4 -> 11 | Z4: =I4-H4 -> 11.576 | AA4: =J4-I4 -> 9.204 | AB4: =K4-J4 -> 11.694 | ... AF4: =O4-N4 -> 11.259
B5: kalorimetr č. 71182233 | C5: 30.733 | D5: 34.232 | E5: 37.698 | F5: 40.611 | G5: 42.743 | H5: 43.469 | I5: 44.106 | J5: 44.559 | K5: 45.081 | L5: 45.694 | M5: 47.12 | N5: 49.831 | O5: 53.409 | Q5: =O5-C5 -> 22.676
A6: 2 | B6: vodoměr č. 190834121 | C6: 235.605 | D6: 243.138 | E6: 249.98 | F6: 258.34 | G6: 266.468 | H6: 273.338 | I6: 279.834 | J6: 285.227 | K6: 291.49 | L6: 298.306 | M6: 304.641 | N6: 310.016 | O6: 314.552 | P6: =O6-C6 -> 78.947 | T6: 2 | U6: =D6-C6 -> 7.533 | V6: =E6-D6 -> 6.842 | W6: =F6-E6 -> 8.36 | X6: =G6-F6 -> 8.128 | Y6: =H6-G6 -> 6.87 | Z6: =I6-H6 -> 6.496 | AA6: =J6-I6 -> 5.393 | AB6: =K6-J6 -> 6.263 | ... AF6: =O6-N6 -> 4.536
B7: kalorimetr č. 71182270 | C7: 16.116 | D7: 17.339 | E7: 18.843 | F7: 19.976 | G7: 20.814 | H7: 21.47 | I7: 22.06 | J7: 22.497 | K7: 22.918 | L7: 23.507 | M7: 24.026 | N7: 24.702 | O7: 25.735 | Q7: =O7-C7 -> 9.619
A8: 3 | B8: vodoměr č. 200015760 | C8: 338.053 | D8: 348.615 | E8: 360.687 | F8: 370.43 | G8: 380.405 | H8: 393.399 | I8: 403.931 | J8: 412.153 | K8: 418.6 | L8: 429.847 | M8: 438.919 | N8: 448.919 | O8: 459.766 | P8: =O8-C8 -> 121.713 | T8: 3 | U8: =D8-C8 -> 10.562 | V8: =E8-D8 -> 12.072 | W8: =F8-E8 -> 9.743 | X8: =G8-F8 -> 9.975 | Y8: =H8-G8 -> 12.994 | Z8: =I8-H8 -> 10.532 | AA8: =J8-I8 -> 8.222 | AB8: =K8-J8 -> 6.447 | ... AF8: =O8-N8 -> 10.847
B9: kalorimetr č. 71182274 | C9: 43.311 | D9: 48.234 | E9: 52.65 | F9: 56.297 | G9: 59.371 | H9: 60.511 | I9: 61.16 | J9: 61.481 | K9: 61.772 | L9: 62.404 | M9: 63.808 | N9: 67.442 | O9: 72.049 | Q9: =O9-C9 -> 28.738
A10: 4 | B10: vodoměr č. 190834096 | C10: 407.947 | D10: 416.924 | E10: 424.135 | F10: 433.11 | G10: 442.024 | H10: 450.118 | I10: 459.617 | J10: 466.052 | K10: 473.014 | L10: 481.991 | M10: 489.046 | N10: 497.472 | O10: 506.213 | P10: =O10-C10 -> 98.266 | T10: 4 | U10: =D10-C10 -> 8.977 | V10: =E10-D10 -> 7.211 | W10: =F10-E10 -> 8.975 | X10: =G10-F10 -> 8.914 | Y10: =H10-G10 -> 8.094 | Z10: =I10-H10 -> 9.499 | AA10: =J10-I10 -> 6.435 | AB10: =K10-J10 -> 6.962 | ... AF10: =O10-N10 -> 8.741
B11: kalorimetr č. 71182244 | C11: 37.265 | D11: 41.493 | E11: 44.998 | F11: 48.1 | G11: 50.49 | H11: 51.37 | I11: 52.12 | J11: 52.557 | K11: 53.026 | L11: 53.695 | M11: 54.49 | N11: 57.212 | O11: 61.01 | Q11: =O11-C11 -> 23.745
A12: 5 | B12: vodoměr č. 190834110 | C12: 236.272 | D12: 243.384 | E12: 249.35 | F12: 256.478 | G12: 262.307 | H12: 269.247 | I12: 274.298 | J12: 278.35 | K12: 285.606 | L12: 293.064 | M12: 300.126 | N12: 307.755 | O12: 314.985 | P12: =O12-C12 -> 78.713 | T12: 5 | U12: =D12-C12 -> 7.112 | V12: =E12-D12 -> 5.966 | W12: =F12-E12 -> 7.128 | X12: =G12-F12 -> 5.829 | Y12: =H12-G12 -> 6.94 | Z12: =I12-H12 -> 5.051 | AA12: =J12-I12 -> 4.052 | AB12: =K12-J12 -> 7.256 | ... AF12: =O12-N12 -> 7.23
B13: kalorimetr č. 71182251 | C13: 20.024 | D13: 21.964 | E13: 23.382 | F13: 24.624 | G13: 25.605 | H13: 26.224 | I13: 26.677 | J13: 26.992 | K13: 27.444 | L13: 27.974 | M13: 28.588 | N13: 29.7 | O13: 30.951 | Q13: =O13-C13 -> 10.927
A14: 6 | B14: vodoměr č. 190834127 | C14: 317.583 | D14: 329.211 | E14: 340.515 | F14: 352.144 | G14: 363.505 | H14: 372.548 | I14: 382.578 | J14: 386.781 | K14: 394.118 | L14: 402.872 | M14: 414.311 | N14: 425.781 | O14: 435.559 | P14: =O14-C14 -> 117.976 | T14: 6 | U14: =D14-C14 -> 11.628 | V14: =E14-D14 -> 11.304 | W14: =F14-E14 -> 11.629 | X14: =G14-F14 -> 11.361 | Y14: =H14-G14 -> 9.043 | Z14: =I14-H14 -> 10.03 | AA14: =J14-I14 -> 4.203 | AB14: =K14-J14 -> 7.337 | ... AF14: =O14-N14 -> 9.778
B15: kalorimetr č. 71182283 | C15: 30.804 | D15: 34.861 | E15: 38.665 | F15: 41.592 | G15: 43.71 | H15: 44.592 | I15: 45.341 | J15: 45.617 | K15: 46.066 | L15: 46.646 | M15: 47.727 | N15: 50.294 | O15: 53.598 | Q15: =O15-C15 -> 22.794
A16: 7 | B16: vodoměr č. 190834123 | C16: 38.227 | D16: 40.071 | E16: 41.382 | F16: 42.241 | G16: 43.442 | H16: 44.211 | I16: 45.322 | J16: 45.687 | K16: 47.944 | L16: 51.251 | M16: 56.456 | N16: 59.877 | O16: 60.945 | P16: =O16-C16 -> 22.718 | T16: 7 | U16: =D16-C16 -> 1.844 | V16: =E16-D16 -> 1.311 | W16: =F16-E16 -> 0.859 | X16: =G16-F16 -> 1.201 | Y16: =H16-G16 -> 0.769 | Z16: =I16-H16 -> 1.111 | AA16: =J16-I16 -> 0.365 | AB16: =K16-J16 -> 2.257 | ... AF16: =O16-N16 -> 1.068
B17: kalorimetr č. 71182277 | C17: 12.76 | D17: 15.17 | E17: 16.906 | F17: 17.754 | G17: 18.392 | H17: 18.403 | I17: 18.43 | J17: 18.434 | K17: 18.476 | L17: 18.558 | M17: 19.312 | N17: 21.597 | O17: 24.092 | Q17: =O17-C17 -> 11.332
A18: 8 | B18: vodoměr č. 190834118 | C18: 355.342 | D18: 365.01 | E18: 372.357 | F18: 382.333 | G18: 391.291 | H18: 401.23 | I18: 408.695 | J18: 416.755 | K18: 424.105 | L18: 433.626 | M18: 444.866 | N18: 453.2 | O18: 464.177 | P18: =O18-C18 -> 108.835 | T18: 8 | U18: =D18-C18 -> 9.668 | V18: =E18-D18 -> 7.347 | W18: =F18-E18 -> 9.976 | X18: =G18-F18 -> 8.958 | Y18: =H18-G18 -> 9.939 | Z18: =I18-H18 -> 7.465 | AA18: =J18-I18 -> 8.06 | AB18: =K18-J18 -> 7.35 | ... AF18: =O18-N18 -> 10.977
B19: kalorimetr č. 71182246 | C19: 19.528 | D19: 21.52 | E19: 22.848 | F19: 24.062 | G19: 24.77 | H19: 25.448 | I19: 25.941 | J19: 26.353 | K19: 26.738 | L19: 27.26 | M19: 27.869 | N19: 29.331 | O19: 31.794 | Q19: =O19-C19 -> 12.266
A20: 9 | B20: vodoměr č. 221525380 | C20: 11.177 | D20: 22.076 | E20: 30.463 | F20: 39.346 | G20: 47.102 | H20: 57.145 | I20: 66.822 | J20: 72.727 | K20: 81.36 | L20: 84.902 | M20: 97.893 | N20: 109.389 | O20: 120.553 | P20: =O20-G33+G32-C20 -> 214.969 | T20: 9 | U20: =D20-C20 -> 10.899 | V20: =E20-D20 -> 8.387 | W20: =F20-E20 -> 8.883 | X20: =G20-F20 -> 7.756 | Y20: =H20-G20 -> 10.043 | Z20: =I20-H20 -> 9.677 | AA20: =J20-I20 -> 5.905 | AB20: =K20-J20 -> 8.633 | ... AF20: =O20-N20 -> 11.164
B21: kalorimetr č. 71182282 | C21: 43.025 | D21: 47.912 | E21: 52.65 | F21: 57.88 | G21: 61.39 | H21: 62.829 | I21: 63.68 | J21: 64.127 | K21: 64.658 | L21: 65.008 | M21: 66.144 | N21: 69.595 | O21: 75.11 | Q21: =O21-C21 -> 32.085
A22: 10 | B22: vodoměr č. 190834129 | C22: 283.974 | D22: 291.963 | E22: 298.702 | F22: 305.034 | G22: 312.139 | H22: 317.95 | I22: 325.397 | J22: 330.702 | K22: 334.849 | L22: 341.33 | M22: 348.843 | N22: 354.589 | O22: 362.081 | P22: =O22-C22 -> 78.107 | T22: 10 | U22: =D22-C22 -> 7.989 | V22: =E22-D22 -> 6.739 | W22: =F22-E22 -> 6.332 | X22: =G22-F22 -> 7.105 | Y22: =H22-G22 -> 5.811 | Z22: =I22-H22 -> 7.447 | AA22: =J22-I22 -> 5.305 | AB22: =K22-J22 -> 4.147 | ... AF22: =O22-N22 -> 7.492
B23: kalorimetr č. 71182240 | C23: 28.409 | D23: 32.184 | E23: 35.319 | F23: 37.557 | G23: 38.88 | H23: 39.45 | I23: 40.041 | J23: 40.418 | K23: 40.755 | L23: 41.29 | M23: 42.303 | N23: 44.606 | O23: 48.123 | Q23: =O23-C23 -> 19.714
P24: =SUM(P4:P23) -> 1050.837 | Q24: =SUM(Q4:Q23) -> 193.896
A25: spol.spotř. | B25: elektroměr č. 2080200097 | C25: 7868 | D25: 8048 | E25: 8224 | F25: 8419 | G25: 8612 | H25: 8787 | I25: 8912 | J25: 9065 | K25: 9241 | L25: 9442 | M25: 9631 | N25: 9880 | O25: 10067 | R25: =O25-C25 -> 2199
B26: patní vodoměr č. 190976792 | C26: 3438.2 | D26: 3533.8 | E26: 3620.3 | F26: 3712.2 | G26: 3799.2 | H26: 3889.2 | I26: 3976.6 | J26: 4041.2 | K26: 4117.6 | L26: 4205.3 | M26: 4303.8 | N26: 4395.4 | O26: 4486.8 | P26: =O26-C26 -> 1048.6
B27: patní kalorimetr č./MWh | C27: 223.61 | D27: 233.37 | E27: 241.66 | F27: 248.74 | G27: 253.76 | H27: 255.48 | I27: 256.61 | J27: 257.22 | K27: 2.45 | L27: 5.95 | M27: 14.29 | N27: 38.04 | O27: 71.6 | Q27: =(J27-C27)*3.6+O27 -> 192.596 | R27: GJ
B28: patní kalorimetr č./kub.m | C28: 8842 | D28: 9058 | E28: 9239 | F28: 9403 | G28: 9510 | H28: 9557 | I28: 9590 | J28: 9610 | K28: 22 | L28: 50 | M28: 107 | N28: 251.3 | O28: 448 | Q28: =J28-C28+O28 -> 1216 | R28: m3
A29: ='1850'!A29 -> fakturační vodoměr č. 63796 | C29: ='1850'!C29 -> 20281.1 | D29: ='1850'!D29 -> 20614.3 | E29: ='1850'!E29 -> 20910.1 | F29: ='1850'!F29 -> 21247.4 | G29: ='1850'!G29 -> 21572.2 | H29: ='1850'!H29 -> 21932.7 | I29: ='1850'!I29 -> 22298.9 | J29: ='1850'!J29 -> 22571.5 | ... O29: ='1850'!O29 -> 24212 | P29: =O29-C29 -> 3930.9
C31: byt | D31: Reklamace - výměna | F31: číslo | G31: stav | I31: Dne 31.7.2023 odpojen kalor. (cejchování), | M31: stav: | N31: 257.22 | O31: MWh
C32: 9 | D32: 43950 | E32: starý | F32: 190834113 | G32: =M20+7.7 -> 105.593 | I32: Dne 3.8.2023 zapojen znovuzapojení, | M32: stav: | N32: 0 | O32: GJ
E33: nový | F33: 221525380 | G33: 0
D35: Výměna elektroměru
D36: 43956 | E36: starý
E37: nový

Sheet 1853
A2: 1853 | C2: ='1850'!C2 -> 44927 | D2: ='1850'!D2 -> 44958 | E2: ='1850'!E2 -> 44986 | F2: ='1850'!F2 -> 45017 | G2: ='1850'!G2 -> 45047 | H2: ='1850'!H2 -> 45078 | I2: ='1850'!I2 -> 45111 | J2: ='1850'!J2 -> 45139 | ... O2: ='1850'!O2 -> 45292 | P2: Voda | Q2: Teplo | R2: Elektr | Y2: spotřeby po měsících
A3: byt č. | C3: prosinec | D3: leden | E3: únor | F3: březen | G3: duben | H3: květen | I3: červen | J3: červenec | K3: srpen | L3: září | M3: říjen | N3: listopad | O3: prosinec | P3: m3 | Q3: GJ | R3: KWh | T3: byt | U3: leden | V3: únor | W3: březen | X3: duben | Y3: květen | Z3: červen | AA3: červenec | AB3: srpen | AC3: září | AD3: říjen | AE3: listopad | AF3: prosinec
A4: 1 | B4: vodoměr č. 190834100 | C4: 530.581 | D4: 543.361 | E4: 554.948 | F4: 568.027 | G4: 580.743 | H4: 594.59 | I4: 606.012 | J4: 615.99 | K4: 628.456 | L4: 640.95 | M4: 654.029 | N4: 667.54 | O4: 681.208 | P4: =O4-C4 -> 150.627 | T4: 1 | U4: =D4-C4 -> 12.78 | V4: =E4-D4 -> 11.587 | W4: =F4-E4 -> 13.079 | X4: =G4-F4 -> 12.716 | Y4: =H4-G4 -> 13.847 | Z4: =I4-H4 -> 11.422 | AA4: =J4-I4 -> 9.978 | AB4: =K4-J4 -> 12.466 | ... AF4: =O4-N4 -> 13.668
B5: kalorimetr č. 71182275 | C5: 37.232 | D5: 40.923 | E5: 44.521 | F5: 47.752 | G5: 49.768 | H5: 50.824 | I5: 51.494 | J5: 51.993 | K5: 52.526 | L5: 53.201 | M5: 54.248 | N5: 57.905 | O5: 63.385 | Q5: =O5-C5 -> 26.153
A6: 2 | B6: vodoměr č. 190906789 | C6: 294.937 | D6: 301.974 | E6: 308.412 | F6: 315.471 | G6: 322.875 | H6: 329.352 | I6: 336.171 | J6: 341.916 | K6: 348.12 | L6: 354.908 | M6: 360.014 | N6: 367.351 | O6: 374.776 | P6: =O6-C6 -> 79.839 | T6: 2 | U6: =D6-C6 -> 7.037 | V6: =E6-D6 -> 6.438 | W6: =F6-E6 -> 7.059 | X6: =G6-F6 -> 7.404 | Y6: =H6-G6 -> 6.477 | Z6: =I6-H6 -> 6.819 | AA6: =J6-I6 -> 5.745 | AB6: =K6-J6 -> 6.204 | ... AF6: =O6-N6 -> 7.425
B7: kalorimetr č. 71182253 | C7: 10.275 | D7: 11.759 | E7: 13.082 | F7: 14.364 | G7: 15.054 | H7: 15.44 | I7: 15.713 | J7: 15.794 | K7: 15.929 | L7: 16.244 | M7: 16.482 | N7: 17.376 | O7: 18.928 | Q7: =O7-C7 -> 8.653
A8: 3 | B8: vodoměr č. 190906786 | C8: 173.735 | D8: 179.219 | E8: 184.563 | F8: 192.12 | G8: 199.422 | H8: 206.158 | I8: 212.291 | J8: 216.667 | K8: 223.934 | L8: 233.278 | M8: 239.747 | N8: 246.5 | O8: 253.555 | P8: =O8-C8 -> 79.82 | T8: 3 | U8: =D8-C8 -> 5.484 | V8: =E8-D8 -> 5.344 | W8: =F8-E8 -> 7.557 | X8: =G8-F8 -> 7.302 | Y8: =H8-G8 -> 6.736 | Z8: =I8-H8 -> 6.133 | AA8: =J8-I8 -> 4.376 | AB8: =K8-J8 -> 7.267 | ... AF8: =O8-N8 -> 7.055
B9: kalorimetr č. 71182217 | C9: 29.607 | D9: 33.265 | E9: 36.443 | F9: 39.077 | G9: 40.847 | H9: 41.252 | I9: 41.536 | J9: 41.72 | K9: 42.002 | L9: 42.496 | M9: 42.965 | N9: 44.461 | O9: 46.913 | Q9: =O9-C9 -> 17.306
A10: 4 | B10: vodoměr č. 190834105 | C10: 194.525 | D10: 198.874 | E10: 202.902 | F10: 208.014 | G10: 212.943 | H10: 216.953 | I10: 220.613 | J10: 224.775 | K10: 229.224 | L10: 234.95 | M10: 239.288 | N10: 243.194 | O10: 248.363 | P10: =O10-C10 -> 53.838 | T10: 4 | U10: =D10-C10 -> 4.349 | V10: =E10-D10 -> 4.028 | W10: =F10-E10 -> 5.112 | X10: =G10-F10 -> 4.929 | Y10: =H10-G10 -> 4.01 | Z10: =I10-H10 -> 3.66 | AA10: =J10-I10 -> 4.162 | AB10: =K10-J10 -> 4.449 | ... AF10: =O10-N10 -> 5.169
B11: kalorimetr č. 71182254 | C11: 12.095 | D11: 13.722 | E11: 15.089 | F11: 15.742 | G11: 16.059 | H11: 16.431 | I11: 16.739 | J11: 16.974 | K11: 17.234 | L11: 17.533 | M11: 17.826 | N11: 19.302 | O11: 20.852 | Q11: =O11-C11 -> 8.757
A12: 5 | B12: vodoměr č. 190906792 | C12: 312.23 | D12: 319.551 | E12: 325.971 | F12: 332.88 | G12: 339.531 | H12: 345.65 | I12: 352.054 | J12: 357.017 | K12: 363.965 | L12: 370.764 | M12: 377.375 | N12: 384.683 | O12: 393.043 | P12: =O12-C12 -> 80.813 | T12: 5 | U12: =D12-C12 -> 7.321 | V12: =E12-D12 -> 6.42 | W12: =F12-E12 -> 6.909 | X12: =G12-F12 -> 6.651 | Y12: =H12-G12 -> 6.119 | Z12: =I12-H12 -> 6.404 | AA12: =J12-I12 -> 4.963 | AB12: =K12-J12 -> 6.948 | ... AF12: =O12-N12 -> 8.36
B13: kalorimetr č. 71182267 | C13: 11.632 | D13: 12.875 | E13: 14.103 | F13: 15.075 | G13: 15.809 | H13: 16.138 | I13: 16.408 | J13: 16.58 | K13: 16.806 | L13: 17.096 | M13: 17.486 | N13: 18.441 | O13: 20.087 | Q13: =O13-C13 -> 8.455
A14: 6 | B14: vodoměr č. 190906795 | C14: 173.968 | D14: 177.84 | E14: 181.193 | F14: 184.947 | G14: 188.91 | H14: 192.232 | I14: 196.207 | J14: 199.334 | K14: 202.346 | L14: 205.48 | M14: 208.456 | N14: 211.813 | O14: 216.426 | P14: =O14-C14 -> 42.458 | T14: 6 | U14: =D14-C14 -> 3.872 | V14: =E14-D14 -> 3.353 | W14: =F14-E14 -> 3.754 | X14: =G14-F14 -> 3.963 | Y14: =H14-G14 -> 3.322 | Z14: =I14-H14 -> 3.975 | AA14: =J14-I14 -> 3.127 | AB14: =K14-J14 -> 3.012 | ... AF14: =O14-N14 -> 4.613
B15: kalorimetr č. 71182261 | C15: 17.234 | D15: 20.031 | E15: 22.084 | F15: 23.565 | G15: 24.416 | H15: 24.572 | I15: 24.737 | J15: 24.837 | K15: 24.933 | L15: 25.035 | M15: 25.216 | N15: 26.633 | O15: 29.189 | Q15: =O15-C15 -> 11.955
A16: 7 | B16: vodoměr č. 190834103 | C16: 419.101 | D16: 429.41 | E16: 436.866 | F16: 448.264 | G16: 459.318 | H16: 469.65 | I16: 479.587 | J16: 484.175 | K16: 493.68 | L16: 505.065 | M16: 516.397 | N16: 528.633 | O16: 542.297 | P16: =O16-C16 -> 123.196 | T16: 7 | U16: =D16-C16 -> 10.309 | V16: =E16-D16 -> 7.456 | W16: =F16-E16 -> 11.398 | X16: =G16-F16 -> 11.054 | Y16: =H16-G16 -> 10.332 | Z16: =I16-H16 -> 9.937 | AA16: =J16-I16 -> 4.588 | AB16: =K16-J16 -> 9.505 | ... AF16: =O16-N16 -> 13.664
B17: kalorimetr č. 71182272 | C17: 33.724 | D17: 38.151 | E17: 40.765 | F17: 43.458 | G17: 45.473 | H17: 46.321 | I17: 47.04 | J17: 47.373 | K17: 47.93 | L17: 48.652 | M17: 49.687 | N17: 52.363 | O17: 56.159 | Q17: =O17-C17 -> 22.435
A18: 8 | B18: vodoměr č. 190834101 | C18: 260.688 | D18: 267.576 | E18: 274.438 | F18: 280.899 | G18: 287.319 | H18: 293.572 | I18: 300.062 | J18: 305.952 | K18: 310.06 | L18: 317.012 | M18: 325.398 | N18: 333.205 | O18: 341.374 | P18: =O18-C18 -> 80.686 | T18: 8 | U18: =D18-C18 -> 6.888 | V18: =E18-D18 -> 6.862 | W18: =F18-E18 -> 6.461 | X18: =G18-F18 -> 6.42 | Y18: =H18-G18 -> 6.253 | Z18: =I18-H18 -> 6.49 | AA18: =J18-I18 -> 5.89 | AB18: =K18-J18 -> 4.108 | ... AF18: =O18-N18 -> 8.169
B19: kalorimetr č. 71182249 | C19: 23.2 | D19: 26.714 | E19: 29.3 | F19: 31.325 | G19: 32.428 | H19: 32.79 | I19: 33.123 | J19: 33.303 | K19: 33.449 | L19: 33.734 | M19: 34.252 | N19: 36.632 | O19: 40.132 | Q19: =O19-C19 -> 16.932
A20: 9 | B20: vodoměr č. 190834108 | C20: 147.58 | D20: 150.967 | E20: 154.012 | F20: 157.629 | G20: 160.944 | H20: 164.139 | I20: 167.784 | J20: 170.953 | K20: 174.339 | L20: 177.764 | M20: 181.24 | N20: 185.073 | O20: 188.598 | P20: =O20-C20 -> 41.018 | T20: 9 | U20: =D20-C20 -> 3.387 | V20: =E20-D20 -> 3.045 | W20: =F20-E20 -> 3.617 | X20: =G20-F20 -> 3.315 | Y20: =H20-G20 -> 3.195 | Z20: =I20-H20 -> 3.645 | AA20: =J20-I20 -> 3.169 | AB20: =K20-J20 -> 3.386 | ... AF20: =O20-N20 -> 3.525
B21: kalorimetr č. 71182281 | C21: 26.124 | D21: 30.017 | E21: 33.388 | F21: 35.976 | G21: 37.541 | H21: 37.852 | I21: 38.146 | J21: 38.359 | K21: 38.585 | L21: 38.857 | M21: 39.525 | N21: 42.404 | O21: 46.407 | Q21: =O21-C21 -> 20.283
A22: 10 | B22: vodoměr č. 190906953 | C22: 162.723 | D22: 165.06 | E22: 167.314 | F22: 169.67 | G22: 172.77 | H22: 174.863 | I22: 176.935 | J22: 178.68 | K22: 181.131 | L22: 183.448 | M22: 186.465 | N22: 188.782 | O22: 191.288 | P22: =O22-C22 -> 28.565 | T22: 10 | U22: =D22-C22 -> 2.337 | V22: =E22-D22 -> 2.254 | W22: =F22-E22 -> 2.356 | X22: =G22-F22 -> 3.1 | Y22: =H22-G22 -> 2.093 | Z22: =I22-H22 -> 2.072 | AA22: =J22-I22 -> 1.745 | AB22: =K22-J22 -> 2.451 | ... AF22: =O22-N22 -> 2.506
B23: kalorimetr č. 71182268 | C23: 27.286 | D23: 31.123 | E23: 34.362 | F23: 37.085 | G23: 38.952 | H23: 39.215 | I23: 39.327 | J23: 39.383 | K23: 39.494 | L23: 39.644 | M23: 40.382 | N23: 42.972 | O23: 46.521 | Q23: =O23-C23 -> 19.235
B24: elektroměr č.2080200105 dům | C24: 6338 | D24: 6536 | E24: 6700 | F24: 6880 | G24: 7051 | H24: 7225 | I24: 7424 | J24: 7593 | K24: 7768 | L24: 7963 | M24: 8136 | N24: 8313 | O24: 8503 | P24: =SUM(P4:P23) -> 760.86 | Q24: =SUM(Q4:Q23) -> 160.164 | R24: =O24-C24 -> 2165
A25: spol.spotř. | B25: elektroměr č. 2080200100 VO | C25: 10842 | D25: 11278 | E25: 11637 | F25: 11986 | G25: 12280 | H25: 12516 | I25: 12737 | J25: 12928 | K25: 13161 | L25: 13399 | M25: 13683 | N25: 14065 | O25: 14439 | R25: =O25-C25 -> 3597 | T25: Zahrada | U25: =D26-C26 -> 0 | V25: =E26-D26 -> 0 | W25: =F26-E26 -> 0 | X25: =G26-F26 -> 0 | Y25: =H26-G26 -> 26.126 | Z25: =I26-H26 -> 30.185 | AA25: =J26-I26 -> 30.597 | AB25: =K26-J26 -> 23.987 | ... AF25: =O26-N26 -> 0
B26: vodoměr areál č.200076532 | C26: 416.747 | D26: 416.747 | E26: 416.747 | F26: 416.747 | G26: 416.747 | H26: 442.873 | I26: 473.058 | J26: 503.655 | K26: 527.642 | L26: 542.56 | M26: 547.48 | N26: 547.775 | O26: 547.775 | P26: =O26-C26 -> 131.028 | Q26: =ROUND(P26,0) -> 131 | R26: zahrada
B27: patní vodoměr č. 190976789 | C27: 3297.6 | D27: 3367.6 | E27: 3429.9 | F27: 3503.7 | G27: 3577.7 | H27: 3685.2 | I27: 3793.1 | J27: 3876.8 | K27: 3966.9 | L27: 4057 | M27: 4133.6 | N27: 4209 | O27: 4291.1 | P27: =O27-C27 -> 993.5 | Q27: =P27-Q26 -> 862.5 | R27: byty | U27: =(D27-C27)-(D26-C26) -> 70 | V27: =(E27-D27)-(E26-D26) -> 62.3 | W27: =(F27-E27)-(F26-E26) -> 73.8 | X27: =(G27-F27)-(G26-F26) -> 74 | Y27: =(H27-G27)-(H26-G26) -> 81.374 | Z27: =(I27-H27)-(I26-H26) -> 77.715 | AA27: =(J27-I27)-(J26-I26) -> 53.103 | AB27: =(K27-J27)-(K26-J26) -> 66.113 | ... AF27: =(O27-N27)-(O26-N26) -> 82.1
B28: patní kalorimetr č./ MWh | C28: 206.92 | D28: 215.75 | E28: 222.98 | F28: 228.9 | G28: 232.63 | H28: 233.67 | I28: 234.42 | J28: 234.86 | K28: 2.08 | L28: 5 | M28: 10.31 | N28: 31.97 | O28: 63.56 | Q28: =(J28-C28)*3.6+O28 -> 164.144 | R28: GJ | U28: =(D28-C28)*3.6 -> 31.788 | V28: =(E28-D28)*3.6 -> 26.028 | W28: =(F28-E28)*3.6 -> 21.312 | X28: =(G28-F28)*3.6 -> 13.428 | Y28: =(H28-G28)*3.6 -> 3.744 | Z28: =(I28-H28)*3.6 -> 2.7 | AA28: =(J28-I28)*3.6 -> 1.584 | AB28: =K28 -> 2.08 | AC28: =(L28-K28) -> 2.92 | AD28: =(M28-L28) -> 5.31 | AE28: =(N28-M28) -> 21.66 | AF28: =(O28-N28) -> 31.59
B29: patní kalorimetr č. /kub.m | C29: 13450 | D29: 13643 | E29: 13805 | F29: 13939 | G29: 14029 | H29: 14058 | I29: 14081 | J29: 14096 | K29: 18 | L29: 43 | M29: 85 | N29: 234 | O29: 442 | Q29: =J29-C29+O29 -> 1088 | R29: m3
A30: ='1850'!A29 -> fakturační vodoměr č. 63796 | C30: ='1850'!C29 -> 20281.1 | D30: ='1850'!D29 -> 20614.3 | E30: ='1850'!E29 -> 20910.1 | F30: ='1850'!F29 -> 21247.4 | G30: ='1850'!G29 -> 21572.2 | H30: ='1850'!H29 -> 21932.7 | I30: ='1850'!I29 -> 22298.9 | J30: ='1850'!J29 -> 22571.5 | ... O30: ='1850'!O29 -> 24212 | P30: =O30-C30 -> 3930.9
A32: 11 | B32: vodoměr SV č. 11717149 | C32: 13.972 | D32: 14.365 | E32: 14.652 | F32: 15.053 | G32: 15.413 | H32: 15.755 | I32: 16.373 | J32: 16.628 | K32: 16.891 | L32: 17.215 | M32: 17.571 | N32: 17.962 | O32: 18.236 | P32: =O32-C32 -> 4.264 | S32: SV | T32: 11 | U32: =D32-C32 -> 0.393 | V32: =E32-D32 -> 0.287 | W32: =F32-E32 -> 0.401 | X32: =G32-F32 -> 0.36 | Y32: =H32-G32 -> 0.342 | Z32: =I32-H32 -> 0.618 | AA32: =J32-I32 -> 0.255 | AB32: =K32-J32 -> 0.263 | ... AF32: =O32-N32 -> 0.274
B33: vodoměr TV č. 11683196 | C33: 0.76 | D33: 0.767 | E33: 0.767 | F33: 0.776 | G33: 0.779 | H33: 0.781 | I33: 0.825 | J33: 0.84 | K33: 0.847 | L33: 0.855 | M33: 0.861 | N33: 0.865 | O33: 0.871 | P33: =O33-C33 -> 0.111 | S33: TV | U33: =D33-C33 -> 0.007 | V33: =E33-D33 -> 0 | W33: =F33-E33 -> 0.009 | X33: =G33-F33 -> 0.003 | Y33: =H33-G33 -> 0.002 | Z33: =I33-H33 -> 0.044 | AA33: =J33-I33 -> 0.015 | AB33: =K33-J33 -> 0.007 | ... AF33: =O33-N33 -> 0.006
D35: Výměna elektroměru DŮM
D36: 43956 | E36: starý | O36: spotřeba SV byt č.3 pro vyúčt. | P36: =P8-P32-P33 -> 75.445
E37: nový | O37: spotřeba SV sklad č.11 pro vyúčt. | P37: =P32+P33 -> 4.375
D38: Výměna elektroměru AREÁL | O38: CELKEM : | P38: =SUM(P36:P37) -> 79.82
D39: 43956 | E39: starý
E40: nový | J40: Dne 31.7.2023 odpojen kalor. (cejchování), | N40: stav: | O40: 234.86 | P40: MWh
J41: Dne 3.8.2023 zapojen znovuzapojení, | N41: stav: | O41: 0 | P41: GJ

Sheet 1854
A2: 1854 | C2: ='1850'!C2 -> 44927 | D2: ='1850'!D2 -> 44958 | E2: ='1850'!E2 -> 44986 | F2: ='1850'!F2 -> 45017 | G2: ='1850'!G2 -> 45047 | H2: ='1850'!H2 -> 45078 | I2: ='1850'!I2 -> 45111 | J2: ='1850'!J2 -> 45139 | ... O2: ='1850'!O2 -> 45292 | P2: voda | Q2: teplo | R2: Elektr | Y2: spotřeby po měsících
A3: byt č. | C3: prosinec | D3: leden | E3: únor | F3: březen | G3: duben | H3: květen | I3: červen | J3: červenec | K3: srpen | L3: září | M3: říjen | N3: listopad | O3: prosinec | P3: m3 | Q3: GJ | R3: KWh | T3: byt | U3: leden | V3: únor | W3: březen | X3: duben | Y3: květen | Z3: červen | AA3: červenec | AB3: srpen | AC3: září | AD3: říjen | AE3: listopad | AF3: prosinec
A4: 1 | B4: vodoměr č. 190906992 | C4: 270.752 | D4: 278.305 | E4: 283.338 | F4: 290.447 | G4: 296.596 | H4: 303.235 | I4: 309.789 | J4: 313.446 | K4: 317.062 | L4: 319.255 | M4: 321.227 | N4: 323.153 | O4: 325.996 | P4: =O4-C4 -> 55.244 | T4: 1 | U4: =D4-C4 -> 7.553 | V4: =E4-D4 -> 5.033 | W4: =F4-E4 -> 7.109 | X4: =G4-F4 -> 6.149 | Y4: =H4-G4 -> 6.639 | Z4: =I4-H4 -> 6.554 | AA4: =J4-I4 -> 3.657 | AB4: =K4-J4 -> 3.616 | ... AF4: =O4-N4 -> 2.843
B5: kalorimetr č. 71182259 | C5: 29.809 | D5: 33.751 | E5: 37.203 | F5: 40.165 | G5: 42.253 | H5: 42.913 | I5: 43.321 | J5: 43.532 | K5: 43.748 | L5: 43.943 | M5: 44.615 | N5: 46.909 | O5: 50.515 | Q5: =O5-C5 -> 20.706
A6: 2 | B6: vodoměr č. 190906991 | C6: 199.445 | D6: 204.188 | E6: 209.848 | F6: 216.105 | G6: 222.373 | H6: 227.656 | I6: 234.185 | J6: 238.313 | K6: 244.128 | L6: 251.386 | M6: 256.546 | N6: 262.203 | O6: 266.566 | P6: =O6-C6 -> 67.121 | T6: 2 | U6: =D6-C6 -> 4.743 | V6: =E6-D6 -> 5.66 | W6: =F6-E6 -> 6.257 | X6: =G6-F6 -> 6.268 | Y6: =H6-G6 -> 5.283 | Z6: =I6-H6 -> 6.529 | AA6: =J6-I6 -> 4.128 | AB6: =K6-J6 -> 5.815 | ... AF6: =O6-N6 -> 4.363
B7: kalorimetr č. 71182248 | C7: 40.553 | D7: 45.848 | E7: 51.463 | F7: 55.967 | G7: 59.522 | H7: 60.911 | I7: 61.493 | J7: 61.797 | K7: 62.181 | L7: 62.702 | M7: 63.262 | N7: 67.246 | O7: 72.397 | Q7: =O7-C7 -> 31.844
A8: 3 | B8: vodoměr č. 190906988 | C8: 275.92 | D8: 282.712 | E8: 288.282 | F8: 294.847 | G8: 301.104 | H8: 307.803 | I8: 314.809 | J8: 320.301 | K8: 327.097 | L8: 333.76 | M8: 339.021 | N8: 344.044 | O8: 349.848 | P8: =O8-C8 -> 73.928 | T8: 3 | U8: =D8-C8 -> 6.792 | V8: =E8-D8 -> 5.57 | W8: =F8-E8 -> 6.565 | X8: =G8-F8 -> 6.257 | Y8: =H8-G8 -> 6.699 | Z8: =I8-H8 -> 7.006 | AA8: =J8-I8 -> 5.492 | AB8: =K8-J8 -> 6.796 | ... AF8: =O8-N8 -> 5.804
B9: kalorimetr č. 71182258 | C9: 43.799 | D9: 49.289 | E9: 54.771 | F9: 59.895 | G9: 63.749 | H9: 65.305 | I9: 65.644 | J9: 65.885 | K9: 66.148 | L9: 66.435 | M9: 68.755 | N9: 74.075 | O9: 80.77 | Q9: =O9-C9 -> 36.971
A10: 4 | B10: vodoměr č. 190906987 | C10: 233.497 | D10: 243.261 | E10: 252.467 | F10: 261.735 | G10: 269.633 | H10: 276.626 | I10: 287.023 | J10: 294.858 | K10: 301.923 | L10: 309.718 | M10: 316.417 | N10: 324.407 | O10: 331.89 | P10: =O10-C10 -> 98.393 | T10: 4 | U10: =D10-C10 -> 9.764 | V10: =E10-D10 -> 9.206 | W10: =F10-E10 -> 9.268 | X10: =G10-F10 -> 7.898 | Y10: =H10-G10 -> 6.993 | Z10: =I10-H10 -> 10.397 | AA10: =J10-I10 -> 7.835 | AB10: =K10-J10 -> 7.065 | ... AF10: =O10-N10 -> 7.483
B11: kalorimetr č. 71182242 | C11: 15.755 | D11: 17.058 | E11: 18.029 | F11: 18.997 | G11: 19.642 | H11: 20.116 | I11: 20.636 | J11: 20.99 | K11: 21.357 | L11: 21.757 | M11: 22.154 | N11: 23.301 | O11: 24.163 | Q11: =O11-C11 -> 8.408
A12: 5 | B12: vodoměr č. 221525395 | C12: 0.111 | D12: 0.139 | E12: 0.165 | F12: 0.269 | G12: 0.29 | H12: 0.308 | I12: 0.355 | J12: 0.391 | K12: 0.436 | L12: 0.511 | M12: 0.551 | N12: 0.612 | O12: 0.643 | P12: =O12-G40+G39-C12 -> 1.114 | T12: 5 | U12: =D12-C12 -> 0.028 | V12: =E12-D12 -> 0.026 | W12: =F12-E12 -> 0.104 | X12: =G12-F12 -> 0.021 | Y12: =H12-G12 -> 0.018 | Z12: =I12-H12 -> 0.047 | AA12: =J12-I12 -> 0.036 | AB12: =K12-J12 -> 0.045 | ... AF12: =O12-N12 -> 0.031
B13: kalorimetr č. 71182255 | C13: 4.916 | D13: 6.314 | E13: 6.66 | F13: 6.705 | G13: 6.706 | H13: 6.706 | I13: 6.706 | J13: 6.707 | K13: 6.707 | L13: 6.707 | M13: 6.708 | N13: 6.71 | O13: 6.71 | Q13: =O13-C13 -> 1.794
A14: 6 | B14: vodoměr č. 190906994 | C14: 323.594 | D14: 333.255 | E14: 341.204 | F14: 349.128 | G14: 356.456 | H14: 366.009 | I14: 375.727 | J14: 382.63 | K14: 390.761 | L14: 400.143 | M14: 406.732 | N14: 416.292 | O14: 424.951 | P14: =O14-C14 -> 101.357 | T14: 6 | U14: =D14-C14 -> 9.661 | V14: =E14-D14 -> 7.949 | W14: =F14-E14 -> 7.924 | X14: =G14-F14 -> 7.328 | Y14: =H14-G14 -> 9.553 | Z14: =I14-H14 -> 9.718 | AA14: =J14-I14 -> 6.903 | AB14: =K14-J14 -> 8.131 | ... AF14: =O14-N14 -> 8.659
B15: kalorimetr č. 71182230 | C15: 12.884 | D15: 14.549 | E15: 15.492 | F15: 16.139 | G15: 16.617 | H15: 17.242 | I15: 17.776 | J15: 18.102 | K15: 18.456 | L15: 18.905 | M15: 19.262 | N15: 20.303 | O15: 21.9 | Q15: =O15-C15 -> 9.016
A16: 7 | B16: vodoměr č. 190906986 | C16: 124.062 | D16: 125.406 | E16: 127.037 | F16: 128.54 | G16: 129.638 | H16: 131.048 | I16: 132.592 | J16: 133.504 | K16: 134.512 | L16: 136.533 | M16: 137.857 | N16: 139.951 | O16: 141.492 | P16: =O16-C16 -> 17.43 | T16: 7 | U16: =D16-C16 -> 1.344 | V16: =E16-D16 -> 1.631 | W16: =F16-E16 -> 1.503 | X16: =G16-F16 -> 1.098 | Y16: =H16-G16 -> 1.41 | Z16: =I16-H16 -> 1.544 | AA16: =J16-I16 -> 0.912 | AB16: =K16-J16 -> 1.008 | ... AF16: =O16-N16 -> 1.541
B17: kalorimetr č. 71182247 | C17: 9.096 | D17: 10.365 | E17: 11.266 | F17: 11.846 | G17: 12.12 | H17: 12.426 | I17: 12.723 | J17: 12.918 | K17: 13.141 | L17: 13.456 | M17: 13.726 | N17: 14.37 | O17: 15.669 | Q17: =O17-C17 -> 6.573
A18: 8 | B18: vodoměr č. 191519281 | C18: 249.7 | D18: 255.868 | E18: 261.453 | F18: 268.358 | G18: 275.02 | H18: 280.983 | I18: 288.665 | J18: 294.111 | K18: 300.507 | L18: 306.237 | M18: 311.67 | N18: 317.074 | O18: 322.8 | P18: =O18-C18 -> 73.1 | T18: 8 | U18: =D18-C18 -> 6.168 | V18: =E18-D18 -> 5.585 | W18: =F18-E18 -> 6.905 | X18: =G18-F18 -> 6.662 | Y18: =H18-G18 -> 5.963 | Z18: =I18-H18 -> 7.682 | AA18: =J18-I18 -> 5.446 | AB18: =K18-J18 -> 6.396 | ... AF18: =O18-N18 -> 5.726
B19: kalorimetr č. 71182232 | C19: 34.484 | D19: 38.239 | E19: 41.836 | F19: 44.737 | G19: 46.825 | H19: 47.128 | I19: 47.396 | J19: 47.562 | K19: 47.723 | L19: 47.938 | M19: 48.194 | N19: 52.281 | O19: 57.194 | Q19: =O19-C19 -> 22.71
A20: 9 | B20: vodoměr č. 190906990 | C20: 473.534 | D20: 485.899 | E20: 496.218 | F20: 505.659 | G20: 516.333 | H20: 527.759 | I20: 539.858 | J20: 549.606 | K20: 557.562 | L20: 570.519 | M20: 580.265 | N20: 591.273 | O20: 602.928 | P20: =O20-C20 -> 129.394 | T20: 9 | U20: =D20-C20 -> 12.365 | V20: =E20-D20 -> 10.319 | W20: =F20-E20 -> 9.441 | X20: =G20-F20 -> 10.674 | Y20: =H20-G20 -> 11.426 | Z20: =I20-H20 -> 12.099 | AA20: =J20-I20 -> 9.748 | AB20: =K20-J20 -> 7.956 | ... AF20: =O20-N20 -> 11.655
B21: kalorimetr č. 71182228 | C21: 40.387 | D21: 46.075 | E21: 51.33 | F21: 55.986 | G21: 59.17 | H21: 59.911 | I21: 60.455 | J21: 60.834 | K21: 61.184 | L21: 61.699 | M21: 62.704 | N21: 66.317 | O21: 71.245 | Q21: =O21-C21 -> 30.858
A22: 10 | B22: vodoměr č. 190906995 | C22: 0.337 | D22: 0.337 | E22: 0.338 | F22: 0.338 | G22: 0.338 | H22: 0.366 | I22: 0.366 | J22: 0.366 | K22: 0.37 | L22: 0.379 | M22: 0.379 | N22: 0.379 | O22: 0.382 | P22: =O22-C22 -> 0.045 | T22: 10 | U22: =D22-C22 -> 0 | V22: =E22-D22 -> 0.001 | W22: =F22-E22 -> 0 | X22: =G22-F22 -> 0 | Y22: =H22-G22 -> 0.028 | Z22: =I22-H22 -> 0 | AA22: =J22-I22 -> 0 | AB22: =K22-J22 -> 0.004 | ... AF22: =O22-N22 -> 0.003
B23: kalorimetr č. 71182263 | C23: 0.092 | D23: 0.098 | E23: 0.106 | F23: 0.118 | G23: 0.128 | H23: 0.134 | I23: 0.134 | J23: 0.134 | K23: 0.134 | L23: 0.134 | M23: 0.135 | N23: 0.136 | O23: 0.136 | Q23: =O23-C23 -> 0.044
P24: =SUM(P4:P23) -> 617.126 | Q24: =SUM(Q4:Q23) -> 168.924
A25: spol.spotř. | B25: elektroměr č. 72370871 | C25: 55126 | D25: 55322 | E25: 55483 | F25: 55684 | G25: 55858 | H25: 56046 | I25: 56244 | J25: 56411 | K25: 56593 | L25: 56784 | M25: 56963 | N25: 57140 | O25: 57342 | R25: =O25-C25 -> 2216
B26: patní vodoměr č. 190976793 | C26: 2361.6 | D26: 2425.8 | E26: 2482.3 | F26: 2543 | G26: 2600.8 | H26: 2659.8 | I26: 2728 | J26: 2776.8 | K26: 2828.8 | L26: 2888.5 | M26: 2934.7 | N26: 2989.1 | O26: 3042.4 | P26: =O26-C26 -> 680.8
B27: patní kalorimetr č. 70465263/ GJ | C27: 496.85 | D27: 528.99 | E27: 557.62 | F27: 581.44 | G27: 598.36 | H27: 604.71 | I27: 608.94 | J27: 611.72 | K27: 614.36 | L27: 617.63 | M27: 624.5 | N27: 647.15 | O27: 678.51 | Q27: =O27-C27 -> 181.66 | R27: GJ
B28: patní kalorimetr č. / kub.m | C28: 4150 | D28: 4354 | E28: 4544 | F28: 4698 | G28: 4812 | H28: 4877 | I28: 4935 | J28: 4976 | K28: 5015 | L28: 5058 | M28: 5119 | N28: 5275 | O28: 5485 | Q28: =O28-C28 -> 1335 | R28: m3
A29: Fakturační vodoměr: 42012114941 | C29: 7844.6 | D29: 8132 | E29: 8376.4 | F29: 8650.8 | G29: 8921.7 | H29: 9183.8 | I29: 9471 | J29: 9681.6 | K29: 9925.8 | L29: 10213.6 | M29: 10486.5 | N29: 10767.6 | O29: 11067 | P29: =O29-C29 -> 3222.4
E32: Výměna kalorimetru pata | H32: MWh | I32: m3 | K32: Výměna faktur.vodoměru výr.č. | N32: m3
D33: demontáž | E33: 43984 | F33: starý | K33: 44095 | L33: starý
G34: výr.č. | H34: GJ | I34: m3 | M34: výr.č. | N34: m3
D35: montáž | E35: 43986 | F35: nový | K35: 44095 | L35: nový
C38: byt | D38: Reklamace - výměna | F38: číslo | G38: stav | N38: Odečet vodárny 31.12.2022 | O38: 7844
C39: 5 | D39: 43950 | E39: starý | F39: 190907002 | G39: 0.602
E40: nový | F40: 221525395 | G40: 0.02 | N40: Odečet vodárny 31.12.2023 | O40: 11067
N42: spotřeba | O42: =O40-O38-O39 -> 3223

Sheet 1855
