Workbook

Sheet Byty odkazy
A1: byt č. | B1: 1850 | C1: SN | D1: datum | E1: Stav
A2: 1 | B2: vodoměr č. | C2: ='1850'!C4 -> 241345698 | D2: ='1850'!P2 -> 0 | E2: ='1850'!P4 -> 0
B3: kalorimetr č. | C3: ='1850'!C5 -> 71182278 | D3: =D2 -> 0 | E3: ='1850'!P5 -> 0
A4: 2 | B4: vodoměr č. | C4: ='1850'!C6 -> 241345701 | D4: =D3 -> 0 | E4: ='1850'!P6 -> 0
B5: kalorimetr č. | C5: ='1850'!C7 -> 71182225 | D5: =D4 -> 0 | E5: ='1850'!P7 -> 0
A6: 3 | B6: vodoměr č. | C6: ='1850'!C8 -> 241345691 | D6: =D5 -> 0 | E6: ='1850'!P8 -> 0
B7: kalorimetr č. | C7: ='1850'!C9 -> 71182284 | D7: =D6 -> 0 | E7: ='1850'!P9 -> 0
A8: 4 | B8: vodoměr č. | C8: ='1850'!C10 -> 241345696 | D8: =D7 -> 0 | E8: ='1850'!P10 -> 0
B9: kalorimetr č. | C9: ='1850'!C11 -> 71182235 | D9: =D8 -> 0 | E9: ='1850'!P11 -> 0
A10: 5 | B10: vodoměr č. | C10: ='1850'!C12 -> 241345690 | D10: =D9 -> 0 | E10: ='1850'!P12 -> 0
B11: kalorimetr č. | C11: ='1850'!C13 -> 71182238 | D11: =D10 -> 0 | E11: ='1850'!P13 -> 0
A12: 6 | B12: vodoměr č. | C12: ='1850'!C14 -> 241345700 | D12: =D11 -> 0 | E12: ='1850'!P14 -> 0
B13: kalorimetr č. | C13: ='1850'!C15 -> 71182269 | D13: =D12 -> 0 | E13: ='1850'!P15 -> 0
A14: 7 | B14: vodoměr č. | C14: ='1850'!C16 -> 241345702 | D14: =D13 -> 0 | E14: ='1850'!P16 -> 0
B15: kalorimetr č. | C15: ='1850'!C17 -> 71182265 | D15: =D14 -> 0 | E15: ='1850'!P17 -> 0
A16: 8 | B16: vodoměr č. | C16: ='1850'!C18 -> 241345699 | D16: =D15 -> 0 | E16: ='1850'!P18 -> 0
B17: kalorimetr č. | C17: ='1850'!C19 -> 71182245 | D17: =D16 -> 0 | E17: ='1850'!P19 -> 0
A18: 9 | B18: vodoměr č. | C18: ='1850'!C20 -> 241345692 | D18: =D17 -> 0 | E18: ='1850'!P20 -> 0
B19: kalorimetr č. | C19: ='1850'!C21 -> 71182280 | D19: =D18 -> 0 | E19: ='1850'!P21 -> 0
A20: 10 | B20: vodoměr č. | C20: ='1850'!C22 -> 241345695 | D20: =D19 -> 0 | E20: ='1850'!P22 -> 0
B21: kalorimetr č. | C21: ='1850'!C23 -> 71182243 | D21: =D20 -> 0 | E21: ='1850'!P23 -> 0
A23: byt č. | B23: 1851 | C23: SN | D23: datum | E23: Stav
A24: 1 | B24: vodoměr č. | C24: ='1851'!D4 -> 241010644 | D24: =D2 -> 0 | E24: ='1851'!Q4 -> 0
B25: kalorimetr č. | C25: ='1851'!D5 -> 71182262 | D25: =D24 -> 0 | E25: ='1851'!Q5 -> 0
A26: 2 | B26: vodoměr č. | C26: ='1851'!D6 -> 241010636 | D26: =D25 -> 0 | E26: ='1851'!Q6 -> 0
A27: 2 a 3 | B27: kalorimetr č. | C27: ='1851'!D7 -> 71182271 | D27: =D26 -> 0 | E27: ='1851'!Q7 -> 0
A28: 5 | B28: vodoměr č. | C28: ='1851'!D8 -> 241010648 | D28: =D27 -> 0 | E28: ='1851'!Q8 -> 0
A29: 5 a 6 | B29: kalorimetr č. | C29: ='1851'!D9 -> 71182241 | D29: =D28 -> 0 | E29: ='1851'!Q9 -> 0
A30: 4 | B30: vodoměr č. | C30: ='1851'!D10 -> 241010642 | D30: =D29 -> 0 | E30: ='1851'!Q10 -> 0
B31: kalorimetr č. | C31: ='1851'!D11 -> 71182237 | D31: =D30 -> 0 | E31: ='1851'!Q11 -> 0
A32: 9 | B32: vodoměr č. | C32: ='1851'!D12 -> 241010637 | D32: =D31 -> 0 | E32: ='1851'!Q12 -> 0
A33: 8 a 9 | B33: kalorimetr č. | C33: ='1851'!D13 -> 71182221 | D33: =D32 -> 0 | E33: ='1851'!Q13 -> 0
A34: 15 | B34: vodoměr č. | C34: ='1851'!D14 -> 241010633 | D34: =D33 -> 0 | E34: ='1851'!Q14 -> 0
A35: 11 a 15 | B35: kalorimetr č. | C35: ='1851'!D15 -> 71182276 | D35: =D34 -> 0 | E35: ='1851'!Q15 -> 0
A36: 7 | B36: vodoměr č. | C36: ='1851'!D16 -> 241010643 | D36: =D35 -> 0 | E36: ='1851'!Q16 -> 0
B37: kalorimetr č. | C37: ='1851'!D17 -> 71182256 | D37: =D36 -> 0 | E37: ='1851'!Q17 -> 0
A38: 13 | B38: vodoměr č. | C38: ='1851'!D18 -> 241010631 | D38: =D37 -> 0 | E38: ='1851'!Q18 -> 0
A39: 12 a 13 | B39: kalorimetr č. | C39: ='1851'!D19 -> 71182279 | D39: =D38 -> 0 | E39: ='1851'!Q19 -> 0
A40: 14 | B40: vodoměr č. | C40: ='1851'!D20 -> 241010632 | D40: =D39 -> 0 | E40: ='1851'!Q20 -> 0
B41: kalorimetr č. | C41: ='1851'!D21 -> 71182252 | D41: =D40 -> 0 | E41: ='1851'!Q21 -> 0
...

Sheet Byty hodnoty
A1: byt č. | B1: 1850 | C1: SN | D1: datum | E1: Stav
A2: 1 | B2: vodoměr č. | C2: 241345698 | D2: 46022 | E2: 131.765
B3: kalorimetr č. | C3: 71182278 | D3: 46022 | E3: 88.237
A4: 2 | B4: vodoměr č. | C4: 241345701 | D4: 46022 | E4: 209.272
B5: kalorimetr č. | C5: 71182225 | D5: 46022 | E5: 116.53
A6: 3 | B6: vodoměr č. | C6: 241345691 | D6: 46022 | E6: 70.033
B7: kalorimetr č. | C7: 71182284 | D7: 46022 | E7: 79.838
A8: 4 | B8: vodoměr č. | C8: 241345696 | D8: 46022 | E8: 125.385
B9: kalorimetr č. | C9: 71182235 | D9: 46022 | E9: 54.863
A10: 5 | B10: vodoměr č. | C10: 241345690 | D10: 46022 | E10: 118.4
B11: kalorimetr č. | C11: 71182238 | D11: 46022 | E11: 78.234
A12: 6 | B12: vodoměr č. | C12: 241345700 | D12: 46022 | E12: 70.558
B13: kalorimetr č. | C13: 71182269 | D13: 46022 | E13: 116.546
A14: 7 | B14: vodoměr č. | C14: 241345702 | D14: 46022 | E14: 47.513
B15: kalorimetr č. | C15: 71182265 | D15: 46022 | E15: 26.122
A16: 8 | B16: vodoměr č. | C16: 241345699 | D16: 46022 | E16: 9.297
B17: kalorimetr č. | C17: 71182245 | D17: 46022 | E17: 77.412
A18: 9 | B18: vodoměr č. | C18: 241345692 | D18: 46022 | E18: 15.707
B19: kalorimetr č. | C19: 71182280 | D19: 46022 | E19: 18.462
A20: 10 | B20: vodoměr č. | C20: 241345695 | D20: 46022 | E20: 114.433
B21: kalorimetr č. | C21: 71182243 | D21: 46022 | E21: 95.253
A23: byt č. | B23: 1851 | C23: SN | D23: datum | E23: Stav
A24: 1 | B24: vodoměr č. | C24: 241010644 | D24: 46022 | E24: 199.73
B25: kalorimetr č. | C25: 71182262 | D25: 46022 | E25: 122.956
A26: 2 | B26: vodoměr č. | C26: 241010636 | D26: 46022 | E26: 90.242
A27: 2 a 3 | B27: kalorimetr č. | C27: 71182271 | D27: 46022 | E27: 148.721
A28: 5 | B28: vodoměr č. | C28: 241010648 | D28: 46022 | E28: 17.065
A29: 5 a 6 | B29: kalorimetr č. | C29: 71182241 | D29: 46022 | E29: 144.359
A30: 4 | B30: vodoměr č. | C30: 241010642 | D30: 46022 | E30: 104.28
B31: kalorimetr č. | C31: 71182237 | D31: 46022 | E31: 30.653
A32: 9 | B32: vodoměr č. | C32: 241010637 | D32: 46022 | E32: 1.588
A33: 8 a 9 | B33: kalorimetr č. | C33: 71182221 | D33: 46022 | E33: 118.131
A34: 15 | B34: vodoměr č. | C34: 241010633 | D34: 46022 | E34: 25.973
A35: 11 a 15 | B35: kalorimetr č. | C35: 71182276 | D35: 46022 | E35: 69.055
A36: 7 | B36: vodoměr č. | C36: 241010643 | D36: 46022 | E36: 108.226
B37: kalorimetr č. | C37: 71182256 | D37: 46022 | E37: 21.263
A38: 13 | B38: vodoměr č. | C38: 241010631 | D38: 46022 | E38: 29.93
A39: 12 a 13 | B39: kalorimetr č. | C39: 71182279 | D39: 46022 | E39: 107.747
A40: 14 | B40: vodoměr č. | C40: 241010632 | D40: 46022 | E40: 120.691
B41: kalorimetr č. | C41: 71182252 | D41: 46022 | E41: 113.934
...

Sheet 1850
A2: 1850 | D2: 46022 | E2: 46055 | F2: 46083 | Q2: voda | R2: teplo | S2: Elektr | Z2: spotřeby po měsících
A3: byt č. | D3: prosinec | E3: leden | F3: únor | G3: březen | H3: duben | I3: květen | J3: červen | K3: červenec | L3: srpen | M3: září | N3: říjen | O3: listopad | P3: prosinec | Q3: m3 | R3: GJ | S3: KWh | U3: byt | V3: leden | W3: únor | X3: březen | Y3: duben | Z3: květen | AA3: červen | AB3: červenec | AC3: srpen | AD3: září | AE3: říjen | AF3: listopad | AG3: prosinec
A4: 1 | B4: vodoměr č. | C4: 241345698 | D4: 131.765 | E4: 147.085 | F4: 160.048 | Q4: =P4-D4 -> -131.765 | U4: 1 | V4: =E4-D4 -> 15.32 | W4: =F4-E4 -> 12.963 | X4: =G4-F4 -> -160.048 | Y4: =H4-G4 -> 0 | Z4: =I4-H4 -> 0 | AA4: =J4-I4 -> 0 | AB4: =K4-J4 -> 0 | AC4: =L4-K4 -> 0 | ... AG4: =P4-O4 -> 0
B5: kalorimetr č. | C5: 71182278 | D5: 88.237 | E5: 93.522 | F5: 97.192 | R5: =P5-D5 -> -88.237 | AA5: =J5-I5 -> 0 | AB5: =K5-J5 -> 0 | AC5: =L5-K5 -> 0 | AD5: =M5-L5 -> 0 | AE5: =N5-M5 -> 0 | AF5: =O5-N5 -> 0 | AG5: =P5-O5 -> 0
A6: 2 | B6: vodoměr č. | C6: 241345701 | D6: 209.272 | E6: 225.269 | F6: 240.162 | Q6: =P6-D6 -> -209.272 | U6: 2 | V6: =E6-D6 -> 15.997 | W6: =F6-E6 -> 14.893 | X6: =G6-F6 -> -240.162 | Y6: =H6-G6 -> 0 | Z6: =I6-H6 -> 0 | AA6: =J6-I6 -> 0 | AB6: =K6-J6 -> 0 | AC6: =L6-K6 -> 0 | ... AG6: =P6-O6 -> 0
B7: kalorimetr č. | C7: 71182225 | D7: 116.53 | E7: 123.989 | F7: 128.851 | R7: =P7-D7 -> -116.53 | AA7: =J7-I7 -> 0 | AB7: =K7-J7 -> 0 | AC7: =L7-K7 -> 0 | AD7: =M7-L7 -> 0 | AE7: =N7-M7 -> 0 | AF7: =O7-N7 -> 0 | AG7: =P7-O7 -> 0
A8: 3 | B8: vodoměr č. | C8: 241345691 | D8: 70.033 | E8: 75.775 | F8: 81.079 | Q8: =P8-D8 -> -70.033 | U8: 3 | V8: =E8-D8 -> 5.742 | W8: =F8-E8 -> 5.304 | X8: =G8-F8 -> -81.079 | Y8: =H8-G8 -> 0 | Z8: =I8-H8 -> 0 | AA8: =J8-I8 -> 0 | AB8: =K8-J8 -> 0 | AC8: =L8-K8 -> 0 | ... AG8: =P8-O8 -> 0
B9: kalorimetr č. | C9: 71182284 | D9: 79.838 | E9: 84.09 | F9: 86.838 | R9: =P9-D9 -> -79.838 | AA9: =J9-I9 -> 0 | AB9: =K9-J9 -> 0 | AC9: =L9-K9 -> 0 | AD9: =M9-L9 -> 0 | AE9: =N9-M9 -> 0 | AF9: =O9-N9 -> 0 | AG9: =P9-O9 -> 0
A10: 4 | B10: vodoměr č. | C10: 241345696 | D10: 125.385 | E10: 137.722 | F10: 147.585 | Q10: =P10-D10 -> -125.385 | U10: 4 | V10: =E10-D10 -> 12.337 | W10: =F10-E10 -> 9.863 | X10: =G10-F10 -> -147.585 | Y10: =H10-G10 -> 0 | Z10: =I10-H10 -> 0 | AA10: =J10-I10 -> 0 | AB10: =K10-J10 -> 0 | AC10: =L10-K10 -> 0 | ... AG10: =P10-O10 -> 0
B11: kalorimetr č. | C11: 71182235 | D11: 54.863 | E11: 58.489 | F11: 60.487 | R11: =P11-D11 -> -54.863 | AA11: =J11-I11 -> 0 | AB11: =K11-J11 -> 0 | AC11: =L11-K11 -> 0 | AD11: =M11-L11 -> 0 | AE11: =N11-M11 -> 0 | AF11: =O11-N11 -> 0 | AG11: =P11-O11 -> 0
A12: 5 | B12: vodoměr č. | C12: 241345690 | D12: 118.4 | E12: 128.766 | F12: 136.495 | Q12: =P12-D12 -> -118.4 | U12: 5 | V12: =E12-D12 -> 10.366 | W12: =F12-E12 -> 7.729 | X12: =G12-F12 -> -136.495 | Y12: =H12-G12 -> 0 | Z12: =I12-H12 -> 0 | AA12: =J12-I12 -> 0 | AB12: =K12-J12 -> 0 | AC12: =L12-K12 -> 0 | ... AG12: =P12-O12 -> 0
B13: kalorimetr č. | C13: 71182238 | D13: 78.234 | E13: 82.586 | F13: 85.151 | R13: =P13-D13 -> -78.234 | AA13: =J13-I13 -> 0 | AB13: =K13-J13 -> 0 | AC13: =L13-K13 -> 0 | AD13: =M13-L13 -> 0 | AE13: =N13-M13 -> 0 | AF13: =O13-N13 -> 0 | AG13: =P13-O13 -> 0
A14: 6 | B14: vodoměr č. | C14: 241345700 | D14: 70.558 | E14: 77.078 | F14: 83.545 | Q14: =P14-D14 -> -70.558 | U14: 6 | V14: =E14-D14 -> 6.52 | W14: =F14-E14 -> 6.467 | X14: =G14-F14 -> -83.545 | Y14: =H14-G14 -> 0 | Z14: =I14-H14 -> 0 | AA14: =J14-I14 -> 0 | AB14: =K14-J14 -> 0 | AC14: =L14-K14 -> 0 | ... AG14: =P14-O14 -> 0
B15: kalorimetr č. | C15: 71182269 | D15: 116.546 | E15: 122.401 | F15: 125.371 | R15: =P15-D15 -> -116.546 | AA15: =J15-I15 -> 0 | AB15: =K15-J15 -> 0 | AC15: =L15-K15 -> 0 | AD15: =M15-L15 -> 0 | AE15: =N15-M15 -> 0 | AF15: =O15-N15 -> 0 | AG15: =P15-O15 -> 0
A16: 7 | B16: vodoměr č. | C16: 241345702 | D16: 47.513 | E16: 52.174 | F16: 55.088 | Q16: =P16-D16 -> -47.513 | U16: 7 | V16: =E16-D16 -> 4.661 | W16: =F16-E16 -> 2.914 | X16: =G16-F16 -> -55.088 | Y16: =H16-G16 -> 0 | Z16: =I16-H16 -> 0 | AA16: =J16-I16 -> 0 | AB16: =K16-J16 -> 0 | AC16: =L16-K16 -> 0 | ... AG16: =P16-O16 -> 0
B17: kalorimetr č. | C17: 71182265 | D17: 26.122 | E17: 27.782 | F17: 28.768 | R17: =P17-D17 -> -26.122 | AA17: =J17-I17 -> 0 | AB17: =K17-J17 -> 0 | AC17: =L17-K17 -> 0 | AD17: =M17-L17 -> 0 | AE17: =N17-M17 -> 0 | AF17: =O17-N17 -> 0 | AG17: =P17-O17 -> 0
A18: 8 | B18: vodoměr č. | C18: 241345699 | D18: 9.297 | E18: 9.725 | F18: 10.496 | Q18: =P18-D18 -> -9.297 | U18: 8 | V18: =E18-D18 -> 0.428 | W18: =F18-E18 -> 0.771 | X18: =G18-F18 -> -10.496 | Y18: =H18-G18 -> 0 | Z18: =I18-H18 -> 0 | AA18: =J18-I18 -> 0 | AB18: =K18-J18 -> 0 | AC18: =L18-K18 -> 0 | ... AG18: =P18-O18 -> 0
B19: kalorimetr č. | C19: 71182245 | D19: 77.412 | E19: 82.314 | F19: 85.484 | R19: =P19-D19 -> -77.412 | AA19: =J19-I19 -> 0 | AB19: =K19-J19 -> 0 | AC19: =L19-K19 -> 0 | AD19: =M19-L19 -> 0 | AE19: =N19-M19 -> 0 | AF19: =O19-N19 -> 0 | AG19: =P19-O19 -> 0
A20: 9 | B20: vodoměr č. | C20: 241345692 | D20: 15.707 | E20: 24.442 | F20: 32.024 | Q20: =P20-D20 -> -15.707 | U20: 9 | V20: =E20-D20 -> 8.735 | W20: =F20-E20 -> 7.582 | X20: =G20-F20 -> -32.024 | Y20: =H20-G20 -> 0 | Z20: =I20-H20 -> 0 | AA20: =J20-I20 -> 0 | AB20: =K20-J20 -> 0 | AC20: =L20-K20 -> 0 | ... AG20: =P20-O20 -> 0
B21: kalorimetr č. | C21: 71182280 | D21: 18.462 | E21: 22.475 | F21: 25.336 | R21: =P21-D21 -> -18.462 | AA21: =J21-I21 -> 0 | AB21: =K21-J21 -> 0 | AC21: =L21-K21 -> 0 | AD21: =M21-L21 -> 0 | AE21: =N21-M21 -> 0 | AF21: =O21-N21 -> 0 | AG21: =P21-O21 -> 0
A22: 10 | B22: vodoměr č. | C22: 241345695 | D22: 114.433 | E22: 121.932 | F22: 129.955 | Q22: =P22-D22 -> -114.433 | U22: 10 | V22: =E22-D22 -> 7.499 | W22: =F22-E22 -> 8.023 | X22: =G22-F22 -> -129.955 | Y22: =H22-G22 -> 0 | Z22: =I22-H22 -> 0 | AA22: =J22-I22 -> 0 | AB22: =K22-J22 -> 0 | AC22: =L22-K22 -> 0 | ... AG22: =P22-O22 -> 0
B23: kalorimetr č. | C23: 71182243 | D23: 95.253 | E23: 99.901 | F23: 103.72 | R23: =P23-D23 -> -95.253 | AA23: =J23-I23 -> 0 | AB23: =K23-J23 -> 0 | AC23: =L23-K23 -> 0 | AD23: =M23-L23 -> 0 | AE23: =N23-M23 -> 0 | AF23: =O23-N23 -> 0 | AG23: =P23-O23 -> 0
Q24: =SUM(Q4:Q23) -> -912.363 | R24: =SUM(R4:R23) -> -751.497
A25: spol.spotř. | B25: elektroměr č. | C25: 1025291034 | D25: 9472 | E25: 9735 | F25: 9949 | S25: =P25-D25 -> -9472
B26: patní vodoměr č. | C26: 241175202 | D26: 996.6 | E26: 1091.8 | F26: 1175.3 | Q26: =P26-D26 -> -996.6
B27: patní kalorimetr č./ GJ | D27: 399.83 | E27: 447.44 | F27: 477.51 | R27: =(P27-D27) -> -399.83 | S27: GJ
B28: patní kalorimetr č./kub.m | D28: 3333 | E28: 3662 | F28: 3866 | R28: =P28-D28 -> -3333 | S28: m3
A29: fakturační vodoměr č. | C29: 63796 | D29: 65454 | E29: 65848.9 | F29: 66193.7 | Q29: =P29-D29 -> -65454
D31: číslo | F31: stav | G31: spotřeba 2025
B32: Výměna fakturač. vodoměru | D32: 63796 | E32: starý | F32: 31933 | G32: =F32-D29 -> -33521 | I32: Dne 31.7.2023 odpojen kalor. (cejchování), | M32: stav: | N32: 210.8 | O32: MWh
B33: dne 1.12.2025 | D33: 203623 | E33: nový | F33: 65108 | G33: =P29-F33 -> -65108 | I33: Dne 3.8.2023 zapojen znovuzapojení, | M33: stav: | N33: 0 | O33: GJ
B34: Výměna elekroměru | D34: 18972503 | E34: starý
B35: dne 13.2.2022 | D35: 1025291034 | E35: nový
O37: Odečet vodárny 31.12.2024 | P37: =D29 -> 65454
O39: Odečet vodárny 31.12.2025 | P39: =P29 -> 0
O41: spotřeba | P41: =P39-P37-P38 -> -65454

Sheet 1851
AF1: Vytipování vadných vodoměrů
A2: Nové | B2: 1851 | E2: ='1850'!D2 -> 46022 | F2: ='1850'!E2 -> 46055 | G2: ='1850'!F2 -> 46083 | R2: voda | S2: teplo | T2: Elektr | AA2: spotřeby po měsících | AL2: Podíl teplé vody na celkové spotřebě vody u dělených bytů (%) | AW2: CELKOVÝ | AX2: =(AX6+AX12+AX14+AX18+AX54+AX56+AX58+AX60+AX62)/9 -> #DIV/0!
A3: číslování | B3: byt č. | E3: prosinec | F3: leden | G3: únor | H3: březen | I3: duben | J3: květen | K3: červen | L3: červenec | M3: srpen | N3: září | O3: říjen | P3: listopad | Q3: prosinec | R3: m3 | S3: GJ | T3: KWh | V3: byt | W3: leden | X3: únor | Y3: březen | Z3: duben | AA3: květen | AB3: červen | AC3: červenec | AD3: srpen | AE3: září | AF3: říjen | AG3: listopad | AH3: prosinec | AL3: 1. | AM3: 2. | AN3: 3. | AO3: 4. | AP3: 5. | AQ3: 6. | AR3: 7. | AS3: 8. | AT3: 9. | AU3: 10. | AV3: 11. | AW3: 12. | AX3: Průměr
A4: 1 | B4: 1 | C4: vodoměr č. | D4: 241010644 | E4: 199.73 | F4: 214.106 | G4: 228.285 | R4: =Q4-E4 -> -199.73 | V4: 1 | W4: =F4-E4 -> 14.376 | X4: =G4-F4 -> 14.179 | Y4: =H4-G4 -> -228.285 | Z4: =I4-H4 -> 0 | AA4: =J4-I4 -> 0 | AB4: =K4-J4 -> 0 | AC4: =L4-K4 -> 0 | AD4: =M4-L4 -> 0 | ... AH4: =Q4-P4 -> 0
C5: kalorimetr č. | D5: 71182262 | E5: 122.956 | F5: 129.373 | G5: 133.409 | S5: =Q5-E5 -> -122.956 | V5: xx
A6: 2 | B6: 2 | C6: vodoměr SV č. | D6: 241010636 | E6: 90.242 | F6: 97.117 | G6: 103.517 | R6: =Q6-E6 -> -90.242 | V6: 2 | W6: =F6-E6 -> 6.875 | X6: =G6-F6 -> 6.4 | Y6: =H6-G6 -> -103.517 | Z6: =I6-H6 -> 0 | AA6: =J6-I6 -> 0 | AB6: =K6-J6 -> 0 | AC6: =L6-K6 -> 0 | AD6: =M6-L6 -> 0 | ... AH6: =Q6-P6 -> 0 | AK6: byt 2 | AL6: =W7/(W6+W7) -> 0.339831 | AM6: =X7/(X6+X7) -> 0.35794543 | AN6: =Y7/(Y6+Y7) -> 0.31298282 | AO6: =Z7/(Z6+Z7) -> #DIV/0! | AP6: =AA7/(AA6+AA7) -> #DIV/0! | AQ6: =AB7/(AB6+AB7) -> #DIV/0! | AR6: =AC7/(AC6+AC7) -> #DIV/0! | AS6: =AD7/(AD6+AD7) -> #DIV/0! | ... AW6: =AH7/(AH6+AH7) -> #DIV/0! | AX6: =SUM(AL6:AW6)/12 -> #DIV/0!
A7: 2 a 3 | C7: kalorimetr č. | D7: 71182271 | E7: 148.721 | F7: 153.823 | G7: 157.312 | S7: =Q7-E7 -> -148.721 | V7: TV | W7: =W40 -> 3.539 | X7: =X40 -> 3.568 | Y7: =Y40 -> -47.159 | Z7: =Z40 -> 0 | AA7: =AA40 -> 0 | AB7: =AB40 -> 0 | AC7: =AC40 -> 0 | AD7: =AD40 -> 0 | ... AH7: =AH40 -> 0
A8: 5 | B8: 3 | C8: vodoměr SV č. | D8: 241010648 | E8: 17.065 | F8: 18.403 | G8: 19.772 | R8: =Q8-E8 -> -17.065 | V8: 5 | W8: =F8-E8 -> 1.338 | X8: =G8-F8 -> 1.369 | Y8: =H8-G8 -> -19.772 | Z8: =I8-H8 -> 0 | AA8: =J8-I8 -> 0 | AB8: =K8-J8 -> 0 | AC8: =L8-K8 -> 0 | AD8: =M8-L8 -> 0 | ... AH8: =Q8-P8 -> 0 | AK8: byt 5 | AL8: =W9/(W8+W9) -> 0.23977273 | AM8: =X9/(X8+X9) -> 0.22655367 | AN8: =Y9/(Y8+Y9) -> 0.22556892 | AO8: =Z9/(Z8+Z9) -> #DIV/0! | AP8: =AA9/(AA8+AA9) -> #DIV/0! | AQ8: =AB9/(AB8+AB9) -> #DIV/0! | AR8: =AC9/(AC8+AC9) -> #DIV/0! | AS8: =AD9/(AD8+AD9) -> #DIV/0! | ... AW8: =AH9/(AH8+AH9) -> #DIV/0! | AX8: =SUM(AL8:AW8)/12 -> #DIV/0!
A9: 5 a 6 | C9: kalorimetr č. | D9: 71182241 | E9: 144.359 | F9: 149.682 | G9: 153.407 | S9: =Q9-E9 -> -144.359 | V9: TV | W9: =W42 -> 0.422 | X9: =X42 -> 0.401 | Y9: =Y42 -> -5.759 | Z9: =Z42 -> 0 | AA9: =AA42 -> 0 | AB9: =AB42 -> 0 | AC9: =AC42 -> 0 | AD9: =AD42 -> 0 | ... AH9: =AH42 -> 0
A10: 4 | B10: 4 | C10: vodoměr č. | D10: 241010642 | E10: 104.28 | F10: 113.38 | G10: 121.348 | R10: =Q10-E10 -> -104.28 | V10: 4 | W10: =F10-E10 -> 9.1 | X10: =G10-F10 -> 7.968 | Y10: =H10-G10 -> -121.348 | Z10: =I10-H10 -> 0 | AA10: =J10-I10 -> 0 | AB10: =K10-J10 -> 0 | AC10: =L10-K10 -> 0 | AD10: =M10-L10 -> 0 | ... AH10: =Q10-P10 -> 0
C11: kalorimetr č. | D11: 71182237 | E11: 30.653 | F11: 33.401 | G11: 35.165 | S11: =Q11-E11 -> -30.653 | V11: xx | BA11: originál
A12: 9 | B12: 5 | C12: vodoměr SV č. | D12: 241010637 | E12: 1.588 | F12: 1.627 | G12: 1.636 | R12: =Q12-E12 -> -1.588 | V12: 9 | W12: =F12-E12 -> 0.039 | X12: =G12-F12 -> 0.009 | Y12: =H12-G12 -> -1.636 | Z12: =I12-H12 -> 0 | AA12: =J12-I12 -> 0 | AB12: =K12-J12 -> 0 | AC12: =L12-K12 -> 0 | AD12: =M12-L12 -> 0 | ... AH12: =Q12-P12 -> 0 | AK12: byt 9 | AX12: =SUM(AL12:AW12)/12 -> 0 | BA12: byt 9 | BB12: =AM13/(AM12+AM13) -> #DIV/0! | BC12: =AN13/(AN12+AN13) -> #DIV/0! | BD12: =AO13/(AO12+AO13) -> #DIV/0! | BE12: =AP13/(AP12+AP13) -> #DIV/0! | BF12: =AQ13/(AQ12+AQ13) -> #DIV/0! | BG12: =AR13/(AR12+AR13) -> #DIV/0! | BH12: =AS13/(AS12+AS13) -> #DIV/0! | BI12: =AT13/(AT12+AT13) -> #DIV/0! | ... BM12: =AX13/(AX12+AX13) -> #DIV/0! | BN12: =SUM(BB12:BM12)/12 -> #DIV/0!
A13: 8 a 9 | C13: kalorimetr č. | D13: 71182221 | E13: 118.131 | F13: 123.936 | G13: 127.609 | S13: =Q13-E13 -> -118.131 | V13: TV | W13: =W44 -> 0.026 | X13: =X44 -> 0.004 | Y13: =Y44 -> -1.404 | Z13: =Z44 -> 0 | AA13: =AA44 -> 0 | AB13: =AB44 -> 0 | AC13: =AC44 -> 0 | AD13: =AD44 -> 0 | ... AH13: =AH44 -> 0
A14: 15 | B14: 6 | C14: vodoměr SV č. | D14: 241010633 | E14: 25.973 | F14: 28.35 | G14: 30.14 | R14: =Q14-E14 -> -25.973 | V14: 15 | W14: =F14-E14 -> 2.377 | X14: =G14-F14 -> 1.79 | Y14: =H14-G14 -> -30.14 | Z14: =I14-H14 -> 0 | AA14: =J14-I14 -> 0 | AB14: =K14-J14 -> 0 | AC14: =L14-K14 -> 0 | AD14: =M14-L14 -> 0 | ... AH14: =Q14-P14 -> 0 | AK14: byt 15 | AL14: =W15/(W14+W15) -> 0.38800206 | AM14: =X15/(X14+X15) -> 0.3665959 | AN14: =Y15/(Y14+Y15) -> 0.39182372 | AO14: =Z15/(Z14+Z15) -> #DIV/0! | AP14: =AA15/(AA14+AA15) -> #DIV/0! | AQ14: =AB15/(AB14+AB15) -> #DIV/0! | AR14: =AC15/(AC14+AC15) -> #DIV/0! | AS14: =AD15/(AD14+AD15) -> #DIV/0! | ... AW14: =AH15/(AH14+AH15) -> #DIV/0! | AX14: =SUM(AL14:AW14)/12 -> #DIV/0!
A15: 11 a 15 | C15: kalorimetr č. | D15: 71182276 | E15: 69.055 | F15: 73.91 | G15: 76.639 | S15: =Q15-E15 -> -69.055 | V15: TV | W15: =W46 -> 1.507 | X15: =X46 -> 1.036 | Y15: =Y46 -> -19.418 | Z15: =Z46 -> 0 | AA15: =AA46 -> 0 | AB15: =AB46 -> 0 | AC15: =AC46 -> 0 | AD15: =AD46 -> 0 | ... AH15: =AH46 -> 0
A16: 7 | B16: 7 | C16: vodoměr č. | D16: 241010643 | E16: 108.226 | F16: 121.363 | G16: 128.556 | R16: =Q16-E16 -> -108.226 | V16: 7 | W16: =F16-E16 -> 13.137 | X16: =G16-F16 -> 7.193 | Y16: =H16-G16 -> -128.556 | Z16: =I16-H16 -> 0 | AA16: =J16-I16 -> 0 | AB16: =K16-J16 -> 0 | AC16: =L16-K16 -> 0 | AD16: =M16-L16 -> 0 | ... AH16: =Q16-P16 -> 0
C17: kalorimetr č. | D17: 71182256 | E17: 21.263 | F17: 22.439 | G17: 23.018 | S17: =Q17-E17 -> -21.263 | V17: xx
A18: 13 | B18: 8 | C18: vodoměr SV č. | D18: 241010631 | E18: 29.93 | F18: 32.268 | G18: 34.28 | R18: =Q18-E18 -> -29.93 | V18: 13 | W18: =F18-E18 -> 2.338 | X18: =G18-F18 -> 2.012 | Y18: =H18-G18 -> -34.28 | Z18: =I18-H18 -> 0 | AA18: =J18-I18 -> 0 | AB18: =K18-J18 -> 0 | AC18: =L18-K18 -> 0 | AD18: =M18-L18 -> 0 | ... AH18: =Q18-P18 -> 0 | AK18: byt 13 | AL18: =W19/(W18+W19) -> 0.4777753 | AM18: =X19/(X18+X19) -> 0.45326087 | AN18: =Y19/(Y18+Y19) -> 0.4164113 | AO18: =Z19/(Z18+Z19) -> #DIV/0! | AP18: =AA19/(AA18+AA19) -> #DIV/0! | AQ18: =AB19/(AB18+AB19) -> #DIV/0! | AR18: =AC19/(AC18+AC19) -> #DIV/0! | AS18: =AD19/(AD18+AD19) -> #DIV/0! | ... AW18: =AH19/(AH18+AH19) -> #DIV/0! | AX18: =SUM(AL18:AW18)/12 -> #DIV/0!
A19: 12 a 13 | C19: kalorimetr č. | D19: 71182279 | E19: 107.747 | F19: 112.938 | G19: 116.593 | S19: =Q19-E19 -> -107.747 | V19: TV | W19: =W48 -> 2.139 | X19: =X48 -> 1.668 | Y19: =Y48 -> -24.46 | Z19: =Z48 -> 0 | AA19: =AA48 -> 0 | AB19: =AB48 -> 0 | AC19: =AC48 -> 0 | AD19: =AD48 -> 0 | ... AH19: =AH48 -> 0
A20: 14 | B20: 9 | C20: vodoměr č. | D20: 241010632 | E20: 120.691 | F20: 130.337 | G20: 139.005 | R20: =Q20-E20 -> -120.691 | V20: 14 | W20: =F20-E20 -> 9.646 | X20: =G20-F20 -> 8.668 | Y20: =H20-G20 -> -139.005 | Z20: =I20-H20 -> 0 | AA20: =J20-I20 -> 0 | AB20: =K20-J20 -> 0 | AC20: =L20-K20 -> 0 | AD20: =M20-L20 -> 0 | ... AH20: =Q20-P20 -> 0
C21: kalorimetr č. | D21: 71182252 | E21: 113.934 | F21: 120.249 | G21: 124.188 | S21: =Q21-E21 -> -113.934 | V21: xx
A22: 10 | B22: 10 | C22: vodoměr č. | D22: 241010635 | E22: 32.06 | F22: 33.982 | G22: 36.04 | R22: =Q22-E22 -> -32.06 | V22: 10 | W22: =F22-E22 -> 1.922 | X22: =G22-F22 -> 2.058 | Y22: =H22-G22 -> -36.04 | Z22: =I22-H22 -> 0 | AA22: =J22-I22 -> 0 | AB22: =K22-J22 -> 0 | AC22: =L22-K22 -> 0 | AD22: =M22-L22 -> 0 | ... AH22: =Q22-P22 -> 0
C23: kalorimetr č. | D23: 71182234 | E23: 71.66 | F23: 77.504 | G23: 81.535 | S23: =Q23-E23 -> -71.66 | V23: xx
B24: spol.spotř. | C24: elektroměr č. | D24: 2080200096 | E24: 16972 | F24: 17186 | G24: 17374 | R24: =SUM(R4:R23)+SUM(R33:R49) -> -1044.746 | S24: =SUM(S4:S23) -> -948.479 | T24: =Q24-E24 -> -16972 | V24: kWh | AL24: Podíl teplé vody na celkové spotřebě vody u dělených bytů po měsících (%)
AK25: CELKEM | AL25: 1. | AM25: 2. | AN25: 3. | AO25: 4. | AP25: 5. | AQ25: 6. | AR25: 7. | AS25: 8. | AT25: 9. | AU25: 10. | AV25: 11. | AW25: 12. | AX25: Průměr | BG25: originál | BH25: 1. | BI25: 2. | BJ25: 3. | BK25: 4. | BL25: 5. | BM25: 6. | BN25: 7. | BO25: 8. | BP25: 9. | BQ25: 10. | BR25: 11. | BS25: 12. | BT25: Průměr
C26: patní vodoměr č. | D26: 241175208 | E26: 1140.1 | F26: 1235.1 | G26: 1314.7 | R26: =Q26-E26 -> -1140.1 | AK26: Průměr po měsících | AL26: =(AL6+AL8+AL12+AL14+AL18+AL54+AL56+AL58+AL60+AL62)/9 -> 0.32294622 | AM26: =(AM6+AM8+AM12+AM14+AM18+AM54+AM56+AM58+AM60+AM62)/9 -> 0.32407051 | AN26: =(AN6+AN8+AN12+AN14+AN18+AN54+AN56+AN58+AN60+AN62)/9 -> 0.31092872 | AO26: =(AO6+AO8+AO12+AO14+AO18+AO54+AO56+AO58+AO60+AO62)/9 -> #DIV/0! | AP26: =(AP6+AP8+AP12+AP14+AP18+AP54+AP56+AP58+AP60+AP62)/9 -> #DIV/0! | AQ26: =(AQ6+AQ8+AQ12+AQ14+AQ18+AQ54+AQ56+AQ58+AQ60+AQ62)/9 -> #DIV/0! | AR26: =(AR6+AR8+AR12+AR14+AR18+AR54+AR56+AR58+AR60+AR62)/9 -> #DIV/0! | AS26: =(AS6+AS8+AS12+AS14+AS18+AS54+AS56+AS58+AS60+AS62)/9 -> #DIV/0! | AT26: =(AT6+AT8+AT12+AT14+AT18+AT56+AT58+AT60+AT62)/8 -> #DIV/0! | AU26: =(AU6+AU8+AU12+AU14+AU18+AU56+AU58+AU60+AU62)/8 -> #DIV/0! | AV26: =(AV6+AV8+AV12+AV14+AV18+AV56+AV58+AV60+AV62)/8 -> #DIV/0! | AW26: =(AW6+AW8+AW12+AW14+AW18+AW56+AW58+AW60+AW62)/8 -> #DIV/0! | AX26: =(AX6+AX8+AX12+AX14+AX18+AX54+AX56+AX58+AX60+AX62)/9 -> #DIV/0! | BA26: Podíl TV po bytech | BG26: Průměr po měsících | BH26: =(BH6+BH8+BH12+BH14+BH18+BH54+BH56+BH58+BH60+BH62)/10 -> #DIV/0! | BI26: =(BI6+BI8+BI12+BI14+BI18+BI54+BI56+BI58+BI60+BI62)/10 -> #DIV/0! | BJ26: =(BJ6+BJ8+BJ12+BJ14+BJ18+BJ54+BJ56+BJ58+BJ60+BJ62)/10 -> #DIV/0! | BK26: =(BK6+BK8+BK12+BK14+BK18+BK54+BK56+BK58+BK60+BK62)/10 -> #DIV/0! | BL26: =(BL6+BL8+BL12+BL14+BL18+BL54+BL56+BL58+BL60+BL62)/10 -> #DIV/0! | BM26: =(BM6+BM8+BM12+BM14+BM18+BM54+BM56+BM58+BM60+BM62)/10 -> #DIV/0! | BN26: =(BN6+BN8+BN12+BN14+BN18+BN54+BN56+BN58+BN60+BN62)/10 -> #DIV/0! | BO26: =(BO6+BO8+BO12+BO14+BO18+BO54+BO56+BO58+BO60+BO62)/10 -> #DIV/0! | ... BT26: =(BT6+BT8+BT12+BT14+BT18+BT54+BT56+BT58+BT60+BT62)/10 -> 0
C27: patní kalorimetr č. / GJ | E27: 570.14 | F27: 622.34 | G27: 655.85 | S27: =(Q27-E27) -> -570.14 | T27: GJ
C28: patní kalorimetr č./kub.m | E28: 7626 | F28: 8105 | G28: 8416 | S28: =Q28-E28 -> -7626 | T28: m3
B29: ='1850'!A29 -> fakturační vodoměr č. | D29: ='1850'!C29 -> 63796 | E29: ='1850'!D29 -> 65454 | F29: ='1850'!E29 -> 65848.9 | G29: ='1850'!F29 -> 66193.7 | H29: ='1850'!G29 -> 0 | I29: ='1850'!H29 -> 0 | J29: ='1850'!I29 -> 0 | K29: ='1850'!J29 -> 0 | ... Q29: ='1850'!P29 -> 0 | R29: =Q29-E29 -> -65454 | W29: studená voda
V31: byt | W31: leden | X31: únor | Y31: březen | Z31: duben | AA31: květen | AB31: červen | AC31: červenec | AD31: srpen | AE31: září | AF31: říjen | AG31: listopad | AH31: prosinec
A33: 3 | B33: 2B | C33: vodoměr SV č. | D33: 241010630 | E33: 21.355 | F33: 21.355 | G33: 21.357 | R33: =Q33-E33 -> -21.355 | V33: 3 | W33: =F33-E33 -> 0 | X33: =G33-F33 -> 0.002 | Y33: =H33-G33 -> -21.357 | Z33: =I33-H33 -> 0 | AA33: =J33-I33 -> 0 | AB33: =K33-J33 -> 0 | AC33: =L33-K33 -> 0 | AD33: =M33-L33 -> 0 | ... AH33: =Q33-P33 -> 0
A34: 6 | B34: 3B | C34: vodoměr SV č. | D34: 241010640 | E34: 20.181 | F34: 21.36 | G34: 22.634 | R34: =Q34-E34 -> -20.181 | V34: 6 | W34: =F34-E34 -> 1.179 | X34: =G34-F34 -> 1.274 | Y34: =H34-G34 -> -22.634 | Z34: =I34-H34 -> 0 | AA34: =J34-I34 -> 0 | AB34: =K34-J34 -> 0 | AC34: =L34-K34 -> 0 | AD34: =M34-L34 -> 0 | ... AH34: =Q34-P34 -> 0
A35: 8 | B35: 5B | C35: vodoměr SV č. | D35: 241010650 | E35: 61.995 | F35: 67.914 | G35: 72.66 | R35: =Q35-E35 -> -61.995 | V35: 8 | W35: =F35-E35 -> 5.919 | X35: =G35-F35 -> 4.746 | Y35: =H35-G35 -> -72.66 | Z35: =I35-H35 -> 0 | AA35: =J35-I35 -> 0 | AB35: =K35-J35 -> 0 | AC35: =L35-K35 -> 0 | AD35: =M35-L35 -> 0 | ... AH35: =Q35-P35 -> 0
A36: 11 | B36: 6B | C36: vodoměr SV č. | D36: 241010639 | E36: 24.088 | F36: 27.97 | G36: 29.992 | R36: =Q36-E36 -> -24.088 | V36: 11 | W36: =F36-E36 -> 3.882 | X36: =G36-F36 -> 2.022 | Y36: =H36-G36 -> -29.992 | Z36: =I36-H36 -> 0 | AA36: =J36-I36 -> 0 | AB36: =K36-J36 -> 0 | AC36: =L36-K36 -> 0 | AD36: =M36-L36 -> 0 | ... AH36: =Q36-P36 -> 0
A37: 12 | B37: 8B | C37: vodoměr SV č. | D37: 241010641 | E37: 22.68 | F37: 23.051 | G37: 23.505 | R37: =Q37-E37 -> -22.68 | V37: 12 | W37: =F37-E37 -> 0.371 | X37: =G37-F37 -> 0.454 | Y37: =H37-G37 -> -23.505 | Z37: =I37-H37 -> 0 | AA37: =J37-I37 -> 0 | AB37: =K37-J37 -> 0 | AC37: =L37-K37 -> 0 | AD37: =M37-L37 -> 0 | ... AH37: =Q37-P37 -> 0
C39: VODOMĚRY TEPLÁ VODA | W39: teplá voda
A40: 2 | B40: 2 | C40: vodoměr TUV č. | D40: 240093441 | E40: 40.052 | F40: 43.591 | G40: 47.159 | R40: =Q40-E40 -> -40.052 | V40: 2 | W40: =F40-E40 -> 3.539 | X40: =G40-F40 -> 3.568 | Y40: =H40-G40 -> -47.159 | Z40: =I40-H40 -> 0 | AA40: =J40-I40 -> 0 | AB40: =K40-J40 -> 0 | AC40: =L40-K40 -> 0 | AD40: =M40-L40 -> 0 | ... AH40: =Q40-P40 -> 0
A41: 3 | B41: 2B | C41: vodoměr TUV č. | D41: 240093452 | E41: 12.203 | F41: 12.204 | G41: 12.205 | R41: =Q41-E41 -> -12.203 | V41: 3 | W41: =F41-E41 -> 0.001 | X41: =G41-F41 -> 0.001 | Y41: =H41-G41 -> -12.205 | Z41: =I41-H41 -> 0 | AA41: =J41-I41 -> 0 | AB41: =K41-J41 -> 0 | AC41: =L41-K41 -> 0 | AD41: =M41-L41 -> 0 | ... AH41: =Q41-P41 -> 0
A42: 5 | B42: 3 | C42: vodoměr TUV č. | D42: 240093448 | E42: 4.936 | F42: 5.358 | G42: 5.759 | R42: =Q42-E42 -> -4.936 | V42: 5 | W42: =F42-E42 -> 0.422 | X42: =G42-F42 -> 0.401 | Y42: =H42-G42 -> -5.759 | Z42: =I42-H42 -> 0 | AA42: =J42-I42 -> 0 | AB42: =K42-J42 -> 0 | AC42: =L42-K42 -> 0 | AD42: =M42-L42 -> 0 | ... AH42: =Q42-P42 -> 0
A43: 6 | B43: 3B | C43: vodoměr TUV č. | D43: 240093431 | E43: 14.064 | F43: 15.25 | G43: 16.664 | R43: =Q43-E43 -> -14.064 | V43: 6 | W43: =F43-E43 -> 1.186 | X43: =G43-F43 -> 1.414 | Y43: =H43-G43 -> -16.664 | Z43: =I43-H43 -> 0 | AA43: =J43-I43 -> 0 | AB43: =K43-J43 -> 0 | AC43: =L43-K43 -> 0 | AD43: =M43-L43 -> 0 | ... AH43: =Q43-P43 -> 0
...

Sheet 1852
A2: 1852 | D2: ='1850'!D2 -> 46022 | E2: ='1850'!E2 -> 46055 | F2: ='1850'!F2 -> 46083 | Q2: voda | R2: teplo | S2: Elektr | Z2: spotřeby po měsících
A3: byt č. | D3: prosinec | E3: leden | F3: únor | G3: březen | H3: duben | I3: květen | J3: červen | K3: červenec | L3: srpen | M3: září | N3: říjen | O3: listopad | P3: prosinec | Q3: m3 | R3: GJ | S3: KWh | U3: byt | V3: leden | W3: únor | X3: březen | Y3: duben | Z3: květen | AA3: červen | AB3: červenec | AC3: srpen | AD3: září | AE3: říjen | AF3: listopad | AG3: prosinec
A4: 1 | B4: vodoměr č. | C4: 241345697 | D4: 132.855 | E4: 143.994 | F4: 156.152 | Q4: =P4-D4 -> -132.855 | U4: 1 | V4: =E4-D4 -> 11.139 | W4: =F4-E4 -> 12.158 | X4: =G4-F4 -> -156.152 | Y4: =H4-G4 -> 0 | Z4: =I4-H4 -> 0 | AA4: =J4-I4 -> 0 | AB4: =K4-J4 -> 0 | AC4: =L4-K4 -> 0 | ... AG4: =P4-O4 -> 0
B5: kalorimetr č. | C5: 71182233 | D5: 101.954 | E5: 108.237 | F5: 112.61 | R5: =P5-D5 -> -101.954
A6: 2 | B6: vodoměr č. | C6: 241345687 | D6: 70.296 | E6: 72.348 | F6: 76.59 | Q6: =P6-D6 -> -70.296 | U6: 2 | V6: =E6-D6 -> 2.052 | W6: =F6-E6 -> 4.242 | X6: =G6-F6 -> -76.59 | Y6: =H6-G6 -> 0 | Z6: =I6-H6 -> 0 | AA6: =J6-I6 -> 0 | AB6: =K6-J6 -> 0 | AC6: =L6-K6 -> 0 | ... AG6: =P6-O6 -> 0
B7: kalorimetr č. | C7: 71182270 | D7: 53.346 | E7: 55.978 | F7: 58.187 | R7: =P7-D7 -> -53.346
A8: 3 | B8: vodoměr č. | C8: 241345688 | D8: 150.035 | E8: 162.726 | F8: 174.351 | Q8: =P8-D8 -> -150.035 | U8: 3 | V8: =E8-D8 -> 12.691 | W8: =F8-E8 -> 11.625 | X8: =G8-F8 -> -174.351 | Y8: =H8-G8 -> 0 | Z8: =I8-H8 -> 0 | AA8: =J8-I8 -> 0 | AB8: =K8-J8 -> 0 | AC8: =L8-K8 -> 0 | ... AG8: =P8-O8 -> 0
B9: kalorimetr č. | C9: 71182274 | D9: 142.691 | E9: 149.913 | F9: 154.878 | R9: =P9-D9 -> -142.691
A10: 4 | B10: vodoměr č. | C10: 250434729 | D10: 71.464 | E10: 80.61 | F10: 87.618 | Q10: =P10-D10 -> -71.464 | U10: 4 | V10: =E10-D10 -> 9.146 | W10: =F10-E10 -> 7.008 | X10: =G10-F10 -> -87.618 | Y10: =H10-G10 -> 0 | Z10: =I10-H10 -> 0 | AA10: =J10-I10 -> 0 | AB10: =K10-J10 -> 0 | AC10: =L10-K10 -> 0 | ... AG10: =P10-O10 -> 0
B11: kalorimetr č. | C11: 71182244 | D11: 104.88 | E11: 109.368 | F11: 111.765 | R11: =P11-D11 -> -104.88
A12: 5 | B12: vodoměr č. | C12: 241345689 | D12: 89.153 | E12: 95.497 | F12: 101.514 | Q12: =P12-D12 -> -89.153 | U12: 5 | V12: =E12-D12 -> 6.344 | W12: =F12-E12 -> 6.017 | X12: =G12-F12 -> -101.514 | Y12: =H12-G12 -> 0 | Z12: =I12-H12 -> 0 | AA12: =J12-I12 -> 0 | AB12: =K12-J12 -> 0 | AC12: =L12-K12 -> 0 | ... AG12: =P12-O12 -> 0
B13: kalorimetr č. | C13: 71182251 | D13: 54.095 | E13: 56.959 | F13: 58.343 | R13: =P13-D13 -> -54.095
A14: 6 | B14: vodoměr č. | C14: 241345694 | D14: 75.263 | E14: 82.742 | F14: 88.188 | Q14: =P14-D14 -> -75.263 | U14: 6 | V14: =E14-D14 -> 7.479 | W14: =F14-E14 -> 5.446 | X14: =G14-F14 -> -88.188 | Y14: =H14-G14 -> 0 | Z14: =I14-H14 -> 0 | AA14: =J14-I14 -> 0 | AB14: =K14-J14 -> 0 | AC14: =L14-K14 -> 0 | ... AG14: =P14-O14 -> 0
B15: kalorimetr č. | C15: 71182283 | D15: 76.675 | E15: 80.934 | F15: 83.313 | R15: =P15-D15 -> -76.675
A16: 7 | B16: vodoměr č. | C16: 241345686 | D16: 13.325 | E16: 14.402 | F16: 15.221 | Q16: =P16-D16 -> -13.325 | U16: 7 | V16: =E16-D16 -> 1.077 | W16: =F16-E16 -> 0.819 | X16: =G16-F16 -> -15.221 | Y16: =H16-G16 -> 0 | Z16: =I16-H16 -> 0 | AA16: =J16-I16 -> 0 | AB16: =K16-J16 -> 0 | AC16: =L16-K16 -> 0 | ... AG16: =P16-O16 -> 0
B17: kalorimetr č. | C17: 71182277 | D17: 49.633 | E17: 55.584 | F17: 58.916 | R17: =P17-D17 -> -49.633
A18: 8 | B18: vodoměr č. | C18: 241345685 | D18: 154.038 | E18: 165.656 | F18: 178.618 | Q18: =P18-D18 -> -154.038 | U18: 8 | V18: =E18-D18 -> 11.618 | W18: =F18-E18 -> 12.962 | X18: =G18-F18 -> -178.618 | Y18: =H18-G18 -> 0 | Z18: =I18-H18 -> 0 | AA18: =J18-I18 -> 0 | AB18: =K18-J18 -> 0 | AC18: =L18-K18 -> 0 | ... AG18: =P18-O18 -> 0
B19: kalorimetr č. | C19: 71182246 | D19: 64.559 | E19: 68.385 | F19: 71.07 | R19: =P19-D19 -> -64.559
A20: 9 | B20: vodoměr č. | C20: 241345704 | D20: 108.135 | E20: 108.525 | F20: 109.944 | Q20: =P20-D20 -> -108.135 | U20: 9 | V20: =E20-D20 -> 0.39 | W20: =F20-E20 -> 1.419 | X20: =G20-F20 -> -109.944 | Y20: =H20-G20 -> 0 | Z20: =I20-H20 -> 0 | AA20: =J20-I20 -> 0 | AB20: =K20-J20 -> 0 | AC20: =L20-K20 -> 0 | ... AG20: =P20-O20 -> 0
B21: kalorimetr č. | C21: 71182282 | D21: 140.442 | E21: 144.696 | F21: 146.219 | R21: =P21-D21 -> -140.442
A22: 10 | B22: vodoměr č. | C22: 241345703 | D22: 87.056 | E22: 95.12 | F22: 101.682 | Q22: =P22-D22 -> -87.056 | U22: 10 | V22: =E22-D22 -> 8.064 | W22: =F22-E22 -> 6.562 | X22: =G22-F22 -> -101.682 | Y22: =H22-G22 -> 0 | Z22: =I22-H22 -> 0 | AA22: =J22-I22 -> 0 | AB22: =K22-J22 -> 0 | AC22: =L22-K22 -> 0 | ... AG22: =P22-O22 -> 0
B23: kalorimetr č. | C23: 71182240 | D23: 89.435 | E23: 95.396 | F23: 99.017 | R23: =P23-D23 -> -89.435
Q24: =SUM(Q4:Q23) -> -951.62 | R24: =SUM(R4:R23) -> -877.71
A25: spol.spotř. | B25: elektroměr č. | C25: 2080200097 | D25: 14615 | E25: 14798 | F25: 14977 | S25: =P25-D25 -> -14615
B26: patní vodoměr č. | C26: 240826415 | D26: 1079.3 | E26: 1156.7 | F26: 1232.2 | Q26: =P26-D26 -> -1079.3
B27: patní kalorimetr č./ GJ | D27: 453.82 | E27: 503.66 | F27: 533.07 | R27: =(P27-D27) -> -453.82 | S27: GJ
B28: patní kalorimetr č./kub.m | D28: 3092 | E28: 3385 | F28: 3545 | R28: =P28-D28 -> -3092 | S28: m3
A29: ='1850'!A29 -> fakturační vodoměr č. | C29: ='1850'!C29 -> 63796 | D29: ='1850'!D29 -> 65454 | E29: ='1850'!E29 -> 65848.9 | F29: ='1850'!F29 -> 66193.7 | G29: ='1850'!G29 -> 0 | H29: ='1850'!H29 -> 0 | I29: ='1850'!I29 -> 0 | J29: ='1850'!J29 -> 0 | ... P29: ='1850'!P29 -> 0 | Q29: =P29-D29 -> -65454
B31: Vodoměr | D31: byt | E31: Reklamace - výměna | G31: číslo | H31: stav | J31: Dne 31.7.2023 odpojen kalor. (cejchování), | N31: stav: | O31: 257.22 | P31: MWh
D32: 4 | E32: 45741 | F32: starý | G32: 241345693 | H32: =9.996+6+7.8+6 -> 29.796 | J32: Dne 3.8.2023 zapojen znovuzapojení, | N32: stav: | O32: 0 | P32: GJ
F33: nový | G33: 250434729 | H33: 0
E35: Výměna elektroměru
E36: 43956 | F36: starý
F37: nový

Sheet 1853
A2: 1853 | D2: ='1850'!D2 -> 46022 | E2: ='1850'!E2 -> 46055 | F2: ='1850'!F2 -> 46083 | Q2: Voda | R2: Teplo | S2: Elektr | Z2: spotřeby po měsících | AJ2: 2025
A3: byt č. | D3: prosinec | E3: leden | F3: únor | G3: březen | H3: duben | I3: květen | J3: červen | K3: červenec | L3: srpen | M3: září | N3: říjen | O3: listopad | P3: prosinec | Q3: m3 | R3: GJ | S3: KWh | U3: byt | V3: leden | W3: únor | X3: březen | Y3: duben | Z3: květen | AA3: červen | AB3: červenec | AC3: srpen | AD3: září | AE3: říjen | AF3: listopad | AG3: prosinec | AI3: říjen | AJ3: listopad | AK3: prosinec
A4: 1 | B4: vodoměr č. | C4: 241010646 | D4: 175.815 | E4: 192.061 | F4: 204.754 | Q4: =P4-D4 -> -175.815 | U4: 1 | V4: =E4-D4 -> 16.246 | W4: =F4-E4 -> 12.693 | X4: =G4-F4 -> -204.754 | Y4: =H4-G4 -> 0 | Z4: =I4-H4 -> 0 | AA4: =J4-I4 -> 0 | AB4: =K4-J4 -> 0 | AC4: =L4-K4 -> 0 | ... AG4: =P4-O4 -> 0 | AI4: 16.003 | AJ4: 13.437 | AK4: 12.961
B5: kalorimetr č. | C5: 71182275 | D5: 129.64 | E5: 137.754 | F5: 142.701 | R5: =P5-D5 -> -129.64
A6: 2 | B6: vodoměr č. | C6: 241010634 | D6: 81.341 | E6: 89.161 | F6: 94.862 | Q6: =P6-D6 -> -81.341 | U6: 2 | V6: =E6-D6 -> 7.82 | W6: =F6-E6 -> 5.701 | X6: =G6-F6 -> -94.862 | Y6: =H6-G6 -> 0 | Z6: =I6-H6 -> 0 | AA6: =J6-I6 -> 0 | AB6: =K6-J6 -> 0 | AC6: =L6-K6 -> 0 | ... AG6: =P6-O6 -> 0 | AI6: 5.459 | AJ6: 6.878 | AK6: 7.254
B7: kalorimetr č. | C7: 71182253 | D7: 38.242 | E7: 40.833 | F7: 42.619 | R7: =P7-D7 -> -38.242
A8: 3 | B8: vodoměr č. | C8: 241010645 | D8: 100.236 | E8: 110.881 | F8: 119.483 | Q8: =P8-D8 -> -100.236 | U8: 3 | V8: =E8-D8 -> 10.645 | W8: =F8-E8 -> 8.602 | X8: =G8-F8 -> -119.483 | Y8: =H8-G8 -> 0 | Z8: =I8-H8 -> 0 | AA8: =J8-I8 -> 0 | AB8: =K8-J8 -> 0 | AC8: =L8-K8 -> 0 | ... AG8: =P8-O8 -> 0 | AI8: 6.519 | AJ8: 5.939 | AK8: 7.818
B9: kalorimetr č. | C9: 71182217 | D9: 83.978 | E9: 89.158 | F9: 93.166 | R9: =P9-D9 -> -83.978
A10: 4 | B10: vodoměr č. | C10: 241010647 | D10: 54.349 | E10: 58.58 | F10: 61.624 | Q10: =P10-D10 -> -54.349 | U10: 4 | V10: =E10-D10 -> 4.231 | W10: =F10-E10 -> 3.044 | X10: =G10-F10 -> -61.624 | Y10: =H10-G10 -> 0 | Z10: =I10-H10 -> 0 | AA10: =J10-I10 -> 0 | AB10: =K10-J10 -> 0 | AC10: =L10-K10 -> 0 | ... AG10: =P10-O10 -> 0 | AI10: 4.132 | AJ10: 3.747 | AK10: 4.871
B11: kalorimetr č. | C11: 71182254 | D11: 43.999 | E11: 47 | F11: 48.398 | R11: =P11-D11 -> -43.999
A12: 5 | B12: vodoměr č. | C12: 241010638 | D12: 88.007 | E12: 95.257 | F12: 101.833 | Q12: =P12-D12 -> -88.007 | U12: 5 | V12: =E12-D12 -> 7.25 | W12: =F12-E12 -> 6.576 | X12: =G12-F12 -> -101.833 | Y12: =H12-G12 -> 0 | Z12: =I12-H12 -> 0 | AA12: =J12-I12 -> 0 | AB12: =K12-J12 -> 0 | AC12: =L12-K12 -> 0 | ... AG12: =P12-O12 -> 0 | AI12: 6.694 | AJ12: 6.903 | AK12: 7.452
B13: kalorimetr č. | C13: 71182267 | D13: 36.796 | E13: 38.966 | F13: 40.395 | R13: =P13-D13 -> -36.796
A14: 6 | B14: vodoměr č. | C14: 241010623 | D14: 84.296 | E14: 91.305 | F14: 97.516 | Q14: =P14-D14 -> -84.296 | U14: 6 | V14: =E14-D14 -> 7.009 | W14: =F14-E14 -> 6.211 | X14: =G14-F14 -> -97.516 | Y14: =H14-G14 -> 0 | Z14: =I14-H14 -> 0 | AA14: =J14-I14 -> 0 | AB14: =K14-J14 -> 0 | AC14: =L14-K14 -> 0 | ... AG14: =P14-O14 -> 0 | AI14: 7.074 | AJ14: 7.671 | AK14: 5.853
B15: kalorimetr č. | C15: 71182261 | D15: 60.341 | E15: 64.824 | F15: 67.762 | R15: =P15-D15 -> -60.341
A16: 7 | B16: vodoměr č. | C16: 241010627 | D16: 148.233 | E16: 162.12 | F16: 171.407 | Q16: =P16-D16 -> -148.233 | U16: 7 | V16: =E16-D16 -> 13.887 | W16: =F16-E16 -> 9.287 | X16: =G16-F16 -> -171.407 | Y16: =H16-G16 -> 0 | Z16: =I16-H16 -> 0 | AA16: =J16-I16 -> 0 | AB16: =K16-J16 -> 0 | AC16: =L16-K16 -> 0 | ... AG16: =P16-O16 -> 0 | AI16: 10.693 | AJ16: 13.132 | AK16: 12.302
B17: kalorimetr č. | C17: 71182272 | D17: 97.447 | E17: 101.902 | F17: 104.289 | R17: =P17-D17 -> -97.447
A18: 8 | B18: vodoměr č. | C18: 241010626 | D18: 129.38 | E18: 141.307 | F18: 151.481 | Q18: =P18-D18 -> -129.38 | U18: 8 | V18: =E18-D18 -> 11.927 | W18: =F18-E18 -> 10.174 | X18: =G18-F18 -> -151.481 | Y18: =H18-G18 -> 0 | Z18: =I18-H18 -> 0 | AA18: =J18-I18 -> 0 | AB18: =K18-J18 -> 0 | AC18: =L18-K18 -> 0 | ... AG18: =P18-O18 -> 0 | AI18: 10.254 | AJ18: 10.502 | AK18: 10.232
B19: kalorimetr č. | C19: 71182249 | D19: 77.098 | E19: 82.438 | F19: 85.699 | R19: =P19-D19 -> -77.098
A20: 9 | B20: vodoměr č. | C20: 241010624 | D20: 44.594 | E20: 48.472 | F20: 52.141 | Q20: =P20-D20 -> -44.594 | U20: 9 | V20: =E20-D20 -> 3.878 | W20: =F20-E20 -> 3.669 | X20: =G20-F20 -> -52.141 | Y20: =H20-G20 -> 0 | Z20: =I20-H20 -> 0 | AA20: =J20-I20 -> 0 | AB20: =K20-J20 -> 0 | AC20: =L20-K20 -> 0 | ... AG20: =P20-O20 -> 0 | AI20: 3.403 | AJ20: 3.708 | AK20: 3.761
B21: kalorimetr č. | C21: 71182281 | D21: 89.992 | E21: 95.679 | F21: 99.18 | R21: =P21-D21 -> -89.992
A22: 10 | B22: vodoměr č. | C22: 241010628 | D22: 34.131 | E22: 36.905 | F22: 39.308 | Q22: =P22-D22 -> -34.131 | U22: 10 | V22: =E22-D22 -> 2.774 | W22: =F22-E22 -> 2.403 | X22: =G22-F22 -> -39.308 | Y22: =H22-G22 -> 0 | Z22: =I22-H22 -> 0 | AA22: =J22-I22 -> 0 | AB22: =K22-J22 -> 0 | AC22: =L22-K22 -> 0 | ... AG22: =P22-O22 -> 0 | AI22: 2.412 | AJ22: 2.338 | AK22: 2.79
B23: kalorimetr č. | C23: 71182268 | D23: 82.508 | E23: 87.315 | F23: 90.543 | R23: =P23-D23 -> -82.508
B24: elektroměr č. dům | C24: 2080200105 | D24: 12933 | E24: 13098 | F24: 13234 | Q24: =SUM(Q4:Q23) -> -940.382 | R24: =SUM(R4:R23) -> -740.041 | S24: =P24-D24 -> -12933
A25: spol.spotř. | B25: elektroměr č. VO | C25: 2080200100 | D25: 21566 | E25: 21938 | F25: 22221 | S25: =P25-D25 -> -21566 | U25: Zahrada | V25: =E26-D26 -> 0 | W25: =F26-E26 -> 0 | X25: =G26-F26 -> -746.371 | Y25: =H26-G26 -> 0 | Z25: =I26-H26 -> 0 | AA25: =J26-I26 -> 0 | AB25: =K26-J26 -> 0 | AC25: =L26-K26 -> 0 | ... AG25: =P26-O26 -> 0
B26: vodoměr areál č. | C26: 200076532 | D26: 746.371 | E26: 746.371 | F26: 746.371 | Q26: =P26-D26 -> -746.371 | R26: =ROUND(Q26,0)-1 -> -747 | S26: zahrada
B27: patní vodoměr č. | C27: 241175207 | D27: 1173.1 | E27: 1285.7 | F27: 1380.1 | Q27: =P27-D27 -> -1173.1 | R27: =Q27-R26 -> -426.1 | S27: byty | V27: =(E27-D27)-(E26-D26) -> 112.6 | W27: =(F27-E27)-(F26-E26) -> 94.4 | X27: =(G27-F27)-(G26-F26) -> -633.729 | Y27: =(H27-G27)-(H26-G26) -> 0 | Z27: =(I27-H27)-(I26-H26) -> 0 | AA27: =(J27-I27)-(J26-I26) -> 0 | AB27: =(K27-J27)-(K26-J26) -> 0 | AC27: =(L27-K27)-(L26-K26) -> 0 | ... AG27: =(P27-O27)-(P26-O26) -> 0 | AI27: 82.003 | AJ27: 84.727 | AK27: 86.8
B28: patní kalorimetr č./ GJ | D28: 416.82 | E28: 465.29 | F28: 494.86 | R28: =(P28-D28) -> -416.82 | S28: GJ | V28: =(E28-D28) -> 48.47 | W28: =(F28-E28) -> 29.57 | X28: =(G28-F28) -> -494.86 | Y28: =(H28-G28) -> 0 | Z28: =(I28-H28) -> 0 | AA28: =(J28-I28) -> 0 | AB28: =(K28-J28) -> 0 | AC28: =(L28-K28) -> 0 | ... AG28: =(P28-O28) -> 0 | AI28: 12.17 | AJ28: 27.33 | AK28: 31.64
B29: patní kalorimetr č. /kub.m | D29: 2894 | E29: 3202 | F29: 3380 | R29: =P29-D29 -> -2894 | S29: m3
A30: ='1850'!A29 -> fakturační vodoměr č. | C30: ='1850'!C29 -> 63796 | D30: ='1850'!D29 -> 65454 | E30: ='1850'!E29 -> 65848.9 | F30: ='1850'!F29 -> 66193.7 | G30: ='1850'!G29 -> 0 | H30: ='1850'!H29 -> 0 | I30: ='1850'!I29 -> 0 | J30: ='1850'!J29 -> 0 | ... P30: ='1850'!P29 -> 0 | Q30: =P30-D30 -> -65454
A32: 11 | B32: vodoměr SV č. | C32: 11717149 | D32: 26.83 | E32: 27.072 | F32: 27.251 | Q32: =P32-D32 -> -26.83 | T32: SV | U32: 11 | V32: =E32-D32 -> 0.242 | W32: =F32-E32 -> 0.179 | X32: =G32-F32 -> -27.251 | Y32: =H32-G32 -> 0 | Z32: =I32-H32 -> 0 | AA32: =J32-I32 -> 0 | AB32: =K32-J32 -> 0 | AC32: =L32-K32 -> 0 | ... AG32: =P32-O32 -> 0
B33: vodoměr TV č. | C33: 11683196 | D33: 1.074 | E33: 1.074 | F33: 1.074 | Q33: =P33-D33 -> -1.074 | T33: TV | V33: =E33-D33 -> 0 | W33: =F33-E33 -> 0 | X33: =G33-F33 -> -1.074 | Y33: =H33-G33 -> 0 | Z33: =I33-H33 -> 0 | AA33: =J33-I33 -> 0 | AB33: =K33-J33 -> 0 | AC33: =L33-K33 -> 0 | ... AG33: =P33-O33 -> 0
E35: Výměna elektroměru DŮM
E36: 43956 | F36: starý | P36: spotřeba SV byt č.3 pro vyúčt. | Q36: =Q8-Q32-Q33 -> -72.332
F37: nový | P37: spotřeba SV sklad č.11 pro vyúčt. | Q37: =Q32+Q33 -> -27.904
E38: Výměna elektroměru AREÁL | P38: CELKEM : | Q38: =SUM(Q36:Q37) -> -100.236
E39: 43956 | F39: starý
F40: nový | K40: Dne 31.7.2023 odpojen kalor. (cejchování), | O40: stav: | P40: 234.86 | Q40: MWh
K41: Dne 3.8.2023 zapojen znovuzapojení, | O41: stav: | P41: 0 | Q41: GJ
E42: Výměna vodoměru ZAHRADA | H42: Příští výměna 2026
E43: 43874 | F43: starý | G43: 10282180 | I43: 655.348
...

Sheet 1854
A2: 1854 | D2: ='1850'!D2 -> 46022 | E2: ='1850'!E2 -> 46055 | F2: ='1850'!F2 -> 46083 | Q2: voda | R2: teplo | S2: Elektr | Z2: spotřeby po měsících
A3: byt č. | D3: prosinec | E3: leden | F3: únor | G3: březen | H3: duben | I3: květen | J3: červen | K3: červenec | L3: srpen | M3: září | N3: říjen | O3: listopad | P3: prosinec | Q3: m3 | R3: GJ | S3: KWh | U3: byt | V3: leden | W3: únor | X3: březen | Y3: duben | Z3: květen | AA3: červen | AB3: červenec | AC3: srpen | AD3: září | AE3: říjen | AF3: listopad | AG3: prosinec
A4: 1 | B4: vodoměr č. | C4: 241010657 | D4: 36.432 | E4: 39.872 | F4: 42.698 | Q4: =P4-D4 -> -36.432 | U4: 1 | V4: =E4-D4 -> 3.44 | W4: =F4-E4 -> 2.826 | X4: =G4-F4 -> -42.698 | Y4: =H4-G4 -> 0 | Z4: =I4-H4 -> 0 | AA4: =J4-I4 -> 0 | AB4: =K4-J4 -> 0 | AC4: =L4-K4 -> 0 | ... AG4: =P4-O4 -> 0
B5: kalorimetr č. | C5: 71182259 | D5: 87.096 | E5: 92.253 | F5: 95.407 | R5: =P5-D5 -> -87.096
A6: 2 | B6: vodoměr č. | C6: 241010655 | D6: 74.11 | E6: 78.894 | F6: 84.682 | Q6: =P6-D6 -> -74.11 | U6: 2 | V6: =E6-D6 -> 4.784 | W6: =F6-E6 -> 5.788 | X6: =G6-F6 -> -84.682 | Y6: =H6-G6 -> 0 | Z6: =I6-H6 -> 0 | AA6: =J6-I6 -> 0 | AB6: =K6-J6 -> 0 | AC6: =L6-K6 -> 0 | ... AG6: =P6-O6 -> 0
B7: kalorimetr č. | C7: 71182248 | D7: 141.336 | E7: 147.312 | F7: 151.599 | R7: =P7-D7 -> -141.336
A8: 3 | B8: vodoměr č. | C8: 241345683 | D8: 71.285 | E8: 72.624 | F8: 79.92 | Q8: =P8-D8 -> -71.285 | U8: 3 | V8: =E8-D8 -> 1.339 | W8: =F8-E8 -> 7.296 | X8: =G8-F8 -> -79.92 | Y8: =H8-G8 -> 0 | Z8: =I8-H8 -> 0 | AA8: =J8-I8 -> 0 | AB8: =K8-J8 -> 0 | AC8: =L8-K8 -> 0 | ... AG8: =P8-O8 -> 0
B9: kalorimetr č. | C9: 71182258 | D9: 158.203 | E9: 166.334 | F9: 171.959 | R9: =P9-D9 -> -158.203
A10: 4 | B10: vodoměr č. | C10: 241010651 | D10: 88.761 | E10: 96.527 | F10: 103.231 | Q10: =P10-D10 -> -88.761 | U10: 4 | V10: =E10-D10 -> 7.766 | W10: =F10-E10 -> 6.704 | X10: =G10-F10 -> -103.231 | Y10: =H10-G10 -> 0 | Z10: =I10-H10 -> 0 | AA10: =J10-I10 -> 0 | AB10: =K10-J10 -> 0 | AC10: =L10-K10 -> 0 | ... AG10: =P10-O10 -> 0
B11: kalorimetr č. | C11: 71182242 | D11: 38.633 | E11: 39.955 | F11: 40.59 | R11: =P11-D11 -> -38.633
A12: 5 | B12: vodoměr č. | C12: 241345677 | D12: 18.231 | E12: 22.036 | F12: 26.087 | Q12: =P12-D12 -> -18.231 | U12: 5 | V12: =E12-D12 -> 3.805 | W12: =F12-E12 -> 4.051 | X12: =G12-F12 -> -26.087 | Y12: =H12-G12 -> 0 | Z12: =I12-H12 -> 0 | AA12: =J12-I12 -> 0 | AB12: =K12-J12 -> 0 | AC12: =L12-K12 -> 0 | ... AG12: =P12-O12 -> 0
B13: kalorimetr č. | C13: 71182255 | D13: 20.766 | E13: 27.041 | F13: 31.276 | R13: =P13-D13 -> -20.766
A14: 6 | B14: vodoměr č. | C14: 241010629 | D14: 150.001 | E14: 162.913 | F14: 173.339 | Q14: =P14-D14 -> -150.001 | U14: 6 | V14: =E14-D14 -> 12.912 | W14: =F14-E14 -> 10.426 | X14: =G14-F14 -> -173.339 | Y14: =H14-G14 -> 0 | Z14: =I14-H14 -> 0 | AA14: =J14-I14 -> 0 | AB14: =K14-J14 -> 0 | AC14: =L14-K14 -> 0 | ... AG14: =P14-O14 -> 0
B15: kalorimetr č. | C15: 71182230 | D15: 48.317 | E15: 51.444 | F15: 52.996 | R15: =P15-D15 -> -48.317
A16: 7 | B16: vodoměr č. | C16: 241010659 | D16: 52.297 | E16: 55.701 | F16: 58.976 | Q16: =P16-D16 -> -52.297 | U16: 7 | V16: =E16-D16 -> 3.404 | W16: =F16-E16 -> 3.275 | X16: =G16-F16 -> -58.976 | Y16: =H16-G16 -> 0 | Z16: =I16-H16 -> 0 | AA16: =J16-I16 -> 0 | AB16: =K16-J16 -> 0 | AC16: =L16-K16 -> 0 | ... AG16: =P16-O16 -> 0
B17: kalorimetr č. | C17: 71182247 | D17: 37.54 | E17: 39.755 | F17: 41.103 | R17: =P17-D17 -> -37.54
A18: 8 | B18: vodoměr č. | C18: 241010622 | D18: 75.76 | E18: 81.828 | F18: 86.603 | Q18: =P18-D18 -> -75.76 | U18: 8 | V18: =E18-D18 -> 6.068 | W18: =F18-E18 -> 4.775 | X18: =G18-F18 -> -86.603 | Y18: =H18-G18 -> 0 | Z18: =I18-H18 -> 0 | AA18: =J18-I18 -> 0 | AB18: =K18-J18 -> 0 | AC18: =L18-K18 -> 0 | ... AG18: =P18-O18 -> 0
B19: kalorimetr č. | C19: 71182232 | D19: 105.695 | E19: 111.471 | F19: 115.032 | R19: =P19-D19 -> -105.695
A20: 9 | B20: vodoměr č. | C20: 241010625 | D20: 153.01 | E20: 165.528 | F20: 176.379 | Q20: =P20-D20 -> -153.01 | U20: 9 | V20: =E20-D20 -> 12.518 | W20: =F20-E20 -> 10.851 | X20: =G20-F20 -> -176.379 | Y20: =H20-G20 -> 0 | Z20: =I20-H20 -> 0 | AA20: =J20-I20 -> 0 | AB20: =K20-J20 -> 0 | AC20: =L20-K20 -> 0 | ... AG20: =P20-O20 -> 0
B21: kalorimetr č. | C21: 71182228 | D21: 127.65 | E21: 135.023 | F21: 139.753 | R21: =P21-D21 -> -127.65
A22: 10 | B22: vodoměr č. | C22: 241010621 | D22: 0.371 | E22: 0.385 | F22: 0.427 | Q22: =P22-D22 -> -0.371 | U22: 10 | V22: =E22-D22 -> 0.014 | W22: =F22-E22 -> 0.042 | X22: =G22-F22 -> -0.427 | Y22: =H22-G22 -> 0 | Z22: =I22-H22 -> 0 | AA22: =J22-I22 -> 0 | AB22: =K22-J22 -> 0 | AC22: =L22-K22 -> 0 | ... AG22: =P22-O22 -> 0
B23: kalorimetr č. | C23: 71182263 | D23: 0.161 | E23: 0.162 | F23: 0.162 | R23: =P23-D23 -> -0.161
Q24: =SUM(Q4:Q23) -> -720.258 | R24: =SUM(R4:R23) -> -765.397
A25: spol.spotř. | B25: elektroměr č. | C25: 2480481736 | D25: 3977 | E25: 4737 | F25: 5050 | S25: =P25-D25 -> -3977
B26: patní vodoměr č. | C26: 240826414 | D26: 783.7 | E26: 847.9 | F26: 906.1 | Q26: =P26-D26 -> -783.7
B27: patní kalorimetr č. / GJ | C27: 70465263 | D27: 1074.78 | E27: 1123.81 | F27: 1155.51 | R27: =P27-D27 -> -1074.78 | S27: GJ
B28: patní kalorimetr č. / kub.m | D28: 8456 | E28: 8758 | F28: 8948 | R28: =P28-D28 -> -8456 | S28: m3
A29: Fakturační vodoměr: | C29: 42012114941 | D29: 211 | E29: 537.6 | F29: 814.4 | Q29: =P29-D29 -> -211
E32: Výměna kalorimetru pata | H32: MWh | I32: m3 | K32: Výměna faktur.vodoměru výr.č. | N32: m3
D33: demontáž | E33: 43984 | F33: starý | K33: 46003 | L33: starý | M33: 42012114941 | N33: 17286 | P33: =N33-D29+200 -> 17275 | Q33: faktur. Spotřeba 2025
G34: výr.č. | H34: GJ | I34: m3 | M34: výr.č. | N34: m3 | P34: =P29 -> 0 | Q34: spotř. Dopočet 2025
D35: montáž | E35: 43986 | F35: nový | K35: 46003 | L35: nový | M35: 42012252632 | N35: 0 | P35: =P33+P34 -> 17275 | Q35: Celkem 2025
C38: byt | D38: Reklamace - výměna | F38: číslo | G38: stav | N38: Odečet vodárny 31.12.2024 | O38: =D29 -> 211
C39: 5 | D39: 43950 | E39: starý | F39: 190907002 | G39: 0.602 | N39: Odečet vodárny 12.12.2025 | O39: =N33+200 -> 17486 | P39: vč. Dopočtu
E40: nový | F40: 221525395 | G40: 0.02 | N40: Odečet vodárny 31.12.2025 | O40: =P29 -> 0
C42: Výměna elektroměru DŮM | N42: spotřeba | O42: =P29+O39-O38 -> 17275
C43: 45415 | D43: starý | E43: 72370871
D44: nový | E44: 2480481736

Sheet 1855
AI1: statistika | AJ1: leden - listopad
A2: 1855 | D2: ='1850'!D2 -> 46022 | E2: ='1850'!E2 -> 46055 | F2: ='1850'!F2 -> 46083 | Q2: voda | R2: teplo | S2: elektr | Z2: spotřeby po měsících | AI2: byt | AJ2: 2025 | AK2: 2024 | AL2: 2023 | AM2: 2022 | AN2: 2021
A3: byt č. | D3: prosinec | E3: leden | F3: únor | G3: březen | H3: duben | I3: květen | J3: červen | K3: červenec | L3: srpen | M3: září | N3: říjen | O3: listopad | P3: prosinec | Q3: m3 | R3: GJ | S3: KWh | U3: byt | V3: leden | W3: únor | X3: březen | Y3: duben | Z3: květen | AA3: červen | AB3: červenec | AC3: srpen | AD3: září | AE3: říjen | AF3: listopad | AG3: prosinec
A4: 1 | B4: vodoměr č. | C4: 241513388 | D4: 143.133 | E4: 157.625 | F4: 171.439 | Q4: =P4-D4 -> -143.133 | U4: 1 | V4: =E4-D4 -> 14.492 | W4: =F4-E4 -> 13.814 | X4: =G4-F4 -> -171.439 | Y4: =H4-G4 -> 0 | Z4: =I4-H4 -> 0 | AA4: =J4-I4 -> 0 | AB4: =K4-J4 -> 0 | AC4: =L4-K4 -> 0 | ... AG4: =P4-O4 -> 0 | AI4: 1 | AJ4: =SUM(V4:AF4) -> -143.133 | AK4: 113.332 | AL4: 124.65 | AM4: 143.755 | AN4: 166.556
B5: kalorimetr č. | C5: 71182223 | D5: 159.824 | E5: 168.366 | F5: 173.024 | R5: =P5-D5 -> -159.824 | U5: teplo | V5: =E5-D5 -> 8.542 | W5: =F5-E5 -> 4.658 | X5: =G5-F5 -> -173.024 | Y5: =H5-G5 -> 0 | Z5: =I5-H5 -> 0 | AA5: =J5-I5 -> 0 | AB5: =K5-J5 -> 0 | AC5: =L5-K5 -> 0 | ... AG5: =P5-O5 -> 0
A6: 2 | B6: vodoměr č. | C6: 241513401 | D6: 207.697 | E6: 225.232 | F6: 242.796 | Q6: =P6-D6 -> -207.697 | U6: 2 | V6: =E6-D6 -> 17.535 | W6: =F6-E6 -> 17.564 | X6: =G6-F6 -> -242.796 | Y6: =H6-G6 -> 0 | Z6: =I6-H6 -> 0 | AA6: =J6-I6 -> 0 | AB6: =K6-J6 -> 0 | AC6: =L6-K6 -> 0 | ... AG6: =P6-O6 -> 0 | AI6: 2 | AJ6: =SUM(V6:AF6) -> -207.697 | AK6: 163.534 | AL6: 153.83 | AM6: 160.272 | AN6: 194.584
B7: kalorimetr č. | C7: 71182224 | D7: 134.892 | E7: 141.927 | F7: 147.2 | R7: =P7-D7 -> -134.892 | V7: =E7-D7 -> 7.035 | W7: =F7-E7 -> 5.273 | X7: =G7-F7 -> -147.2 | Y7: =H7-G7 -> 0 | Z7: =I7-H7 -> 0 | AA7: =J7-I7 -> 0 | AB7: =K7-J7 -> 0 | AC7: =L7-K7 -> 0 | ... AG7: =P7-O7 -> 0
A8: 3 | B8: vodoměr č. | C8: 241513408 | D8: 48.602 | E8: 52.615 | F8: 56.61 | Q8: =P8-D8 -> -48.602 | U8: 3 | V8: =E8-D8 -> 4.013 | W8: =F8-E8 -> 3.995 | X8: =G8-F8 -> -56.61 | Y8: =H8-G8 -> 0 | Z8: =I8-H8 -> 0 | AA8: =J8-I8 -> 0 | AB8: =K8-J8 -> 0 | AC8: =L8-K8 -> 0 | ... AG8: =P8-O8 -> 0 | AI8: 3 | AJ8: =SUM(V8:AF8) -> -48.602 | AK8: 39.264 | AL8: 38.845 | AM8: 40.903 | AN8: 45.515
B9: kalorimetr č. | C9: 71182236 | D9: 82.227 | E9: 87.342 | F9: 90.895 | R9: =P9-D9 -> -82.227 | V9: =E9-D9 -> 5.115 | W9: =F9-E9 -> 3.553 | X9: =G9-F9 -> -90.895 | Y9: =H9-G9 -> 0 | Z9: =I9-H9 -> 0 | AA9: =J9-I9 -> 0 | AB9: =K9-J9 -> 0 | AC9: =L9-K9 -> 0 | ... AG9: =P9-O9 -> 0
A10: 4 | B10: vodoměr č. | C10: 241513380 | D10: 57.064 | E10: 61.956 | F10: 65.957 | Q10: =P10-D10 -> -57.064 | U10: 4 | V10: =E10-D10 -> 4.892 | W10: =F10-E10 -> 4.001 | X10: =G10-F10 -> -65.957 | Y10: =H10-G10 -> 0 | Z10: =I10-H10 -> 0 | AA10: =J10-I10 -> 0 | AB10: =K10-J10 -> 0 | AC10: =L10-K10 -> 0 | ... AG10: =P10-O10 -> 0 | AI10: 4 | AJ10: =SUM(V10:AF10) -> -57.064 | AK10: 22.183 | AL10: 16.192 | AM10: 13.025 | AN10: 10.867
B11: kalorimetr č. | C11: 71182218 | D11: 11.997 | E11: 12.713 | F11: 13.103 | R11: =P11-D11 -> -11.997 | V11: =E11-D11 -> 0.716 | W11: =F11-E11 -> 0.39 | X11: =G11-F11 -> -13.103 | Y11: =H11-G11 -> 0 | Z11: =I11-H11 -> 0 | AA11: =J11-I11 -> 0 | AB11: =K11-J11 -> 0 | AC11: =L11-K11 -> 0 | ... AG11: =P11-O11 -> 0
A12: 5 | B12: vodoměr č. | C12: 241513406 | D12: 69.183 | E12: 75.947 | F12: 80.707 | Q12: =P12-D12 -> -69.183 | U12: 5 | V12: =E12-D12 -> 6.764 | W12: =F12-E12 -> 4.76 | X12: =G12-F12 -> -80.707 | Y12: =H12-G12 -> 0 | Z12: =I12-H12 -> 0 | AA12: =J12-I12 -> 0 | AB12: =K12-J12 -> 0 | AC12: =L12-K12 -> 0 | ... AG12: =P12-O12 -> 0 | AI12: 5 | AJ12: =SUM(V12:AF12) -> -69.183 | AK12: 55.89 | AL12: 51.191 | AM12: 59.694 | AN12: 66.633
B13: kalorimetr č. | C13: 71182273 | D13: 71.989 | E13: 76.492 | F13: 79.258 | R13: =P13-D13 -> -71.989 | V13: =E13-D13 -> 4.503 | W13: =F13-E13 -> 2.766 | X13: =G13-F13 -> -79.258 | Y13: =H13-G13 -> 0 | Z13: =I13-H13 -> 0 | AA13: =J13-I13 -> 0 | AB13: =K13-J13 -> 0 | AC13: =L13-K13 -> 0 | ... AG13: =P13-O13 -> 0
A14: 6 | B14: vodoměr č. | C14: 241513382 | D14: 71.203 | E14: 76.83 | F14: 81.825 | Q14: =P14-D14 -> -71.203 | U14: 6 | V14: =E14-D14 -> 5.627 | W14: =F14-E14 -> 4.995 | X14: =G14-F14 -> -81.825 | Y14: =H14-G14 -> 0 | Z14: =I14-H14 -> 0 | AA14: =J14-I14 -> 0 | AB14: =K14-J14 -> 0 | AC14: =L14-K14 -> 0 | ... AG14: =P14-O14 -> 0 | AI14: 6 | AJ14: =SUM(V14:AF14) -> -71.203 | AK14: 52.51 | AL14: 43.543 | AM14: 37.147 | AN14: 30.636
B15: kalorimetr č. | C15: 71182215 | D15: 123.199 | E15: 129.636 | F15: 134.165 | R15: =P15-D15 -> -123.199 | V15: =E15-D15 -> 6.437 | W15: =F15-E15 -> 4.529 | X15: =G15-F15 -> -134.165 | Y15: =H15-G15 -> 0 | Z15: =I15-H15 -> 0 | AA15: =J15-I15 -> 0 | AB15: =K15-J15 -> 0 | AC15: =L15-K15 -> 0 | ... AG15: =P15-O15 -> 0
A16: 7 | B16: vodoměr č. | C16: 241513386 | D16: 88.68 | E16: 97.156 | F16: 102.6 | Q16: =P16-D16 -> -88.68 | U16: 7 | V16: =E16-D16 -> 8.476 | W16: =F16-E16 -> 5.444 | X16: =G16-F16 -> -102.6 | Y16: =H16-G16 -> 0 | Z16: =I16-H16 -> 0 | AA16: =J16-I16 -> 0 | AB16: =K16-J16 -> 0 | AC16: =L16-K16 -> 0 | ... AG16: =P16-O16 -> 0 | AI16: 7 | AJ16: =SUM(V16:AF16) -> -88.68 | AK16: 41.961 | AL16: 51.851 | AM16: 14.01 | AN16: 21.309
B17: kalorimetr č. | C17: 71182220 | D17: 26.045 | E17: 28.556 | F17: 30.314 | R17: =P17-D17 -> -26.045 | V17: =E17-D17 -> 2.511 | W17: =F17-E17 -> 1.758 | X17: =G17-F17 -> -30.314 | Y17: =H17-G17 -> 0 | Z17: =I17-H17 -> 0 | AA17: =J17-I17 -> 0 | AB17: =K17-J17 -> 0 | AC17: =L17-K17 -> 0 | ... AG17: =P17-O17 -> 0
A18: 8 | B18: vodoměr č. | C18: 241513387 | D18: 45.596 | E18: 49.416 | F18: 52.74 | Q18: =P18-D18 -> -45.596 | U18: 8 | V18: =E18-D18 -> 3.82 | W18: =F18-E18 -> 3.324 | X18: =G18-F18 -> -52.74 | Y18: =H18-G18 -> 0 | Z18: =I18-H18 -> 0 | AA18: =J18-I18 -> 0 | AB18: =K18-J18 -> 0 | AC18: =L18-K18 -> 0 | ... AG18: =P18-O18 -> 0 | AI18: 8 | AJ18: =SUM(V18:AF18) -> -45.596 | AK18: 34.7 | AL18: 29.064 | AM18: 24.359 | AN18: 19.303
B19: kalorimetr č. | C19: 71182264 | D19: 52.285 | E19: 55.868 | F19: 57.365 | R19: =P19-D19 -> -52.285 | V19: =E19-D19 -> 3.583 | W19: =F19-E19 -> 1.497 | X19: =G19-F19 -> -57.365 | Y19: =H19-G19 -> 0 | Z19: =I19-H19 -> 0 | AA19: =J19-I19 -> 0 | AB19: =K19-J19 -> 0 | AC19: =L19-K19 -> 0 | ... AG19: =P19-O19 -> 0
A20: 9 | B20: vodoměr č. | C20: 241513383 | D20: 84.087 | E20: 90.456 | F20: 93.02 | Q20: =P20-D20 -> -84.087 | U20: 9 | V20: =E20-D20 -> 6.369 | W20: =F20-E20 -> 2.564 | X20: =G20-F20 -> -93.02 | Y20: =H20-G20 -> 0 | Z20: =I20-H20 -> 0 | AA20: =J20-I20 -> 0 | AB20: =K20-J20 -> 0 | AC20: =L20-K20 -> 0 | ... AG20: =P20-O20 -> 0 | AI20: 9 | AJ20: =SUM(V20:AF20) -> -84.087 | AK20: 71.377 | AL20: 71.522 | AM20: 69.057 | AN20: 78.232
B21: kalorimetr č. | C21: 71182231 | D21: 84.504 | E21: 88.888 | F21: 90.831 | R21: =P21-D21 -> -84.504 | V21: =E21-D21 -> 4.384 | W21: =F21-E21 -> 1.943 | X21: =G21-F21 -> -90.831 | Y21: =H21-G21 -> 0 | Z21: =I21-H21 -> 0 | AA21: =J21-I21 -> 0 | AB21: =K21-J21 -> 0 | AC21: =L21-K21 -> 0 | ... AG21: =P21-O21 -> 0
A22: 10 | B22: vodoměr č. | C22: 241513399 | D22: 102.353 | E22: 111.756 | F22: 118.731 | Q22: =P22-D22 -> -102.353 | U22: 10 | V22: =E22-D22 -> 9.403 | W22: =F22-E22 -> 6.975 | X22: =G22-F22 -> -118.731 | Y22: =H22-G22 -> 0 | Z22: =I22-H22 -> 0 | AA22: =J22-I22 -> 0 | AB22: =K22-J22 -> 0 | AC22: =L22-K22 -> 0 | ... AG22: =P22-O22 -> 0 | AI22: 10 | AJ22: =SUM(V22:AF22) -> -102.353 | AK22: 79.075 | AL22: 94.421 | AM22: 141.682 | AN22: 199.088
B23: kalorimetr č. | C23: 71182227 | D23: 67.726 | E23: 71.923 | F23: 74.411 | R23: =P23-D23 -> -67.726 | V23: =E23-D23 -> 4.197 | W23: =F23-E23 -> 2.488 | X23: =G23-F23 -> -74.411 | Y23: =H23-G23 -> 0 | Z23: =I23-H23 -> 0 | AA23: =J23-I23 -> 0 | AB23: =K23-J23 -> 0 | AC23: =L23-K23 -> 0 | ... AG23: =P23-O23 -> 0
Q24: =SUM(Q4:Q23) -> -917.598 | R24: =SUM(R4:R23) -> -814.688 | AI24: byty | AJ24: =SUM(AJ4:AJ22) -> -917.598 | AK24: =SUM(AK4:AK22)+2.6 -> 676.426 | AL24: =SUM(AL4:AL22) -> 675.109 | AM24: =SUM(AM4:AM22) -> 703.904 | AN24: =SUM(AN4:AN22) -> 832.723
A25: spol.spotř. | B25: elektroměr č. | C25: 72846558 | D25: 6197 | E25: 6586 | F25: 6847 | S25: =P25-D25 -> -6197
B26: patní vodoměr č. | C26: 241175209 | D26: 973.3 | E26: 1059.9 | F26: 1132.1 | Q26: =P26-D26 -> -973.3 | AI26: pata | AJ26: =O26-D26 -> -973.3 | AK26: 785.2 | AL26: 771.6 | AM26: 795 | AN26: 949.4
B27: patní kalorimetr č./GJ | C27: 70465264 | D27: 1197.4 | E27: 1249.07 | F27: 1280.75 | R27: =P27-D27 -> -1197.4 | S27: GJ
B28: patní kalorimetr č./kub.m | D28: 8361 | E28: 8784 | F28: 9002 | R28: =P28-D28 -> -8361 | S28: m3
A29: ='1854'!A29 -> Fakturační vodoměr: | C29: ='1854'!C29 -> 42012114941 | D29: ='1854'!D29 -> 211 | E29: ='1854'!E29 -> 537.6 | F29: ='1854'!F29 -> 814.4 | G29: ='1854'!G29 -> 0 | H29: ='1854'!H29 -> 0 | I29: ='1854'!I29 -> 0 | J29: ='1854'!J29 -> 0 | ... Q29: ='1854'!Q29 -> -211 | X29: zápočet rozdílu nových vodoměrů | Y29: 2.6 | Z29: m3 | AJ29: =1-AJ24/AJ26 -> 0.057230042 | AK29: =1-AK24/AK26 -> 0.13853031 | AL29: =1-AL24/AL26 -> 0.12505314 | AM29: =1-AM24/AM26 -> 0.11458616 | AN29: =1-AN24/AN26 -> 0.12289551
E32: Výměna kalorimetru pata | H32: MWh | I32: m3 | K32: Výměna faktur.vodoměru výr.č. | N32: m3
D33: demontáž | E33: 43984 | F33: starý | K33: 44095 | L33: starý
G34: výr.č. | H34: GJ | I34: m3 | M34: výr.č. | N34: m3
D35: montáž | E35: 43986 | F35: nový | K35: 44095 | L35: nový
C37: Výměna elektroměru DŮM
C38: 45415 | D38: starý | E38: 72370870
D39: nový | E39: 72846558
B41: 17.5.2024 reset rohoží | C41: 79:00 hod

Sheet 1856
A2: 1856 | D2: ='1850'!D2 -> 46022 | E2: ='1850'!E2 -> 46055 | F2: ='1850'!F2 -> 46083 | Q2: Voda | R2: Teplo | S2: Elektr | Z2: spotřeby po měsících
A3: byt č. | D3: prosinec | E3: leden | F3: únor | G3: březen | H3: duben | I3: květen | J3: červen | K3: červenec | L3: srpen | M3: září | N3: říjen | O3: listopad | P3: prosinec | Q3: m3 | R3: GJ | S3: KWh | U3: byt | V3: leden | W3: únor | X3: březen | Y3: duben | Z3: květen | AA3: červen | AB3: červenec | AC3: srpen | AD3: září | AE3: říjen | AF3: listopad | AG3: prosinec
A4: 1 | B4: vodoměr č. | C4: 241345680 | D4: 146.869 | E4: 158.773 | F4: 167.288 | Q4: =P4-D4 -> -146.869 | U4: 1 | V4: =E4-D4 -> 11.904 | W4: =F4-E4 -> 8.515 | X4: =G4-F4 -> -167.288 | Y4: =H4-G4 -> 0 | Z4: =I4-H4 -> 0 | AA4: =J4-I4 -> 0 | AB4: =K4-J4 -> 0 | AC4: =L4-K4 -> 0 | ... AG4: =P4-O4 -> 0
B5: kalorimetr č. | C5: 71869912 | D5: 72.937 | E5: 80.614 | F5: 85.211 | R5: =P5-D5 -> -72.937
