Workbook

Sheet 1850
A2: 1850 | C2: 45292 | D2: 45323 | E2: 45352 | F2: 45383 | G2: 45413 | H2: 45444 | I2: 45474 | J2: 45505 | K2: 45536 | L2: 45566 | M2: 45597 | N2: 45628 | O2: 45658 | P2: voda | Q2: teplo | R2: Elektr | Y2: spotřeby po měsících
A3: byt č. | C3: prosinec | D3: leden | E3: únor | F3: březen | G3: duben | H3: květen | I3: červen | J3: červenec | K3: srpen | L3: září | M3: říjen | N3: listopad | O3: prosinec | P3: m3 | Q3: GJ | R3: KWh | T3: byt | U3: leden | V3: únor | W3: březen | X3: duben | Y3: květen | Z3: červen | AA3: červenec | AB3: srpen | AC3: září | AD3: říjen | AE3: listopad | AF3: prosinec
A4: 1 | B4: vodoměr č. 190834092 | C4: 49.332 | D4: 50.154 | E4: 50.887 | F4: 51.667 | G4: 52.689 | H4: 53.583 | I4: 54.908 | J4: 55.022 | K4: 55.626 | L4: 55.627 | M4: 55.634 | N4: 55.634 | O4: 3.829 | P4: =O4+N4-C4 -> 10.131 | T4: 1 | U4: =D4-C4 -> 0.822 | V4: =E4-D4 -> 0.733 | W4: =F4-E4 -> 0.78 | X4: =G4-F4 -> 1.022 | Y4: =H4-G4 -> 0.894 | Z4: =I4-H4 -> 1.325 | AA4: =J4-I4 -> 0.114 | AB4: =K4-J4 -> 0.604 | ... AE4: =N4-M4 -> 0 | AF4: =O4 -> 3.829
B5: kalorimetr č. 71182278 | C5: 44.448 | D5: 50.231 | E5: 53.821 | F5: 56.339 | G5: 57.615 | H5: 57.831 | I5: 58.074 | J5: 58.266 | K5: 58.468 | L5: 62.508 | M5: 62.694 | N5: 62.855 | O5: 67.779 | Q5: =O5-C5 -> 23.331 | Z5: =I5-H5 -> 0.243 | AA5: =J5-I5 -> 0.192 | AB5: =K5-J5 -> 0.202 | AC5: =L5-K5 -> 4.04 | AD5: =M5-L5 -> 0.186 | AE5: =N5-M5 -> 0.161 | AF5: =O5-N5 -> 4.924
A6: 2 | B6: vodoměr č. 190834090 | C6: 739.504 | D6: 755.43 | E6: 769.86 | F6: 788.743 | G6: 804.74 | H6: 820.062 | I6: 835.326 | J6: 846.381 | K6: 861.315 | L6: 875.875 | M6: 890.189 | N6: 904.19 | O6: 19.095 | P6: =O6+N6-C6 -> 183.781 | T6: 2 | U6: =D6-C6 -> 15.926 | V6: =E6-D6 -> 14.43 | W6: =F6-E6 -> 18.883 | X6: =G6-F6 -> 15.997 | Y6: =H6-G6 -> 15.322 | Z6: =I6-H6 -> 15.264 | AA6: =J6-I6 -> 11.055 | AB6: =K6-J6 -> 14.934 | ... AE6: =N6-M6 -> 14.001 | AF6: =O6 -> 19.095
B7: kalorimetr č. 71182225 | C7: 57.354 | D7: 62.234 | E7: 65.287 | F7: 67.647 | G7: 68.723 | H7: 69.623 | I7: 70.401 | J7: 70.823 | K7: 71.312 | L7: 71.917 | M7: 73.374 | N7: 77.842 | O7: 83.238 | Q7: =O7-C7 -> 25.884 | Z7: =I7-H7 -> 0.778 | AA7: =J7-I7 -> 0.422 | AB7: =K7-J7 -> 0.489 | AC7: =L7-K7 -> 0.605 | AD7: =M7-L7 -> 1.457 | AE7: =N7-M7 -> 4.468 | AF7: =O7-N7 -> 5.396
A8: 3 | B8: vodoměr č. 190834097 | C8: 291.679 | D8: 295.83 | E8: 301.664 | F8: 307.011 | G8: 312.818 | H8: 318.655 | I8: 324.165 | J8: 329.835 | K8: 335.017 | L8: 338.764 | M8: 343.898 | N8: 348.91 | O8: 6.06 | P8: =O8+N8-C8 -> 63.291 | T8: 3 | U8: =D8-C8 -> 4.151 | V8: =E8-D8 -> 5.834 | W8: =F8-E8 -> 5.347 | X8: =G8-F8 -> 5.807 | Y8: =H8-G8 -> 5.837 | Z8: =I8-H8 -> 5.51 | AA8: =J8-I8 -> 5.67 | AB8: =K8-J8 -> 5.182 | ... AE8: =N8-M8 -> 5.012 | AF8: =O8 -> 6.06
B9: kalorimetr č. 71182284 | C9: 43.117 | D9: 45.895 | E9: 47.665 | F9: 48.77 | G9: 49.554 | H9: 50.025 | I9: 50.443 | J9: 50.807 | K9: 51.133 | L9: 51.405 | M9: 52.929 | N9: 56.927 | O9: 60.193 | Q9: =O9-C9 -> 17.076 | Z9: =I9-H9 -> 0.418 | AA9: =J9-I9 -> 0.364 | AB9: =K9-J9 -> 0.326 | AC9: =L9-K9 -> 0.272 | AD9: =M9-L9 -> 1.524 | AE9: =N9-M9 -> 3.998 | AF9: =O9-N9 -> 3.266
A10: 4 | B10: vodoměr č. 190834098 | C10: 443.676 | D10: 453.808 | E10: 463.137 | F10: 472.667 | G10: 482.13 | H10: 491.337 | I10: 500.048 | J10: 507.927 | K10: 516.532 | L10: 526.596 | M10: 537.805 | N10: 547.83 | O10: 12.77 | P10: =O10+N10-C10 -> 116.924 | T10: 4 | U10: =D10-C10 -> 10.132 | V10: =E10-D10 -> 9.329 | W10: =F10-E10 -> 9.53 | X10: =G10-F10 -> 9.463 | Y10: =H10-G10 -> 9.207 | Z10: =I10-H10 -> 8.711 | AA10: =J10-I10 -> 7.879 | AB10: =K10-J10 -> 8.605 | ... AE10: =N10-M10 -> 10.025 | AF10: =O10 -> 12.77
B11: kalorimetr č. 71182235 | C11: 29.642 | D11: 30.995 | E11: 31.891 | F11: 32.774 | G11: 33.619 | H11: 34.403 | I11: 35.033 | J11: 35.556 | K11: 36.039 | L11: 36.704 | M11: 37.661 | N11: 39.161 | O11: 40.877 | Q11: =O11-C11 -> 11.235 | Z11: =I11-H11 -> 0.63 | AA11: =J11-I11 -> 0.523 | AB11: =K11-J11 -> 0.483 | AC11: =L11-K11 -> 0.665 | AD11: =M11-L11 -> 0.957 | AE11: =N11-M11 -> 1.5 | AF11: =O11-N11 -> 1.716
A12: 5 | B12: vodoměr č. 190834095 | C12: 357.076 | D12: 365 | E12: 371.838 | F12: 381.096 | G12: 389.621 | H12: 399.637 | I12: 409.148 | J12: 418.559 | K12: 428.878 | L12: 435.395 | M12: 445.289 | N12: 453.9 | O12: 9.296 | P12: =O12+N12-C12 -> 106.12 | T12: 5 | U12: =D12-C12 -> 7.924 | V12: =E12-D12 -> 6.838 | W12: =F12-E12 -> 9.258 | X12: =G12-F12 -> 8.525 | Y12: =H12-G12 -> 10.016 | Z12: =I12-H12 -> 9.511 | AA12: =J12-I12 -> 9.411 | AB12: =K12-J12 -> 10.319 | ... AE12: =N12-M12 -> 8.611 | AF12: =O12 -> 9.296
B13: kalorimetr č. 71182238 | C13: 37.944 | D13: 41.89 | E13: 44.019 | F13: 46.108 | G13: 47.2 | H13: 47.833 | I13: 48.438 | J13: 48.985 | K13: 49.497 | L13: 49.831 | M13: 50.855 | N13: 54.139 | O13: 57.859 | Q13: =O13-C13 -> 19.915 | Z13: =I13-H13 -> 0.605 | AA13: =J13-I13 -> 0.547 | AB13: =K13-J13 -> 0.512 | AC13: =L13-K13 -> 0.334 | AD13: =M13-L13 -> 1.024 | AE13: =N13-M13 -> 3.284 | AF13: =O13-N13 -> 3.72
A14: 6 | B14: vodoměr č. 190834099 | C14: 375.966 | D14: 381.468 | E14: 385.76 | F14: 390.978 | G14: 395.355 | H14: 400.484 | I14: 407.414 | J14: 411.747 | K14: 416.963 | L14: 421.823 | M14: 425.903 | N14: 430.26 | O14: 7.545 | P14: =O14+N14-C14 -> 61.839 | T14: 6 | U14: =D14-C14 -> 5.502 | V14: =E14-D14 -> 4.292 | W14: =F14-E14 -> 5.218 | X14: =G14-F14 -> 4.377 | Y14: =H14-G14 -> 5.129 | Z14: =I14-H14 -> 6.93 | AA14: =J14-I14 -> 4.333 | AB14: =K14-J14 -> 5.216 | ... AE14: =N14-M14 -> 4.357 | AF14: =O14 -> 7.545
B15: kalorimetr č. 71182269 | C15: 63.645 | D15: 70.4 | E15: 74.242 | F15: 76.988 | G15: 78.838 | H15: 79.321 | I15: 79.84 | J15: 80.155 | K15: 80.533 | L15: 80.905 | M15: 81.314 | N15: 85.045 | O15: 91.113 | Q15: =O15-C15 -> 27.468 | Z15: =I15-H15 -> 0.519 | AA15: =J15-I15 -> 0.315 | AB15: =K15-J15 -> 0.378 | AC15: =L15-K15 -> 0.372 | AD15: =M15-L15 -> 0.409 | AE15: =N15-M15 -> 3.731 | AF15: =O15-N15 -> 6.068
A16: 7 | B16: vodoměr č. 190834102 | C16: 68.381 | D16: 69.716 | E16: 70.628 | F16: 72.061 | G16: 73.545 | H16: 74.675 | I16: 75.79 | J16: 77.052 | K16: 78.163 | L16: 79.423 | M16: 80.839 | N16: 82.07 | O16: 4.463 | P16: =O16+N16-C16 -> 18.152 | T16: 7 | U16: =D16-C16 -> 1.335 | V16: =E16-D16 -> 0.912 | W16: =F16-E16 -> 1.433 | X16: =G16-F16 -> 1.484 | Y16: =H16-G16 -> 1.13 | Z16: =I16-H16 -> 1.115 | AA16: =J16-I16 -> 1.262 | AB16: =K16-J16 -> 1.111 | ... AE16: =N16-M16 -> 1.231 | AF16: =O16 -> 4.463
B17: kalorimetr č. 71182265 | C17: 16.056 | D17: 17.506 | E17: 17.945 | F17: 18.15 | G17: 18.327 | H17: 18.409 | I17: 18.5 | J17: 18.579 | K17: 18.648 | L17: 18.732 | M17: 18.871 | N17: 19.66 | O17: 21.004 | Q17: =O17-C17 -> 4.948 | Z17: =I17-H17 -> 0.091 | AA17: =J17-I17 -> 0.079 | AB17: =K17-J17 -> 0.069 | AC17: =L17-K17 -> 0.084 | AD17: =M17-L17 -> 0.139 | AE17: =N17-M17 -> 0.789 | AF17: =O17-N17 -> 1.344
A18: 8 | B18: vodoměr č. 200015742 | C18: 74.952 | D18: 76.1 | E18: 77.053 | F18: 78.551 | G18: 79.749 | H18: 81.317 | I18: 82.004 | J18: 83.116 | K18: 83.895 | L18: 85.531 | M18: 86.56 | N18: 87.22 | O18: 0.446 | P18: =O18+N18-C18 -> 12.714 | T18: 8 | U18: =D18-C18 -> 1.148 | V18: =E18-D18 -> 0.953 | W18: =F18-E18 -> 1.498 | X18: =G18-F18 -> 1.198 | Y18: =H18-G18 -> 1.568 | Z18: =I18-H18 -> 0.687 | AA18: =J18-I18 -> 1.112 | AB18: =K18-J18 -> 0.779 | ... AE18: =N18-M18 -> 0.66 | AF18: =O18 -> 0.446
B19: kalorimetr č. 71182245 | C19: 47.294 | D19: 51.103 | E19: 53.466 | F19: 55.253 | G19: 56.174 | H19: 56.584 | I19: 56.745 | J19: 56.907 | K19: 57.057 | L19: 57.25 | M19: 58.346 | N19: 59.88 | O19: 62.224 | Q19: =O19-C19 -> 14.93 | Z19: =I19-H19 -> 0.161 | AA19: =J19-I19 -> 0.162 | AB19: =K19-J19 -> 0.15 | AC19: =L19-K19 -> 0.193 | AD19: =M19-L19 -> 1.096 | AE19: =N19-M19 -> 1.534 | AF19: =O19-N19 -> 2.344
A20: 9 | B20: vodoměr č. 190834109 | C20: 2.702 | D20: 2.72 | E20: 7.248 | F20: 9.868 | G20: 9.889 | H20: 9.912 | I20: 9.938 | J20: 9.961 | K20: 9.993 | L20: 13.953 | M20: 17.777 | N20: 20 | O20: 0.073 | P20: =O20+N20-C20 -> 17.371 | T20: 9 | U20: =D20-C20 -> 0.018 | V20: =E20-D20 -> 4.528 | W20: =F20-E20 -> 2.62 | X20: =G20-F20 -> 0.021 | Y20: =H20-G20 -> 0.023 | Z20: =I20-H20 -> 0.026 | AA20: =J20-I20 -> 0.023 | AB20: =K20-J20 -> 0.032 | ... AE20: =N20-M20 -> 2.223 | AF20: =O20 -> 0.073
B21: kalorimetr č. 71182280 | C21: 4.222 | D21: 4.382 | E21: 7.309 | F21: 8.353 | G21: 8.528 | H21: 8.694 | I21: 8.851 | J21: 9.006 | K21: 9.152 | L21: 9.509 | M21: 10.265 | N21: 11.865 | O21: 12.012 | Q21: =O21-C21 -> 7.79 | Z21: =I21-H21 -> 0.157 | AA21: =J21-I21 -> 0.155 | AB21: =K21-J21 -> 0.146 | AC21: =L21-K21 -> 0.357 | AD21: =M21-L21 -> 0.756 | AE21: =N21-M21 -> 1.6 | AF21: =O21-N21 -> 0.147
A22: 10 | B22: vodoměr č. 191519263 | C22: 357.404 | D22: 363.717 | E22: 370.673 | F22: 377.626 | G22: 384.35 | H22: 390.688 | I22: 397.736 | J22: 402.689 | K22: 409.62 | L22: 418.014 | M22: 426.629 | N22: 433.77 | O22: 8.359 | P22: =O22+N22-C22 -> 84.725 | T22: 10 | U22: =D22-C22 -> 6.313 | V22: =E22-D22 -> 6.956 | W22: =F22-E22 -> 6.953 | X22: =G22-F22 -> 6.724 | Y22: =H22-G22 -> 6.338 | Z22: =I22-H22 -> 7.048 | AA22: =J22-I22 -> 4.953 | AB22: =K22-J22 -> 6.931 | ... AE22: =N22-M22 -> 7.141 | AF22: =O22 -> 8.359
B23: kalorimetr č. 71182243 | C23: 48.342 | D23: 53.217 | E23: 55.863 | F23: 57.874 | G23: 58.38 | H23: 58.821 | I23: 59.234 | J23: 59.508 | K23: 59.814 | L23: 60.184 | M23: 61.061 | N23: 64.95 | O23: 68.947 | Q23: =O23-C23 -> 20.605 | Z23: =I23-H23 -> 0.413 | AA23: =J23-I23 -> 0.274 | AB23: =K23-J23 -> 0.306 | AC23: =L23-K23 -> 0.37 | AD23: =M23-L23 -> 0.877 | AE23: =N23-M23 -> 3.889 | AF23: =O23-N23 -> 3.997
P24: =SUM(P4:P23) -> 675.048 | Q24: =SUM(Q4:Q23) -> 173.182
A25: spol.spotř. | B25: elektroměr č. 1025291034 | C25: 4886 | D25: 5055 | E25: 5292 | F25: 5468 | G25: 5652 | H25: 5840 | I25: 6059 | J25: 6245 | K25: 6421 | L25: 6595 | M25: 6857 | N25: 7052 | O25: 7220 | R25: =O25-C25 -> 2334
B26: patní vodoměr č. 190976787 | C26: 3172 | D26: 3232.6 | E26: 3294.8 | F26: 3366 | G26: 3430 | H26: 3493.9 | I26: 3558.9 | J26: 3611.7 | K26: 3671.6 | L26: 3733.8 | M26: 3801.3 | N26: 3862.3 | O26: 79.1 | P26: =O26+N26-C26 -> 769.4
B27: patní kalorimetr č./ GJ | C27: 67.3 | D27: 106.62 | E27: 132.18 | F27: 150.02 | G27: 158.13 | H27: 161.18 | I27: 163.44 | J27: 164.75 | K27: 165.96 | L27: 167.99 | M27: 174.16 | N27: 197.97 | O27: 227.97 | Q27: =(O27-C27) -> 160.67 | R27: GJ
B28: patní kalorimetr č./kub.m | C28: 564 | D28: 928 | E28: 1124 | F28: 1268 | G28: 1342 | H28: 1376 | I28: 1401 | J28: 1418 | K28: 1434 | L28: 1456 | M28: 1513 | N28: 1708 | O28: 1970 | Q28: =O28-C28 -> 1406 | R28: m3
A29: fakturační vodoměr č. 63796 | C29: 24212 | D29: 24552.7 | E29: 24857.7 | F29: 25187.3 | G29: 25525.5 | H29: 25865 | I29: 26188.7 | J29: 26482.4 | K29: 26791.4 | L29: 27107 | M29: 27434.1 | N29: 27732.5 | O29: 28101 | P29: =O29-C29 -> 3889
C31: číslo | E31: stav
B32: Výměna fakturač. vodoměru | C32: 110109308 | D32: starý | E32: 12875 | H32: Dne 31.7.2023 odpojen kalor. (cejchování), | L32: stav: | M32: 210.8 | N32: MWh
B33: dne 14.2.2019 | C33: 63796 | D33: nový | E33: 4174 | H33: Dne 3.8.2023 zapojen znovuzapojení, | L33: stav: | M33: 0 | N33: GJ
B34: Výměna elekroměru | C34: 18972503 | D34: starý
B35: dne 13.2.2022 | C35: 1025291034 | D35: nový
N37: Odečet vodárny 31.12.2023 | O37: =C29 -> 24212
N39: Odečet vodárny 31.12.2024 | O39: =O29 -> 28101
N41: spotřeba | O41: =O39-O37-O38 -> 3889

Sheet 1851
AE1: Vytipování vadných vodoměrů
A2: Nové | B2: 1851 | D2: ='1850'!C2 -> 45292 | E2: ='1850'!D2 -> 45323 | F2: ='1850'!E2 -> 45352 | G2: ='1850'!F2 -> 45383 | H2: ='1850'!G2 -> 45413 | I2: ='1850'!H2 -> 45444 | J2: ='1850'!I2 -> 45474 | K2: ='1850'!J2 -> 45505 | ... P2: ='1850'!O2 -> 45658 | Q2: voda | R2: teplo | S2: Elektr | Z2: spotřeby po měsících | AH2: předloňský | AK2: Podíl teplé vody na celkové spotřebě vody u dělených bytů (%) | AV2: CELKOVÝ | AW2: =(AW6+AW12+AW14+AW18+AW54+AW56+AW58+AW60+AW62)/9 -> 0.3496029
A3: číslování | B3: byt č. | D3: prosinec | E3: leden | F3: únor | G3: březen | H3: duben | I3: květen | J3: červen | K3: červenec | L3: srpen | M3: září | N3: říjen | O3: listopad | P3: prosinec | Q3: m3 | R3: GJ | S3: KWh | U3: byt | V3: leden | W3: únor | X3: březen | Y3: duben | Z3: květen | AA3: červen | AB3: červenec | AC3: srpen | AD3: září | AE3: říjen | AF3: listopad | AG3: prosinec | AH3: průměr | AK3: 1. | AL3: 2. | AM3: 3. | AN3: 4. | AO3: 5. | AP3: 6. | AQ3: 7. | AR3: 8. | AS3: 9. | AT3: 10. | AU3: 11. | AV3: 12. | AW3: Průměr
A4: 1 | B4: 1 | C4: vodoměr č. 190834116 | D4: 682.225 | E4: 695.862 | F4: 709.479 | G4: 721.811 | H4: 734.592 | I4: 749.688 | J4: 761.126 | K4: 775.137 | L4: 790.402 | M4: 804.17 | N4: 820.295 | O4: 833.69 | P4: 15.011 | Q4: =P4+O4-D4 -> 166.476 | U4: 1 | V4: =E4-D4 -> 13.637 | W4: =F4-E4 -> 13.617 | X4: =G4-F4 -> 12.332 | Y4: =H4-G4 -> 12.781 | Z4: =I4-H4 -> 15.096 | AA4: =J4-I4 -> 11.438 | AB4: =K4-J4 -> 14.011 | AC4: =L4-K4 -> 15.265 | ... AF4: =O4-N4 -> 13.395 | AG4: =P4 -> 15.011 | AH4: 11.905222
C5: kalorimetr č. 71182262 | D5: 64.751 | E5: 69.694 | F5: 72.949 | G5: 75.384 | H5: 77.25 | I5: 78.37 | J5: 79.19 | K5: 79.95 | L5: 80.661 | M5: 81.472 | N5: 83.573 | O5: 87.433 | P5: 91.799 | R5: =P5-D5 -> 27.048 | U5: xx
A6: 2 | B6: 2 | C6: vodoměr SV č. 190834120 | D6: 261.012 | E6: 265.817 | F6: 269.734 | G6: 274.054 | H6: 278.031 | I6: 280.424 | J6: 283.56 | K6: 286.002 | L6: 290.129 | M6: 297.287 | N6: 304.812 | O6: 310.53 | P6: 7.346 | Q6: =P6+O6-D6 -> 56.864 | U6: 2 | V6: =E6-D6 -> 4.805 | W6: =F6-E6 -> 3.917 | X6: =G6-F6 -> 4.32 | Y6: =H6-G6 -> 3.977 | Z6: =I6-H6 -> 2.393 | AA6: =J6-I6 -> 3.136 | AB6: =K6-J6 -> 2.442 | AC6: =L6-K6 -> 4.127 | ... AF6: =O6-N6 -> 5.718 | AG6: =P6 -> 7.346 | AH6: 4.9828889 | AJ6: byt 2 | AK6: =V7/(V6+V7) -> 0.45422535 | AL6: =W7/(W6+W7) -> 0.43502091 | AM6: =X7/(X6+X7) -> 0.40902873 | AN6: =Y7/(Y6+Y7) -> 0.39769802 | AO6: =Z7/(Z6+Z7) -> 0.3681014 | AP6: =AA7/(AA6+AA7) -> 0.30140343 | AQ6: =AB7/(AB6+AB7) -> 0.24953903 | AR6: =AC7/(AC6+AC7) -> 0.23968312 | ... AV6: =AG7/(AG6+AG7) -> 0.343521 | AW6: =SUM(AK6:AV6)/12 -> 0.34393874
A7: 2 a 3 | C7: kalorimetr č. 71182271 | D7: 78.034 | E7: 84.406 | F7: 88.574 | G7: 91.764 | H7: 93.764 | I7: 94.562 | J7: 95.338 | K7: 95.877 | L7: 96.489 | M7: 97.842 | N7: 100.452 | O7: 105.918 | P7: 111.032 | R7: =P7-D7 -> 32.998 | U7: TV | V7: =V40 -> 3.999 | W7: =W40 -> 3.016 | X7: =X40 -> 2.99 | Y7: =Y40 -> 2.626 | Z7: =Z40 -> 1.394 | AA7: =AA40 -> 1.353 | AB7: =AB40 -> 0.812 | AC7: =AC40 -> 1.301 | ... AG7: =AG40 -> 3.844 | AH7: 4.43
A8: 5 | B8: 3 | C8: vodoměr SV č. 221525378 | D8: 14.203 | E8: 15.285 | F8: 16.69 | G8: 18.16 | H8: 19.468 | I8: 20.824 | J8: 21.969 | K8: 23.047 | L8: 24.144 | M8: 25.382 | N8: 26.583 | O8: 27.6 | P8: 1.227 | Q8: =P8+O8-D8 -> 14.624 | U8: 5 | V8: =E8-D8 -> 1.082 | W8: =F8-E8 -> 1.405 | X8: =G8-F8 -> 1.47 | Y8: =H8-G8 -> 1.308 | Z8: =I8-H8 -> 1.356 | AA8: =J8-I8 -> 1.145 | AB8: =K8-J8 -> 1.078 | AC8: =L8-K8 -> 1.097 | ... AF8: =O8-N8 -> 1.017 | AG8: =P8 -> 1.227 | AH8: 0.94022222 | AJ8: byt 5 | AK8: =V9/(V8+V9) -> 0.25686813 | AL8: =W9/(W8+W9) -> 0.19760137 | AM8: =X9/(X8+X9) -> 0.20711974 | AN8: =Y9/(Y8+Y9) -> 0.2228164 | AO8: =Z9/(Z8+Z9) -> 0.21345708 | AP8: =AA9/(AA8+AA9) -> 0.23051075 | AQ8: =AB9/(AB8+AB9) -> 0.22109827 | AR8: =AC9/(AC8+AC9) -> 0.21418338 | ... AV8: =AG9/(AG8+AG9) -> 0.25091575 | AW8: =SUM(AK8:AV8)/12 -> 0.22017804
A9: 5 a 6 | C9: kalorimetr č. 71182241 | D9: 100 | E9: 105.293 | F9: 109.095 | G9: 111.465 | H9: 112.882 | I9: 113.288 | J9: 113.443 | K9: 113.562 | L9: 113.647 | M9: 114.066 | N9: 115.589 | O9: 119.579 | P9: 124.131 | R9: =P9-D9 -> 24.131 | U9: TV | V9: =V42 -> 0.374 | W9: =W42 -> 0.346 | X9: =X42 -> 0.384 | Y9: =Y42 -> 0.375 | Z9: =Z42 -> 0.368 | AA9: =AA42 -> 0.343 | AB9: =AB42 -> 0.306 | AC9: =AC42 -> 0.299 | ... AG9: =AG42 -> 0.411 | AH9: 0.37122222
A10: 4 | B10: 4 | C10: vodoměr č. 190834126 | D10: 201.491 | E10: 209.237 | F10: 217.032 | G10: 225.9 | H10: 233.537 | I10: 241.45 | J10: 246.204 | K10: 251.381 | L10: 256.872 | M10: 263.764 | N10: 271.355 | O10: 278.83 | P10: 9.465 | Q10: =P10+O10-D10 -> 86.804 | U10: 4 | V10: =E10-D10 -> 7.746 | W10: =F10-E10 -> 7.795 | X10: =G10-F10 -> 8.868 | Y10: =H10-G10 -> 7.637 | Z10: =I10-H10 -> 7.913 | AA10: =J10-I10 -> 4.754 | AB10: =K10-J10 -> 5.177 | AC10: =L10-K10 -> 5.491 | ... AF10: =O10-N10 -> 7.475 | AG10: =P10 -> 9.465 | AH10: 5.9373333
C11: kalorimetr č. 71182237 | D11: 10.27 | E11: 12.122 | F11: 13.196 | G11: 13.994 | H11: 14.517 | I11: 14.969 | J11: 15.208 | K11: 15.399 | L11: 15.601 | M11: 15.907 | N11: 16.333 | O11: 17.821 | P11: 19.687 | R11: =P11-D11 -> 9.417 | U11: xx
A12: 9 | B12: 5 | C12: vodoměr SV č. 190834122 | D12: 229.006 | E12: 233.118 | F12: 237.566 | G12: 243.339 | H12: 248.685 | I12: 253.476 | J12: 258.943 | K12: 264.09 | L12: 269.661 | M12: 272.665 | N12: 275.714 | O12: 275.724 | P12: 1.517 | Q12: =P12+O12-D12 -> 48.235 | U12: 9 | V12: =E12-D12 -> 4.112 | W12: =F12-E12 -> 4.448 | X12: =G12-F12 -> 5.773 | Y12: =H12-G12 -> 5.346 | Z12: =I12-H12 -> 4.791 | AA12: =J12-I12 -> 5.467 | AB12: =K12-J12 -> 5.147 | AC12: =L12-K12 -> 5.571 | ... AF12: =O12-N12 -> 0.01 | AG12: =P12 -> 1.517 | AH12: 4.7323333 | AJ12: byt 9 | AK12: =V13/(V12+V13) -> 0.22121212 | AL12: =W13/(W12+W13) -> 0.23349991 | AM12: =X13/(X12+X13) -> 0.20961117 | AN12: =Y13/(Y12+Y13) -> 0.20764784 | AO12: =Z13/(Z12+Z13) -> 0.2063939 | AP12: =AA13/(AA12+AA13) -> 0.19673817 | AQ12: =AB13/(AB12+AB13) -> 0.1748958 | AR12: =AC13/(AC12+AC13) -> 0.1427912 | ... AV12: =AG13/(AG12+AG13) -> 0.47435897 | AW12: =SUM(AK12:AV12)/12 -> 0.23984402
A13: 8 a 9 | C13: kalorimetr č. 71182221 | D13: 64.284 | E13: 69.641 | F13: 73.116 | G13: 76.425 | H13: 78.908 | I13: 80.529 | J13: 81.451 | K13: 82.15 | L13: 82.704 | M13: 83.867 | N13: 86.599 | O13: 91.005 | P13: 95.26 | R13: =P13-D13 -> 30.976 | U13: TV | V13: =V44 -> 1.168 | W13: =W44 -> 1.355 | X13: =X44 -> 1.531 | Y13: =Y44 -> 1.401 | Z13: =Z44 -> 1.246 | AA13: =AA44 -> 1.339 | AB13: =AB44 -> 1.091 | AC13: =AC44 -> 0.928 | ... AG13: =AG44 -> 1.369 | AH13: 4.7182222
A14: 15 | B14: 6 | C14: vodoměr SV č. 200015757 | D14: 189.371 | E14: 190.459 | F14: 191.354 | G14: 192.22 | H14: 193.627 | I14: 194.447 | J14: 195.322 | K14: 196.225 | L14: 197.638 | M14: 198.988 | N14: 200.365 | O14: 201.91 | P14: 2.171 | Q14: =P14+O14-D14 -> 14.71 | U14: 15 | V14: =E14-D14 -> 1.088 | W14: =F14-E14 -> 0.895 | X14: =G14-F14 -> 0.866 | Y14: =H14-G14 -> 1.407 | Z14: =I14-H14 -> 0.82 | AA14: =J14-I14 -> 0.875 | AB14: =K14-J14 -> 0.903 | AC14: =L14-K14 -> 1.413 | ... AF14: =O14-N14 -> 1.545 | AG14: =P14 -> 2.171 | AH14: 1.6821111 | AJ14: byt 15 | AK14: =V15/(V14+V15) -> 0.55207904 | AL14: =W15/(W14+W15) -> 0.63882163 | AM14: =X15/(X14+X15) -> 0.58425348 | AN14: =Y15/(Y14+Y15) -> 0.59510791 | AO14: =Z15/(Z14+Z15) -> 0.5030303 | AP14: =AA15/(AA14+AA15) -> 0.39530062 | AQ14: =AB15/(AB14+AB15) -> 0.46694215 | AR14: =AC15/(AC14+AC15) -> 0.45486111 | ... AV14: =AG15/(AG14+AG15) -> 0.46222442 | AW14: =SUM(AK14:AV14)/12 -> 0.48027609
A15: 11 a 15 | C15: kalorimetr č. 71182276 | D15: 39.081 | E15: 41.567 | F15: 42.459 | G15: 44.957 | H15: 46.652 | I15: 47.002 | J15: 47.26 | K15: 47.564 | L15: 47.907 | M15: 48.16 | N15: 48.465 | O15: 49.296 | P15: 52.481 | R15: =P15-D15 -> 13.4 | U15: TV | V15: =V46 -> 1.341 | W15: =W46 -> 1.583 | X15: =X46 -> 1.217 | Y15: =Y46 -> 2.068 | Z15: =Z46 -> 0.83 | AA15: =AA46 -> 0.572 | AB15: =AB46 -> 0.791 | AC15: =AC46 -> 1.179 | ... AG15: =AG46 -> 1.866 | AH15: 0.73344444
A16: 7 | B16: 7 | C16: vodoměr č. 190834119 | D16: 288.419 | E16: 295.294 | F16: 299.749 | G16: 301.407 | H16: 307.46 | I16: 313.17 | J16: 317.535 | K16: 323.061 | L16: 328.924 | M16: 334.539 | N16: 340.534 | O16: 345.75 | P16: 6.863 | Q16: =P16+O16-D16 -> 64.194 | U16: 7 | V16: =E16-D16 -> 6.875 | W16: =F16-E16 -> 4.455 | X16: =G16-F16 -> 1.658 | Y16: =H16-G16 -> 6.053 | Z16: =I16-H16 -> 5.71 | AA16: =J16-I16 -> 4.365 | AB16: =K16-J16 -> 5.526 | AC16: =L16-K16 -> 5.863 | ... AF16: =O16-N16 -> 5.216 | AG16: =P16 -> 6.863 | AH16: 6.2735556
C17: kalorimetr č. 71182256 | D17: 9.895 | E17: 10.456 | F17: 10.814 | G17: 10.968 | H17: 11.249 | I17: 11.472 | J17: 11.63 | K17: 11.777 | L17: 11.913 | M17: 12.082 | N17: 12.327 | O17: 12.994 | P17: 13.934 | R17: =P17-D17 -> 4.039 | U17: xx
A18: 13 | B18: 8 | C18: vodoměr SV č. 190834112 | D18: 136.261 | E18: 138.405 | F18: 140.321 | G18: 142.406 | H18: 144.717 | I18: 147.266 | J18: 150.029 | K18: 151.863 | L18: 153.328 | M18: 156.783 | N18: 159.213 | O18: 161.35 | P18: 2.59 | Q18: =P18+O18-D18 -> 27.679 | U18: 13 | V18: =E18-D18 -> 2.144 | W18: =F18-E18 -> 1.916 | X18: =G18-F18 -> 2.085 | Y18: =H18-G18 -> 2.311 | Z18: =I18-H18 -> 2.549 | AA18: =J18-I18 -> 2.763 | AB18: =K18-J18 -> 1.834 | AC18: =L18-K18 -> 1.465 | ... AF18: =O18-N18 -> 2.137 | AG18: =P18 -> 2.59 | AH18: 2.5207778 | AJ18: byt 13 | AK18: =V19/(V18+V19) -> 0.41912761 | AL18: =W19/(W18+W19) -> 0.44720138 | AM18: =X19/(X18+X19) -> 0.4355712 | AN18: =Y19/(Y18+Y19) -> 0.46392948 | AO18: =Z19/(Z18+Z19) -> 0.4394106 | AP18: =AA19/(AA18+AA19) -> 0.40835118 | AQ18: =AB19/(AB18+AB19) -> 0.32992327 | AR18: =AC19/(AC18+AC19) -> 0.46376281 | ... AV18: =AG19/(AG18+AG19) -> 0.36065169 | AW18: =SUM(AK18:AV18)/12 -> 0.418903
A19: 12 a 13 | C19: kalorimetr č. 71182279 | D19: 60.986 | E19: 65.288 | F19: 68.522 | G19: 70.953 | H19: 71.856 | I19: 72.464 | J19: 73.019 | K19: 73.379 | L19: 73.759 | M19: 74.272 | N19: 74.944 | O19: 78.677 | P19: 83.883 | R19: =P19-D19 -> 22.897 | U19: TV | V19: =V48 -> 1.547 | W19: =W48 -> 1.55 | X19: =X48 -> 1.609 | Y19: =Y48 -> 2 | Z19: =Z48 -> 1.998 | AA19: =AA48 -> 1.907 | AB19: =AB48 -> 0.903 | AC19: =AC48 -> 1.267 | ... AG19: =AG48 -> 1.461 | AH19: 1.2623333
A20: 14 | B20: 9 | C20: vodoměr č. 190834124 | D20: 470.877 | E20: 479.288 | F20: 485.675 | G20: 495.084 | H20: 504.157 | I20: 514.484 | J20: 525.521 | K20: 531.604 | L20: 539.295 | M20: 547.561 | N20: 556.795 | O20: 564.58 | P20: 9.871 | Q20: =P20+O20-D20 -> 103.574 | U20: 14 | V20: =E20-D20 -> 8.411 | W20: =F20-E20 -> 6.387 | X20: =G20-F20 -> 9.409 | Y20: =H20-G20 -> 9.073 | Z20: =I20-H20 -> 10.327 | AA20: =J20-I20 -> 11.037 | AB20: =K20-J20 -> 6.083 | AC20: =L20-K20 -> 7.691 | ... AF20: =O20-N20 -> 7.785 | AG20: =P20 -> 9.871 | AH20: 6.9983333
C21: kalorimetr č. 71182252 | D21: 60.793 | E21: 66.601 | F21: 69.805 | G21: 72.576 | H21: 73.908 | I21: 74.508 | J21: 75.146 | K21: 75.459 | L21: 75.803 | M21: 76.202 | N21: 77.91 | O21: 82.217 | P21: 87.236 | R21: =P21-D21 -> 26.443 | U21: xx
A22: 10 | B22: 10 | C22: vodoměr č. 190834091 | D22: 92.85 | E22: 94.735 | F22: 96.361 | G22: 98.138 | H22: 99.955 | I22: 102.11 | J22: 103.892 | K22: 106.218 | L22: 108.085 | M22: 109.833 | N22: 111.85 | O22: 113.67 | P22: 2.516 | Q22: =P22+O22-D22 -> 23.336 | U22: 10 | V22: =E22-D22 -> 1.885 | W22: =F22-E22 -> 1.626 | X22: =G22-F22 -> 1.777 | Y22: =H22-G22 -> 1.817 | Z22: =I22-H22 -> 2.155 | AA22: =J22-I22 -> 1.782 | AB22: =K22-J22 -> 2.326 | AC22: =L22-K22 -> 1.867 | ... AF22: =O22-N22 -> 1.82 | AG22: =P22 -> 2.516 | AH22: 2.9007778
C23: kalorimetr č. 71182234 | D23: 35.464 | E23: 39.352 | F23: 41.299 | G23: 42.609 | H23: 43.191 | I23: 43.431 | J23: 43.639 | K23: 43.856 | L23: 44.05 | M23: 44.273 | N23: 45.312 | O23: 48.239 | P23: 51.809 | R23: =P23-D23 -> 16.345 | U23: xx
B24: spol.spotř. | C24: elektroměr č. 2080200096 | D24: 12070 | E24: 12339 | F24: 12578 | G24: 12771 | H24: 12980 | I24: 13186 | J24: 13489 | K24: 13690 | L24: 13926 | M24: 14126 | N24: 14332 | O24: 14533 | P24: 14724 | Q24: =SUM(Q4:Q23)+SUM(Q33:Q49) -> 934.401 | R24: =SUM(R4:R23) -> 207.694 | S24: =P24-D24 -> 2654 | U24: kWh | AK24: Podíl teplé vody na celkové spotřebě vody u dělených bytů po měsících (%)
AJ25: CELKEM | AK25: 1. | AL25: 2. | AM25: 3. | AN25: 4. | AO25: 5. | AP25: 6. | AQ25: 7. | AR25: 8. | AS25: 9. | AT25: 10. | AU25: 11. | AV25: 12. | AW25: Průměr
C26: patní vodoměr č. 190976791 | D26: 4882.6 | E26: 4972.6 | F26: 5055.1 | G26: 5141.1 | H26: 5229.7 | I26: 5317.5 | J26: 5394.8 | K26: 5467.5 | L26: 5546.3 | M26: 5631.4 | N26: 5722 | O26: 5801.9 | P26: 101.3 | Q26: =P26+O26-D26 -> 1020.6 | AJ26: Průměr po měsících | AK26: =(AK6+AK8+AK12+AK14+AK18+AK54+AK56+AK58+AK60+AK62)/10 -> 0.37181068 | AL26: =(AL6+AL8+AL12+AL14+AL18+AL54+AL56+AL58+AL60+AL62)/10 -> 0.37412304 | AM26: =(AM6+AM8+AM12+AM14+AM18+AM54+AM56+AM58+AM60+AM62)/10 -> 0.36785657 | AN26: =(AN6+AN8+AN12+AN14+AN18+AN54+AN56+AN58+AN60+AN62)/10 -> 0.36522837 | AO26: =(AO6+AO8+AO12+AO14+AO18+AO54+AO56+AO58+AO60+AO62)/10 -> 0.35498223 | AP26: =(AP6+AP8+AP12+AP14+AP18+AP54+AP56+AP58+AP60+AP62)/10 -> 0.30623108 | AQ26: =(AQ6+AQ8+AQ12+AQ14+AQ18+AQ54+AQ56+AQ58+AQ60+AQ62)/10 -> 0.28212867 | AR26: =(AR6+AR8+AR12+AR14+AR18+AR54+AR56+AR58+AR60+AR62)/10 -> 0.28538075 | ... AW26: =(AW6+AW8+AW12+AW14+AW18+AW54+AW56+AW58+AW60+AW62)/10 -> 0.33666041 | AZ26: Podíl TV po bytech
C27: patní kalorimetr č. / GJ | D27: 100.05 | E27: 144.21 | F27: 171.79 | G27: 194.78 | H27: 209.71 | I27: 219.56 | J27: 227.39 | K27: 234.32 | L27: 240.28 | M27: 248.26 | N27: 263.39 | O27: 297.55 | P27: 337.39 | R27: =(P27-D27) -> 237.34 | S27: GJ
C28: patní kalorimetr č./kub.m | D28: 1827 | E28: 2286 | F28: 2541 | G28: 2770 | H28: 2981 | I28: 3267 | J28: 3525 | K28: 3764 | L28: 3961 | M28: 4151 | N28: 4351 | O28: 4693 | P28: 5081 | R28: =P28-D28 -> 3254 | S28: m3
B29: ='1850'!A29 -> fakturační vodoměr č. 63796 | D29: ='1850'!C29 -> 24212 | E29: ='1850'!D29 -> 24552.7 | F29: ='1850'!E29 -> 24857.7 | G29: ='1850'!F29 -> 25187.3 | H29: ='1850'!G29 -> 25525.5 | I29: ='1850'!H29 -> 25865 | J29: ='1850'!I29 -> 26188.7 | K29: ='1850'!J29 -> 26482.4 | ... P29: ='1850'!O29 -> 28101 | Q29: =P29-D29 -> 3889 | V29: studená voda
U31: byt | V31: leden | W31: únor | X31: březen | Y31: duben | Z31: květen | AA31: červen | AB31: červenec | AC31: srpen | AD31: září | AE31: říjen | AF31: listopad | AG31: prosinec
A33: 3 | B33: 2B | C33: vodoměr SV č. 200015745 | D33: 243.244 | E33: 246.588 | F33: 249.337 | G33: 252.101 | H33: 254.62 | I33: 257.152 | J33: 259.791 | K33: 261.316 | L33: 263.377 | M33: 264.883 | N33: 267.561 | O33: 269.95 | P33: 2.112 | Q33: =P33+O33-D33 -> 28.818 | U33: 3 | V33: =E33-D33 -> 3.344 | W33: =F33-E33 -> 2.749 | X33: =G33-F33 -> 2.764 | Y33: =H33-G33 -> 2.519 | Z33: =I33-H33 -> 2.532 | AA33: =J33-I33 -> 2.639 | AB33: =K33-J33 -> 1.525 | AC33: =L33-K33 -> 2.061 | ... AF33: =O33-N33 -> 2.389 | AG33: =P33 -> 2.112 | AH33: 7.9723
A34: 6 | B34: 3B | C34: vodoměr SV č. 190834107 | D34: 160.511 | E34: 161.622 | F34: 163.28 | G34: 164.707 | H34: 165.602 | I34: 167.968 | J34: 169.103 | K34: 170.755 | L34: 171.817 | M34: 174.115 | N34: 175.435 | O34: 176.16 | P34: 1.782 | Q34: =P34+O34-D34 -> 17.431 | U34: 6 | V34: =E34-D34 -> 1.111 | W34: =F34-E34 -> 1.658 | X34: =G34-F34 -> 1.427 | Y34: =H34-G34 -> 0.895 | Z34: =I34-H34 -> 2.366 | AA34: =J34-I34 -> 1.135 | AB34: =K34-J34 -> 1.652 | AC34: =L34-K34 -> 1.062 | ... AF34: =O34-N34 -> 0.725 | AG34: =P34 -> 1.782 | AH34: 2.9773
A35: 8 | B35: 5B | C35: vodoměr SV č. 190834094 | D35: 278.202 | E35: 283.851 | F35: 289.492 | G35: 295.012 | H35: 300.086 | I35: 305.334 | J35: 310.415 | K35: 314.783 | L35: 319.045 | M35: 324.553 | N35: 330.01 | O35: 335.7 | P35: 5.744 | Q35: =P35+O35-D35 -> 63.242 | U35: 8 | V35: =E35-D35 -> 5.649 | W35: =F35-E35 -> 5.641 | X35: =G35-F35 -> 5.52 | Y35: =H35-G35 -> 5.074 | Z35: =I35-H35 -> 5.248 | AA35: =J35-I35 -> 5.081 | AB35: =K35-J35 -> 4.368 | AC35: =L35-K35 -> 4.262 | ... AF35: =O35-N35 -> 5.69 | AG35: =P35 -> 5.744 | AH35: 5.4084
A36: 11 | B36: 6B | C36: vodoměr SV č. 200015744 | D36: 31.35 | E36: 31.75 | F36: 31.907 | G36: 33.415 | H36: 34.987 | I36: 35.684 | J36: 36.306 | K36: 37.253 | L36: 38.134 | M36: 38.722 | N36: 39.39 | O36: 39.63 | P36: 1.937 | Q36: =P36+O36-D36 -> 10.217 | U36: 11 | V36: =E36-D36 -> 0.4 | W36: =F36-E36 -> 0.157 | X36: =G36-F36 -> 1.508 | Y36: =H36-G36 -> 1.572 | Z36: =I36-H36 -> 0.697 | AA36: =J36-I36 -> 0.622 | AB36: =K36-J36 -> 0.947 | AC36: =L36-K36 -> 0.881 | ... AF36: =O36-N36 -> 0.24 | AG36: =P36 -> 1.937 | AH36: 0.4723
A37: 12 | B37: 8B | C37: vodoměr SV č. 190834128 | D37: 127.366 | E37: 131.268 | F37: 134.676 | G37: 138.335 | H37: 141.441 | I37: 143.823 | J37: 147.964 | K37: 152.148 | L37: 155.506 | M37: 160.087 | N37: 163.309 | O37: 166.4 | P37: 4.145 | Q37: =P37+O37-D37 -> 43.179 | U37: 12 | V37: =E37-D37 -> 3.902 | W37: =F37-E37 -> 3.408 | X37: =G37-F37 -> 3.659 | Y37: =H37-G37 -> 3.106 | Z37: =I37-H37 -> 2.382 | AA37: =J37-I37 -> 4.141 | AB37: =K37-J37 -> 4.184 | AC37: =L37-K37 -> 3.358 | ... AF37: =O37-N37 -> 3.091 | AG37: =P37 -> 4.145 | AH37: 2.1434
C39: VODOMĚRY TEPLÁ VODA | V39: teplá voda
A40: 2 | B40: 2 | C40: vodoměr TUV č. 200105142 | D40: 116.144 | E40: 120.143 | F40: 123.159 | G40: 126.149 | H40: 128.775 | I40: 130.169 | J40: 131.522 | K40: 132.334 | L40: 133.635 | M40: 136.486 | N40: 139.607 | O40: 142.7 | P40: 3.844 | Q40: =P40+O40-D40 -> 30.4 | U40: 2 | V40: =E40-D40 -> 3.999 | W40: =F40-E40 -> 3.016 | X40: =G40-F40 -> 2.99 | Y40: =H40-G40 -> 2.626 | Z40: =I40-H40 -> 1.394 | AA40: =J40-I40 -> 1.353 | AB40: =K40-J40 -> 0.812 | AC40: =L40-K40 -> 1.301 | ... AF40: =O40-N40 -> 3.093 | AG40: =P40 -> 3.844 | AH40: 4.0477
A41: 3 | B41: 2B | C41: vodoměr TUV č. 200105133 | D41: 153.634 | E41: 155.346 | F41: 156.753 | G41: 158.224 | H41: 159.532 | I41: 160.773 | J41: 162.086 | K41: 162.793 | L41: 163.647 | M41: 164.381 | N41: 165.695 | O41: 167.17 | P41: 1.277 | Q41: =P41+O41-D41 -> 14.813 | U41: 3 | V41: =E41-D41 -> 1.712 | W41: =F41-E41 -> 1.407 | X41: =G41-F41 -> 1.471 | Y41: =H41-G41 -> 1.308 | Z41: =I41-H41 -> 1.241 | AA41: =J41-I41 -> 1.313 | AB41: =K41-J41 -> 0.707 | AC41: =L41-K41 -> 0.854 | ... AF41: =O41-N41 -> 1.475 | AG41: =P41 -> 1.277 | AH41: 4.1811
A42: 5 | B42: 3 | C42: vodoměr TUV č. 190049448 | D42: 21.303 | E42: 21.677 | F42: 22.023 | G42: 22.407 | H42: 22.782 | I42: 23.15 | J42: 23.493 | K42: 23.799 | L42: 24.098 | M42: 24.406 | N42: 24.73 | O42: 25.01 | P42: 0.411 | Q42: =P42+O42-D42 -> 4.118 | U42: 5 | V42: =E42-D42 -> 0.374 | W42: =F42-E42 -> 0.346 | X42: =G42-F42 -> 0.384 | Y42: =H42-G42 -> 0.375 | Z42: =I42-H42 -> 0.368 | AA42: =J42-I42 -> 0.343 | AB42: =K42-J42 -> 0.306 | AC42: =L42-K42 -> 0.299 | ... AF42: =O42-N42 -> 0.28 | AG42: =P42 -> 0.411 | AH42: 0.3771
A43: 6 | B43: 3B | C43: vodoměr TUV č. 190049255 | D43: 132.966 | E43: 133.571 | F43: 134.358 | G43: 135.11 | H43: 135.555 | I43: 136.622 | J43: 137.055 | K43: 137.432 | L43: 137.576 | M43: 138.022 | N43: 138.604 | O43: 138.99 | P43: 1.286 | Q43: =P43+O43-D43 -> 7.31 | U43: 6 | V43: =E43-D43 -> 0.605 | W43: =F43-E43 -> 0.787 | X43: =G43-F43 -> 0.752 | Y43: =H43-G43 -> 0.445 | Z43: =I43-H43 -> 1.067 | AA43: =J43-I43 -> 0.433 | AB43: =K43-J43 -> 0.377 | AC43: =L43-K43 -> 0.144 | ... AF43: =O43-N43 -> 0.386 | AG43: =P43 -> 1.286 | AH43: 1.5876
...

Sheet 1852
A2: 1852 | C2: ='1850'!C2 -> 45292 | D2: ='1850'!D2 -> 45323 | E2: ='1850'!E2 -> 45352 | F2: ='1850'!F2 -> 45383 | G2: ='1850'!G2 -> 45413 | H2: ='1850'!H2 -> 45444 | I2: ='1850'!I2 -> 45474 | J2: ='1850'!J2 -> 45505 | ... O2: ='1850'!O2 -> 45658 | P2: voda | Q2: teplo | R2: Elektr | Y2: spotřeby po měsících
A3: byt č. | C3: prosinec | D3: leden | E3: únor | F3: březen | G3: duben | H3: květen | I3: červen | J3: červenec | K3: srpen | L3: září | M3: říjen | N3: listopad | O3: prosinec | P3: m3 | Q3: GJ | R3: KWh | T3: byt | U3: leden | V3: únor | W3: březen | X3: duben | Y3: květen | Z3: červen | AA3: červenec | AB3: srpen | AC3: září | AD3: říjen | AE3: listopad | AF3: prosinec
A4: 1 | B4: vodoměr č. 190834115 | C4: 576.312 | D4: 587.196 | E4: 597.775 | F4: 606.444 | G4: 613.428 | H4: 621.38 | I4: 628.465 | J4: 636.737 | K4: 645.367 | L4: 653.735 | M4: 662.366 | N4: 672.61 | O4: 12.545 | P4: =O4+N4-C4 -> 108.843 | T4: 1 | U4: =D4-C4 -> 10.884 | V4: =E4-D4 -> 10.579 | W4: =F4-E4 -> 8.669 | X4: =G4-F4 -> 6.984 | Y4: =H4-G4 -> 7.952 | Z4: =I4-H4 -> 7.085 | AA4: =J4-I4 -> 8.272 | AB4: =K4-J4 -> 8.63 | ... AE4: =N4-M4 -> 10.244 | AF4: =O4 -> 12.545
B5: kalorimetr č. 71182233 | C5: 53.409 | D5: 57.834 | E5: 60.603 | F5: 62.999 | G5: 64.409 | H5: 65.012 | I5: 65.493 | J5: 65.919 | K5: 66.32 | L5: 66.922 | M5: 68.725 | N5: 72.334 | O5: 76.346 | Q5: =O5-C5 -> 22.937
A6: 2 | B6: vodoměr č. 190834121 | C6: 314.552 | D6: 319.65 | E6: 324.372 | F6: 330.087 | G6: 335.621 | H6: 341.966 | I6: 346.944 | J6: 352.573 | K6: 356.229 | L6: 361.876 | M6: 368.251 | N6: 373.67 | O6: 5.285 | P6: =O6+N6-C6 -> 64.403 | T6: 2 | U6: =D6-C6 -> 5.098 | V6: =E6-D6 -> 4.722 | W6: =F6-E6 -> 5.715 | X6: =G6-F6 -> 5.534 | Y6: =H6-G6 -> 6.345 | Z6: =I6-H6 -> 4.978 | AA6: =J6-I6 -> 5.629 | AB6: =K6-J6 -> 3.656 | ... AE6: =N6-M6 -> 5.419 | AF6: =O6 -> 5.285
B7: kalorimetr č. 71182270 | C7: 25.735 | D7: 27.45 | E7: 28.535 | F7: 29.35 | G7: 29.877 | H7: 30.361 | I7: 30.72 | J7: 31.044 | K7: 31.202 | L7: 31.546 | M7: 32.105 | N7: 33.681 | O7: 35.462 | Q7: =O7-C7 -> 9.727
A8: 3 | B8: vodoměr č. 200015760 | C8: 459.766 | D8: 469.685 | E8: 477.143 | F8: 488.201 | G8: 501.162 | H8: 513.72 | I8: 527.268 | J8: 531.771 | K8: 541.418 | L8: 555.404 | M8: 566.122 | N8: 577.94 | O8: 12.117 | P8: =O8+N8-C8 -> 130.291 | T8: 3 | U8: =D8-C8 -> 9.919 | V8: =E8-D8 -> 7.458 | W8: =F8-E8 -> 11.058 | X8: =G8-F8 -> 12.961 | Y8: =H8-G8 -> 12.558 | Z8: =I8-H8 -> 13.548 | AA8: =J8-I8 -> 4.503 | AB8: =K8-J8 -> 9.647 | ... AE8: =N8-M8 -> 11.818 | AF8: =O8 -> 12.117
B9: kalorimetr č. 71182274 | C9: 72.049 | D9: 77.522 | E9: 81.146 | F9: 85.25 | G9: 87.081 | H9: 87.914 | I9: 88.643 | J9: 88.88 | K9: 89.247 | L9: 90.796 | M9: 93.948 | N9: 99.727 | O9: 106.363 | Q9: =O9-C9 -> 34.314
A10: 4 | B10: vodoměr č. 190834096 | C10: 506.213 | D10: 515.587 | E10: 523.53 | F10: 532.885 | G10: 542.449 | H10: 552.251 | I10: 561.504 | J10: 570.002 | K10: 577.89 | L10: 586.757 | M10: 595.911 | N10: 603.84 | O10: 6.82 | P10: =O10+N10-C10 -> 104.447 | T10: 4 | U10: =D10-C10 -> 9.374 | V10: =E10-D10 -> 7.943 | W10: =F10-E10 -> 9.355 | X10: =G10-F10 -> 9.564 | Y10: =H10-G10 -> 9.802 | Z10: =I10-H10 -> 9.253 | AA10: =J10-I10 -> 8.498 | AB10: =K10-J10 -> 7.888 | ... AE10: =N10-M10 -> 7.929 | AF10: =O10 -> 6.82
B11: kalorimetr č. 71182244 | C11: 61.01 | D11: 65.757 | E11: 68.449 | F11: 70.425 | G11: 71.603 | H11: 72.348 | I11: 72.966 | J11: 73.462 | K11: 73.904 | L11: 74.669 | M11: 75.892 | N11: 78.854 | O11: 82.226 | Q11: =O11-C11 -> 21.216
A12: 5 | B12: vodoměr č. 190834110 | C12: 314.985 | D12: 323.529 | E12: 332.685 | F12: 339.665 | G12: 347.744 | H12: 354.654 | I12: 361.6 | J12: 366.493 | K12: 371.605 | L12: 378.123 | M12: 384.776 | N12: 390.39 | O12: 5.789 | P12: =O12+N12-C12 -> 81.194 | T12: 5 | U12: =D12-C12 -> 8.544 | V12: =E12-D12 -> 9.156 | W12: =F12-E12 -> 6.98 | X12: =G12-F12 -> 8.079 | Y12: =H12-G12 -> 6.91 | Z12: =I12-H12 -> 6.946 | AA12: =J12-I12 -> 4.893 | AB12: =K12-J12 -> 5.112 | ... AE12: =N12-M12 -> 5.614 | AF12: =O12 -> 5.789
B13: kalorimetr č. 71182251 | C13: 30.951 | D13: 33.237 | E13: 34.647 | F13: 35.751 | G13: 36.549 | H13: 37.101 | I13: 37.596 | J13: 37.993 | K13: 38.344 | L13: 38.772 | M13: 39.456 | N13: 40.975 | O13: 42.479 | Q13: =O13-C13 -> 11.528
A14: 6 | B14: vodoměr č. 190834127 | C14: 435.559 | D14: 446.725 | E14: 454.449 | F14: 454.82 | G14: 455.207 | H14: 455.208 | I14: 455.225 | J14: 455.225 | K14: 455.415 | L14: 455.537 | M14: 455.539 | N14: 455.539 | O14: 0.043 | P14: =O14+N14-C14 -> 20.023 | T14: 6 | U14: =D14-C14 -> 11.166 | V14: =E14-D14 -> 7.724 | W14: =F14-E14 -> 0.371 | X14: =G14-F14 -> 0.387 | Y14: =H14-G14 -> 0.001 | Z14: =I14-H14 -> 0.017 | AA14: =J14-I14 -> 0 | AB14: =K14-J14 -> 0.19 | ... AE14: =N14-M14 -> 0 | AF14: =O14 -> 0.043
B15: kalorimetr č. 71182283 | C15: 53.598 | D15: 57.706 | E15: 59.585 | F15: 59.687 | G15: 59.83 | H15: 60.014 | I15: 60.183 | J15: 60.354 | K15: 60.51 | L15: 60.679 | M15: 60.849 | N15: 60.916 | O15: 60.997 | Q15: =O15-C15 -> 7.399
A16: 7 | B16: vodoměr č. 190834123 | C16: 60.945 | D16: 63.628 | E16: 64.193 | F16: 66.017 | G16: 68.028 | H16: 71.009 | I16: 74.011 | J16: 76.687 | K16: 77.884 | L16: 78.63 | M16: 79.381 | N16: 80.3 | O16: 0.757 | P16: =O16+N16-C16 -> 20.112 | T16: 7 | U16: =D16-C16 -> 2.683 | V16: =E16-D16 -> 0.565 | W16: =F16-E16 -> 1.824 | X16: =G16-F16 -> 2.011 | Y16: =H16-G16 -> 2.981 | Z16: =I16-H16 -> 3.002 | AA16: =J16-I16 -> 2.676 | AB16: =K16-J16 -> 1.197 | ... AE16: =N16-M16 -> 0.919 | AF16: =O16 -> 0.757
B17: kalorimetr č. 71182277 | C17: 24.092 | D17: 26.973 | E17: 27.934 | F17: 28.5 | G17: 28.655 | H17: 28.76 | I17: 28.848 | J17: 28.904 | K17: 28.925 | L17: 28.947 | M17: 28.959 | N17: 30.703 | O17: 33.49 | Q17: =O17-C17 -> 9.398
A18: 8 | B18: vodoměr č. 190834118 | C18: 464.177 | D18: 474.124 | E18: 480.467 | F18: 489.438 | G18: 499.764 | H18: 509.14 | I18: 516.79 | J18: 526.861 | K18: 533.048 | L18: 544.927 | M18: 557.473 | N18: 570.15 | O18: 13.38 | P18: =O18+N18-C18 -> 119.353 | T18: 8 | U18: =D18-C18 -> 9.947 | V18: =E18-D18 -> 6.343 | W18: =F18-E18 -> 8.971 | X18: =G18-F18 -> 10.326 | Y18: =H18-G18 -> 9.376 | Z18: =I18-H18 -> 7.65 | AA18: =J18-I18 -> 10.071 | AB18: =K18-J18 -> 6.187 | ... AE18: =N18-M18 -> 12.677 | AF18: =O18 -> 13.38
B19: kalorimetr č. 71182246 | C19: 31.794 | D19: 34.533 | E19: 35.619 | F19: 37.195 | G19: 38.159 | H19: 38.744 | I19: 39.196 | J19: 39.667 | K19: 39.974 | L19: 40.514 | M19: 41.645 | N19: 44.499 | O19: 47.794 | Q19: =O19-C19 -> 16
A20: 9 | B20: vodoměr č. 221525380 | C20: 120.553 | D20: 134.243 | E20: 145.541 | F20: 158.092 | G20: 170.298 | H20: 183.58 | I20: 193.644 | J20: 204.368 | K20: 217.372 | L20: 225.864 | M20: 237.317 | N20: 249.9 | O20: 13.636 | P20: =O20+N20-C20 -> 142.983 | T20: 9 | U20: =D20-C20 -> 13.69 | V20: =E20-D20 -> 11.298 | W20: =F20-E20 -> 12.551 | X20: =G20-F20 -> 12.206 | Y20: =H20-G20 -> 13.282 | Z20: =I20-H20 -> 10.064 | AA20: =J20-I20 -> 10.724 | AB20: =K20-J20 -> 13.004 | ... AE20: =N20-M20 -> 12.583 | AF20: =O20 -> 13.636
B21: kalorimetr č. 71182282 | C21: 75.11 | D21: 81.221 | E21: 86.536 | F21: 91.323 | G21: 94.656 | H21: 96.408 | I21: 97.124 | J21: 97.814 | K21: 98.55 | L21: 100.229 | M21: 105.668 | N21: 112.131 | O21: 118.749 | Q21: =O21-C21 -> 43.639
A22: 10 | B22: vodoměr č. 190834129 | C22: 362.081 | D22: 369.734 | E22: 377.57 | F22: 385.083 | G22: 393.384 | H22: 399.9 | I22: 408.013 | J22: 415.715 | K22: 416.362 | L22: 422.891 | M22: 429.256 | N22: 436.16 | O22: 6.461 | P22: =O22+N22-C22 -> 80.54 | T22: 10 | U22: =D22-C22 -> 7.653 | V22: =E22-D22 -> 7.836 | W22: =F22-E22 -> 7.513 | X22: =G22-F22 -> 8.301 | Y22: =H22-G22 -> 6.516 | Z22: =I22-H22 -> 8.113 | AA22: =J22-I22 -> 7.702 | AB22: =K22-J22 -> 0.647 | ... AE22: =N22-M22 -> 6.904 | AF22: =O22 -> 6.461
B23: kalorimetr č. 71182240 | C23: 48.123 | D23: 52.404 | E23: 55.042 | F23: 56.853 | G23: 57.95 | H23: 58.56 | I23: 59.211 | J23: 59.742 | K23: 59.938 | L23: 60.554 | M23: 61.767 | N23: 64.99 | O23: 68.613 | Q23: =O23-C23 -> 20.49
P24: =SUM(P4:P23) -> 872.189 | Q24: =SUM(Q4:Q23) -> 196.648
A25: spol.spotř. | B25: elektroměr č. 2080200097 | C25: 10067 | D25: 10256 | E25: 10441 | F25: 10628 | G25: 10825 | H25: 11005 | I25: 11220 | J25: 11398 | K25: 11597 | L25: 11775 | M25: 11950 | N25: 12144 | O25: 12333 | R25: =O25-C25 -> 2266
B26: patní vodoměr č. 190976792 | C26: 4486.8 | D26: 4584.8 | E26: 4666.6 | F26: 4746.9 | G26: 4831.5 | H26: 4915.7 | I26: 4995 | J26: 5064.9 | K26: 5127.8 | L26: 5207 | M26: 5288.5 | N26: 5371.6 | O26: 85.5 | P26: =O26+N26-C26 -> 970.3
B27: patní kalorimetr č./ GJ | C27: 71.6 | D27: 112.34 | E27: 136.92 | F27: 157.11 | G27: 168.42 | H27: 173.53 | I27: 176.57 | J27: 178.53 | K27: 180 | L27: 184.56 | M27: 198.23 | N27: 226.21 | O27: 258.05 | Q27: =(O27-C27) -> 186.45 | R27: GJ
B28: patní kalorimetr č./kub.m | C28: 448 | D28: 699 | E28: 849 | F28: 973 | G28: 1148 | H28: 1188 | I28: 1215 | J28: 1233 | K28: 1248 | L28: 1281 | M28: 1382 | N28: 1569 | O28: 1803 | Q28: =O28-C28 -> 1355 | R28: m3
A29: ='1850'!A29 -> fakturační vodoměr č. 63796 | C29: ='1850'!C29 -> 24212 | D29: ='1850'!D29 -> 24552.7 | E29: ='1850'!E29 -> 24857.7 | F29: ='1850'!F29 -> 25187.3 | G29: ='1850'!G29 -> 25525.5 | H29: ='1850'!H29 -> 25865 | I29: ='1850'!I29 -> 26188.7 | J29: ='1850'!J29 -> 26482.4 | ... O29: ='1850'!O29 -> 28101 | P29: =O29-C29 -> 3889
C31: byt | D31: Reklamace - výměna | F31: číslo | G31: stav | I31: Dne 31.7.2023 odpojen kalor. (cejchování), | M31: stav: | N31: 257.22 | O31: MWh
C32: 9 | D32: 43950 | E32: starý | F32: 190834113 | G32: =M20+7.7 -> 245.017 | I32: Dne 3.8.2023 zapojen znovuzapojení, | M32: stav: | N32: 0 | O32: GJ
E33: nový | F33: 221525380 | G33: 0
D35: Výměna elektroměru
D36: 43956 | E36: starý
E37: nový

Sheet 1853
A2: 1853 | C2: ='1850'!C2 -> 45292 | D2: ='1850'!D2 -> 45323 | E2: ='1850'!E2 -> 45352 | F2: ='1850'!F2 -> 45383 | G2: ='1850'!G2 -> 45413 | H2: ='1850'!H2 -> 45444 | I2: ='1850'!I2 -> 45474 | J2: ='1850'!J2 -> 45505 | ... O2: ='1850'!O2 -> 45658 | P2: Voda | Q2: Teplo | R2: Elektr | Y2: spotřeby po měsících
A3: byt č. | C3: prosinec | D3: leden | E3: únor | F3: březen | G3: duben | H3: květen | I3: červen | J3: červenec | K3: srpen | L3: září | M3: říjen | N3: listopad | O3: prosinec | P3: m3 | Q3: GJ | R3: KWh | T3: byt | U3: leden | V3: únor | W3: březen | X3: duben | Y3: květen | Z3: červen | AA3: červenec | AB3: srpen | AC3: září | AD3: říjen | AE3: listopad | AF3: prosinec
A4: 1 | B4: vodoměr č. 190834100 | C4: 681.208 | D4: 695.246 | E4: 706.109 | F4: 719.292 | G4: 733.247 | H4: 748.32 | I4: 760.38 | J4: 772.512 | K4: 783.343 | L4: 797.527 | M4: 811.583 | N4: 823.7 | O4: 15.692 | P4: =O4+N4-C4 -> 158.184 | T4: 1 | U4: =D4-C4 -> 14.038 | V4: =E4-D4 -> 10.863 | W4: =F4-E4 -> 13.183 | X4: =G4-F4 -> 13.955 | Y4: =H4-G4 -> 15.073 | Z4: =I4-H4 -> 12.06 | AA4: =J4-I4 -> 12.132 | AB4: =K4-J4 -> 10.831 | ... AE4: =N4-M4 -> 12.117 | AF4: =O4 -> 15.692
B5: kalorimetr č. 71182275 | C5: 63.385 | D5: 69.98 | E5: 73.73 | F5: 77.335 | G5: 79.244 | H5: 80.351 | I5: 81.105 | J5: 81.747 | K5: 82.213 | L5: 83.103 | M5: 84.905 | N5: 89.972 | O5: 95.658 | Q5: =O5-C5 -> 32.273
A6: 2 | B6: vodoměr č. 190906789 | C6: 374.776 | D6: 380.622 | E6: 381.514 | F6: 385.369 | G6: 392.761 | H6: 399.297 | I6: 404.69 | J6: 410.22 | K6: 416.625 | L6: 421.818 | M6: 427.984 | N6: 433.52 | O6: 7.571 | P6: =O6+N6-C6 -> 66.315 | T6: 2 | U6: =D6-C6 -> 5.846 | V6: =E6-D6 -> 0.892 | W6: =F6-E6 -> 3.855 | X6: =G6-F6 -> 7.392 | Y6: =H6-G6 -> 6.536 | Z6: =I6-H6 -> 5.393 | AA6: =J6-I6 -> 5.53 | AB6: =K6-J6 -> 6.405 | ... AE6: =N6-M6 -> 5.536 | AF6: =O6 -> 7.571
B7: kalorimetr č. 71182253 | C7: 18.928 | D7: 20.662 | E7: 20.897 | F7: 21.694 | G7: 22.445 | H7: 22.755 | I7: 22.944 | J7: 23.148 | K7: 23.398 | L7: 23.59 | M7: 24.01 | N7: 25.547 | O7: 27.501 | Q7: =O7-C7 -> 8.573
A8: 3 | B8: vodoměr č. 190906786 | C8: 253.555 | D8: 260.323 | E8: 266.013 | F8: 271.106 | G8: 277.774 | H8: 287.424 | I8: 296.309 | J8: 301.97 | K8: 306.653 | L8: 311.587 | M8: 316.617 | N8: 321.46 | O8: 6.239 | P8: =O8+N8-C8 -> 74.144 | T8: 3 | U8: =D8-C8 -> 6.768 | V8: =E8-D8 -> 5.69 | W8: =F8-E8 -> 5.093 | X8: =G8-F8 -> 6.668 | Y8: =H8-G8 -> 9.65 | Z8: =I8-H8 -> 8.885 | AA8: =J8-I8 -> 5.661 | AB8: =K8-J8 -> 4.683 | ... AE8: =N8-M8 -> 4.843 | AF8: =O8 -> 6.239
B9: kalorimetr č. 71182217 | C9: 46.913 | D9: 50.2 | E9: 52.259 | F9: 54.218 | G9: 55.004 | H9: 55.498 | I9: 55.859 | J9: 56.083 | K9: 56.245 | L9: 56.441 | M9: 56.781 | N9: 59.041 | O9: 62.257 | Q9: =O9-C9 -> 15.344
A10: 4 | B10: vodoměr č. 190834105 | C10: 248.363 | D10: 253.546 | E10: 258.606 | F10: 263.645 | G10: 268.074 | H10: 273.553 | I10: 278.398 | J10: 283.576 | K10: 288.085 | L10: 291.682 | M10: 295.627 | N10: 298.14 | O10: 3.377 | P10: =O10+N10-C10 -> 53.154 | T10: 4 | U10: =D10-C10 -> 5.183 | V10: =E10-D10 -> 5.06 | W10: =F10-E10 -> 5.039 | X10: =G10-F10 -> 4.429 | Y10: =H10-G10 -> 5.479 | Z10: =I10-H10 -> 4.845 | AA10: =J10-I10 -> 5.178 | AB10: =K10-J10 -> 4.509 | ... AE10: =N10-M10 -> 2.513 | AF10: =O10 -> 3.377
B11: kalorimetr č. 71182254 | C11: 20.852 | D11: 23.041 | E11: 23.879 | F11: 24.46 | G11: 24.813 | H11: 25.179 | I11: 25.491 | J11: 25.765 | K11: 26.009 | L11: 26.269 | M11: 26.792 | N11: 29.164 | O11: 31.791 | Q11: =O11-C11 -> 10.939
A12: 5 | B12: vodoměr č. 190906792 | C12: 393.043 | D12: 402.168 | E12: 411.061 | F12: 420.477 | G12: 428.158 | H12: 435.667 | I12: 443.959 | J12: 451.326 | K12: 456.416 | L12: 462.846 | M12: 469.497 | N12: 475.18 | O12: 7.298 | P12: =O12+N12-C12 -> 89.435 | T12: 5 | U12: =D12-C12 -> 9.125 | V12: =E12-D12 -> 8.893 | W12: =F12-E12 -> 9.416 | X12: =G12-F12 -> 7.681 | Y12: =H12-G12 -> 7.509 | Z12: =I12-H12 -> 8.292 | AA12: =J12-I12 -> 7.367 | AB12: =K12-J12 -> 5.09 | ... AE12: =N12-M12 -> 5.683 | AF12: =O12 -> 7.298
B13: kalorimetr č. 71182267 | C13: 20.087 | D13: 21.899 | E13: 23.499 | F13: 24.603 | G13: 25.047 | H13: 25.413 | I13: 25.774 | J13: 26.067 | K13: 26.255 | L13: 26.55 | M13: 26.946 | N13: 27.558 | O13: 28.57 | Q13: =O13-C13 -> 8.483
A14: 6 | B14: vodoměr č. 190906795 | C14: 216.426 | D14: 220.66 | E14: 225.233 | F14: 230.104 | G14: 234.518 | H14: 238.842 | I14: 242.11 | J14: 245.317 | K14: 249.984 | L14: 253.374 | M14: 258.492 | N14: 262.88 | O14: 6.274 | P14: =O14+N14-C14 -> 52.728 | T14: 6 | U14: =D14-C14 -> 4.234 | V14: =E14-D14 -> 4.573 | W14: =F14-E14 -> 4.871 | X14: =G14-F14 -> 4.414 | Y14: =H14-G14 -> 4.324 | Z14: =I14-H14 -> 3.268 | AA14: =J14-I14 -> 3.207 | AB14: =K14-J14 -> 4.667 | ... AE14: =N14-M14 -> 4.388 | AF14: =O14 -> 6.274
B15: kalorimetr č. 71182261 | C15: 29.189 | D15: 32.329 | E15: 33.929 | F15: 34.832 | G15: 35.31 | H15: 35.49 | I15: 35.618 | J15: 35.744 | K15: 35.886 | L15: 36.003 | M15: 36.882 | N15: 39.923 | O15: 43.35 | Q15: =O15-C15 -> 14.161
A16: 7 | B16: vodoměr č. 190834103 | C16: 542.297 | D16: 554.67 | E16: 566.46 | F16: 578.364 | G16: 589.986 | H16: 600.976 | I16: 612.43 | J16: 620.362 | K16: 630.345 | L16: 641.043 | M16: 650.999 | N16: 662.04 | O16: 14.626 | P16: =O16+N16-C16 -> 134.369 | T16: 7 | U16: =D16-C16 -> 12.373 | V16: =E16-D16 -> 11.79 | W16: =F16-E16 -> 11.904 | X16: =G16-F16 -> 11.622 | Y16: =H16-G16 -> 10.99 | Z16: =I16-H16 -> 11.454 | AA16: =J16-I16 -> 7.932 | AB16: =K16-J16 -> 9.983 | ... AE16: =N16-M16 -> 11.041 | AF16: =O16 -> 14.626
B17: kalorimetr č. 71182272 | C17: 56.159 | D17: 60.185 | E17: 62.802 | F17: 64.586 | G17: 65.856 | H17: 66.692 | I17: 67.51 | J17: 68.03 | K17: 68.567 | L17: 69.244 | M17: 70.145 | N17: 72.98 | O17: 76.723 | Q17: =O17-C17 -> 20.564
A18: 8 | B18: vodoměr č. 190834101 | C18: 341.374 | D18: 350.045 | E18: 358.468 | F18: 368.423 | G18: 376.905 | H18: 387.052 | I18: 394.917 | J18: 402.476 | K18: 407.095 | L18: 416.893 | M18: 428.176 | N18: 437.37 | O18: 11.299 | P18: =O18+N18-C18 -> 107.295 | T18: 8 | U18: =D18-C18 -> 8.671 | V18: =E18-D18 -> 8.423 | W18: =F18-E18 -> 9.955 | X18: =G18-F18 -> 8.482 | Y18: =H18-G18 -> 10.147 | Z18: =I18-H18 -> 7.865 | AA18: =J18-I18 -> 7.559 | AB18: =K18-J18 -> 4.619 | ... AE18: =N18-M18 -> 9.194 | AF18: =O18 -> 11.299
B19: kalorimetr č. 71182249 | C19: 40.132 | D19: 44.522 | E19: 47.216 | F19: 48.726 | G19: 49.483 | H19: 50.123 | I19: 50.514 | J19: 50.875 | K19: 51.089 | L19: 51.548 | M19: 52.246 | N19: 55.01 | O19: 58.519 | Q19: =O19-C19 -> 18.387
A20: 9 | B20: vodoměr č. 190834108 | C20: 188.598 | D20: 192.019 | E20: 195.226 | F20: 198.464 | G20: 201.788 | H20: 205.111 | I20: 208.37 | J20: 212.078 | K20: 216.369 | L20: 216.934 | M20: 217.289 | N20: 218.68 | O20: 3.939 | P20: =O20+N20-C20 -> 34.021 | T20: 9 | U20: =D20-C20 -> 3.421 | V20: =E20-D20 -> 3.207 | W20: =F20-E20 -> 3.238 | X20: =G20-F20 -> 3.324 | Y20: =H20-G20 -> 3.323 | Z20: =I20-H20 -> 3.259 | AA20: =J20-I20 -> 3.708 | AB20: =K20-J20 -> 4.291 | ... AE20: =N20-M20 -> 1.391 | AF20: =O20 -> 3.939
B21: kalorimetr č. 71182281 | C21: 46.407 | D21: 51.336 | E21: 54.224 | F21: 56.337 | G21: 57.22 | H21: 57.532 | I21: 57.792 | J21: 58.025 | K21: 58.255 | L21: 59.365 | M21: 60.746 | N21: 64.044 | O21: 68.216 | Q21: =O21-C21 -> 21.809
A22: 10 | B22: vodoměr č. 190906953 | C22: 191.288 | D22: 193.853 | E22: 196.036 | F22: 198.678 | G22: 200.591 | H22: 202.963 | I22: 205.17 | J22: 206.802 | K22: 209.705 | L22: 212.494 | M22: 215.703 | N22: 218.09 | O22: 3.745 | P22: =O22+N22-C22 -> 30.547 | T22: 10 | U22: =D22-C22 -> 2.565 | V22: =E22-D22 -> 2.183 | W22: =F22-E22 -> 2.642 | X22: =G22-F22 -> 1.913 | Y22: =H22-G22 -> 2.372 | Z22: =I22-H22 -> 2.207 | AA22: =J22-I22 -> 1.632 | AB22: =K22-J22 -> 2.903 | ... AE22: =N22-M22 -> 2.387 | AF22: =O22 -> 3.745
B23: kalorimetr č. 71182268 | C23: 46.521 | D23: 50.274 | E23: 52.867 | F23: 54.755 | G23: 55.529 | H23: 55.689 | I23: 55.797 | J23: 55.862 | K23: 55.939 | L23: 56.156 | M23: 57.471 | N23: 60.354 | O23: 64.113 | Q23: =O23-C23 -> 17.592
B24: elektroměr č.2080200105 dům | C24: 8503 | D24: 8687 | E24: 8856 | F24: 9052 | G24: 9239 | H24: 9428 | I24: 9614 | J24: 9795 | K24: 9991 | L24: 10221 | M24: 10404 | N24: 10604 | O24: 10800 | P24: =SUM(P4:P23) -> 800.192 | Q24: =SUM(Q4:Q23) -> 168.125 | R24: =O24-C24 -> 2297
A25: spol.spotř. | B25: elektroměr č. 2080200100 VO | C25: 14439 | D25: 14792 | E25: 15114 | F25: 15436 | G25: 15694 | H25: 15925 | I25: 16128 | J25: 16352 | K25: 16611 | L25: 16904 | M25: 17247 | N25: 17630 | O25: 18016 | R25: =O25-C25 -> 3577 | T25: Zahrada | U25: =D26-C26 -> 0 | V25: =E26-D26 -> 0 | W25: =F26-E26 -> 0 | X25: =G26-F26 -> 13.007 | Y25: =H26-G26 -> 7.114 | Z25: =I26-H26 -> 15.413 | AA25: =J26-I26 -> 17.829 | AB25: =K26-J26 -> 28.312 | ... AF25: =O26-N26 -> 0
B26: vodoměr areál č.200076532 | C26: 547.775 | D26: 547.775 | E26: 547.775 | F26: 547.775 | G26: 560.782 | H26: 567.896 | I26: 583.309 | J26: 601.138 | K26: 629.45 | L26: 638.627 | M26: 640.722 | N26: 640.722 | O26: 640.722 | P26: =O26-C26 -> 92.947 | Q26: =ROUND(P26,0) -> 93 | R26: zahrada
B27: patní vodoměr č. 190976789 | C27: 4291.1 | D27: 4370.6 | E27: 4438.3 | F27: 4516.5 | G27: 4605.2 | H27: 4695.3 | I27: 4784.8 | J27: 4869.2 | K27: 4961.6 | L27: 5039.6 | M27: 5115 | N27: 5181.4 | O27: 90.7 | P27: =O27+N27-C27 -> 981 | Q27: =P27-Q26 -> 888 | R27: byty | U27: =(D27-C27)-(D26-C26) -> 79.5 | V27: =(E27-D27)-(E26-D26) -> 67.7 | W27: =(F27-E27)-(F26-E26) -> 78.2 | X27: =(G27-F27)-(G26-F26) -> 75.693 | Y27: =(H27-G27)-(H26-G26) -> 82.986 | Z27: =(I27-H27)-(I26-H26) -> 74.087 | AA27: =(J27-I27)-(J26-I26) -> 66.571 | AB27: =(K27-J27)-(K26-J26) -> 64.088 | ... AE27: =(N27-M27)-(N26-M26) -> 66.4 | AF27: =(O27)-(O26-N26) -> 90.7
B28: patní kalorimetr č./ GJ | C28: 63.56 | D28: 101.23 | E28: 123.24 | F28: 140.44 | G28: 148.66 | H28: 152.75 | I28: 155.75 | J28: 157.91 | K28: 159.63 | L28: 163.3 | M28: 171.49 | N28: 199.27 | O28: 232.37 | Q28: =(O28-C28) -> 168.81 | R28: GJ | U28: =(D28-C28) -> 37.67 | V28: =(E28-D28) -> 22.01 | W28: =(F28-E28) -> 17.2 | X28: =(G28-F28) -> 8.22 | Y28: =(H28-G28) -> 4.09 | Z28: =(I28-H28) -> 3 | AA28: =(J28-I28) -> 2.16 | AB28: =(K28-J28) -> 1.72 | ... AF28: =(O28-N28) -> 33.1
B29: patní kalorimetr č. /kub.m | C29: 442 | D29: 704 | E29: 850 | F29: 972.8 | G29: 1034 | H29: 1067 | I29: 1094 | J29: 1114 | K29: 1132 | L29: 1162 | M29: 1225 | N29: 1423 | O29: 1649 | Q29: =O29-C29 -> 1207 | R29: m3
A30: ='1850'!A29 -> fakturační vodoměr č. 63796 | C30: ='1850'!C29 -> 24212 | D30: ='1850'!D29 -> 24552.7 | E30: ='1850'!E29 -> 24857.7 | F30: ='1850'!F29 -> 25187.3 | G30: ='1850'!G29 -> 25525.5 | H30: ='1850'!H29 -> 25865 | I30: ='1850'!I29 -> 26188.7 | J30: ='1850'!J29 -> 26482.4 | ... O30: ='1850'!O29 -> 28101 | P30: =O30-C30 -> 3889
A32: 11 | B32: vodoměr SV č. 11717149 | C32: 18.236 | D32: 18.717 | E32: 19.598 | F32: 19.981 | G32: 20.418 | H32: 20.808 | I32: 21.447 | J32: 21.839 | K32: 22.26 | L32: 22.679 | M32: 23.002 | N32: 23.514 | O32: 23.853 | P32: =O32-C32 -> 5.617 | S32: SV | T32: 11 | U32: =D32-C32 -> 0.481 | V32: =E32-D32 -> 0.881 | W32: =F32-E32 -> 0.383 | X32: =G32-F32 -> 0.437 | Y32: =H32-G32 -> 0.39 | Z32: =I32-H32 -> 0.639 | AA32: =J32-I32 -> 0.392 | AB32: =K32-J32 -> 0.421 | ... AF32: =O32-N32 -> 0.339
B33: vodoměr TV č. 11683196 | C33: 0.871 | D33: 0.878 | E33: 0.95 | F33: 0.953 | G33: 0.957 | H33: 0.96 | I33: 0.989 | J33: 0.997 | K33: 1 | L33: 1.019 | M33: 1.024 | N33: 1.026 | O33: 1.05 | P33: =O33-C33 -> 0.179 | S33: TV | U33: =D33-C33 -> 0.007 | V33: =E33-D33 -> 0.072 | W33: =F33-E33 -> 0.003 | X33: =G33-F33 -> 0.004 | Y33: =H33-G33 -> 0.003 | Z33: =I33-H33 -> 0.029 | AA33: =J33-I33 -> 0.008 | AB33: =K33-J33 -> 0.003 | ... AF33: =O33-N33 -> 0.024
D35: Výměna elektroměru DŮM
D36: 43956 | E36: starý | O36: spotřeba SV byt č.3 pro vyúčt. | P36: =P8-P32-P33 -> 68.348
E37: nový | O37: spotřeba SV sklad č.11 pro vyúčt. | P37: =P32+P33 -> 5.796
D38: Výměna elektroměru AREÁL | O38: CELKEM : | P38: =SUM(P36:P37) -> 74.144
D39: 43956 | E39: starý
E40: nový | J40: Dne 31.7.2023 odpojen kalor. (cejchování), | N40: stav: | O40: 234.86 | P40: MWh
J41: Dne 3.8.2023 zapojen znovuzapojení, | N41: stav: | O41: 0 | P41: GJ
D42: Výměna vodoměru ZAHRADA | G42: Příští výměna 2026
D43: 43874 | E43: starý | F43: 10282180 | H43: 655.348
...

Sheet 1854
A2: 1854 | C2: ='1850'!C2 -> 45292 | D2: ='1850'!D2 -> 45323 | E2: ='1850'!E2 -> 45352 | F2: ='1850'!F2 -> 45383 | G2: ='1850'!G2 -> 45413 | H2: ='1850'!H2 -> 45444 | I2: ='1850'!I2 -> 45474 | J2: ='1850'!J2 -> 45505 | ... O2: ='1850'!O2 -> 45658 | P2: voda | Q2: teplo | R2: Elektr | Y2: spotřeby po měsících
A3: byt č. | C3: prosinec | D3: leden | E3: únor | F3: březen | G3: duben | H3: květen | I3: červen | J3: červenec | K3: srpen | L3: září | M3: říjen | N3: listopad | O3: prosinec | P3: m3 | Q3: GJ | R3: KWh | T3: byt | U3: leden | V3: únor | W3: březen | X3: duben | Y3: květen | Z3: červen | AA3: červenec | AB3: srpen | AC3: září | AD3: říjen | AE3: listopad | AF3: prosinec
A4: 1 | B4: vodoměr č. 190906992 | C4: 325.996 | D4: 328.527 | E4: 331.037 | F4: 333.661 | G4: 336.396 | H4: 339.073 | I4: 341.338 | J4: 343.28 | K4: 345.066 | L4: 347.737 | M4: 349.905 | N4: 352.01 | O4: 2.875 | P4: =O4+N4-C4 -> 28.889 | T4: 1 | U4: =D4-C4 -> 2.531 | V4: =E4-D4 -> 2.51 | W4: =F4-E4 -> 2.624 | X4: =G4-F4 -> 2.735 | Y4: =H4-G4 -> 2.677 | Z4: =I4-H4 -> 2.265 | AA4: =J4-I4 -> 1.942 | AB4: =K4-J4 -> 1.786 | ... AE4: =N4-M4 -> 2.105 | AF4: =O4 -> 2.875
B5: kalorimetr č. 71182259 | C5: 50.515 | D5: 54.441 | E5: 57.165 | F5: 59.376 | G5: 60.59 | H5: 60.859 | I5: 61.069 | J5: 61.252 | K5: 61.419 | L5: 61.639 | M5: 62.884 | N5: 65.735 | O5: 69.398 | Q5: =O5-C5 -> 18.883
A6: 2 | B6: vodoměr č. 190906991 | C6: 266.566 | D6: 272.14 | E6: 276.014 | F6: 282.535 | G6: 287.058 | H6: 293.768 | I6: 299.902 | J6: 305.205 | K6: 310.877 | L6: 317.434 | M6: 324.256 | N6: 329.88 | O6: 5.8 | P6: =O6+N6-C6 -> 69.114 | T6: 2 | U6: =D6-C6 -> 5.574 | V6: =E6-D6 -> 3.874 | W6: =F6-E6 -> 6.521 | X6: =G6-F6 -> 4.523 | Y6: =H6-G6 -> 6.71 | Z6: =I6-H6 -> 6.134 | AA6: =J6-I6 -> 5.303 | AB6: =K6-J6 -> 5.672 | ... AE6: =N6-M6 -> 5.624 | AF6: =O6 -> 5.8
B7: kalorimetr č. 71182248 | C7: 72.397 | D7: 78.843 | E7: 82.657 | F7: 85.796 | G7: 87.629 | H7: 88.355 | I7: 88.922 | J7: 89.268 | K7: 89.623 | L7: 90.049 | M7: 92.237 | N7: 96.864 | O7: 102.543 | Q7: =O7-C7 -> 30.146
A8: 3 | B8: vodoměr č. 190906988 | C8: 349.848 | D8: 354.799 | E8: 359.792 | F8: 366.148 | G8: 371.5 | H8: 376.717 | I8: 382.853 | J8: 388.634 | K8: 394.888 | L8: 399.738 | M8: 404.987 | N8: 409.11 | O8: 5.638 | P8: =O8+N8-C8 -> 64.9 | T8: 3 | U8: =D8-C8 -> 4.951 | V8: =E8-D8 -> 4.993 | W8: =F8-E8 -> 6.356 | X8: =G8-F8 -> 5.352 | Y8: =H8-G8 -> 5.217 | Z8: =I8-H8 -> 6.136 | AA8: =J8-I8 -> 5.781 | AB8: =K8-J8 -> 6.254 | ... AE8: =N8-M8 -> 4.123 | AF8: =O8 -> 5.638
B9: kalorimetr č. 71182258 | C9: 80.77 | D9: 87.89 | E9: 93.204 | F9: 97.842 | G9: 100.887 | H9: 101.548 | I9: 101.867 | J9: 102.116 | K9: 102.34 | L9: 102.802 | M9: 105.44 | N9: 111.102 | O9: 117.96 | Q9: =O9-C9 -> 37.19
A10: 4 | B10: vodoměr č. 190906987 | C10: 331.89 | D10: 339.344 | E10: 347.045 | F10: 355.69 | G10: 363.038 | H10: 370.42 | I10: 377.378 | J10: 384.552 | K10: 391.386 | L10: 397.758 | M10: 403.506 | N10: 409.56 | O10: 7.666 | P10: =O10+N10-C10 -> 85.336 | T10: 4 | U10: =D10-C10 -> 7.454 | V10: =E10-D10 -> 7.701 | W10: =F10-E10 -> 8.645 | X10: =G10-F10 -> 7.348 | Y10: =H10-G10 -> 7.382 | Z10: =I10-H10 -> 6.958 | AA10: =J10-I10 -> 7.174 | AB10: =K10-J10 -> 6.834 | ... AE10: =N10-M10 -> 6.054 | AF10: =O10 -> 7.666
B11: kalorimetr č. 71182242 | C11: 24.163 | D11: 25.936 | E11: 26.626 | F11: 27.158 | G11: 27.634 | H11: 28.091 | I11: 28.477 | J11: 28.838 | K11: 29.138 | L11: 29.475 | M11: 29.784 | N11: 30.647 | O11: 31.658 | Q11: =O11-C11 -> 7.495
A12: 5 | B12: vodoměr č. 221525395 | C12: 0.643 | D12: 0.76 | E12: 1.014 | F12: 1.059 | G12: 1.216 | H12: 1.248 | I12: 1.474 | J12: 1.523 | K12: 1.551 | L12: 1.579 | M12: 1.851 | N12: 1.851 | O12: 0.057 | P12: =O12+N12-C12 -> 1.265 | T12: 5 | U12: =D12-C12 -> 0.117 | V12: =E12-D12 -> 0.254 | W12: =F12-E12 -> 0.045 | X12: =G12-F12 -> 0.157 | Y12: =H12-G12 -> 0.032 | Z12: =I12-H12 -> 0.226 | AA12: =J12-I12 -> 0.049 | AB12: =K12-J12 -> 0.028 | ... AE12: =N12-M12 -> 0 | AF12: =O12 -> 0.057
B13: kalorimetr č. 71182255 | C13: 6.71 | D13: 6.712 | E13: 6.714 | F13: 6.715 | G13: 6.717 | H13: 6.717 | I13: 6.723 | J13: 6.724 | K13: 6.726 | L13: 6.726 | M13: 6.728 | N13: 6.729 | O13: 6.73 | Q13: =O13-C13 -> 0.02
A14: 6 | B14: vodoměr č. 190906994 | C14: 424.951 | D14: 435.33 | E14: 442.197 | F14: 449.43 | G14: 457.981 | H14: 468.467 | I14: 477.96 | J14: 481.304 | K14: 490.841 | L14: 506.766 | M14: 520.373 | N14: 534 | O14: 14.895 | P14: =O14+N14-C14 -> 123.944 | T14: 6 | U14: =D14-C14 -> 10.379 | V14: =E14-D14 -> 6.867 | W14: =F14-E14 -> 7.233 | X14: =G14-F14 -> 8.551 | Y14: =H14-G14 -> 10.486 | Z14: =I14-H14 -> 9.493 | AA14: =J14-I14 -> 3.344 | AB14: =K14-J14 -> 9.537 | ... AE14: =N14-M14 -> 13.627 | AF14: =O14 -> 14.895
B15: kalorimetr č. 71182230 | C15: 21.9 | D15: 23.801 | E15: 24.465 | F15: 24.875 | G15: 25.422 | H15: 25.996 | I15: 26.459 | J15: 26.702 | K15: 27.234 | L15: 28.276 | M15: 29.355 | N15: 31.671 | O15: 34.229 | Q15: =O15-C15 -> 12.329
A16: 7 | B16: vodoměr č. 190906986 | C16: 141.492 | D16: 142.585 | E16: 144.777 | F16: 147.672 | G16: 150.358 | H16: 153.847 | I16: 157.334 | J16: 160.635 | K16: 163.871 | L16: 167.234 | M16: 171.713 | N16: 175.46 | O16: 4.367 | P16: =O16+N16-C16 -> 38.335 | T16: 7 | U16: =D16-C16 -> 1.093 | V16: =E16-D16 -> 2.192 | W16: =F16-E16 -> 2.895 | X16: =G16-F16 -> 2.686 | Y16: =H16-G16 -> 3.489 | Z16: =I16-H16 -> 3.487 | AA16: =J16-I16 -> 3.301 | AB16: =K16-J16 -> 3.236 | ... AE16: =N16-M16 -> 3.747 | AF16: =O16 -> 4.367
B17: kalorimetr č. 71182247 | C17: 15.669 | D17: 16.387 | E17: 17.358 | F17: 18.012 | G17: 18.427 | H17: 18.888 | I17: 19.314 | J17: 19.696 | K17: 20.04 | L17: 20.436 | M17: 20.959 | N17: 22.435 | O17: 24.471 | Q17: =O17-C17 -> 8.802
A18: 8 | B18: vodoměr č. 191519281 | C18: 322.8 | D18: 328.711 | E18: 333.853 | F18: 339.466 | G18: 344.969 | H18: 352.462 | I18: 358.678 | J18: 365.297 | K18: 371.626 | L18: 378.725 | M18: 384.749 | N18: 389.9 | O18: 6.421 | P18: =O18+N18-C18 -> 73.521 | T18: 8 | U18: =D18-C18 -> 5.911 | V18: =E18-D18 -> 5.142 | W18: =F18-E18 -> 5.613 | X18: =G18-F18 -> 5.503 | Y18: =H18-G18 -> 7.493 | Z18: =I18-H18 -> 6.216 | AA18: =J18-I18 -> 6.619 | AB18: =K18-J18 -> 6.329 | ... AE18: =N18-M18 -> 5.151 | AF18: =O18 -> 6.421
B19: kalorimetr č. 71182232 | C19: 57.194 | D19: 62.948 | E19: 66.594 | F19: 69.307 | G19: 70.506 | H19: 70.839 | I19: 71.097 | J19: 71.297 | K19: 71.464 | L19: 71.702 | M19: 73.36 | N19: 77.601 | O19: 82.638 | Q19: =O19-C19 -> 25.444
A20: 9 | B20: vodoměr č. 190906990 | C20: 602.928 | D20: 614.188 | E20: 624.109 | F20: 636.758 | G20: 646.045 | H20: 656.683 | I20: 668.582 | J20: 679.059 | K20: 691.88 | L20: 704.331 | M20: 715.417 | N20: 727.64 | O20: 12.707 | P20: =O20+N20-C20 -> 137.419 | T20: 9 | U20: =D20-C20 -> 11.26 | V20: =E20-D20 -> 9.921 | W20: =F20-E20 -> 12.649 | X20: =G20-F20 -> 9.287 | Y20: =H20-G20 -> 10.638 | Z20: =I20-H20 -> 11.899 | AA20: =J20-I20 -> 10.477 | AB20: =K20-J20 -> 12.821 | ... AE20: =N20-M20 -> 12.223 | AF20: =O20 -> 12.707
